File: tensile_test_ontology_TTO/data/primary_data/Zd2.csv
Time;Crosshead travel;Force;Strain
(s);(mm);(kN);(%)
0;0;0,27944;0
1,012;0,0526;0,97428;0,002627451
1,698;0,1644;20,135;0,00682338
2,318;0,32556;283,667;0,010140162
2,808;0,48476;376,721;0,01428614
3,168;0,61616;48,996;0,01884172
3,474;0,73472;605,105;0,023617087
3,724;0,83456;720,381;0,028532318
3,944;0,92408;835,185;0,033097888
4,164;101,424;955,725;0,038142994
4,366;109,744;1,069,998;0,042598671
4,564;117,896;1,185,937;0,047493921
4,762;12,604;1,302,998;0,05231924
4,96;134,156;1,421,609;0,057354355
5,158;142,256;1,540,785;0,062129722
5,356;150,312;1,661,499;0,06727473
5,554;158,336;1,782,629;0,072110039
5,752;166,344;1,905,107;0,077295008
5,95;174,284;2,026,814;0,082180269
6,148;18,218;2,149,157;0,087355248
6,346;190,032;2,271,026;0,092480276
6,542;197,756;2,392,189;0,097535371
6,74;20,552;2,513,959;0,102580476
6,938;213,208;2,635,756;0,10789532
7,136;220,832;2,756,358;0,113000367
7,334;228,368;2,876,936;0,11829523
7,532;235,816;2,995,898;0,123560122
7,73;24,322;3,115,616;0,128785053
7,928;250,472;3,232,309;0,134099896
8,126;257,652;334,877;0,139614546
8,324;264,716;346,371;0,145119205
8,522;271,656;3,575,858;0,150843651
8,726;278,656;3,689,773;0,156727943
8,942;285,916;3,807,068;0,163251613
9,162;29,308;3,922,177;0,170074993
9,39;300,272;4,036,474;0,177138141
9,632;30,766;4,151,338;0,184391104
9,89;315,172;4,264,595;0,193202555
10,186;32,322;4,379,208;0,203962116
10,556;332,232;4,492,551;0,217538944
11,312;3,472;4,591,158;0,245631688
12,412;358,136;460,267;0,288709894
13,498;364,448;4,641,825;0,315713695
14,598;369,656;4,660,209;0,34514514
15,698;374,516;4,687,851;0,373137982
16,798;378,956;4,711,738;0,400211715
17,898;383,924;4,745,263;0,427635108
18,998;387,776;4,755,607;0,455827756
20,098;391,604;4,773,726;0,483810607
21,198;39,514;4,789,442;0,511044185
22,298;398,476;4,800,249;0,53881724
23,398;402,204;4,811,807;0,56776915
24,498;404,816;4,810,012;0,594583135
25,598;407,432;4,811,224;0,622575977
26,698;409,788;4,810,036;0,650129245
27,798;411,968;4,807,821;0,677752445
28,898;41,408;4,807,762;0,705745286
29,998;415,908;4,801,922;0,732968874
31,098;417,764;480,039;0,760652015
32,198;419,488;4,797,593;0,787915564
33,298;421,192;4,794,626;0,81573857
34,398;422,852;479,342;0,843151974
35,498;424,484;4,792,134;0,870565377
36,598;426,124;4,792,292;0,8979588
37,698;427,736;479,158;0,925761826
38,798;429,352;4,792,533;0,953055346
39,898;430,936;4,791,903;0,980658565
40,998;432,468;479,111;100,780,223
42,098;4,34;4,789,644;1,035,465,391
43,198;435,544;4,790,162;1,062,818,853
44,298;437,036;4,788,595;1,090,172,315
45,398;438,516;4,787,532;1,117,405,893
46,498;440,048;4,787,662;1,145,378,754
47,598;441,524;4,787,478;1,172,642,302
48,698;443,028;4,788,789;1,200,115,648
49,798;444,532;478,938;1,227,658,925
50,898;446,044;4,791,035;1,254,892,503
51,998;447,512;4,789,509;1,282,525,694
53,098;448,972;4,788,286;1,310,078,961
54,198;450,364;4,784,024;1,337,632,229
55,298;45,166;4,775,887;1,365,095,584
56,398;453,076;4,773,728;1,392,828,678
57,498;454,548;47,752;1,419,922,391
58,598;456,148;4,783,825;1,447,036,086
59,698;457,836;479,493;1,474,339,596
60,798;459,636;4,808,772;1,501,713,038
61,898;461,424;4,820,592;1,528,826,732
62,998;46,334;483,395;1,556,100,272
64,098;465,284;4,844,965;1,583,333,849
65,198;467,404;4,856,232;1,610,927,079
6,629,801;469,972;4,863,097;163,891,992
67,398;472,296;4,878,509;1,665,504,128
68,498;474,608;488,698;169,285,759
69,598;477,088;4,897,722;1,720,370,896
7,069,801;479,656;4,907,749;1,747,984,106
7,179,801;482,196;4,915,566;1,774,977,916
72,898;4,849;4,925,843;1,802,311,397
73,998;487,652;4,934,374;1,829,814,714
7,509,801;490,456;4,944,787;1,856,958,379
7,619,801;49,336;4,955,428;188,462,154
7,729,801;496,268;4,964,835;1,912,114,866
78,398;499,216;4,974,913;1,939,518,279
79,498;502,164;4,983,937;1,966,901,712
8,059,801;505,204;4,994,027;1,994,694,747
8,169,801;508,112;5,001,547;2,021,558,684
8,278,401;511,652;5,013,963;2,049,581,496
83,884;51,454;5,022,483;2,076,405,471
84,984;517,512;5,032,318;2,103,708,982
8,608,401;520,556;5,042,655;2,131,242,269
8,718,401;52,354;5,050,712;2,158,795,537
8,828,401;526,532;5,060,565;2,186,158,989
89,384;529,528;5,070,111;2,213,532,431
90,484;532,568;5,079,604;224,112,566
9,158,401;535,584;5,089,013;2,268,449,151
9,268,401;538,612;5,098,358;2,296,112,312
9,378,401;541,592;5,106,811;232,335,588
94,884;54,462;5,116,295;2,350,729,322
95,984;547,616;5,124,243;2,378,072,794
9,708,401;551,284;5,137,386;2,406,585,131
9,818,401;55,416;5,142,901;2,433,229,281
9,928,401;557,148;5,150,862;2,460,622,704
100,384;560,164;5,159,513;2,487,976,166
101,484;563,196;5,167,859;2,515,299,656
10,258,401;566,228;5,176,437;2,542,912,866
10,368,401;56,926;5,185,369;2,570,086,502
10,478,401;572,368;5,193,717;2,597,839,576
105,884;5,754;5,202,084;2,625,302,931
10,698,401;578,468;5,210,436;2,652,866,189
10,808,401;58,152;5,218,886;2,680,309,564
10,918,401;584,608;52,277;2,708,082,618
11,028,401;587,616;5,234,731;2,735,296,216
111,384;591,304;5,257,367;2,761,970,336
11,248,401;59,402;5,248,839;2,789,873,265
11,358,401;597,068;5,259,377;2,817,466,494
11,468,401;600,048;526,647;2,845,009,772
11,578,401;60,308;527,527;2,872,513,088
116,884;60,606;528,159;2,899,846,569
11,798,401;60,908;5,290,059;2,927,449,788
11,908,401;61,204;5,295,681;2,954,913,143
12,018,401;615,056;5,304,471;298,210,676
12,128,401;618,064;5,311,438;3,009,949,747
122,384;621,032;5,318,982;3,037,163,344
12,348,401;624,084;532,698;3,064,896,437
12,458,401;627,084;5,334,231;3,092,369,783
12,568,401;630,608;5,355,299;3,118,254,669
12,678,401;633,392;5,346,732;3,147,236,551
127,884;636,404;5,355,781;3,175,189,431
12,898,401;639,252;5,360,897;3,201,843,571
130,084;642,292;5,370,424;3,229,476,762
131,184;645,264;5,375,655;325,704,002
13,228,402;648,224;5,382,649;3,284,383,491
133,384;651,252;5,389,321;3,312,046,652
13,448,402;65,424;5,395,473;3,339,440,075
135,584;657,232;5,401,805;336,689,344
136,684;660,236;5,409,198;3,394,146,999
13,778,402;663,284;5,415,711;3,421,790,179
138,884;666,296;5,422,058;3,449,173,612
13,998,402;669,836;5,442,509;3,474,628,915
141,084;672,704;5,432,294;3,504,200,225
142,184;67,576;5,441,468;3,531,813,435
14,328,402;678,752;5,447,274;3,559,057,003
144,384;681,816;5,454,728;3,586,500,377
14,548,402;684,872;5,459,696;3,613,963,732
146,584;68,796;5,466,253;3,641,457,058
147,684;69,106;5,471,988;3,668,630,695
14,878,402;694,204;5,477,875;3,696,193,953
149,884;697,296;5,482,867;3,723,547,414
15,098,402;700,436;5,489,571;3,750,761,012
152,084;70,364;549,494;3,778,504,095
153,184;706,816;5,500,886;3,805,877,538
15,428,402;71,054;5,518,694;3,832,721,494
155,384;71,346;5,510,411;3,861,143,918
15,648,402;716,576;5,517,007;3,888,617,264
157,41;717,948;5,488,909;3,905,660,728
15,851,002;72,012;5,507,869;3,922,394,493
159,61;722,316;5,514,718;3,941,286,164
160,71;724,504;5,519,537;3,960,227,787
16,181,002;726,704;5,523,998;3,979,289,294
162,91;728,904;5,527,867;3,998,610,548
16,401,002;731,104;5,531,693;4,017,672,055
165,11;733,308;5,536,044;4,036,843,454
166,21;7,355;5,539,389;4,055,904,961
16,731,002;7,377;5,543,553;4,075,136,303
168,41;73,992;5,547,834;409,454,747
188,358;74,156;541,398;-0,004955192
189,458;743,732;5,499,201;-0,004975173
19,055,802;745,924;5,545,397;-0,004975173
191,658;748,128;5,562,233;-0,004995154
19,275,802;75,032;5,569,142;-0,005065086
193,858;75,252;5,573,508;-0,005035115
194,958;754,732;557,672;-0,005035115
19,605,802;756,944;5,580,072;-0,005085066
197,158;759,132;5,583,094;-0,005115037
19,825,802;761,332;5,586,173;-0,005125028
19,935,802;763,528;5,589,458;-0,005125028
200,458;76,574;5,593,485;-0,005125028
20,155,802;76,794;5,596,336;-0,005135018
202,658;77,012;5,599,621;-0,005145008
20,375,802;77,232;5,603,259;-0,00519496
20,485,802;77,452;5,606,514;-0,00520495
205,958;776,716;5,609,833;-0,005164989
20,705,802;778,924;5,613,893;-0,00519496
208,158;78,112;5,616,602;-0,00518497
20,925,802;783,324;5,620,272;-0,005244911
21,035,802;785,524;5,623,554;-0,005264892
211,458;787,716;5,626,828;-0,005244911
21,255,802;789,912;5,630,319;-0,005234921
213,658;792,112;5,634,246;-0,005254902
21,475,802;794,316;5,637,291;-0,005274882
21,585,802;79,652;5,640,741;-0,005264892
216,958;798,732;5,643,994;-0,005274882
21,805,802;800,924;5,646,957;-0,005264892
219,158;80,312;565,029;-0,005264892
22,025,802;805,332;5,654,284;-0,005244911
22,135,802;807,524;5,656,959;-0,005314844
222,458;80,972;5,660,304;-0,005274882
22,355,802;811,928;5,664,018;-0,005284873
224,658;81,412;5,666,716;-0,005304853
22,575,802;816,328;5,670,041;-0,005314844
22,685,802;818,536;5,673,577;-0,005284873
227,958;820,732;5,676,445;-0,005334824
22,905,802;822,928;5,679,722;-0,005304853
230,158;825,136;5,683,191;-0,005314844
23,125,802;82,732;5,686,039;-0,005344814
23,235,802;829,516;5,688,811;-0,005334824
233,458;831,724;5,692,512;-0,005334824
23,455,802;83,392;5,695,415;-0,005364795
235,658;836,116;569,864;-0,005314844
23,675,802;838,328;5,701,991;-0,005374785
23,785,802;840,516;5,704,467;-0,005374785
238,958;842,716;5,707,647;-0,005404756
24,005,802;844,932;5,711,107;-0,005374785
241,158;847,124;5,713,937;-0,005374785
24,225,802;84,932;5,716,633;-0,005384776
24,335,802;851,528;5,720,037;-0,005354805
244,458;853,712;5,722,746;-0,005424737
24,555,802;8,559;5,725,413;-0,005424737
246,658;85,812;5,728,833;-0,005394766
24,775,802;860,308;5,731,544;-0,005424737
24,885,802;862,504;5,734,258;-0,005414747
249,958;864,712;5,737,456;-0,005424737
25,105,802;8,669;574,033;-0,005424737
252,158;869,096;5,743,337;-0,005414747
25,325,802;871,324;5,746,466;-0,005454708
25,435,802;873,504;574,867;-0,005414747
255,458;875,696;5,751,623;-0,005424737
25,655,802;877,904;5,754,951;-0,005414747
25,765,802;880,096;5,757,618;-0,005424737
25,875,803;882,284;5,760,112;-0,005414747
259,858;884,508;576,356;-0,005444718
260,958;886,704;5,766,226;-0,005414747
26,205,802;888,908;5,768,652;-0,005434727
26,315,803;891,108;5,771,315;-0,005424737
26,425,803;893,308;5,774,217;-0,005464698
265,358;895,508;5,777,141;-0,005414747
266,458;897,724;5,780,135;-0,005444718
267,558;8,999;5,781,828;-0,005444718
26,865,803;902,096;5,785,041;-0,005444718
26,975,803;904,312;5,787,745;-0,005434727
270,858;906,512;5,790,358;-0,005444718
271,958;9,087;5,792,884;-0,005454708
273,058;910,912;5,795,691;-0,005454708
27,415,803;913,116;5,798,461;-0,005484679
27,525,803;915,312;5,800,921;-0,005484679
276,358;917,512;5,803,069;-0,005494669
277,458;919,712;5,805,984;-0,005464698
278,558;921,916;5,808,486;-0,005474688
27,965,803;92,412;581,108;-0,00551465
28,075,803;92,632;5,813,583;-0,005484679
281,858;928,516;5,816,258;-0,005484679
282,958;93,072;5,818,489;-0,005504659
284,058;932,912;5,821,176;-0,005484679
28,515,803;935,112;5,823,495;-0,005484679
28,625,803;93,732;5,826,251;-0,005544621
287,358;93,952;5,828,612;-0,005474688
288,458;941,704;5,830,866;-0,00551465
289,558;9,439;5,833,206;-0,005484679
29,065,803;946,104;5,836,132;-0,005494669
29,175,803;9,483;5,838,296;-0,005564601
292,858;950,496;5,840,427;-0,00551465
293,958;952,704;5,843,096;-0,00551465
295,058;954,896;5,845,447;-0,005564601
29,615,803;957,092;5,847,647;-0,00552464
29,725,803;959,288;5,850,089;-0,00553463
298,358;961,492;585,278;-0,005544621
299,458;963,692;5,854,851;-0,00553463
300,558;965,896;5,857,134;-0,00553463
30,165,803;968,096;5,859,203;-0,00552464
30,275,803;970,296;5,861,463;-0,005544621
303,858;972,496;5,863,738;-0,005554611
304,958;974,708;5,866,454;-0,00552464
306,058;976,904;5,868,284;-0,005544621
30,715,803;9,791;5,870,403;-0,00551465
30,825,803;981,304;5,872,843;-0,005584582
309,358;983,496;5,874,638;-0,005554611
310,458;985,692;5,876,889;-0,005584582
311,558;987,908;5,879,706;-0,005584582
31,265,803;990,108;588,142;-0,005564601
31,375,803;9,923;5,883,523;-0,005554611
314,858;994,512;5,886,127;-0,00553463
315,958;996,696;5,887,681;-0,005554611
317,058;998,896;5,889,887;-0,00553463
31,815,803;1,001,124;5,892,582;-0,005564601
31,925,803;100,332;5,893,882;-0,005564601
320,358;1,005,508;5,895,913;-0,005564601
321,458;1,007,724;5,898,286;-0,005544621
322,558;1,009,908;5,900,077;-0,005614553
32,365,803;10,121;5,902,005;-0,005584582
32,475,803;1,014,308;5,904,701;-0,005624543
325,858;1,016,508;5,906,416;-0,005604562
326,958;1,018,708;5,908,619;-0,005614553
328,058;1,020,916;5,910,747;-0,005554611
32,915,803;1,023,104;591,265;-0,00551465
33,025,803;1,025,304;5,914,289;-0,005564601
331,358;1,027,528;5,917,003;-0,005594572
332,458;1,029,716;5,918,405;-0,005574592
333,558;103,188;5,920,157;-0,005584582
33,465,803;1,034,096;5,922,619;-0,005564601
33,575,803;1,036,304;5,924,587;-0,005594572
336,858;1,038,496;5,926,391;-0,005574592
337,958;1,040,712;5,928,597;-0,005614553
339,058;1,042,904;593,001;-0,005564601
34,015,803;1,045,096;5,931,802;-0,005594572
34,125,803;10,473;5,934,317;-0,005584582
342,358;1,049,488;5,936,108;-0,005614553
343,458;1,051,684;5,937,966;-0,005584582
344,558;10,539;5,940,208;-0,005544621
34,565,803;1,056,096;5,941,898;-0,005544621
34,675,803;1,058,292;5,943,384;-0,005604562
347,858;10,605;5,945,624;-0,00553463
348,958;1,062,692;5,947,361;-0,005604562
350,058;106,488;5,948,964;-0,005594572
35,115,803;1,067,092;5,951,002;-0,005564601
35,225,803;1,069,292;5,952,684;-0,005584582
353,358;1,071,488;5,954,173;-0,005594572
354,458;1,073,692;595,614;-0,005604562
355,558;1,075,892;5,958,034;-0,005604562
35,665,803;1,078,084;5,959,896;-0,005584582
35,775,803;1,080,296;5,961,798;-0,005584582
35,885,803;1,082,492;5,963,445;-0,005594572
359,958;1,084,688;5,965,071;-0,005634533
361,058;1,086,892;5,966,743;-0,005564601
36,215,803;10,891;5,968,682;-0,005584582
36,325,803;1,091,288;5,970,199;-0,005614553
36,435,803;1,093,496;597,196;-0,005634533
365,458;1,095,696;5,973,635;-0,005614553
366,558;1,097,892;5,975,325;-0,005644524
36,765,803;1,100,092;5,976,708;-0,005614553
36,875,803;11,023;5,978,387;-0,005644524
36,985,803;1,104,496;5,980,117;-0,005634533
370,958;1,106,708;5,981,754;-0,005614553
372,058;1,108,908;5,983,323;-0,005644524
37,315,803;1,111,092;5,984,762;-0,005594572
37,425,803;1,113,292;5,986,304;-0,005624543
37,535,803;1,115,488;5,988,356;-0,005654514
376,458;1,117,684;5,989,853;-0,005664504
377,558;1,119,888;5,991,579;-0,005664504
37,865,803;1,122,096;5,993,344;-0,005624543
37,975,803;1,124,292;5,995,044;-0,005664504
38,085,803;1,126,488;5,996,209;-0,005644524
381,958;1,128,684;5,998,089;-0,005624543
383,058;11,309;5,999,807;-0,005674495
38,415,803;1,133,108;6,001,297;-0,005644524
38,525,803;11,353;6,002,386;-0,005674495
38,635,803;1,137,496;6,004,063;-0,005674495
387,458;1,139,696;6,005,479;-0,005644524
388,558;1,141,892;6,007,085;-0,005654514
38,965,803;1,144,092;6,009,066;-0,005634533
39,075,803;1,146,292;6,010,399;-0,005664504
39,185,803;1,148,492;6,011,901;-0,005654514
392,958;1,150,696;6,013,446;-0,005664504
394,058;1,152,888;6,014,486;-0,005694475
39,515,803;1,155,092;6,015,908;-0,005614553
39,625,803;115,732;6,018,225;-0,005644524
39,735,803;1,159,508;6,018,873;-0,005664504
398,458;116,168;6,019,467;-0,005674495
399,558;1,163,884;6,022,243;-0,005674495
40,065,803;1,166,084;6,023,559;-0,005674495
40,175,803;1,168,284;602,464;-0,005654514
40,285,803;1,170,492;6,026,286;-0,005704466
403,958;1,172,688;6,027,389;-0,005684485
405,058;1,174,888;6,028,921;-0,005674495
40,615,803;1,177,096;6,030,654;-0,005644524
40,725,803;1,179,284;6,031,725;-0,005674495
40,835,803;1,181,476;6,032,835;-0,005704466
409,458;1,183,696;6,034,697;-0,005664504
410,558;1,185,884;6,035,585;-0,005664504
41,165,803;118,808;60,369;-0,005674495
41,275,803;11,903;603,878;-0,005704466
41,385,803;1,192,488;6,039,675;-0,005684485
414,958;119,468;6,040,729;-0,005684485
416,058;1,196,892;6,042,869;-0,005684485
41,715,803;1,199,088;604,381;-0,005654514
41,825,803;1,201,284;6,045,124;-0,005714456
41,935,803;1,203,492;6,046,409;-0,005664504
420,458;1,205,684;6,047,767;-0,005724446
421,558;1,207,888;6,048,895;-0,005724446
42,265,803;1,210,096;6,050,442;-0,005694475
42,375,803;1,212,288;6,051,326;-0,005704466
42,485,803;121,448;6,052,925;-0,005704466
425,958;1,216,692;6,054,484;-0,005704466
427,058;1,218,876;6,055,485;-0,005734436
42,815,803;1,221,072;6,056,424;-0,005674495
42,925,803;1,223,284;6,058,299;-0,005704466
43,035,803;122,548;605,915;-0,005714456
431,458;1,227,676;6,060,261;-0,005754417
432,558;1,229,888;6,061,803;-0,005744427
43,365,803;1,232,076;6,063,043;-0,005714456
43,475,803;1,234,276;6,064,016;-0,005754417
43,585,803;1,236,496;6,065,657;-0,005734436
436,958;12,387;6,066,665;-0,005784388
438,058;1,240,888;606,754;-0,005774398
43,915,803;1,243,096;6,069,043;-0,005734436
44,025,803;1,245,288;6,070,122;-0,005774398
44,135,803;1,247,472;6,071,329;-0,005764407
442,458;1,249,688;6,072,516;-0,005784388
443,558;1,251,888;6,073,583;-0,005764407
44,465,803;125,408;6,074,473;-0,005764407
44,575,803;1,256,284;6,075,652;-0,005804369
44,685,803;125,848;6,076,702;-0,005804369
447,958;1,260,672;6,078,033;-0,005774398
449,058;1,262,892;6,079,368;-0,005764407
45,015,803;1,265,092;608,041;-0,005774398
45,125,803;1,267,272;6,081,156;-0,005744427
45,235,803;126,948;6,082,439;-0,005774398
453,458;1,271,688;6,083,622;-0,005754417
454,558;1,273,868;6,084,455;-0,005754417
45,565,803;1,276,072;6,085,601;-0,005724446
45,675,803;1,278,288;6,087,472;-0,005714456
45,785,803;128,048;6,087,973;-0,005744427
458,958;1,282,684;6,088,902;-0,005764407
460,058;1,284,884;6,090,186;-0,005764407
46,115,803;1,287,084;6,091,359;-0,005714456
46,225,803;1,289,304;6,092,257;-0,005774398
46,335,803;1,291,488;6,092,975;-0,005744427
464,458;1,293,668;6,093,989;-0,005744427
465,558;1,295,872;6,095,366;-0,005764407
46,665,803;129,808;6,096,416;-0,005744427
46,775,803;130,028;609,737;-0,005774398
46,885,803;1,302,484;609,809;-0,005744427
469,958;1,304,688;6,099,449;-0,005744427
471,058;1,306,888;6,100,353;-0,005784388
47,215,803;1,309,084;6,101,054;-0,005714456
47,325,803;1,311,276;6,102,172;-0,005794378
47,435,803;1,313,492;6,103,811;-0,005774398
475,458;1,315,688;6,104,049;-0,005754417
476,558;1,317,888;61,05;-0,005784388
47,765,803;1,320,092;6,106,315;-0,005754417
47,875,803;1,322,284;6,107,005;-0,005784388
47,985,803;1,324,476;6,107,848;-0,005764407
480,958;1,326,688;6,109,464;-0,005754417
482,058;132,888;6,110,353;-0,005774398
48,315,803;1,331,084;6,111,117;-0,005744427
48,425,803;1,333,284;6,112,539;-0,005724446
48,535,803;1,335,476;6,112,776;-0,005784388
48,645,803;1,337,676;6,113,827;-0,005754417
487,558;1,339,888;6,115,143;-0,005794378
48,865,803;134,208;6,115,593;-0,005764407
48,975,803;1,344,276;6,116,483;-0,005744427
49,085,803;1,346,484;6,117,939;-0,005754417
49,195,803;1,348,672;6,118,491;-0,005734436
493,058;135,086;6,119,193;-0,005784388
49,415,803;1,353,076;6,120,369;-0,005724446
49,525,803;1,355,264;612,086;-0,005764407
49,635,803;1,357,468;6,121,794;-0,005734436
49,745,803;1,359,676;6,123,067;-0,005734436
498,558;1,361,864;6,123,515;-0,005784388
49,965,803;136,406;6,124,384;-0,005744427
50,075,803;1,366,284;6,125,816;-0,005724446
50,185,803;136,848;6,126,171;-0,005784388
50,295,803;137,068;6,126,844;-0,005744427
504,058;1,372,888;6,128,027;-0,005724446
50,515,803;1,375,076;6,128,675;-0,005724446
50,625,803;1,377,268;612,927;-0,005704466
50,735,803;1,379,484;6,130,825;-0,005784388
50,845,803;138,168;6,130,933;-0,005784388
509,558;1,383,876;6,131,833;-0,005724446
51,065,803;1,386,092;6,132,851;-0,005764407
51,175,803;138,828;6,133,373;-0,005754417
51,285,803;1,390,464;613,414;-0,005764407
513,958;1,392,692;6,135,836;-0,005774398
51,505,803;1,394,896;6,136,154;-0,005764407
51,615,803;1,397,076;6,136,637;-0,005774398
517,258;1,399,288;6,137,261;-0,005754417
51,835,803;1,401,488;6,138,291;-0,005774398
519,458;1,403,676;6,138,571;-0,005764407
52,055,803;1,405,888;613,979;-0,005774398
52,165,803;1,408,088;6,140,522;-0,005744427
522,758;1,410,288;6,141,302;-0,005774398
52,385,803;14,125;6,142,164;-0,005774398
524,958;1,414,688;6,142,695;-0,005744427
52,605,806;1,416,888;6,143,138;-0,005754417
527,158;1,419,112;6,144,442;-0,005804369
528,258;1,421,312;6,144,787;-0,005744427
52,935,806;1,423,476;6,144,965;-0,005764407
530,458;142,568;6,146,251;-0,005754417
53,155,806;142,788;6,147,265;-0,005804369
532,658;143,008;6,147,822;-0,005714456
533,758;1,432,284;614,843;-0,005764407
53,485,806;1,434,492;6,149,305;-0,005764407
535,958;1,436,684;6,149,682;-0,005774398
53,705,806;1,438,888;6,150,238;-0,005814359
538,158;1,441,084;6,151,099;-0,005764407
539,258;1,443,276;6,151,664;-0,005754417
54,035,806;1,445,488;615,258;-0,005784388
541,458;1,447,688;6,153,417;-0,005784388
54,255,806;144,988;6,153,741;-0,005794378
543,658;1,452,084;615,432;-0,005784388
544,758;1,454,284;6,155,119;-0,005804369
54,585,806;1,456,476;6,155,729;-0,005754417
546,958;145,868;6,156,246;-0,005814359
54,805,806;1,460,884;6,157,288;-0,005784388
549,158;1,463,076;6,157,459;-0,005754417
55,025,806;1,465,268;6,158,029;-0,005774398
55,135,806;1,467,472;6,158,841;-0,005784388
552,458;1,469,676;615,972;-0,005784388
55,355,806;1,471,884;6,160,123;-0,005804369
554,658;147,408;6,160,764;-0,005784388
55,575,806;1,476,268;6,161,247;-0,005774398
55,685,806;1,478,464;6,162,165;-0,005774398
557,958;1,480,664;6,162,866;-0,005804369
55,905,806;1,482,868;6,163,765;-0,005784388
560,158;1,485,068;6,164,026;-0,005764407
56,125,806;1,487,272;6,164,685;-0,005764407
56,235,806;1,489,472;6,165,126;-0,005784388
563,458;1,491,664;6,165,444;-0,005814359
56,455,806;1,493,864;6,166,205;-0,005804369
565,658;1,496,076;6,167,279;-0,005774398
56,675,806;1,498,272;6,167,393;-0,005774398
56,785,806;1,500,472;6,167,951;-0,005794378
568,958;1,502,672;6,168,482;-0,005774398
57,005,806;150,486;6,168,895;-0,005784388
571,158;150,706;6,169,555;-0,005774398
57,225,806;1,509,268;6,170,523;-0,005784388
57,335,806;1,511,464;6,170,807;-0,005784388
574,458;1,513,664;6,171,245;-0,005774398
57,555,806;1,515,872;617,206;-0,005774398
576,658;1,518,056;6,171,938;-0,005774398
57,775,806;152,026;617,274;-0,005784388
57,885,806;1,522,476;6,173,645;-0,005794378
579,958;1,524,692;6,174,057;-0,005794378
58,105,806;1,526,876;6,174,009;-0,005774398
582,158;1,529,076;6,175,197;-0,005784388
58,325,806;1,531,268;6,175,397;-0,005784388
58,435,806;1,533,468;617,593;-0,005804369
585,458;153,568;6,176,779;-0,005784388
58,655,806;1,537,872;6,176,797;-0,005754417
587,658;1,540,076;6,177,257;-0,005774398
58,875,806;1,542,292;6,178,301;-0,005824349
58,985,806;1,544,476;6,178,221;-0,005804369
590,958;1,546,668;6,178,839;-0,005804369
59,205,806;1,548,892;6,179,928;-0,005804369
593,158;1,551,092;617,989;-0,00583434
59,425,806;1,553,272;6,179,661;-0,005824349
59,535,806;1,555,472;6,180,812;-0,005804369
596,458;1,557,672;6,181,476;-0,00585432
59,755,806;1,559,864;6,181,656;-0,005784388
598,658;1,562,076;6,182,321;-0,00584433
59,975,806;1,564,264;6,182,539;-0,00583434
60,085,806;1,566,464;6,183,034;-0,005824349
601,958;1,568,672;6,183,601;-0,00583434
60,305,806;1,570,868;6,183,786;-0,005814359
604,158;157,306;6,184,134;-0,005804369
60,525,806;157,528;6,185,133;-0,00585432
60,635,806;1,577,468;6,185,192;-0,005814359
607,458;1,579,664;6,185,246;-0,005804369
60,855,806;1,581,876;618,606;-0,00583434
609,658;1,584,076;618,647;-0,005824349
61,075,806;1,586,268;6,186,546;-0,005814359
61,185,806;1,588,484;6,187,233;-0,005824349
612,958;159,068;6,187,598;-0,00583434
61,405,806;1,592,872;6,187,863;-0,00584433
615,158;1,595,076;618,811;-0,005824349
61,625,806;1,597,272;6,188,787;-0,005824349
61,735,806;1,599,472;6,189,201;-0,00584433
618,458;1,601,688;6,189,623;-0,00585432
61,955,806;1,603,888;6,189,792;-0,00585432
620,658;160,608;6,190,054;-0,005824349
62,175,806;160,828;6,190,434;-0,00583434
62,285,806;1,610,476;6,191,052;-0,00584433
623,958;1,612,672;6,191,282;-0,005824349
62,505,806;161,488;6,191,963;-0,00583434
626,158;1,617,088;6,192,179;-0,005764407
62,725,806;161,928;6,192,406;-0,00583434
62,835,806;1,621,484;6,192,418;-0,005794378
629,458;1,623,688;6,193,305;-0,005774398
63,055,806;1,625,884;6,193,542;-0,00583434
631,658;1,628,096;619,387;-0,005764407
63,275,806;16,303;6,194,161;-0,00584433
63,385,806;1,632,488;6,194,369;-0,00584433
634,958;1,634,684;6,194,438;-0,005824349
63,605,806;1,636,884;61,952;-0,005804369
637,158;163,908;6,195,569;-0,005814359
63,825,806;1,641,288;6,195,907;-0,005804369
63,935,806;1,643,492;6,196,259;-0,005794378
640,458;1,645,684;6,196,537;-0,005804369
64,155,806;164,788;6,196,768;-0,005824349
642,658;165,008;619,706;-0,005814359
64,375,806;1,652,288;6,197,687;-0,00583434
64,485,806;1,654,496;6,197,734;-0,00584433
645,958;16,567;6,198,086;-0,005814359
64,705,806;165,888;6,197,945;-0,005814359
648,158;1,661,076;619,816;-0,005794378
64,925,806;1,663,276;6,198,633;-0,005824349
65,035,806;166,548;6,199,484;-0,005824349
651,458;1,667,672;6,199,295;-0,005804369
65,255,806;1,669,868;6,199,548;-0,00585432
653,658;1,672,072;6,200,102;-0,005804369
65,475,806;167,426;6,200,051;-0,00583434
65,585,806;1,676,456;620,011;-0,00583434
656,958;1,678,668;6,201,143;-0,00583434
65,805,806;1,680,876;620,115;-0,005824349
659,158;1,683,072;6,201,409;-0,00583434
66,025,806;1,685,256;6,201,174;-0,00586431
66,135,806;1,687,448;6,201,444;-0,00584433
662,458;168,966;6,201,746;-0,005814359
66,355,806;1,691,872;6,202,378;-0,00586431
664,658;169,406;6,202,154;-0,00583434
66,575,806;169,626;6,202,729;-0,005804369
66,685,806;1,698,472;6,203,154;-0,00586431
667,958;1,700,656;6,202,929;-0,00583434
66,905,806;170,286;6,202,943;-0,005874301
670,158;1,705,076;6,203,828;-0,005794378
67,125,806;1,707,268;6,203,462;-0,00583434
67,235,806;170,946;6,203,438;-0,00583434
673,458;171,168;6,204,402;-0,00586431
67,455,806;1,713,872;6,204,517;-0,005824349
675,658;1,716,072;6,204,483;-0,005804369
67,675,806;1,718,284;6,205,069;-0,00585432
67,785,806;1,720,476;6,204,855;-0,005824349
678,958;1,722,676;6,205,071;-0,00585432
68,005,806;1,724,888;6,205,657;-0,005824349
681,158;1,727,072;6,205,477;-0,00585432
68,225,806;1,729,268;6,205,771;-0,00584433
68,335,806;1,731,488;6,206,501;-0,00583434
684,458;1,733,672;6,206,282;-0,00585432
68,555,806;1,735,872;6,206,279;-0,00584433
686,658;173,808;6,206,831;-0,00585432
68,775,806;1,740,268;6,206,667;-0,00583434
68,885,806;1,742,456;6,206,769;-0,005814359
689,958;1,744,664;6,207,075;-0,00583434
69,105,806;1,746,856;6,207,335;-0,00586431
692,158;174,906;6,207,541;-0,00583434
69,325,806;1,751,272;6,207,828;-0,00586431
69,435,806;1,753,464;6,207,552;-0,005874301
695,458;1,755,656;6,207,741;-0,005924252
69,655,806;175,788;6,208,183;-0,005874301
697,658;1,760,072;6,208,149;-0,00585432
69,875,806;1,762,264;6,208,161;-0,00586431
69,985,806;1,764,468;6,208,508;-0,005894281
700,958;1,766,672;6,208,921;-0,00584433
70,205,806;176,886;6,208,674;-0,00583434
703,158;1,771,072;6,209,047;-0,005824349
70,425,806;1,773,268;6,209,182;-0,00586431
70,535,806;1,775,464;6,209,173;-0,00584433
706,458;1,777,668;6,208,842;-0,005884291
70,755,806;1,779,868;6,209,409;-0,005824349
708,658;178,206;6,209,341;-0,00585432
70,975,806;178,428;6,209,922;-0,00583434
71,085,806;1,786,492;6,210,051;-0,00585432
711,958;1,788,676;620,944;-0,005884291
71,305,806;1,790,872;620,966;-0,00585432
714,158;179,308;621,007;-0,005814359
71,525,806;1,795,272;6,210,042;-0,00583434
71,635,806;1,797,472;6,210,293;-0,00584433
717,458;179,968;6,210,584;-0,00584433
71,855,806;180,188;6,210,548;-0,00585432
719,658;1,804,084;6,210,443;-0,00584433
72,075,806;1,806,276;6,210,518;-0,00584433
72,185,806;1,808,476;6,210,682;-0,00584433
722,958;1,810,688;6,210,659;-0,00584433
72,405,806;1,812,892;621,068;-0,00586431
725,158;1,815,068;6,210,592;-0,00583434
72,625,806;1,817,264;6,210,781;-0,00585432
72,735,806;1,819,476;621,134;-0,00584433
728,458;1,821,684;6,211,572;-0,00585432
72,955,806;1,823,872;6,211,242;-0,005874301
730,658;1,826,076;6,211,191;-0,00584433
73,175,806;182,828;6,211,727;-0,005824349
73,285,806;1,830,472;6,211,439;-0,00583434
733,958;1,832,668;6,211,394;-0,00585432
73,505,806;183,488;6,211,882;-0,00585432
736,158;1,837,076;621,164;-0,00584433
73,725,806;183,928;6,211,577;-0,00583434
73,835,806;1,841,476;6,211,813;-0,00586431
739,458;1,843,672;6,211,734;-0,005884291
74,055,806;1,845,864;6,211,382;-0,00585432
741,658;1,848,076;6,212,413;-0,005804369
74,275,806;1,850,268;6,211,867;-0,00586431
74,385,806;1,852,472;6,211,987;-0,005874301
744,958;185,468;6,212,041;-0,005824349
74,605,806;1,856,864;6,211,648;-0,00584433
747,158;1,859,064;6,211,697;-0,00586431
74,825,806;1,861,284;6,212,339;-0,00586431
74,935,806;1,863,472;6,211,527;-0,005894281
750,458;1,865,672;6,211,628;-0,00586431
75,155,806;186,788;6,212,108;-0,00585432
752,658;1,870,068;6,211,797;-0,00583434
75,375,806;187,226;6,211,596;-0,005904272
75,485,806;1,874,476;6,212,224;-0,005884291
755,958;1,876,668;6,211,777;-0,005874301
75,705,806;187,886;6,211,844;-0,005874301
758,158;1,881,072;6,212,167;-0,00585432
75,925,806;1,883,264;6,211,984;-0,00584433
76,035,806;1,885,464;6,211,902;-0,005824349
761,458;1,887,684;6,212,372;-0,005884291
76,255,806;1,889,884;6,211,872;-0,005874301
763,658;1,892,076;6,211,751;-0,00585432
76,475,806;1,894,284;6,211,917;-0,00585432
76,585,806;1,896,468;6,211,625;-0,00584433
766,958;189,866;6,211,662;-0,00585432
76,805,806;1,900,872;6,211,886;-0,00584433
769,158;1,903,072;6,211,667;-0,005874301
77,025,806;1,905,272;6,211,638;-0,00584433
77,135,806;1,907,484;6,211,722;-0,00586431
772,458;1,909,672;6,211,556;-0,005824349
77,355,806;1,911,856;6,211,059;-0,005884291
774,658;1,914,072;6,211,929;-0,005884291
77,575,806;191,628;6,211,724;-0,00585432
77,685,806;191,848;6,211,296;-0,005874301
777,958;1,920,676;6,211,125;-0,005884291
77,905,806;1,922,868;6,211,203;-0,00586431
780,158;1,925,064;6,210,926;-0,005884291
78,125,806;1,927,276;6,211,183;-0,005904272
78,235,806;1,929,472;6,211,225;-0,00586431
783,458;1,931,664;6,210,704;-0,005874301
78,455,806;193,388;6,210,846;-0,00586431
785,658;1,936,076;6,210,711;-0,005904272
78,675,806;1,938,268;6,210,728;-0,005884291
78,785,806;194,048;6,210,748;-0,005884291
788,958;1,942,692;621,079;-0,005884291
79,005,806;1,944,876;6,210,331;-0,005874301
791,158;1,947,052;6,210,248;-0,005884291
79,225,806;1,949,256;6,210,583;-0,005904272
79,335,806;195,146;6,210,522;-0,005924252
794,458;1,953,672;6,210,246;-0,005904272
79,555,806;1,955,876;6,210,344;-0,005874301
796,658;1,958,064;6,209,803;-0,005894281
79,775,806;1,960,264;6,209,775;-0,005914262
79,885,806;196,246;6,209,801;-0,00586431
799,958;1,964,652;620,962;-0,005884291
80,105,806;1,966,864;620,954;-0,005904272
802,158;1,969,072;6,209,487;-0,005874301
80,325,806;1,971,264;6,208,965;-0,005894281
80,435,806;1,973,468;6,208,827;-0,005884291
805,458;1,975,668;6,208,933;-0,005914262
80,655,806;1,977,868;6,208,934;-0,00586431
807,658;1,980,068;6,208,661;-0,005884291
80,875,806;1,982,268;6,208,491;-0,00586431
80,985,806;1,984,472;6,208,523;-0,005914262
81,095,806;1,986,664;6,208,071;-0,005884291
81,205,806;1,988,864;620,813;-0,005894281
813,158;1,991,068;6,208,237;-0,00586431
81,425,806;1,993,276;6,207,936;-0,005924252
81,535,806;1,995,476;6,207,868;-0,005934243
81,645,806;1,997,672;6,207,769;-0,005894281
81,755,806;1,999,864;620,718;-0,005894281
818,658;200,206;6,207,073;-0,005884291
81,975,806;200,426;6,207,191;-0,005884291
82,085,806;2,006,464;6,206,972;-0,005914262
82,195,806;2,008,672;620,691;-0,005914262
82,305,806;2,010,872;6,206,596;-0,005894281
824,158;2,013,064;6,206,287;-0,005894281
82,525,806;2,015,264;6,206,193;-0,005884291
82,635,806;201,748;6,206,232;-0,005914262
82,745,806;201,968;6,205,848;-0,005904272
82,855,806;2,021,888;6,205,587;-0,005884291
829,658;2,024,092;6,205,552;-0,005894281
83,075,806;2,026,272;6,204,738;-0,005914262
83,185,806;2,028,468;620,485;-0,005894281
83,295,806;203,068;6,205,371;-0,005894281
83,405,806;2,032,872;6,204,588;-0,005904272
835,158;2,035,076;6,204,199;-0,005884291
83,625,806;2,037,288;6,204,469;-0,005904272
83,735,806;2,039,476;6,203,836;-0,005924252
83,845,806;2,041,668;6,203,492;-0,005874301
83,955,806;2,043,884;6,203,758;-0,005894281
840,658;2,046,084;6,203,522;-0,005914262
84,175,806;2,048,288;6,203,103;-0,005904272
84,285,806;2,050,488;6,202,704;-0,005904272
84,395,806;2,052,676;6,202,275;-0,005894281
84,505,806;2,054,872;6,202,052;-0,005904272
846,158;2,057,088;6,202,335;-0,005904272
84,725,806;2,059,276;6,201,768;-0,005904272
84,835,806;2,061,476;62,014;-0,005904272
84,945,806;2,063,684;6,201,698;-0,005924252
85,055,806;2,065,876;6,201,079;-0,005894281
851,658;2,068,064;6,200,575;-0,005874301
85,275,806;2,070,284;6,200,898;-0,005894281
85,385,806;2,072,488;6,200,422;-0,005884291
85,495,806;2,074,688;6,199,836;-0,005944233
85,605,806;2,076,872;6,199,279;-0,005884291
857,158;207,906;619,946;-0,005914262
85,825,806;2,081,264;6,199,303;-0,005914262
85,935,806;2,083,484;6,199,311;-0,005914262
86,045,806;2,085,676;6,198,605;-0,005914262
86,155,806;2,087,868;619,827;-0,005924252
862,658;2,090,076;6,198,197;-0,005924252
86,375,806;2,092,268;6,197,906;-0,005884291
86,485,806;209,446;6,197,512;-0,005874301
86,595,806;2,096,672;6,197,336;-0,005904272
86,705,806;2,098,876;6,197,085;-0,005874301
868,158;2,101,068;6,196,708;-0,00585432
86,925,806;2,103,276;6,196,249;-0,005924252
87,035,806;2,105,476;6,196,176;-0,005904272
87,145,806;2,107,676;6,195,757;-0,005914262
87,255,806;2,109,884;6,195,526;-0,005924252
873,658;211,208;6,195,133;-0,005874301
87,475,806;2,114,276;6,194,769;-0,005884291
87,585,806;2,116,476;6,194,019;-0,005924252
87,695,806;2,118,672;6,194,079;-0,005884291
87,805,806;2,120,868;619,365;-0,00585432
879,158;212,308;6,193,711;-0,005904272
88,025,806;2,125,284;6,193,206;-0,005904272
88,135,806;2,127,468;6,192,696;-0,005924252
88,245,806;2,129,676;6,192,183;-0,005894281
88,355,806;2,131,872;6,191,944;-0,005914262
884,658;2,134,064;619,148;-0,005924252
88,575,806;2,136,272;6,191,266;-0,005884291
88,685,806;2,138,476;6,191,002;-0,005914262
88,795,806;2,140,672;619,048;-0,005944233
88,905,806;2,142,868;6,189,816;-0,005934243
890,158;2,145,068;6,189,799;-0,005934243
89,125,806;2,147,268;618,953;-0,005944233
89,235,806;214,948;6,188,814;-0,005944233
89,345,806;2,151,688;6,188,633;-0,005924252
89,455,806;215,388;6,187,863;-0,005894281
895,658;2,156,068;6,187,374;-0,005884291
89,675,806;2,158,268;6,187,211;-0,005954223
89,785,806;2,160,464;6,187,026;-0,005924252
89,895,806;2,162,664;6,186,404;-0,005934243
90,005,806;2,164,864;6,186,035;-0,005904272
901,158;2,167,068;6,185,448;-0,005934243
90,225,806;2,169,264;6,184,694;-0,005924252
90,335,806;2,171,468;6,184,439;-0,005964214
90,445,806;2,173,668;6,184,324;-0,005974204
90,555,806;2,175,876;6,183,655;-0,005924252
906,658;2,178,084;6,183,411;-0,005894281
90,775,806;2,180,288;6,182,771;-0,005914262
90,885,806;2,182,464;6,181,452;-0,005944233
90,995,806;2,184,668;618,139;-0,005944233
91,105,806;2,186,876;6,181,314;-0,005934243
912,158;2,189,072;6,180,323;-0,005914262
91,325,806;2,191,276;6,179,965;-0,005964214
91,435,806;2,193,484;617,979;-0,005924252
91,545,806;219,568;6,178,932;-0,005954223
91,655,806;219,788;6,178,063;-0,005944233
917,658;2,200,092;6,177,971;-0,005924252
91,875,806;2,202,292;6,176,848;-0,005964214
91,985,806;22,045;6,176,509;-0,005914262
92,095,806;2,206,704;6,176,051;-0,005934243
92,205,806;2,208,872;6,175,026;-0,005984194
923,158;2,211,076;6,174,754;-0,005944233
92,425,806;22,133;6,174,588;-0,005954223
92,535,806;2,215,492;6,173,413;-0,005944233
92,645,806;2,217,684;617,248;-0,005974204
92,755,806;2,219,896;6,172,405;-0,005914262
928,658;2,222,088;617,142;-0,005944233
92,975,806;2,224,276;6,170,749;-0,005964214
93,085,806;2,226,492;6,170,521;-0,005954223
93,195,806;2,228,684;6,169,742;-0,005954223
93,305,806;223,088;6,168,725;-0,005944233
934,158;2,233,088;6,168,483;-0,005914262
93,525,806;2,235,284;6,167,601;-0,005944233
93,635,806;2,237,476;6,166,894;-0,005974204
93,745,806;2,239,696;6,166,453;-0,005934243
93,855,806;2,241,888;6,165,419;-0,005994184
939,658;224,408;6,164,539;-0,005954223
94,075,806;2,246,284;6,163,791;-0,005964214
94,185,806;2,248,484;6,163,505;-0,005944233
94,295,806;2,250,672;616,217;-0,005964214
94,405,806;2,252,896;616,177;-0,005934243
945,158;2,255,092;6,160,825;-0,005964214
94,625,806;2,257,288;6,159,841;-0,005954223
94,735,806;2,259,484;6,159,158;-0,005944233
94,845,806;226,168;615,839;-0,005984194
94,955,806;2,263,864;6,157,408;-0,005984194
950,658;226,608;6,156,973;-0,005964214
95,175,806;2,268,268;6,155,785;-0,005984194
95,285,806;2,270,468;6,154,999;-0,005964214
95,395,806;2,272,672;6,154,323;-0,005934243
95,505,806;2,274,876;6,153,576;-0,005964214
956,158;2,277,064;615,221;-0,005944233
95,725,806;2,279,284;6,151,798;-0,005954223
95,835,806;2,281,484;6,150,515;-0,005974204
95,945,806;2,283,684;6,149,304;-0,005964214
96,055,806;228,588;6,148,163;-0,005954223
961,658;2,288,076;6,147,319;-0,005934243
96,275,806;2,290,264;6,146,176;-0,005964214
96,385,806;2,292,476;6,145,372;-0,005964214
96,495,806;2,294,672;6,144,348;-0,005954223
96,605,806;2,296,864;6,142,763;-0,005934243
967,158;2,299,068;6,141,713;-0,005954223
96,825,806;2,301,276;6,141,019;-0,005954223
96,935,806;2,303,468;6,139,593;-0,005954223
97,045,806;2,305,676;6,138,545;-0,005914262
97,155,806;2,307,892;6,137,603;-0,006024155
972,658;2,310,092;6,136,343;-0,005954223
97,375,806;231,228;6,134,568;-0,005944233
97,485,806;2,314,472;6,133,616;-0,006014165
97,595,806;231,668;613,252;-0,005954223
97,705,806;2,318,884;6,131,083;-0,005994184
978,158;2,321,084;612,972;-0,005934243
97,925,806;232,328;6,128,426;-0,005974204
98,035,806;2,325,488;6,127,101;-0,005974204
98,145,806;2,327,684;6,125,994;-0,005914262
98,255,806;2,329,884;6,124,402;-0,005964214
983,658;2,332,084;6,123,012;-0,005934243
98,475,806;2,334,304;6,121,711;-0,005954223
98,585,806;23,365;6,119,949;-0,005964214
98,695,806;2,338,668;6,117,798;-0,005964214
98,805,806;2,340,868;6,116,878;-0,005944233
989,158;2,343,092;6,116,094;-0,005934243
99,025,806;2,345,292;6,114,008;-0,005974204
99,135,806;2,347,484;611,231;-0,005984194
99,245,806;2,349,688;6,110,467;-0,005974204
99,355,806;235,188;6,108,667;-0,006014165
994,658;235,408;6,106,872;-0,005944233
99,575,806;2,356,288;6,105,778;-0,005964214
99,685,806;235,848;6,103,601;-0,005944233
99,795,806;2,360,684;6,102,048;-0,005944233
99,905,806;2,362,884;6,100,607;-0,005974204
1,000,158;2,365,072;6,098,307;-0,005944233
100,125,806;2,367,276;6,096,514;-0,005984194
100,235,806;2,369,496;6,095,253;-0,005994184
100,345,806;2,371,692;6,092,685;-0,005974204
100,455,806;2,373,884;609,072;-0,006004175
1,005,658;2,376,096;6,089,231;-0,005964214
100,675,806;2,378,284;608,673;-0,005984194
100,785,806;2,380,476;6,084,441;-0,005944233
100,895,806;2,382,692;6,083,186;-0,005954223
101,005,806;2,384,892;6,080,577;-0,005964214
1,011,158;2,387,096;6,078,388;-0,005954223
101,225,806;23,893;6,076,519;-0,005964214
101,335,806;2,391,488;6,074,159;-0,005974204
101,445,806;239,368;6,071,801;-0,005954223
101,555,806;2,395,884;6,069,781;-0,006004175
1,016,658;2,398,072;6,067,477;-0,005924252
101,775,806;2,400,272;6,065,156;-0,005964214
101,885,806;2,402,484;6,063,321;-0,005924252
101,995,806;2,404,676;6,060,725;-0,005984194
102,105,806;2,406,872;605,809;-0,005984194
1,022,158;2,409,088;6,056,379;-0,005984194
102,325,806;2,411,292;6,053,584;-0,005974204
102,435,806;2,413,492;6,050,967;-0,005974204
1,025,458;2,415,704;6,048,556;-0,005944233
102,655,812;2,417,892;6,045,664;-0,005984194
102,765,806;242,008;6,043,122;-0,005944233
102,875,806;2,422,296;604,083;-0,005964214
102,985,806;2,424,484;6,037,857;-0,006004175
1,030,958;242,668;6,035,226;-0,005994184
103,205,812;2,428,888;6,033,126;-0,005994184
103,315,806;243,108;6,030,231;-0,005994184
103,425,806;2,433,272;6,027,216;-0,006014165
103,535,806;2,435,488;6,024,736;-0,005984194
1,036,458;2,437,692;60,219;-0,006024155
103,755,812;2,439,904;6,018,917;-0,005984194
103,865,806;2,442,104;6,015,866;-0,005944233
103,975,806;2,444,292;6,012,653;-0,005984194
104,085,806;2,446,484;6,010,008;-0,006014165
1,041,958;24,487;6,006,989;-0,005994184
104,305,812;2,450,892;6,003,807;-0,005994184
104,415,806;2,453,092;6,000,876;-0,005934243
104,525,806;2,455,296;5,997,748;-0,006024155
104,635,806;2,457,504;5,994,844;-0,006024155
1,047,458;2,459,688;5,991,336;-0,005984194
104,855,812;2,461,896;5,988,188;-0,006034146
104,965,812;24,641;5,985,004;-0,006024155
1,050,758;2,466,308;5,981,622;-0,005974204
1,051,858;2,468,496;5,977,605;-0,006004175
1,052,958;2,470,684;5,974,794;-0,005994184
105,405,812;247,288;5,971,774;-0,006024155
105,515,812;24,751;5,968,372;-0,005984194
1,056,258;2,477,296;596,469;-0,006014165
1,057,358;2,479,492;5,961,024;-0,006024155
1,058,458;2,481,692;5,957,307;-0,006054126
105,955,812;2,483,896;5,953,926;-0,005994184
106,065,812;2,486,092;5,950,299;-0,005974204
1,061,758;2,488,288;594,647;-0,006004175
1,062,858;2,490,508;5,943,342;-0,006004175
1,063,958;24,927;5,939,487;-0,006004175
106,505,812;2,494,904;5,935,412;-0,006024155
106,615,812;24,971;5,931,554;-0,005994184
1,067,258;2,499,308;5,928,076;-0,006024155
1,068,358;2,501,508;5,923,613;-0,005994184
1,069,458;2,503,712;5,919,952;-0,006024155
107,055,812;2,505,912;5,916,099;-0,005994184
107,165,812;2,508,112;5,911,715;-0,005984194
1,072,758;2,510,304;5,907,848;-0,006014165
1,073,858;2,512,512;5,903,977;-0,006004175
1,074,958;2,514,712;5,899,566;-0,006004175
107,605,812;251,692;5,895,091;-0,006024155
107,715,812;2,519,116;5,891,336;-0,005974204
1,078,258;2,521,308;5,886,908;-0,006014165
1,079,358;2,523,504;5,882,706;-0,005984194
1,080,458;2,525,712;5,878,649;-0,006014165
108,155,812;25,279;5,873,931;-0,006014165
108,265,812;2,530,104;5,869,229;-0,005984194
1,083,758;2,532,308;5,865,234;-0,005984194
1,084,858;2,534,496;586,004;-0,006034146
1,085,958;2,536,696;5,855,635;-0,005974204
108,705,812;2,538,916;5,851,536;-0,006004175
108,815,812;2,541,112;5,846,427;-0,006004175
1,089,258;254,332;5,841,844;-0,006004175
1,090,358;2,545,528;5,837,194;-0,006044136
1,091,458;2,547,712;5,831,823;-0,005994184
109,255,812;25,499;5,826,952;-0,006044136
109,365,812;2,552,116;5,822,725;-0,005984194
1,094,758;25,543;581,693;-0,006004175
1,095,858;25,565;5,812,179;-0,005974204
1,096,958;2,558,712;5,807,686;-0,006014165
109,805,812;2,560,904;5,802,283;-0,006024155
109,915,812;25,631;5,796,974;-0,006004175
1,100,258;2,565,308;5,792,033;-0,006014165
1,101,358;2,567,508;5,786,054;-0,006034146
1,102,458;2,569,716;5,780,971;-0,006004175
110,355,812;2,571,932;5,775,697;-0,006024155
110,465,812;2,574,104;5,769,792;-0,005984194
1,105,758;2,576,296;5,764,385;-0,006024155
1,106,858;2,578,512;5,759,528;-0,005984194
1,107,958;2,580,712;5,753,025;-0,006014165
110,905,812;2,582,904;5,747,102;-0,006024155
111,015,812;258,512;574,185;-0,005974204
1,111,258;258,732;573,606;-0,006024155
1,112,358;2,589,512;5,729,927;-0,005994184
1,113,458;2,591,724;5,724,532;-0,006014165
111,455,812;2,593,924;57,186;-0,006024155
111,565,812;2,596,128;5,712,675;-0,005984194
1,116,758;2,598,336;570,637;-0,006034146
1,117,858;2,600,508;5,699,604;-0,006034146
1,118,958;2,602,704;5,693,787;-0,006024155
112,005,812;2,604,932;5,688,127;-0,006074107
112,115,812;2,607,132;5,681,368;-0,006004175
1,122,258;2,609,324;567,493;-0,006004175
1,123,358;2,611,532;5,668,354;-0,006024155
1,124,458;2,613,736;5,662,158;-0,006034146
112,555,812;2,615,924;5,654,963;-0,006044136
112,665,812;261,814;5,648,305;-0,005974204
1,127,758;2,620,336;5,641,645;-0,006004175
1,128,858;2,622,536;5,634,814;-0,005994184
1,129,958;2,624,736;5,627,623;-0,006014165
113,105,812;2,626,936;5,620,905;-0,006014165
113,215,812;2,629,128;5,613,971;-0,005964214
1,133,258;2,631,344;5,606,908;-0,006044136
1,134,358;2,633,544;5,599,621;-0,006024155
1,135,458;263,574;5,591,889;-0,006044136
113,655,812;2,637,944;5,584,522;-0,006034146
113,765,812;264,014;5,577,633;-0,006034146
1,138,758;2,642,328;5,569,947;-0,006024155
1,139,858;264,454;5,562,267;-0,006054126
1,140,958;2,646,744;5,555,029;-0,006044136
114,205,812;264,894;5,546,693;-0,005984194
114,315,812;2,651,136;5,538,541;-0,006024155
1,144,258;2,653,344;5,530,897;-0,006034146
1,145,358;2,655,532;5,522,949;-0,005994184
1,146,458;265,774;5,514,776;-0,006024155
114,755,812;265,994;550,667;-0,006024155
114,865,812;2,662,136;5,498,332;-0,006004175
1,149,758;2,664,332;5,489,881;-0,006034146
1,150,858;266,654;5,481,468;-0,006024155
1,151,958;2,668,732;5,472,895;-0,006004175
115,305,812;2,670,948;5,464,176;-0,006064117
115,415,812;2,673,152;5,455,652;-0,006034146
1,155,258;2,675,352;5,446,578;-0,006004175
1,156,358;2,677,544;5,437,508;-0,006044136
1,157,458;2,679,748;5,428,854;-0,006034146
115,855,812;2,681,944;5,419,288;-0,006004175
115,965,812;2,684,156;5,410,063;-0,006024155
1,160,758;2,686,352;5,400,234;-0,006084097
1,161,858;2,688,556;5,390,951;-0,006014165
1,162,958;2,690,748;5,381,102;-0,006034146
116,405,812;2,692,948;5,371,762;-0,006004175
116,515,812;2,695,152;5,362,085;-0,006034146
1,166,258;2,697,352;5,352,018;-0,006044136
1,167,358;269,956;5,341,517;-0,006044136
1,168,458;2,701,772;533,148;-0,006044136
116,955,812;270,396;5,320,551;-0,006054126
117,065,812;2,706,152;5,310,546;-0,006014165
1,171,758;2,708,364;5,300,475;-0,006034146
1,172,858;271,056;5,289,362;-0,006004175
1,173,958;2,712,756;5,278,139;-0,006024155
117,505,812;271,496;5,267,658;-0,006014165
117,615,812;2,717,156;5,255,877;-0,006014165
1,177,258;271,936;5,244,544;-0,006054126
1,178,358;2,721,572;5,233,356;-0,006054126
1,179,458;2,723,764;5,221,625;-0,006044136
118,055,812;2,725,972;5,209,921;-0,006034146
118,165,812;2,728,184;5,198,187;-0,006004175
1,182,758;2,730,352;5,185,277;-0,006084097
1,183,858;273,254;5,173,317;-0,006044136
1,184,958;2,734,768;5,161,471;-0,006014165
118,605,812;273,698;5,148,305;-0,006024155
118,715,812;2,739,172;5,135,379;-0,006044136
1,188,258;2,741,376;5,122,886;-0,006034146
1,189,358;2,743,568;5,109,392;-0,006054126
1,190,458;274,576;5,095,882;-0,006034146
119,155,812;2,747,972;5,082,373;-0,006014165
119,265,812;275,016;5,068,312;-0,005994184
1,193,758;2,752,372;5,054,316;-0,006024155
1,194,858;2,754,584;5,040,451;-0,006034146
1,195,958;2,756,776;5,025,592;-0,006024155
119,705,812;2,758,972;5,010,819;-0,006024155
119,815,812;2,761,196;4,996,179;-0,006034146
1,199,258;2,763,388;498,062;-0,006054126
1,200,358;2,765,588;49,651;-0,006024155
1,201,458;27,678;4,949,526;-0,006034146
120,255,812;2,769,992;493,324;-0,006044136
120,365,812;2,772,184;4,916,969;-0,005994184
1,204,758;27,744;4,900,776;-0,006074107
1,205,858;27,766;4,883,724;-0,006064117
1,206,958;2,778,796;4,866,483;-0,006054126
120,805,812;2,781,004;4,848,697;-0,006024155
120,915,812;2,783,196;4,830,757;-0,005994184
1,210,258;2,785,396;4,812,215;-0,006014165
1,211,358;2,787,608;4,793,861;-0,006014165
1,212,458;2,789,808;4,774,318;-0,006044136
121,355,812;27,92;4,754,605;-0,006064117
121,465,812;2,794,208;4,734,339;-0,006014165
1,215,758;2,796,408;4,713,228;-0,006064117
1,216,858;2,798,604;4,690,276;-0,006034146
1217,78;2,800,472;4,632,033;-0,006034146
1,217,812;2,800,708;272,013;-0,00291717