File: tensile_test_ontology_TTO/data/primary_data/Zd3.csv
Time;Crosshead travel;Force;Strain
(s);(mm);(kN);(%)
0;0;0,26531;0
1;0,05508;0,45477;0,001369765
1,73;0,18976;127,112;0,005199107
2,012;0,25724;230,904;0,009628347
2,248;0,3158;335,131;0,014237555
2,468;0,37232;440,741;0,018616803
2,686;0,42964;548,657;0,023156024
2,89;0,4844;651,681;0,027365301
3,09;0,53904;753,609;0,031514589
3,296;0,5964;857,233;0,035903835
3,514;0,65796;964,599;0,040623025
3,734;0,72056;106,829;0,045572175
3,968;0,78808;1,171,879;0,050861267
4,208;0,8572;1,273,852;0,056920227
4,45;0,92648;1,376,358;0,063079169
4,69;0,99456;1,477,318;0,0693081
4,934;106,324;1,580,338;0,075507035
5,194;11,364;168,723;0,081216055
5,436;12,058;1,789,077;0,086205199
5,676;127,648;1,893,051;0,090754417
5,91;134,708;1,998,901;0,095433614
6,134;141,608;2,102,122;0,099772869
6,354;148,512;2,207,237;0,10448206
6,574;155,528;2,313,244;0,109231245
6,792;162,524;2,419,683;0,113890445
7,01;169,588;2,527,564;0,11892958
7,224;17,652;26,333;0,123868732
7,43;183,208;273,657;0,128837879
7,65;190,348;2,845,306;0,134096976
7,864;197,276;2,951,912;0,139586033
8,08;204,216;3,057,984;0,145075091
8,3;211,208;3,165,325;0,151004073
8,52;218,092;3,270,618;0,15713302
8,74;224,848;3,373,352;0,163351952
8,968;23,168;3,477,726;0,17041074
9,212;238,652;3,582,407;0,17920923
9,626;246,228;3,685,644;0,208884135
10,078;252,952;3,787,453;0,218392502
10,506;25,978;3,889,663;0,227480942
10,928;266,772;3,991,382;0,236669364
11,354;274,032;4,093,852;0,246737635
11,79;281,528;4,196,537;0,257145848
12,256;289,468;4,298,557;0,26936375
12,774;297,936;4,400,509;0,283161381
13,378;30,734;4,502,586;0,299438586
14,1;317,508;4,604,049;0,321154858
15,09;32,746;4,688,104;0,352679445
16,09;333,984;4,732,043;0,381334525
17,09;338,736;4,756,256;0,408289897
18,09;342,464;4,769,468;0,433845509
19,09;345,644;4,775,557;0,459701069
20,09;348,348;4,777,217;0,485006724
21,09;350,736;4,774,242;0,510292383
22,09;35,344;4,778,792;0,535398072
23,09;355,312;4,758,373;0,560143823
24,09;357,464;4,746,946;0,585709434
25,09;35,936;473,241;0,610795126
26,09;36,122;4,725,165;0,635450893
27,09;363,904;4,738,511;0,661166478
28,09;365,756;4,730,477;0,684922399
29,09;367,836;4,733,963;0,710108074
30,09;369,796;4,736,096;0,73564369
31,09;371,516;4,733,841;0,76027946
32,09;373,224;4,732,936;0,785825074
33,09;374,824;4,731,414;0,81054083
34,09;376,392;4,729,458;0,836126437
35,09;377,852;4,727,062;0,860892185
36,09;379,296;4,724,514;0,885897891
37,09;380,704;4,722,303;0,910863605
38,09;382,148;4,722,169;0,935859313
39,09;383,544;4,721,297;0,960955004
40,09;384,968;4,721,625;0,985840731
41,09;38,636;4,721,553;1,010,856,436
42,09;38,776;4,721,465;1,035,982,122
43,09;389,172;4,721,615;1,061,467,746
44,09;390,504;4,719,633;1,086,343,475
45,09;391,832;4,718,394;1,110,979,245
46,09;393,152;4,716,887;1,135,924,962
47,09;394,524;4,717,826;1,160,770,696
48,09;395,852;4,716,151;1,186,076,351
49,09;397,172;4,715,143;1,210,742,116
50,09;398,488;4,713,533;123,581,781
51,09;399,756;4,710,454;1,260,673,542
52,09;401,068;4,709,305;1,285,699,245
53,09;402,372;4,707,172;131,112,488
54,09;403,652;4,705,027;1,335,870,631
55,09;404,976;4,705,651;1,360,786,353
56,09;406,352;4,708,085;1,385,692,077
57,09;407,812;471,466;1,410,567,806
58,09;409,296;4,721,643;1,435,503,524
59,09;410,848;4,731,388;1,460,269,272
60,09;412,436;4,741,038;1,485,214,989
61,09;41,418;4,753,167;1,510,420,661
62,07;41,626;4,766,665;153,657,617
63,07;41,772;4,768,843;155,917,229
64,07;419,476;4,777,575;1,584,187,995
65,07;421,332;4,787,498;160,914,371
66,07;4,232;4,793,818;1,634,219,405
67,07;425,192;4,803,098;1,659,195,116
68,07;4,272;4,810,133;1,683,640,919
69,07;429,352;4,817,846;1,708,896,582
70,07;431,548;4,825,983;1,733,592,342
71,07;433,872;4,834,725;175,835,809
72,07;436,208;4,841,304;1,783,453,781
73,07;438,632;4,850,845;180,820,953
7,407,001;44,112;4,860,233;1,833,205,239
7,507,001;443,604;4,867,097;1,858,210,945
7,607,001;446,112;4,875,498;1,883,026,684
7,707,001;448,708;4,884,861;1,908,332,339
7,807,001;451,276;4,893,575;1,932,988,106
79,05;454,272;4,915,225;1,953,364,607
80,05;456,908;4,907,131;1,982,799,553
81,05;459,544;4,919,399;2,007,495,313
82,05;462,208;492,855;2,032,511,018
83,05;464,884;4,937,818;205,742,674
84,05;467,624;4,947,706;208,235,246
85,05;470,304;4,954,762;2,107,368,165
86,05;473,032;4,963,803;2,132,193,902
87,05;475,772;497,193;2,157,199,609
88,05;47,852;4,980,828;2,181,975,355
89,05;481,328;4,990,584;2,207,141,034
90,05;484,096;4,998,827;2,232,026,761
91,05;486,916;5,008,046;2,256,952,481
92,05;48,972;5,015,677;228,176,822
9,304,201;493,036;5,023,217;2,307,593,786
9,404,201;495,756;5,032,301;233,208,958
9,504,201;4,985;504,102;2,356,905,319
9,604,201;501,312;5,050,128;2,381,881,031
9,704,201;504,128;5,058,797;2,406,746,762
9,804,201;506,988;506,773;2,431,982,429
9,904,201;509,752;5,074,504;2,456,858,157
10,004,201;512,588;5,083,627;2,481,913,855
10,104,201;515,356;5,090,463;2,506,749,591
10,204,201;518,152;5,099,113;2,531,675,311
10,304,201;521,004;5,108,074;255,702,096
10,404,201;523,704;5,114,414;258,159,674
10,504,201;526,536;5,124,403;2,606,642,439
10,604,201;52,974;5,129,744;2,632,288,036
10,704,201;53,238;5,139,121;265,643,389
10,804,201;535,076;5,145,594;2,681,519,583
10,904,201;537,764;5,153,177;2,706,535,288
11,004,201;540,504;5,161,186;2,731,560,991
11,104,201;543,224;5,168,988;2,756,516,706
11,204,201;545,968;5,177,374;2,781,842,358
11,304,201;548,608;5,182,511;2,806,418,138
11,404,201;551,284;5,190,884;2,831,053,908
11,504,201;55,402;519,798;2,856,369,561
11,604,201;556,692;520,508;28,811,853
11,704,201;559,432;5,213,425;2,906,340,981
11,804,201;562,616;5,234,474;2,928,457,184
11,904,201;565,196;5,224,606;2,956,592,353
12,004,201;567,808;5,232,781;2,981,038,156
12,104,201;570,424;5,240,122;3,005,993,871
12,204,201;573,116;52,475;3,031,239,536
12,304,201;5,758;525,489;3,056,255,241
12,404,201;578,464;52,618;3,081,410,922
12,504,201;581,072;526,741;3,106,186,668
12,604,201;583,712;5,274,693;3,130,962,414
12,704,201;586,396;5,281,042;3,156,248,072
12,804,201;589,052;5,287,703;3,181,163,794
12,904,201;591,728;52,948;3,206,169,501
13,004,201;594,388;5,301,068;323,092,525
13,104,201;597,496;5,305,744;3,256,830,802
132,042;600,036;5,312,408;3,281,206,617
133,042;602,636;5,318,934;3,306,122,339
134,042;605,276;5,325,634;3,331,138,044
135,042;60,794;5,332,463;3,355,923,788
136,042;610,552;5,337,972;3,380,619,548
137,042;613,224;5,343,825;3,406,105,172
138,042;615,888;535,078;3,431,080,883
139,042;618,524;5,355,905;3,456,156,578
140,042;621,164;5,362,661;3,480,982,315
141,042;623,844;5,369,325;3,505,968,025
142,042;626,812;5,383,369;3,527,454,336
143,042;629,492;5,376,441;355,637,937
144,042;632,072;5,384,521;3,581,175,112
145,042;634,656;5,390,748;360,600,085
146,042;637,296;5,397,681;363,092,657
147,042;639,928;5,402,272;3,656,032,259
148,042;642,548;5,408,175;368,095,798
149,042;64,518;5,413,047;3,706,133,657
150,042;64,782;5,419,168;3,730,969,393
151,042;650,504;5,425,813;3,756,285,046
152,042;653,112;5,429,349;378,113,078
153,042;655,724;5,434,859;3,805,586,581
154,042;659,056;5,450,636;3,831,182,186
155,042;6,614;5,443,469;385,573,797
156,042;66,406;5,451,543;388,107,362
157,042;666,636;5,456,138;390,605,933
158,042;669,284;5,462,142;3,930,875,069
159,042;671,888;5,465,672;3,955,900,772
160,042;674,544;5,471,742;3,980,816,494
16,089,602;675,408;5,450,628;3,993,024,398
16,189,602;67,742;5,464,892;4,010,281,435
16,289,602;679,392;5,470,268;402,859,829
16,389,602;681,376;5,474,864;4,046,895,148
16,489,602;683,392;5,478,776;4,065,741,912
16,589,602;685,392;5,482,492;4,084,268,731
16,689,602;68,738;5,485,928;4,102,745,559
16,789,602;6,894;5,490,345;4,121,172,395
16,889,602;691,388;5,493,529;413,506,001
16,989,602;693,388;5,497,224;4,154,036,752
17,089,602;695,392;5,501,119;4,173,083,482
171,662;69,692;5,503,455;4,187,730,967
19,216,802;698,728;5,420,187;0,058269995
19,316,802;700,716;5,479,728;0,058319986
19,416,802;702,736;5,508,775;0,058269995
19,516,802;704,728;5,520,324;0,058319986
19,616,802;706,732;5,525,182;0,05835998
19,716,802;708,744;5,529,304;0,058339983
19,816,802;710,736;5,531,888;0,058369978
19,916,802;712,732;5,534,719;0,058339983
20,016,802;714,736;5,538,008;0,058369978
20,116,802;716,736;5,540,451;0,05835998
20,216,802;718,736;5,543,818;0,058379976
20,316,802;720,728;554,661;0,058409971
20,416,802;722,732;5,549,643;0,058399973
20,516,802;724,732;5,552,799;0,058379976
20,616,802;726,724;555,592;0,058379976
20,716,802;728,736;5,559,143;0,058389974
20,816,802;730,728;5,562,047;0,058419969
20,916,802;732,724;5,565,305;0,058429968
21,016,802;734,736;5,568,525;0,058439966
21,116,802;736,716;5,571,526;0,058429968
21,216,802;738,716;5,574,791;0,058459962
21,316,802;740,712;5,578,199;0,058439966
21,416,802;74,272;5,581,114;0,058439966
21,516,802;744,724;5,584,384;0,058469961
21,616,802;746,716;5,586,964;0,058389974
21,716,802;74,872;5,590,034;0,058439966
21,816,802;750,712;5,593,523;0,058469961
21,916,802;752,712;5,596,339;0,058439966
22,016,802;754,728;5,599,915;0,058469961
22,116,802;756,728;5,602,434;0,058469961
22,216,802;758,724;5,605,185;0,058459962
22,316,802;760,724;5,608,388;0,058479959
22,416,802;762,712;561,103;0,058489957
22,516,802;764,708;5,614,141;0,058459962
22,616,802;766,712;5,617,391;0,058499956
22,716,802;768,712;5,620,294;0,058509954
22,816,802;770,716;5,623,084;0,058479959
22,916,802;772,704;5,625,923;0,058489957
23,016,802;77,472;5,628,961;0,058509954
23,116,802;776,708;5,631,605;0,058519952
23,216,802;778,708;5,634,726;0,05852995
23,316,802;780,732;5,638,011;0,058499956
23,416,802;782,728;5,640,186;0,058509954
23,516,802;784,716;5,642,686;0,058539949
23,616,802;786,716;5,646,133;0,058519952
23,716,802;788,716;5,648,684;0,058539949
23,816,802;790,712;5,651,521;0,058559945
23,916,802;792,708;5,654,342;0,058519952
24,016,802;794,716;5,657,284;0,058519952
24,116,802;796,716;5,660,001;0,058519952
24,216,802;798,712;5,662,563;0,05852995
24,316,802;800,716;5,665,352;0,058539949
24,416,802;802,712;5,667,916;0,05852995
24,516,802;804,708;5,670,641;0,058539949
24,616,802;806,736;5,673,701;0,058559945
24,716,802;80,872;5,676,047;0,058519952
24,816,802;8,107;5,678,391;0,058539949
24,916,802;812,708;5,681,635;0,058519952
25,016,802;814,712;5,684,489;0,058549947
25,116,802;816,716;5,687,034;0,058579942
25,216,802;818,708;5,689,714;0,058549947
25,316,802;82,072;5,692,193;0,058549947
25,416,802;82,272;5,695,277;0,058559945
25,516,802;824,708;5,697,399;0,058559945
256,168;826,716;5,700,344;0,058549947
257,168;828,708;5,702,528;0,058579942
258,168;8,307;5,705,097;0,058549947
259,168;83,272;5,708,058;0,058559945
260,168;834,704;5,710,239;0,058569944
261,168;8,367;5,712,918;0,058569944
262,168;838,716;5,716,071;0,058579942
263,168;840,708;5,718,153;0,058559945
264,168;842,712;5,720,804;0,058599938
265,168;844,704;5,723,246;0,058609937
266,168;846,712;5,725,665;0,058559945
267,168;848,712;5,728,378;0,05858994
268,168;8,507;5,730,264;0,058599938
269,168;8,527;5,732,783;0,058619935
270,168;8,547;5,735,664;0,058579942
271,168;8,567;5,737,824;0,058619935
272,168;858,716;5,740,698;0,058599938
273,168;860,704;5,742,382;0,058559945
274,168;862,704;5,744,836;0,058609937
275,168;864,704;5,747,516;0,058619935
276,168;8,667;5,749,485;0,058599938
277,168;868,696;5,752,389;0,058629933
278,168;870,692;5,754,706;0,058619935
279,168;8,727;5,757,126;0,058639932
280,168;874,696;5,759,409;0,058629933
281,168;876,692;5,761,451;0,058639932
282,168;878,708;5,764,232;0,058629933
283,168;8,807;5,765,994;0,058639932
284,168;882,692;576,855;0,058599938
285,168;884,712;577,132;0,05864993
286,168;886,712;5,773,278;0,058609937
287,168;888,712;5,775,537;0,058659928
288,168;890,704;5,777,642;0,05864993
289,168;892,704;5,779,798;0,058659928
290,168;894,696;5,782,266;0,058639932
291,168;896,688;5,784,438;0,058639932
292,168;8,987;5,786,526;0,058639932
293,168;9,007;5,789,011;0,05864993
294,168;902,688;5,790,756;0,05864993
295,168;904,704;5,793,552;0,058639932
296,168;906,696;5,795,291;0,058629933
297,168;908,692;579,761;0,058629933
298,168;910,712;5,800,469;0,058629933
299,168;912,708;5,801,996;0,058669926
300,168;914,704;5,803,719;0,058659928
301,168;916,692;5,805,988;0,058619935
302,168;918,692;580,853;0,058599938
303,168;920,696;5,810,706;0,058639932
304,168;922,688;5,812,585;0,058609937
305,168;924,696;5,814,758;0,058639932
30,616,803;926,696;5,816,993;0,05864993
30,716,803;928,696;5,818,735;0,058639932
30,816,803;930,704;5,821,149;0,058579942
30,916,803;932,692;5,823,067;0,058629933
31,016,803;934,692;5,825,058;0,058639932
31,116,803;936,712;5,827,968;0,05864993
31,216,803;938,704;5,829,046;0,058639932
31,316,803;9,407;5,831,046;0,058629933
31,416,803;942,688;5,833,076;0,058629933
31,516,803;9,447;5,835,201;0,058629933
31,616,803;946,708;5,837,329;0,058629933
31,716,803;948,696;5,839,109;0,05864993
31,816,803;950,704;5,841,525;0,058689923
31,916,803;9,527;5,843,211;0,058659928
32,016,803;954,696;5,845,043;0,058669926
32,116,803;956,708;5,847,437;0,058629933
32,216,803;958,692;5,848,971;0,058659928
32,316,803;960,688;5,850,852;0,058659928
32,416,803;9,627;5,853,356;0,05864993
32,516,803;964,696;5,854,797;0,05864993
32,616,803;966,696;5,856,892;0,058659928
32,716,803;968,688;5,858,686;0,05864993
32,816,803;970,696;5,860,525;0,058619935
32,916,803;972,692;5,862,594;0,058619935
33,016,803;974,688;5,864,292;0,058659928
33,116,803;976,704;5,866,428;0,058679925
33,216,803;9,787;5,868,114;0,05864993
33,316,803;980,688;5,869,591;0,058639932
33,416,803;982,696;587,193;0,058639932
33,516,803;984,684;5,873,365;0,05864993
33,616,803;986,688;5,875,635;0,058599938
33,716,803;988,704;5,877,737;0,058619935
33,816,803;9,907;587,915;0,058669926
33,916,803;9,927;5,880,928;0,058669926
34,016,803;994,692;5,882,578;0,058659928
34,116,803;996,692;5,884,252;0,058659928
34,216,803;998,692;5,886,114;0,058669926
34,316,803;1,000,684;5,887,774;0,058659928
34,416,803;1,002,692;5,889,372;0,05864993
34,516,803;1,004,672;5,890,844;0,058669926
34,616,803;1,006,676;589,269;0,05864993
34,716,803;1,008,692;5,894,933;0,058629933
34,816,803;1,010,684;589,617;0,058679925
34,916,803;1,012,676;5,897,886;0,058679925
35,016,803;1,014,692;5,900,393;0,058669926
35,116,803;1,016,696;5,901,665;0,058659928
35,216,803;1,018,696;5,903,791;0,058619935
35,316,803;1,020,688;590,507;0,058669926
35,416,803;1,022,684;5,906,893;0,058669926
35,516,803;1,024,684;5,908,682;0,058669926
35,616,803;1,026,672;5,910,197;0,058639932
35,716,803;1,028,688;5,912,215;0,058629933
35,816,803;1,030,688;5,913,666;0,058669926
35,916,803;103,268;5,914,805;0,058659928
36,016,803;1,034,692;5,917,028;0,058619935
36,116,803;103,668;5,918,355;0,058629933
36,216,803;103,868;5,919,757;0,05864993
36,316,803;1,040,692;5,921,867;0,058669926
36,416,803;1,042,704;5,923,304;0,058609937
36,516,803;1,044,708;5,924,934;0,058659928
36,616,803;1,046,688;5,926,167;0,05864993
36,716,803;1,048,692;5,927,925;0,05864993
36,816,803;1,050,688;5,929,607;0,058639932
36,916,803;105,268;5,930,682;0,05864993
37,016,803;1,054,692;5,932,955;0,058669926
37,116,803;1,056,692;5,934,165;0,058669926
37,216,803;1,058,692;5,935,624;0,05864993
37,316,803;1,060,708;5,937,697;0,05864993
37,416,803;1,062,696;5,938,546;0,058679925
37,516,803;1,064,692;594,039;0,058689923
37,616,803;1,066,696;5,942,042;0,058669926
37,716,803;1,068,712;594,358;0,05864993
37,816,803;1,070,712;5,944,846;0,058679925
37,916,803;107,268;5,945,698;0,058679925
38,016,803;1,074,684;5,947,573;0,058659928
38,116,803;1,076,688;5,949,117;0,058639932
38,216,803;1,078,684;5,950,481;0,058699921
38,316,803;1,080,688;5,952,201;0,058679925
38,416,803;108,268;5,953,544;0,058699921
38,516,803;1,084,684;5,954,736;0,058669926
38,616,803;1,086,692;5,956,564;0,058699921
38,716,803;108,868;5,957,514;0,058669926
38,816,803;109,068;5,959,028;0,058679925
38,916,803;1,092,684;5,960,757;0,058669926
39,016,803;109,468;5,962,096;0,058689923
39,116,803;1,096,688;5,963,938;0,058689923
39,216,803;1,098,676;5,964,649;0,058669926
39,316,803;1,100,696;5,966,506;0,058669926
39,416,803;1,102,688;596,763;0,058659928
39,516,803;1,104,676;5,968,857;0,05864993
39,616,803;1,106,696;5,970,659;0,05864993
39,716,803;1,108,692;5,971,764;0,058669926
39,816,803;1,110,692;5,972,965;0,058639932
39,916,803;1,112,704;5,974,794;0,058679925
40,016,803;1,114,688;5,975,658;0,058679925
40,116,803;1,116,692;5,977,163;0,058689923
40,216,803;1,118,696;5,978,729;0,058659928
40,316,803;1,120,704;5,979,545;0,058669926
40,416,803;11,227;5,980,933;0,058659928
40,516,803;1,124,692;5,982,012;0,058669926
40,616,803;1,126,696;5,983,537;0,05864993
40,716,803;1,128,688;5,984,745;0,058669926
40,816,803;1,130,676;5,985,951;0,058679925
40,916,803;1,132,688;5,988,076;0,058669926
41,016,803;1,134,676;5,988,857;0,058669926
41,116,803;113,668;5,990,092;0,058669926
41,216,803;1,138,696;5,991,855;0,058659928
41,316,803;114,068;5,992,547;0,058659928
41,416,803;1,142,688;5,993,898;0,058699921
41,516,803;1,144,684;5,995,399;0,058679925
41,616,803;1,146,696;5,996,544;0,058699921
41,716,803;1,148,696;5,997,527;0,058659928
41,816,803;1,150,684;5,998,869;0,058669926
41,916,803;1,152,692;6,000,091;0,058679925
42,016,803;1,154,676;6,001,242;0,058679925
42,116,803;1,156,672;6,002,299;0,058659928
42,216,803;1,158,688;6,004,169;0,058659928
42,316,803;116,068;6,004,836;0,058699921
42,416,803;116,268;6,006,129;0,058639932
42,516,803;116,468;6,007,549;0,058669926
42,616,803;1,166,672;6,008,537;0,058639932
42,716,803;1,168,668;6,010,004;0,058689923
42,816,803;1,170,668;6,011,131;0,058679925
42,916,803;1,172,684;6,012,633;0,058669926
43,016,803;1,174,692;6,013,409;0,058679925
43,116,803;1,176,672;6,014,124;0,058669926
43,216,803;1,178,676;6,015,664;0,058669926
43,316,803;1,180,668;6,016,622;0,058669926
43,416,803;118,266;6,017,704;0,058679925
43,516,803;1,184,668;6,019,171;0,058679925
43,616,803;1,186,664;6,020,092;0,058669926
43,716,803;1,188,672;6,021,489;0,05870992
43,816,803;1,190,684;6,022,882;0,058639932
43,916,803;119,268;6,023,619;0,058699921
44,016,803;119,468;6,024,835;0,058689923
44,116,803;1,196,676;6,026,102;0,058689923
44,216,803;11,987;6,027,379;0,058689923
44,316,803;1,200,692;6,027,951;0,05870992
44,416,803;1,202,668;6,028,341;0,058669926
44,516,803;1,204,676;603,034;0,05864993
44,616,803;1,206,676;6,031,282;0,05870992
44,716,803;1,208,672;6,032,128;0,058689923
44,816,803;1,210,688;6,033,619;0,058669926
44,916,803;1,212,676;6,034,058;0,058729916
45,016,803;121,468;6,035,157;0,058689923
45,116,803;1,216,688;6,036,619;0,058669926
45,216,803;121,868;6,037,172;0,058669926
45,316,803;1,220,684;6,038,249;0,058699921
45,416,803;1,222,676;6,039,293;0,058689923
45,516,803;1,224,696;604,055;0,058659928
45,616,803;1,226,688;6,041,456;0,05870992
45,716,803;122,868;6,042,212;0,058669926
45,816,803;1,230,692;6,043,819;0,058699921
45,916,803;123,268;6,044,688;0,058729916
46,016,803;1,234,672;6,045,319;0,058679925
46,116,803;1,236,688;6,046,924;0,05870992
46,216,803;1,238,688;6,047,446;0,058669926
46,316,803;1,240,688;6,048,572;0,058729916
46,416,803;1,242,692;60,497;0,058659928
46,516,803;1,244,676;6,050,217;0,058689923
46,616,803;1,246,672;6,051,477;0,058689923
46,716,803;1,248,668;6,052,413;0,058699921
46,816,803;125,068;6,053,642;0,058659928
46,916,803;125,268;605,407;0,058689923
47,016,803;1,254,664;6,055,073;0,058659928
47,116,803;125,668;6,056,294;0,058659928
47,216,803;1,258,664;6,056,864;0,05864993
47,316,803;126,066;6,057,638;0,058669926
47,416,803;1,262,672;6,059,196;0,058669926
47,516,803;1,264,668;6,059,747;0,058659928
47,616,803;1,266,668;6,060,781;0,05870992
47,716,803;1,268,672;6,061,707;0,058689923
47,816,803;1,270,672;6,062,452;0,05864993
47,916,803;1,272,672;6,063,427;0,058689923
48,016,803;1,274,668;6,064,186;0,05864993
48,116,803;1,276,684;6,065,437;0,058659928
48,216,803;1,278,688;606,612;0,05864993
48,316,803;128,068;6,066,729;0,058659928
48,416,803;1,282,684;6,067,901;0,058679925
48,516,803;1,284,672;6,068,045;0,058669926
48,616,803;1,286,664;6,069,031;0,058669926
48,716,803;1,288,688;6,070,578;0,058679925
48,816,803;1,290,684;6,071,013;0,058679925
48,916,803;1,292,688;6,071,807;0,058679925
49,016,803;1,294,684;6,072,581;0,058679925
49,116,803;1,296,684;6,073,406;0,058679925
49,216,803;1,298,684;6,074,499;0,058699921
49,316,803;1,300,676;6,075,042;0,058669926
49,416,803;13,027;6,076,406;0,058689923
49,516,803;1,304,704;607,711;0,05870992
49,616,803;13,067;6,077,358;0,058699921
49,716,803;1,308,696;6,078,562;0,058699921
49,816,803;1,310,692;6,079,324;0,058679925
49,916,803;1,312,684;6,079,844;0,058689923
50,016,803;1,314,696;6,081,223;0,058679925
50,116,803;1,316,688;6,081,405;0,058669926
50,216,803;1,318,688;6,082,718;0,05870992
50,316,803;1,320,692;6,083,468;0,058679925
50,416,803;1,322,692;6,084,171;0,05870992
50,516,803;1,324,692;6,085,084;0,058679925
50,616,803;1,326,688;6,085,904;0,058739914
50,716,803;1,328,704;6,086,835;0,058689923
50,816,803;1,330,704;6,087,167;0,05870992
50,916,803;1,332,696;6,087,731;0,058669926
51,016,803;1,334,684;608,893;0,058699921
51,116,803;1,336,664;6,089,447;0,058659928
51,216,803;1,338,672;6,090,353;0,05870992
51,316,803;1,340,688;6,091,563;0,058699921
51,416,803;1,342,692;6,091,917;0,058659928
51,516,803;1,344,692;6,092,646;0,058679925
51,616,803;1,346,684;6,093,131;0,058699921
51,716,803;1,348,684;609,416;0,058659928
51,816,803;1,350,676;6,095,099;0,058689923
51,916,803;1,352,668;6,095,671;0,058669926
52,016,803;1,354,684;6,096,712;0,058679925
52,116,803;135,668;6,097,054;0,058679925
52,216,803;1,358,672;6,097,651;0,058689923
52,316,803;1,360,684;6,098,733;0,058679925
52,416,803;1,362,672;6,098,998;0,058679925
525,168;1,364,668;609,926;0,058699921
526,168;136,668;6,100,933;0,05864993
527,168;1,368,672;6,101,257;0,058669926
528,168;137,068;6,102,061;0,05870992
529,168;1,372,672;6,102,533;0,058679925
530,168;1,374,676;6,103,101;0,058689923
531,168;1,376,676;6,104,112;0,058699921
532,168;1,378,672;6,104,628;0,05870992
533,168;1,380,688;6,105,528;0,058689923
534,168;138,268;6,105,948;0,058689923
535,168;1,384,672;6,106,349;0,058659928
536,168;1,386,684;6,107,447;0,058699921
537,168;1,388,672;6,107,646;0,058679925
538,168;1,390,668;6,108,214;0,058679925
539,168;1,392,688;6,109,543;0,058699921
540,168;139,468;6,109,631;0,058679925
541,168;139,668;6,110,405;0,05870992
542,168;1,398,672;61,112;0,058689923
543,168;1,400,676;6,111,971;0,05870992
544,168;1,402,676;6,112,598;0,058689923
545,168;1,404,664;6,112,993;0,058729916
546,168;1,406,692;6,114,016;0,058759911
547,168;1,408,688;6,114,187;0,058749913
548,168;1,410,688;6,114,541;0,058699921
549,168;1,412,688;6,115,316;0,058699921
550,168;1,414,672;6,115,612;0,058699921
551,168;1,416,668;6,116,472;0,058729916
552,168;1,418,672;6,117,525;0,058689923
553,168;1,420,676;6,117,615;0,058699921
554,168;142,268;6,118,487;0,058729916
555,168;1,424,668;6,118,937;0,058739914
556,168;1,426,672;6,119,443;0,058699921
557,168;1,428,672;6,120,083;0,058669926
558,168;143,066;6,120,563;0,058699921
559,168;143,268;6,121,734;0,058689923
560,168;143,468;6,121,786;0,058689923
561,168;143,668;612,244;0,058659928
562,168;1,438,688;6,122,954;0,058679925
563,168;1,440,668;6,123,126;0,058689923
564,168;1,442,676;6,123,945;0,058669926
565,168;144,468;6,124,688;0,05870992
566,168;1,446,676;6,124,896;0,058659928
567,168;144,868;6,125,734;0,05870992
568,168;1,450,668;6,126,222;0,058679925
569,168;145,268;6,126,717;0,05870992
570,168;1,454,672;612,744;0,058679925
571,168;1,456,668;6,127,596;0,058719918
572,168;1,458,684;6,128,684;0,058679925
573,168;1,460,696;6,129,147;0,058699921
574,168;1,462,692;6,129,251;0,058689923
575,168;1,464,672;6,129,553;0,058659928
576,168;146,666;6,130,239;0,058699921
577,168;1,468,664;6,130,904;0,058679925
578,168;1,470,676;6,131,658;0,058699921
579,168;1,472,676;6,131,629;0,058719918
580,168;147,468;6,132,377;0,058679925
581,168;1,476,672;6,132,665;0,058699921
582,168;147,868;613,323;0,058679925
583,168;1,480,672;6,133,527;0,058679925
584,168;1,482,664;6,134,048;0,058719918
585,168;1,484,684;6,135,013;0,05870992
586,168;1,486,668;6,134,908;0,058669926
587,168;1,488,668;6,135,334;0,058659928
588,168;1,490,676;6,136,255;0,058699921
589,168;1,492,668;6,136,477;0,05870992
590,168;1,494,668;6,137,192;0,05870992
591,168;1,496,676;613,742;0,058669926
592,168;1,498,676;6,138,048;0,058719918
593,168;1,500,676;6,138,599;0,058689923
594,168;1,502,668;6,138,763;0,05870992
595,168;1,504,676;6,139,351;0,058689923
596,168;1,506,672;6,139,647;0,058759911
597,168;1,508,664;6,139,904;0,05870992
598,168;1,510,696;6,140,934;0,058699921
599,168;1,512,684;614,057;0,058719918
600,168;1,514,676;614,112;0,058669926
601,168;151,668;6,141,866;0,058699921
602,168;1,518,668;6,142,235;0,058729916
603,168;1,520,664;6,142,582;0,058689923
604,168;1,522,668;6,143,396;0,05870992
605,168;1,524,668;6,143,455;0,058689923
606,168;1,526,664;6,144,157;0,058719918
607,168;1,528,664;6,144,356;0,058679925
608,168;1,530,672;6,145,028;0,058669926
609,168;1,532,664;6,145,356;0,058729916
610,168;1,534,656;6,145,537;0,058699921
611,168;1,536,676;6,146,697;0,05870992
612,168;1,538,676;614,649;0,058729916
613,168;154,068;6,146,899;0,058719918
614,168;1,542,688;6,147,519;0,058729916
615,168;1,544,676;614,746;0,058699921
616,168;1,546,672;6,147,925;0,058719918
617,168;1,548,672;6,148,332;0,058699921
618,168;1,550,676;6,148,733;0,05870992
619,168;1,552,676;6,149,151;0,058719918
620,168;1,554,668;6,149,188;0,058689923
621,168;155,668;6,149,832;0,05864993
622,168;1,558,672;615,003;0,058669926
623,168;1,560,664;6,150,212;0,058719918
624,168;1,562,672;6,151,057;0,058719918
625,168;1,564,672;6,151,357;0,058669926
626,168;156,668;6,151,507;0,058729916
627,168;1,568,672;6,151,741;0,058699921
628,168;1,570,664;6,151,892;0,058659928
629,168;1,572,664;615,267;0,058689923
630,168;1,574,664;6,152,904;0,058699921
631,168;1,576,668;6,153,079;0,058699921
632,168;1,578,664;6,153,537;0,058689923
633,168;1,580,652;6,153,648;0,058739914
634,168;1,582,672;6,154,519;0,058719918
635,168;1,584,668;615,452;0,058729916
636,168;1,586,656;6,154,339;0,05870992
637,168;1,588,676;615,533;0,058689923
638,168;1,590,676;6,155,361;0,058699921
639,168;159,268;6,155,439;0,058699921
640,168;1,594,672;6,155,486;0,058689923
641,168;1,596,652;6,155,742;0,058769909
642,168;159,866;6,156,663;0,05870992
643,168;1,600,656;6,157,098;0,058699921
644,168;1,602,664;6,157,265;0,058689923
645,168;1,604,664;6,157,598;0,058699921
646,168;1,606,664;6,157,478;0,058689923
647,168;1,608,676;6,158,001;0,058719918
648,168;1,610,668;6,158,084;0,058689923
649,168;1,612,664;6,158,049;0,058669926
650,168;161,468;6,159,116;0,058699921
651,168;1,616,672;6,158,185;0,058679925
652,168;1,618,668;6,159,284;0,05870992
653,168;1,620,672;6,159,713;0,058689923
654,168;1,622,664;6,159,731;0,05870992
655,168;1,624,668;6,160,153;0,058679925
656,168;162,666;6,160,489;0,058679925
657,168;1,628,668;6,160,727;0,058659928
658,168;1,630,668;6,160,993;0,058679925
659,168;163,266;6,161,419;0,058689923
660,168;1,634,668;6,161,563;0,058669926
661,168;1,636,652;6,161,919;0,058699921
662,168;1,638,652;6,161,941;0,058669926
663,168;1,640,672;6,162,728;0,058639932
664,168;1,642,668;616,253;0,058679925
665,168;1,644,664;6,162,765;0,058679925
666,168;1,646,668;6,162,985;0,058669926
667,168;164,866;6,162,819;0,058679925
668,168;1,650,656;6,163,496;0,058679925
669,168;1,652,648;6,163,447;0,058669926
670,168;165,466;6,164,028;0,058669926
671,168;165,666;6,164,025;0,058699921
672,168;1,658,652;616,419;0,058669926
673,168;1,660,664;616,465;0,058659928
674,168;1,662,656;6,164,605;0,058659928
675,168;1,664,648;6,164,823;0,058689923
676,168;1,666,664;6,165,498;0,05864993
677,168;166,866;6,165,539;0,05870992
678,168;1,670,672;6,165,662;0,058679925
679,168;1,672,676;6,165,718;0,058669926
680,168;1,674,672;6,165,481;0,058699921
681,168;1,676,664;6,165,942;0,05870992
682,168;167,866;6,166,266;0,058679925
683,168;1,680,672;6,166,607;0,058679925
684,168;1,682,672;6,166,835;0,058669926
685,168;1,684,668;6,166,484;0,058689923
686,168;1,686,676;6,166,987;0,058679925
687,168;1,688,668;6,166,972;0,058669926
688,168;1,690,664;6,166,962;0,058669926
689,168;1,692,676;6,167,739;0,058679925
690,168;1,694,668;6,167,421;0,05864993
691,168;169,668;6,168,061;0,058679925
692,168;1,698,684;6,168,028;0,058659928
693,168;1,700,664;6,168,017;0,05870992
694,168;1,702,672;6,168,304;0,058679925
695,168;1,704,668;6,168,347;0,058689923
696,168;170,668;6,168,581;0,058699921
697,168;1,708,672;6,168,606;0,058659928
698,168;1,710,672;6,168,774;0,058679925
699,168;1,712,684;6,169,254;0,058639932
700,168;171,468;6,169,019;0,058659928
701,168;1,716,668;6,169,031;0,058679925
702,168;1,718,684;6,169,854;0,058679925
703,168;1,720,684;6,169,128;0,058699921
704,168;1,722,692;6,169,757;0,058739914
705,168;17,247;6,169,813;0,058689923
706,168;1,726,672;6,169,204;0,058699921
707,168;1,728,676;6,170,013;0,058699921
708,168;1,730,668;6,170,073;0,05870992
709,168;1,732,684;6,170,574;0,058699921
710,168;173,468;6,170,017;0,058669926
711,168;1,736,668;617,017;0,058659928
712,168;1,738,684;6,170,673;0,058679925
713,168;1,740,672;6,170,442;0,058699921
714,168;1,742,664;6,170,434;0,058659928
715,168;1,744,676;6,171,001;0,058679925
716,168;1,746,672;6,170,948;0,058669926
717,168;1,748,676;6,171,252;0,058689923
718,168;1,750,668;6,171,218;0,05870992
719,168;1,752,668;6,171,241;0,058689923
720,168;1,754,672;6,171,461;0,058659928
721,168;1,756,668;617,131;0,058679925
722,168;1,758,676;6,171,479;0,058699921
723,168;1,760,672;617,147;0,058679925
724,168;1,762,668;6,171,402;0,058659928
725,168;1,764,676;6,171,942;0,058679925
726,168;176,666;617,145;0,058699921
727,168;1,768,648;6,171,721;0,058689923
728,168;1,770,668;617,242;0,058689923
729,168;1,772,668;6,172,099;0,058679925
730,168;177,468;6,172,197;0,058669926
731,168;1,776,668;6,171,958;0,058699921
732,168;1,778,668;6,172,085;0,058689923
733,168;178,066;6,172,231;0,058719918
734,168;1,782,652;6,172,497;0,05870992
735,168;1,784,668;6,172,917;0,05870992
736,168;178,666;6,172,808;0,058699921
737,168;1,788,656;6,172,487;0,058689923
738,168;1,790,668;6,172,869;0,058669926
739,168;179,266;6,172,475;0,058689923
740,168;1,794,652;6,172,232;0,058679925
741,168;1,796,668;6,173,036;0,058669926
742,168;1,798,664;6,172,724;0,05870992
743,168;1,800,668;6,173,216;0,058739914
744,168;1,802,668;6,172,924;0,058699921
745,168;180,466;6,172,441;0,05870992
746,168;180,666;6,172,636;0,058699921
747,168;1,808,648;6,172,603;0,058739914
748,168;1,810,668;617,321;0,058699921
749,168;181,266;617,282;0,058689923
750,168;1,814,656;6,172,933;0,058669926
751,168;1,816,668;617,319;0,058699921
752,168;1,818,652;6,172,804;0,058719918
753,168;1,820,652;6,172,599;0,058669926
754,168;1,822,652;6,173,108;0,05870992
755,168;182,466;6,173,291;0,058689923
756,168;1,826,672;6,173,304;0,058719918
757,168;1,828,684;617,317;0,058689923
758,168;1,830,664;6,172,508;0,058699921
759,168;183,266;6,172,854;0,058669926
760,168;1,834,656;6,172,836;0,058739914
761,168;1,836,672;6,173,148;0,058729916
762,168;1,838,664;6,172,642;0,058719918
763,168;1,840,656;6,172,609;0,058679925
764,168;1,842,676;6,173,273;0,058749913
765,168;1,844,664;6,172,491;0,058699921
766,168;1,846,664;6,172,686;0,05870992
767,168;1,848,668;6,173,186;0,058729916
768,168;1,850,668;6,172,903;0,058699921
769,168;1,852,684;6,173,106;0,058699921
770,168;185,468;6,172,673;0,058739914
771,168;1,856,664;617,191;0,058699921
772,168;1,858,656;6,172,246;0,058699921
773,168;186,066;6,172,659;0,058729916
774,168;1,862,676;6,172,724;0,05870992
775,168;1,864,664;6,172,189;0,058689923
776,168;186,666;6,171,869;0,058739914
777,168;1,868,668;6,172,449;0,058739914
778,168;1,870,656;6,172,032;0,058719918
779,168;1,872,656;6,171,872;0,058689923
780,168;1,874,668;6,172,298;0,058719918
781,168;1,876,664;6,171,707;0,058689923
782,168;1,878,672;6,172,184;0,05870992
783,168;188,066;6,171,793;0,058719918
784,168;188,266;617,163;0,058729916
785,168;1,884,664;6,171,574;0,058719918
786,168;1,886,652;6,171,482;0,058739914
787,168;1,888,676;6,171,709;0,05870992
788,168;1,890,664;6,171,343;0,058719918
789,168;1,892,668;6,171,353;0,058699921
790,168;1,894,676;6,171,487;0,058689923
791,168;1,896,668;6,171,026;0,058699921
792,168;1,898,664;6,170,664;0,058739914
793,168;1,900,672;6,171,328;0,058729916
794,168;190,268;6,170,866;0,058689923
795,168;1,904,684;6,170,761;0,05870992
796,168;190,668;6,170,419;0,05870992
797,168;1,908,676;6,170,404;0,058679925
798,168;1,910,676;6,170,458;0,058699921
799,168;1,912,664;6,169,941;0,058719918
800,168;1,914,676;6,170,465;0,05870992
801,168;1,916,672;6,170,041;0,05870992
802,168;1,918,672;616,988;0,05870992
803,168;1,920,684;6,169,809;0,058719918
804,168;1,922,676;6,169,503;0,05870992
805,168;192,468;6,169,411;0,05870992
806,168;1,926,684;6,169,543;0,058729916
807,168;1,928,688;6,169,284;0,058729916
808,168;1,930,692;6,169,115;0,058699921
809,168;1,932,688;6,168,811;0,05870992
810,168;1,934,688;6,168,796;0,058689923
811,168;193,668;6,168,669;0,058699921
812,168;1,938,668;6,168,141;0,058719918
813,168;1,940,684;6,168,663;0,058729916
814,168;194,268;616,828;0,058769909
815,168;194,468;6,168,118;0,058699921
816,168;1,946,688;6,168,171;0,058749913
817,168;194,868;6,167,739;0,058689923
818,168;1,950,676;6,167,865;0,058669926
819,168;1,952,676;6,167,766;0,05870992
820,168;195,468;6,167,596;0,058699921
821,168;1,956,692;616,755;0,058689923
822,168;1,958,688;6,167,127;0,058669926
823,168;1,960,688;6,166,664;0,058719918
824,168;1,962,672;6,166,291;0,058689923
825,168;1,964,664;6,166,254;0,058699921
826,168;1,966,684;616,631;0,058679925
827,168;1,968,668;6,165,881;0,058659928
828,168;1,970,668;6,165,768;0,058689923
829,168;1,972,672;6,165,696;0,05870992
830,168;1,974,664;6,165,221;0,05870992
831,168;1,976,664;6,165,105;0,058679925
832,168;197,866;616,513;0,058659928
833,168;1,980,668;6,164,657;0,058699921
834,168;1,982,672;6,165,166;0,058699921
835,168;1,984,668;616,454;0,058739914
836,168;1,986,672;6,164,265;0,058679925
837,168;1,988,656;6,163,779;0,058699921
838,168;1,990,648;6,163,428;0,058679925
839,168;1,992,676;6,163,777;0,058689923
840,168;1,994,668;6,162,961;0,058669926
841,168;1,996,668;6,162,762;0,058679925
842,168;1,998,672;6,162,836;0,05870992
843,168;2,000,664;6,162,469;0,058699921
844,168;2,002,668;6,162,159;0,058679925
845,168;2,004,664;6,162,063;0,058719918
846,168;200,668;6,161,667;0,058719918
847,168;2,008,676;6,161,439;0,058689923
848,168;2,010,672;6,160,909;0,05870992
849,168;201,268;6,160,975;0,058719918
850,168;2,014,668;6,160,527;0,058679925
851,168;2,016,668;6,160,231;0,058679925
852,168;2,018,688;6,160,749;0,05870992
853,168;2,020,684;6,159,814;0,058719918
854,168;2,022,676;6,159,338;0,05870992
855,168;2,024,684;6,159,463;0,058689923
856,168;2,026,676;615,887;0,058679925
857,168;2,028,672;6,158,435;0,058699921
858,168;2,030,672;6,158,225;0,058719918
859,168;2,032,684;6,158,573;0,058689923
860,168;2,034,688;6,158,253;0,058719918
861,168;2,036,668;6,157,495;0,058689923
862,168;203,868;6,157,437;0,058689923
863,168;2,040,668;6,157,007;0,058699921
864,168;204,266;6,156,332;0,058699921
865,168;2,044,672;6,156,435;0,058659928
866,168;2,046,664;6,155,654;0,058669926
867,168;204,866;6,155,246;0,058669926
868,168;205,066;6,155,482;0,058699921
869,168;205,266;6,154,943;0,058699921
870,168;2,054,664;6,154,861;0,058699921
871,168;205,666;6,154,303;0,058679925
872,168;2,058,668;6,153,957;0,05870992
873,168;2,060,672;6,153,543;0,05870992
874,168;2,062,664;6,153,147;0,05870992
875,168;2,064,668;6,152,841;0,058699921
876,168;206,666;6,152,117;0,058679925
877,168;2,068,648;615,176;0,058669926
878,168;2,070,676;6,152,061;0,058659928
879,168;2,072,664;6,151,108;0,05864993
880,168;2,074,672;6,150,732;0,058679925
881,168;2,076,668;6,150,436;0,058659928
882,168;2,078,664;6,149,891;0,058659928
883,168;2,080,664;6,149,353;0,058659928
884,168;208,266;6,148,757;0,058679925
885,168;2,084,668;6,148,766;0,058699921
886,168;2,086,664;6,148,461;0,058669926
887,168;2,088,676;6,147,904;0,058699921
888,168;2,090,692;614,776;0,058639932
889,168;2,092,668;6,146,719;0,058639932
890,168;2,094,656;6,146,237;0,058679925
891,168;209,668;6,146,695;0,058659928
892,168;2,098,672;6,145,215;0,058669926
893,168;2,100,672;6,145,086;0,058669926
894,168;2,102,672;6,145,105;0,058679925
895,168;2,104,676;6,144,332;0,058669926
896,168;2,106,684;6,143,827;0,05864993
897,168;2,108,672;6,143,075;0,058659928
898,168;211,068;6,142,666;0,058669926
899,168;211,268;6,142,208;0,058659928
900,168;2,114,688;6,141,515;0,058629933
901,168;2,116,696;6,141,086;0,058699921
902,168;2,118,664;6,140,401;0,05864993
903,168;2,120,664;6,140,171;0,058699921
904,168;2,122,688;6,140,409;0,058699921
905,168;2,124,684;6,139,141;0,058659928
906,168;212,668;6,138,616;0,058679925
907,168;212,868;613,816;0,058659928
908,168;2,130,672;613,705;0,05864993
909,168;2,132,676;61,37;0,05870992
910,168;2,134,668;613,647;0,058689923
911,168;2,136,672;6,136,428;0,058689923
912,168;2,138,672;6,135,767;0,05870992
913,168;2,140,668;6,135,034;0,058699921
914,168;2,142,684;6,134,611;0,058699921
915,168;2,144,668;6,133,641;0,058669926
916,168;2,146,668;6,133,056;0,058679925
917,168;2,148,684;6,132,782;0,058689923
918,168;2,150,672;6,131,679;0,058699921
919,168;2,152,676;6,131,265;0,058699921
920,168;2,154,672;6,130,657;0,058689923
921,168;215,668;6,129,839;0,058679925
922,168;2,158,676;6,129,235;0,058659928
923,168;2,160,668;6,128,568;0,058719918
924,168;2,162,684;6,127,971;0,058699921
925,168;2,164,684;6,127,306;0,058699921
926,168;2,166,676;6,126,079;0,058659928
927,168;216,868;6,125,956;0,05864993
928,168;2,170,672;6,125,047;0,058669926
929,168;2,172,668;6,124,187;0,058699921
930,168;217,468;6,124,005;0,058659928
931,168;2,176,676;6,122,691;0,058689923
932,168;2,178,676;6,122,178;0,058669926
933,168;2,180,668;612,138;0,058689923
934,168;2,182,668;6,120,549;0,058669926
935,168;2,184,672;612,008;0,05870992
936,168;2,186,664;6,119,263;0,058689923
937,168;2,188,684;6,118,717;0,058719918
938,168;2,190,684;6,117,732;0,058699921
939,168;2,192,684;611,668;0,058729916
940,168;2,194,692;6,115,999;0,058669926
941,168;219,668;6,114,851;0,058689923
942,168;2,198,672;6,113,729;0,058669926
943,168;220,068;6,113,728;0,058699921
944,168;2,202,672;6,112,555;0,058699921
945,168;2,204,676;6,111,855;0,058729916
946,168;2,206,676;6,110,684;0,05870992
947,168;2,208,672;6,109,506;0,058719918
948,168;221,068;6,108,902;0,05870992
949,168;2,212,668;6,107,829;0,058669926
950,168;2,214,676;6,107,284;0,058679925
951,168;2,216,668;6,106,214;0,05864993
952,168;2,218,672;6,105,574;0,058689923
953,168;2,220,692;6,104,795;0,05870992
954,168;2,222,676;6,102,914;0,058689923
955,168;2,224,668;6,101,829;0,058699921
956,168;2,226,684;6,101,658;0,058699921
957,168;222,868;6,099,973;0,058719918
958,168;2,230,676;6,099,024;0,058699921
959,168;2,232,668;6,098,059;0,058689923
960,168;2,234,668;6,096,912;0,058699921
961,168;2,236,676;60,963;0,058699921
962,168;2,238,668;6,094,819;0,05870992
963,168;224,068;6,094,105;0,058639932
964,168;224,268;6,092,833;0,058719918
965,168;224,468;609,166;0,058689923
966,168;2,246,692;6,090,667;0,058699921
967,168;2,248,664;6,088,793;0,05864993
968,168;2,250,652;6,087,843;0,058669926
969,168;2,252,664;6,087,338;0,058689923
970,168;2,254,668;6,085,885;0,058659928
971,168;225,668;6,084,448;0,058659928
972,168;2,258,668;6,082,835;0,058689923
973,168;2,260,676;6,081,721;0,058689923
974,168;2,262,672;6,080,387;0,05864993
975,168;2,264,664;6,078,944;0,058689923
976,168;2,266,672;6,078,041;0,058689923
977,168;2,268,668;6,076,533;0,058689923
978,168;2,270,672;6,075,004;0,058729916
979,168;2,272,684;607,393;0,058659928
980,168;2,274,672;6,071,923;0,058719918
981,168;2,276,668;6,070,573;0,058659928
982,168;2,278,684;6,069,843;0,058689923
983,168;2,280,676;6,067,874;0,058679925
984,168;228,268;6,066,681;0,058659928
985,168;2,284,668;6,064,944;0,058659928
986,168;2,286,676;6,063,568;0,05870992
987,168;2,288,676;606,182;0,058679925
988,168;229,066;6,060,042;0,058659928
989,168;2,292,684;6,059,147;0,058699921
990,168;229,468;6,057,402;0,058689923
991,168;229,668;6,055,678;0,058689923
992,168;2,298,688;6,054,449;0,058699921
993,168;2,300,676;6,052,505;0,058659928
994,168;2,302,672;6,050,681;0,058689923
995,168;2,304,676;6,049,349;0,058699921
996,168;2,306,672;6,047,239;0,058679925
997,168;2,308,676;6,045,921;0,058689923
998,168;2,310,672;604,374;0,058679925
999,168;2,312,684;6,042,249;0,058659928
1,000,168;231,468;6,040,406;0,058679925
1,001,168;2,316,668;6,037,986;0,058689923
1,002,168;2,318,684;6,037,116;0,058669926
1,003,168;232,068;6,034,639;0,058659928
1,004,168;2,322,688;6,033,095;0,05864993
1,005,168;2,324,704;6,031,405;0,058639932
1,006,168;2,326,692;6,029,068;0,05864993
1,007,168;2,328,684;6,027,062;0,058669926
1,008,168;2,330,684;6,025,538;0,058669926
1,009,168;2,332,684;6,023,497;0,058599938
1,010,168;2,334,688;6,021,647;0,058659928
1,011,168;2,336,684;6,019,158;0,058629933
1,012,168;2,338,692;6,017,013;0,058639932
1,013,168;2,340,688;6,014,997;0,05864993
1,014,168;2,342,684;6,012,807;0,058639932
1,015,168;23,447;6,011,237;0,058629933
1,016,168;2,346,692;6,008,553;0,058659928
1,017,168;2,348,692;6,006,517;0,058619935
1,018,168;2,350,708;6,004,882;0,058659928
1,019,168;2,352,696;6,001,626;0,05864993
1,020,168;2,354,684;5,999,542;0,058609937
1,021,168;2,356,692;5,997,565;0,058639932
1,022,168;2,358,696;5,995,263;0,058619935
1,023,168;2,360,696;599,297;0,05864993
102,416,806;2,362,684;5,990,348;0,058639932
102,516,806;2,364,696;5,988,212;0,058619935
102,616,806;2,366,692;5,985,753;0,05864993
102,716,806;2,368,684;5,983,098;0,058659928
102,816,806;2,370,696;5,980,985;0,058669926
102,916,806;2,372,692;5,978,094;0,058639932
103,016,806;2,374,696;5,975,823;0,058659928
103,116,806;2,376,712;5,973,688;0,058619935
103,216,806;23,787;5,970,611;0,058629933
103,316,806;2,380,676;5,967,989;0,058659928
103,416,806;238,268;5,966,121;0,058679925
103,516,806;2,384,692;596,301;0,058669926
103,616,806;2,386,696;5,960,692;0,058639932
103,716,806;2,388,684;5,957,404;0,05864993
103,816,806;2,390,692;5,955,065;0,05864993
103,916,806;2,392,688;5,952,086;0,058699921
104,016,806;2,394,676;5,949,343;0,058679925
104,116,806;2,396,692;5,947,067;0,05864993
104,216,806;2,398,684;5,943,918;0,05864993
104,316,806;2,400,688;5,941,351;0,058669926
104,416,806;24,027;593,859;0,058699921
104,516,806;2,404,692;5,935,307;0,058689923
104,616,806;2,406,692;5,932,257;0,058689923
104,716,806;2,408,696;5,929,591;0,058659928
104,816,806;2,410,704;5,926,359;0,058699921
104,916,812;24,127;5,923,477;0,058679925
105,016,812;2,414,688;5,920,256;0,05864993
105,116,812;24,167;5,917,506;0,05864993
105,216,812;2,418,692;591,418;0,05864993
105,316,812;2,420,688;5,911,032;0,05864993
105,416,812;24,227;5,908,481;0,058659928
105,516,812;24,247;5,904,735;0,058679925
105,616,812;24,267;5,901,579;0,058669926
105,716,812;2,428,708;5,898,369;0,058679925
105,816,812;2,430,696;5,894,671;0,05864993
105,916,812;2,432,696;58,918;0,05864993
106,016,812;2,434,696;5,888,409;0,058659928
106,116,812;2,436,696;5,884,998;0,05864993
106,216,812;24,387;5,881,689;0,058659928
106,316,812;2,440,692;5,877,877;0,058659928
106,416,812;2,442,708;5,874,462;0,05864993
106,516,812;24,447;5,870,938;0,058639932
106,616,812;2,446,692;5,867,294;0,058659928
106,716,812;2,448,704;5,864,232;0,058659928
106,816,812;2,450,696;5,860,425;0,058669926
106,916,812;2,452,708;5,856,612;0,058659928
107,016,812;2,454,712;585,328;0,05864993
107,116,812;2,456,708;5,849,187;0,05864993
107,216,812;2,458,696;5,845,315;0,058679925
107,316,812;2,460,688;5,841,874;0,058669926
107,416,812;2,462,696;5,838,052;0,058659928
107,516,812;2,464,696;5,834,317;0,058659928
107,616,812;2,466,692;5,830,262;0,05864993
107,716,812;24,687;5,826,608;0,058689923
107,816,812;2,470,692;5,822,406;0,058659928
107,916,812;2,472,684;581,802;0,058669926
108,016,812;2,474,704;5,814,711;0,058679925
108,116,812;2,476,696;58,101;0,05864993
108,216,812;24,787;5,806,274;0,058659928
108,316,812;2,480,708;5,802,484;0,058639932
108,416,812;2,482,712;5,797,995;0,058679925
108,516,812;2,484,704;5,793,548;0,058639932
108,616,812;2,486,692;5,789,313;0,058669926
108,716,812;2,488,712;5,785,196;0,05864993
108,816,812;2,490,712;5,780,905;0,05864993
108,916,812;2,492,708;5,776,259;0,058659928
109,016,812;2,494,712;5,772,153;0,05870992
109,116,812;2,496,708;5,767,679;0,058659928
109,216,812;2,498,708;5,763,171;0,058659928
109,316,812;2,500,724;5,759,218;0,058679925
109,416,812;250,272;5,753,779;0,058659928
109,516,812;2,504,724;5,749,459;0,058659928
109,616,812;250,674;5,745,287;0,058659928
109,716,812;2,508,736;574,006;0,058629933
109,816,812;2,510,712;573,487;0,058689923
109,916,812;2,512,712;5,730,721;0,05870992
110,016,812;2,514,732;5,726,197;0,058639932
110,116,812;2,516,736;5,721,301;0,058669926
110,216,812;2,518,724;5,715,768;0,058689923
110,316,812;2,520,736;5,711,061;0,058679925
110,416,812;2,522,724;5,705,903;0,058699921
110,516,812;252,472;5,701,007;0,058689923
110,616,812;2,526,736;5,696,542;0,058699921
110,716,812;2,528,728;5,690,978;0,058689923
110,816,812;2,530,728;5,686,184;0,058719918
110,916,812;2,532,728;5,681,044;0,058679925
111,016,812;2,534,724;5,675,392;0,058659928
111,116,812;253,672;567,001;0,058679925
111,216,812;253,872;5,664,781;0,058669926
111,316,812;2,540,736;5,659,714;0,058639932
111,416,812;2,542,732;5,654,071;0,058679925
111,516,812;2,544,728;5,648,285;0,05864993
111,616,812;2,546,736;5,643,167;0,058659928
111,716,812;2,548,724;5,637,465;0,058659928
111,816,812;2,550,712;5,631,704;0,05870992
111,916,812;2,552,728;5,626,419;0,05870992
112,016,812;2,554,728;5,620,108;0,058699921
112,116,812;255,674;5,614,544;0,058699921
112,216,812;2,558,736;5,608,578;0,058689923
112,316,812;2,560,732;5,602,441;0,058669926
112,416,812;2,562,724;5,596,711;0,058699921
112,516,812;256,472;5,590,786;0,05864993
112,616,812;2,566,728;5,584,761;0,058689923
112,716,812;256,872;5,578,678;0,058639932
112,816,812;2,570,712;5,572,236;0,058659928
112,916,812;2,572,728;5,566,354;0,058659928
113,016,812;2,574,716;5,559,801;0,058689923
113,116,812;2,576,712;555,336;0,058679925
113,216,812;2,578,728;5,547,622;0,058659928
113,316,812;2,580,724;5,540,552;0,05864993
113,416,812;2,582,736;553,456;0,05870992
113,516,812;2,584,732;552,756;0,058679925
113,616,812;2,586,736;5,520,519;0,058679925
113,716,812;2,588,736;5,513,821;0,058659928
113,816,812;2,590,724;5,506,701;0,058669926
113,916,812;2,592,732;5,500,074;0,058699921
114,016,812;2,594,728;5,493,057;0,058689923
114,116,812;2,596,728;5,485,983;0,05870992
114,216,812;259,874;5,479,105;0,058659928
114,316,812;2,600,728;5,471,762;0,058689923
114,416,812;2,602,728;5,464,274;0,058669926
114,516,812;260,474;5,457,455;0,058669926
114,616,812;260,674;5,449,388;0,058699921
114,716,812;260,874;5,442,055;0,058679925
114,816,812;2,610,748;5,434,903;0,058669926
114,916,812;2,612,756;5,426,905;0,058679925
115,016,812;2,614,748;5,418,929;0,058679925
115,116,812;2,616,736;5,411,434;0,058669926
115,216,812;2,618,752;5,403,829;0,058659928
115,316,812;2,620,752;539,546;0,058679925
115,416,812;2,622,748;5,387,331;0,058659928
115,516,812;2,624,756;5,379,587;0,058699921
115,616,812;2,626,748;5,371,273;0,058669926
115,716,812;2,628,748;5,363,193;0,058659928
115,816,812;263,076;5,355,178;0,058689923
115,916,812;2,632,748;5,346,186;0,058639932
116,016,812;2,634,756;5,337,613;0,058689923
116,116,812;2,636,756;5,329,118;0,058669926
116,216,812;2,638,768;5,319,818;0,058659928
116,316,812;264,076;5,311,064;0,058669926
116,416,812;264,274;5,302,263;0,058689923
116,516,812;264,476;5,293,773;0,058659928
116,616,812;2,646,764;5,284,473;0,058679925
116,716,812;264,876;5,274,884;0,058689923
116,816,812;2,650,764;5,266,046;0,058679925
116,916,812;2,652,756;5,255,996;0,058669926
117,016,812;2,654,752;5,246,599;0,058689923
117,116,812;2,656,768;5,237,198;0,058689923
117,216,812;2,658,764;5,227,198;0,058689923
117,316,812;2,660,764;5,217,431;0,058729916
117,416,812;2,662,764;5,207,464;0,058699921
117,516,812;2,664,764;5,197,324;0,058699921
117,616,812;266,676;5,186,933;0,05864993
117,716,812;2,668,748;5,176,651;0,058679925
117,816,812;2,670,772;5,166,163;0,05870992
117,916,812;2,672,772;5,155,353;0,058679925
118,016,812;2,674,772;5,144,614;0,058679925
118,116,812;267,678;5,134,119;0,058639932
118,216,812;2,678,776;5,122,991;0,058699921
118,316,812;2,680,772;5,111,815;0,058669926
118,416,812;2,682,776;5,100,955;0,058669926
118,516,812;2,684,776;5,088,735;0,058699921
118,616,812;2,686,784;5,077,539;0,058669926
118,716,812;2,688,784;5,065,513;0,058659928
118,816,812;2,690,788;5,053,499;0,058669926
118,916,812;2,692,784;504,158;0,058669926
119,016,812;2,694,776;5,029,222;0,058679925
119,116,812;2,696,792;5,017,117;0,058699921
119,216,812;269,878;5,004,362;0,05864993
119,316,812;2,700,776;499,142;0,058659928
119,416,812;270,278;4,978,903;0,058679925
119,516,812;2,704,772;4,965,439;0,058669926
119,616,812;2,706,776;4,952,364;0,058669926
119,716,812;2,708,784;4,939,224;0,058689923
119,816,812;2,710,788;4,925,226;0,058679925
119,916,812;2,712,792;4,911,325;0,058679925
120,016,812;2,714,796;4,897,211;0,058659928
120,116,812;2,716,808;488,277;0,058639932
120,216,812;27,188;4,867,896;0,058669926
120,316,812;2,720,796;4,852,587;0,058669926
120,416,812;2,722,808;4,837,991;0,058679925
120,516,812;2,724,804;482,223;0,058679925
120,616,812;27,268;4,806,765;0,058669926
120,716,812;2,728,812;479,064;0,058729916
120,816,812;2,730,804;4,774,022;0,058699921
120,916,812;27,328;4,756,848;0,058669926
121,016,812;2,734,808;4,738,884;0,05870992
121,116,812;2,736,816;4,715,959;0,058679925
1212,02;2,738,524;4,651,235;0,058689923
121,208,012;2,738,716;4,056,079;0,058339983
1,212,092;273,884;2,550,116;0,054160701