File: tensile_test_ontology_TTO/data/primary_data/Zx1.csv
Time;Crosshead travel;Force;Strain
(s);(mm);(kN);(%)
0;0;0,25459;0
0,2;0,00284;0,25807;5,00E-05
0,4;0,00888;0,28904;0,000159906
0,596;0,01936;0,46857;0,000969432
0,754;0,03116;0,66987;0,002028812
0,926;0,04748;0,87257;0,002848332
1,126;0,07236;101,332;0,003188133
1,326;0,10336;117,029;0,003977671
1,49;0,13296;137,123;0,004767209
1,634;0,1618;157,409;0,005646694
1,76;0,18932;178,015;0,006516185
1,872;0,21544;198,614;0,007355693
1,972;0,23992;218,888;0,008195202
2,062;0,26284;239,256;0,009044704
2,144;0,2844;259,737;0,009914195
2,222;0,30552;280,477;0,010843651
2,294;0,32544;300,981;0,011793095
2,362;0,34472;321,446;0,012762528
2,426;0,36316;341,894;0,013681989
2,49;0,38188;363,078;0,014641427
2,552;0,4002;383,985;0,015560889
2,612;0,41808;405,074;0,016490345
2,668;0,43508;425,798;0,017399812
2,722;0,45164;446,526;0,018359251
2,774;0,46768;466,847;0,019258724
2,826;0,48392;487,436;0,020198174
2,878;0,50024;508,633;0,021207583
2,928;0,51612;529,302;0,022137039
2,976;0,5314;54,964;0,0230565
3,024;0,54672;570,415;0,023925991
3,072;0,56212;591,683;0,024925406
3,118;0,577;612,365;0,025814885
3,164;0,59192;63,341;0,026714359
3,208;0,60624;653,732;0,02763382
3,252;0,6206;674,305;0,028493317
3,296;0,63508;695,095;0,029322831
3,34;0,64956;716,064;0,030292264
3,384;0,66404;737,119;0,031241708
3,428;0,67852;758,395;0,032171164
3,472;0,69316;779,965;0,033040655
3,514;0,70716;8,01;0,03392014
3,554;0,72052;821,304;0,034769642
3,594;0,73392;841,738;0,035639133
3,634;0,74728;862,211;0,036528612
3,674;0,76068;882,922;0,037408098
3,714;0,77412;903,965;0,038297577
3,754;0,78756;925,144;0,039207044
3,794;0,801;946,209;0,040176477
3,834;0,81448;967,379;0,041105932
3,874;0,828;988,475;0,041975423
3,914;0,84156;1,009,624;0,042884891
3,954;0,85512;1,030,955;0,043754382
3,994;0,86864;105,223;0,044663849
4,034;0,88216;1,073,364;0,04553334
4,074;0,89572;1,094,545;0,046402831
4,114;0,90928;1,115,729;0,047282316
4,154;0,92276;1,136,583;0,048111831
4,194;0,93632;1,157,127;0,04900131
4,234;0,94984;117,793;0,049880795
4,274;0,96348;1,198,436;0,050700315
4,314;0,97716;1,218,735;0,051649759
4,354;0,9908;1,239,112;0,052529244
4,394;100,452;1,259,504;0,053438712
4,436;101,896;1,280,646;0,054378162
4,476;103,272;1,301,419;0,055247652
4,516;104,652;1,322,652;0,056077167
4,556;106,036;1,343,749;0,056986634
4,596;107,432;1,364,886;0,057876114
4,636;108,828;1,386,472;0,058805569
4,676;11,022;1,407,812;0,059645078
4,716;111,596;1,428,864;0,060584528
4,756;112,968;145,015;0,061503989
4,796;114,348;1,471,569;0,062383474
4,836;11,574;1,493,046;0,063302936
4,876;117,132;151,499;0,064222398
4,916;11,852;1,536,892;0,06519183
4,956;119,908;1,558,603;0,066101298
4,996;121,304;1,580,737;0,067060736
5,032;12,256;1,600,949;0,067920233
5,072;123,952;1,622,932;0,068899659
5,112;125,348;1,644,664;0,069799133
5,15;126,676;1,665,721;0,070678618
5,19;128,072;168,768;0,07164805
5,23;12,948;1,709,542;0,072577506
5,27;13,088;1,731,593;0,073506962
5,31;132,268;1,753,298;0,074416429
5,35;13,366;1,774,422;0,075355879
5,39;135,056;1,795,977;0,076255352
5,43;13,646;1,818,023;0,077154826
5,47;137,868;1,839,861;0,078094276
5,51;139,272;1,861,783;0,079033726
5,546;140,536;1,881,841;0,079903217
5,586;141,936;1,903,705;0,08092262
5,626;14,334;1,925,679;0,081852076
5,664;144,664;1,946,704;0,08280152
5,704;146,056;1,968,675;0,083780946
5,744;147,456;1,990,573;0,084690414
5,782;148,788;2,011,689;0,085609875
5,82;15,012;2,032,851;0,086549325
5,86;15,152;2,055,011;0,087518758
5,896;152,784;2,075,221;0,088358266
5,932;15,404;2,095,728;0,089247745
5,97;155,372;2,116,911;0,090167207
6,006;156,624;21,371;0,091086669
6,042;157,876;2,157,574;0,09195616
6,078;159,124;2,177,994;0,092925592
6,116;160,444;2,199,205;0,093905019
6,152;161,696;2,219,353;0,09482448
6,188;162,944;2,239,767;0,095713959
6,224;164,192;2,260,044;0,096573456
6,262;165,512;2,281,182;0,097532894
6,298;166,764;2,301,519;0,098432368
6,334;168,012;2,321,984;0,099321847
6,37;169,264;2,342,517;0,100261297
6,406;170,512;2,362,917;0,101180759
6,442;171,748;2,383,303;0,102150191
6,478;172,984;2,403,602;0,103079647
6,514;174,224;2,423,797;0,10397912
6,55;17,546;2,444,247;0,104948553
6,586;176,696;246,491;0,105878008
6,622;177,932;248,522;0,106787476
6,658;179,164;2,505,407;0,107746914
6,694;180,392;2,525,612;0,10867637
6,73;181,628;2,545,824;0,109595832
6,766;182,856;2,565,963;0,110565264
6,804;184,152;2,587,176;0,111544691
6,84;185,372;2,607,511;0,112494135
6,876;186,588;2,627,886;0,113533526
6,912;187,808;2,648,114;0,114442994
6,948;189,024;266,844;0,115442408
6,984;190,236;2,689,016;0,116401847
7,022;191,508;2,710,203;0,117451232
7,06;192,776;2,731,327;0,118440653
7,096;193,976;2,751,402;0,11942008
7,132;195,176;2,771,574;0,120399506
7,172;1,965;2,793,386;0,121498862
7,212;197,816;2,815,133;0,122608213
7,252;199,132;2,836,956;0,123707569
7,292;200,444;2,858,675;0,124806926
7,332;20,176;2,880,497;0,125906282
7,37;2,03;2,901,559;0,126975656
7,406;204,172;2,921,615;0,127945088
7,446;205,472;2,943,365;0,129054439
7,486;206,768;296,509;0,130163789
7,526;20,806;2,987,104;0,131313116
7,564;20,928;3,007,991;0,132422467
7,604;21,056;3,029,343;0,133641753
7,644;211,836;3,050,786;0,134841051
7,684;213,108;3,072,217;0,136010366
7,724;214,376;3,093,412;0,137159693
7,764;21,564;3,114,412;0,138289032
7,804;216,892;3,135,505;0,139468341
7,844;21,814;3,156,556;0,140587686
7,884;21,938;3,177,214;0,141757001
7,924;220,616;3,198,082;0,142946305
7,964;221,844;3,219,241;0,14423555
8,004;223,064;3,239,951;0,145454836
8,044;224,276;326,037;0,146694111
8,084;225,476;328,062;0,147973362
8,124;226,672;3,300,915;0,149192648
8,166;22,792;3,321,708;0,150471899
8,21;22,922;3,343,321;0,151781132
8,254;230,512;336,493;0,153180313
8,298;231,792;3,386,362;0,154539517
8,342;23,306;3,407,151;0,155978674
8,386;234,328;3,428,306;0,157307896
8,43;23,558;3,449,536;0,158697083
8,474;236,824;347,037;0,160106258
8,518;238,068;3,491,198;0,161545415
8,562;2,393;3,512,118;0,163044537
8,606;240,516;3,532,874;0,164583636
8,652;241,756;3,553,532;0,166132729
8,7;243,024;357,416;0,167671828
8,748;244,284;3,595,051;0,16917095
8,796;245,528;3,615,432;0,170750026
8,844;246,776;3,635,729;0,172309113
8,892;248,008;3,656,163;0,173908177
8,942;249,272;36,769;0,175657153
8,994;250,568;3,698,046;0,177426117
9,046;251,844;371,879;0,17926504
9,098;253,108;3,739,696;0,18102401
9,15;254,356;3,760,229;0,182802969
9,204;255,628;378,092;0,184721845
9,26;25,692;3,802,006;0,186720675
9,316;258,188;3,822,427;0,188689522
9,376;259,532;3,843,572;0,190818276
9,436;260,844;3,864,395;0,192937035
9,498;262,164;3,885,251;0,19511576
9,562;263,484;39,055;0,197434402
9,628;264,808;3,926,066;0,199703074
9,696;266,152;3,946,909;0,20215164
9,764;267,468;3,967,322;0,204530248
9,836;26,882;3,987,943;0,207198685
9,908;270,132;4,008,056;0,209717211
9,986;271,504;4,028,809;0,212505578
10,068;272,892;4,049,249;0,215443858
10,152;27,426;4,069,499;0,218432108
10,242;275,664;4,089,783;0,221560276
10,338;277,104;4,110,347;0,224798381
10,44;278,564;4,130,566;0,228396274
10,546;280,016;415,087;0,23202415
10,66;2,815;4,171,076;0,235711991
10,784;283,028;4,191,545;0,239849568
10,916;284,564;4,211,682;0,24416704
11,06;286,148;4,232,126;0,248824313
11,212;287,716;425,223;0,253511569
11,388;289,384;4,272,556;0,258988362
11,576;291,056;4,292,823;0,264435173
11,776;292,736;4,312,935;0,270331721
11,976;294,312;4,331,096;0,276008397
12,176;295,792;4,347,445;0,281645097
12,376;297,196;4,362,523;0,287141878
12,576;298,528;4,376,975;0,292588689
12,776;299,832;4,390,849;0,297945553
12,976;301,048;4,403,107;0,30326244
13,176;302,216;4,414,779;0,308559339
13,376;303,332;4,425,581;0,313826255
13,576;304,416;4,435,752;0,318973241
13,776;305,488;4,446,032;0,324360087
13,976;306,504;4,455,381;0,329646992
14,176;307,468;4,463,208;0,334863937
14,376;308,392;4,470,536;0,340100871
14,576;309,296;4,477,484;0,34515791
14,776;310,176;4,484,489;0,350274914
14,976;31,104;449,109;0,355381924
15,176;311,916;449,875;0,360538904
15,376;312,768;4,505,197;0,365765844
15,576;313,576;4,510,241;0,370992784
15,776;314,352;4,514,575;0,375999852
15,976;315,124;4,519,769;0,381076879
16,176;315,876;4,524,472;0,386103936
16,376;316,604;4,528,544;0,391061034
16,576;317,328;453,258;0,39603812
16,776;318,072;4,537,522;0,4010252
16,976;318,792;4,541,587;0,406162192
17,176;319,492;4,545,055;0,411229225
17,376;320,164;4,547,834;0,416326241
17,576;320,828;4,550,449;0,421323315
17,776;321,476;455,288;0,426340378
17,976;322,132;4,555,687;0,431347446
18,176;322,768;4,557,903;0,43646445
18,376;3,234;456,003;0,441301618
18,576;324,028;4,562,241;0,446388639
18,776;324,664;4,564,736;0,451445679
18,976;325,292;4,566,627;0,456552688
19,176;326,072;4,571,024;0,45735222
19,376;32,704;4,583,232;0,464647949
19,576;327,736;4,579,279;0,471384005
19,776;328,268;4,570,995;0,477300541
19,976;328,748;4,563,796;0,482337591
20,176;329,236;4,559,273;0,487084812
20,376;329,768;4,557,202;0,491542202
20,576;33,034;4,557,114;0,496339393
20,776;330,956;4,557,365;0,50112659
20,976;33,158;4,557,061;0,506213612
21,176;332,196;4,555,758;0,511260657
21,376;332,776;4,553,514;0,516367667
21,576;333,352;4,551,505;0,521174852
21,776;333,936;4,550,862;0,526042002
21,976;334,528;4,550,637;0,530939135
22,176;335,132;4,550,982;0,535776303
22,376;335,744;4,551,198;0,540753389
22,576;336,348;4,550,875;0,545750463
22,776;336,956;4,550,724;0,550687572
22,976;337,584;4,551,342;0,555814571
23,176;338,204;455,151;0,561081487
23,376;3,388;4,550,376;0,566368391
23,576;339,356;4,548,137;0,571525372
23,776;339,888;4,545,611;0,576522446
23,976;340,428;4,543,751;0,581369608
24,176;340,988;4,543,274;0,586326706
24,376;34,156;4,543,023;0,59144371
24,576;342,116;4,541,607;0,596460772
24,776;342,656;4,540,161;0,601457846
24,976;343,232;4,539,307;0,60522564
25,176;344,092;454,934;0,609683031
25,376;34,476;4,547,582;0,616169233
25,576;345,256;4,540,106;0,62230564
25,776;345,676;4,532,478;0,627442632
25,976;346,108;4,528,385;0,632119894
26,176;34,658;4,527,142;0,636747185
26,376;347,076;452,742;0,641514393
26,576;347,596;4,528,411;0,646191655
26,776;34,812;4,529,175;0,651188729
26,976;34,864;4,529,224;0,656145827
27,176;349,148;4,528,894;0,661222854
27,376;349,656;4,528,251;0,666169957
27,576;350,176;4,528,058;0,671226997
27,776;350,708;4,528,287;0,676284036
27,976;351,236;4,528,473;0,681530964
28,176;351,744;4,527,566;0,686657962
28,376;352,228;4,526,101;0,691794954
28,576;352,704;4,524,565;0,696662104
28,776;353,172;4,523,419;0,701659179
28,976;353,656;4,522,756;0,706546317
29,176;354,156;4,522,999;0,711463438
29,376;354,664;4,523,409;0,716490495
29,576;35,534;4,528,668;0,719048997
29,776;356,028;4,533,506;0,725505217
29,976;356,528;4,529,055;0,731721577
30,176;356,936;4,522,961;0,737238347
30,376;357,336;4,519,029;0,742195445
30,576;357,756;4,517,485;0,746942665
30,776;358,204;451,792;0,751729862
30,976;358,656;451,873;0,756646983
31,176;359,108;4,519,188;0,761604081
31,376;359,556;4,519,557;0,766651126
31,576;3,6;4,519,944;0,771578241
31,776;360,444;4,520,312;0,776645274
31,976;360,876;4,520,401;0,781712307
32,176;361,296;4,520,131;0,786719376
32,376;361,708;4,519,752;0,791746432
32,576;362,104;4,519,036;0,796833454
32,776;3,625;4,518,388;0,801760569
32,976;362,904;4,518,665;0,806757643
33,176;363,316;4,519,242;0,811834671
33,376;363,732;4,519,731;0,81701164
33,576;364,136;4,519,898;0,822198603
33,776;364,512;4,518,977;0,827325601
33,976;364,876;4,517,951;0,832352658
34,176;365,236;4,517,138;0,837349732
34,376;365,588;4,516,531;0,842226876
34,576;365,944;4,516,107;0,847163985
34,776;366,308;4,516,276;0,852111089
34,976;36,668;4,516,735;0,857138146
35,176;36,706;4,517,651;0,862315115
35,376;367,448;4,518,337;0,867542054
35,576;367,808;451,808;0,872818964
35,776;368,132;4,516,445;0,877985939
35,976;368,448;4,514,849;0,88290306
36,176;36,876;4,513,846;0,887860158
36,376;369,076;4,513,106;0,892727308
36,576;369,408;4,513,264;0,897644429
36,776;369,748;451,362;0,902711462
36,976;370,084;4,513,928;0,907798484
37,176;370,412;4,513,818;0,912835535
37,376;37,072;4,512,929;0,91793255
37,576;371,008;4,511,638;0,92286966
37,776;371,276;4,509,691;0,927666851
37,976;371,548;4,508,597;0,932324124
38,176;371,844;450,849;0,936991392
38,376;372,168;4,509,715;0,941768594
38,576;372,496;4,510,852;0,946765669
38,776;372,812;4,511,078;0,951772737
38,976;373,116;4,510,849;0,956829776
39,176;373,412;4,510,387;0,961786874
39,376;373,712;4,510,126;0,966803936
39,576;374,004;450,971;0,971820999
39,776;374,296;4,509,355;0,976778096
39,976;37,458;4,508,675;0,981785165
40,176;374,856;4,507,863;0,986822216
40,376;375,144;4,507,453;0,991649389
40,576;37,544;450,766;0,99668644
40,776;375,736;4,507,738;1,001,753,473
40,976;37,604;4,508,114;1,006,830,501
41,176;376,344;4,508,258;1,012,027,458
41,376;37,664;4,507,718;1,017,264,392
41,576;376,912;4,506,424;1,022,491,331
41,776;377,176;4,505,134;1,027,538,376
41,976;377,444;4,503,987;1,032,505,468
42,176;377,712;4,503,206;1,037,462,566
42,376;377,988;4,502,826;1,042,309,728
42,576;378,268;4,502,928;1,047,276,819
42,776;378,548;4,502,823;1,052,283,888
42,976;37,882;4,502,262;1,057,260,974
43,176;379,096;4,502,088;1,062,178,095
43,376;379,372;4,501,675;1,067,185,163
43,576;379,648;4,501,511;1,072,192,231
43,776;379,932;4,501,746;1,077,229,282
43,976;380,208;4,501,263;1,082,246,345
44,176;380,492;4,501,519;1,087,223,431
44,376;380,768;4,501,179;1,092,330,441
44,576;381,036;4,500,606;1,097,237,567
44,776;381,312;4,500,412;1,102,154,688
44,976;381,592;450,067;1,107,191,739
45,176;381,864;4,500,391;111,210,886
45,376;382,148;4,500,584;1,117,085,946
45,576;382,428;450,075;1,122,142,985
45,776;382,716;4,501,112;1,127,090,089
45,976;383,008;4,501,862;1,132,157,122
46,176;383,304;4,502,464;1,137,214,161
46,376;383,592;4,502,813;1,142,291,189
46,576;383,864;4,502,418;1,147,388,204
46,776;384,136;450,212;1,152,345,302
46,976;384,408;4,502,173;1,157,292,405
47,176;38,468;4,502,276;1,162,269,491
47,376;384,964;4,502,646;1,167,056,688
47,576;385,264;4,503,955;1,172,043,768
47,776;385,556;4,504,626;1,177,030,848
47,976;38,584;4,504,978;1,182,027,923
48,176;386,124;4,505,435;1,187,094,956
48,376;386,404;4,505,301;1,192,102,024
48,576;386,684;4,505,343;1,197,039,134
48,776;386,964;4,505,433;1,202,096,173
48,976;387,236;4,505,225;1,207,043,276
49,176;387,512;450,529;1,212,130,298
49,376;387,772;450,466;1,217,037,425
49,576;388,044;4,504,739;1,221,934,557
49,776;38,832;4,504,965;1,226,991,596
49,976;3,886;4,504,965;1,231,968,682
50,176;38,888;4,505,189;1,236,945,768
50,376;389,164;4,505,563;1,242,162,714
50,576;389,444;4,505,231;1,247,219,753
50,776;389,724;4,505,269;1,252,366,739
50,976;389,992;4,504,767;125,752,372
51,176;39,026;4,503,962;1,262,530,788
51,376;39,052;4,503,548;1,267,507,874
51,576;390,784;4,503,312;1,272,454,978
51,776;391,064;4,503,689;127,730,214
51,976;391,344;4,504,192;128,233,919
52,176;391,624;4,504,719;1,287,186,352
52,376;391,916;4,505,669;1,292,033,514
52,576;392,204;4,506,653;1,297,140,524
52,776;392,496;4,507,644;1,301,977,692
52,976;392,784;4,508,799;1,306,964,772
53,176;393,084;4,510,098;1,311,871,899
53,376;393,388;4,511,682;1,316,878,967
53,576;3,937;4,513,454;1,321,846,059
53,776;393,996;4,514,647;1,326,873,116
53,976;394,296;45,158;1,331,770,249
54,176;394,604;4,517,446;1,336,707,358
54,376;394,912;4,518,959;1,341,534,532
54,576;39,524;4,521,578;1,346,511,617
54,776;395,564;4,523,586;1,351,508,692
54,976;395,904;4,526,149;1,356,565,731
55,176;396,252;4,528,574;1,361,652,752
55,376;396,584;45,306;1,366,839,715
55,576;396,904;4,531,922;1,371,866,772
55,776;397,224;4,533,468;1,376,913,817
55,976;397,544;4,534,805;1,381,780,967
56,176;397,876;4,537,086;1,386,628,129
56,376;39,822;4,539,498;1,391,605,215
56,576;398,844;4,550,502;1,392,494,694
56,776;3,995;4,562,484;140,052,999
56,976;39,982;4,557,645;1,407,735,771
57,176;400,004;4,549,662;1,413,032,669
57,376;400,216;4,545,422;1,417,520,042
57,576;400,512;4,546,366;1,421,747,567
57,776;400,888;4,550,889;1,426,144,992
57,976;401,292;4,555,933;1,431,122,078
58,176;401,684;4,559,479;1,436,129,146
58,376;402,052;4,561,515;1,441,236,156
58,576;402,412;4,563,095;1,446,363,154
58,776;402,784;4,564,973;1,451,330,246
58,976;403,164;4,567,188;1,456,347,309
59,176;403,544;4,569,099;1,461,464,313
59,376;403,924;4,570,849;1,466,391,428
59,576;404,296;4,572,272;1,471,488,444
59,776;404,672;4,573,764;1,476,305,623
59,976;405,052;45,755;1,481,272,715
60,176;40,544;4,577,295;1,486,109,883
60,376;405,844;4,579,844;1,491,046,992
60,576;406,256;4,582,159;1,496,014,084
60,776;40,666;4,584,133;1,501,211,041
60,976;407,056;4,585,379;1,506,108,174
61,176;407,448;4,586,721;1,511,105,248
61,376;40,784;4,587,978;1,515,882,451
61,576;40,826;4,590,134;1,520,739,607
61,776;408,688;4,592,323;1,525,676,716
61,976;409,132;4,595,008;1,530,703,773
62,176;40,958;4,597,433;1,535,750,818
62,362;409,992;4,599,076;1,540,558,003
62,442;411,036;4,609,508;1,543,076,529
62,464;411,788;4,630,834;1,544,985,411
62,484;412,576;4,654,346;1,547,743,796
62,504;413,436;4,677,321;1,551,811,414
62,526;414,444;4,698,884;155,808,774
62,558;415,988;4,720,856;1,570,980,191
62,636;419,984;4,741,639;1,614,574,667
62,768;427,004;4,762,029;169,374,831
62,888;433,436;478,241;1,758,980,117
62,996;439,236;4,802,763;181,697,616
63,062;44,278;4,814,911;1,851,356,031
63,09;444,284;4,820,001;1,865,627,675
8,825,201;4,493;4,572,144;-0,14153713
88,274;450,036;4,596,829;-0,141497153
88,29;450,656;4,620,671;-0,141497153
88,304;451,236;4,643,897;-0,141487159
88,316;451,756;4,664,905;-0,141507148
88,328;452,296;4,686,447;-0,141527136
8,834,001;452,852;4,708,152;-0,14153713
8,835,201;453,428;4,729,603;-0,141517142
8,836,401;454,008;4,750,409;-0,14153713
8,837,801;4,547;4,773,376;-0,14153713
8,839,401;455,508;479,718;-0,141547124
88,412;456,432;4,820,057;-0,141517142
8,843,401;457,564;4,842,286;-0,141517142
88,466;459,232;4,864,128;-0,141547124
88,524;4,623;4,884,858;-0,141527136
8,862,801;467,852;4,905,232;-0,141527136
88,744;474,068;4,925,354;-0,141597095
8,886,401;480,496;4,945,765;-0,141527136
88,982;486,824;4,966,099;-0,141577107
8,910,001;493,156;4,986,378;-0,141547124
89,22;4,996;5,006,692;-0,141577107
89,342;506,124;502,701;-0,141577107
8,946,201;512,556;5,047,291;-0,141527136
89,582;518,992;5,067,366;-0,141597095
89,704;525,532;5,087,519;-0,141567112
89,828;532,192;5,107,747;-0,141587101
89,956;539,044;5,128,182;-0,141557118
9,008,601;546,012;5,148,603;-0,141547124
90,218;55,308;5,168,923;-0,141547124
9,034,801;560,056;5,189,124;-0,141577107
9,048,601;567,448;5,209,347;-0,141547124
90,624;574,856;5,229,729;-0,141577107
9,077,001;58,266;5,250,011;-0,141557118
90,912;590,256;5,270,304;-0,141547124
91,068;59,862;5,290,754;-0,141517142
9,122,601;607,096;5,311,093;-0,141567112
9,138,801;615,772;5,331,374;-0,141567112
9,154,601;624,244;5,351,587;-0,141547124
91,716;633,376;5,371,827;-0,141557118
91,886;642,476;5,392,126;-0,141557118
92,064;652,024;5,412,285;-0,141577107
92,234;661,132;5,432,526;-0,141517142
9,242,001;671,092;545,287;-0,141547124
92,608;681,164;5,473,093;-0,141557118
9,279,201;691,032;5,493,196;-0,14153713
9,298,601;701,432;5,513,357;-0,141557118
9,318,401;712,036;55,33;-0,141527136
93,384;72,274;5,552,745;-0,141527136
9,358,401;73,348;5,571,375;-0,141557118
9,378,401;744,204;5,589,982;-0,141567112
93,984;754,916;5,608,366;-0,14153713
9,418,401;76,562;5,625,498;-0,141567112
94,384;776,332;5,642,769;-0,141587101
9,458,401;787,052;5,658,713;-0,14153713
9,478,401;79,778;5,675,042;-0,141577107
94,984;808,508;5,691,219;-0,141587101
9,518,401;819,236;5,706,134;-0,141547124
95,384;829,944;5,721,238;-0,141577107
9,558,401;840,668;5,735,897;-0,141587101
9,578,401;85,138;574,998;-0,141577107
95,984;862,096;576,422;-0,141567112
9,618,401;872,816;5,778,075;-0,141587101
96,384;883,532;5,791,448;-0,141607089
9,658,401;89,426;5,804,505;-0,141567112
9,678,401;90,496;5,817,005;-0,141567112
96,984;915,692;5,828,925;-0,141547124
9,718,401;926,416;5,841,721;-0,141577107
97,384;937,136;585,308;-0,141547124
9,758,401;947,848;5,864,328;-0,141527136
9,778,401;958,552;5,875,693;-0,141587101
97,984;969,284;5,886,279;-0,141577107
9,818,401;9,8;5,897,065;-0,141617083
98,384;99,072;5,907,441;-0,141547124
9,858,401;1,001,448;5,917,203;-0,141627077
9,878,401;1,012,156;5,926,788;-0,141547124
98,984;1,022,884;593,658;-0,141567112
9,918,401;1,033,592;5,945,749;-0,141567112
99,384;104,432;5,954,922;-0,141567112
9,958,401;1,055,048;5,963,728;-0,141607089
9,978,401;1,065,748;5,971,984;-0,141627077
99,984;1,076,456;5,980,664;-0,141547124
10,018,401;1,087,184;5,988,331;-0,141567112
100,384;1,097,916;5,996,474;-0,141587101
10,058,401;1,108,632;6,004,329;-0,141527136
10,078,401;1,119,356;6,011,751;-0,141597095
100,984;113,008;6,019,338;-0,141597095
10,118,401;1,140,792;6,026,402;-0,141557118
101,384;1,151,508;6,033,024;-0,141587101
10,158,401;1,162,212;604,009;-0,141557118
10,178,401;117,294;6,046,574;-0,141607089
101,984;1,183,652;6,052,562;-0,141547124
10,218,401;1,194,368;6,058,983;-0,141577107
102,384;1,205,084;6,064,884;-0,141597095
10,258,401;1,215,816;6,070,604;-0,141617083
10,278,401;1,226,544;6,077,226;-0,141617083
102,984;1,237,268;6,082,156;-0,141587101
10,318,401;1,247,976;6,087,134;-0,141577107
103,384;1,258,704;6,092,789;-0,141597095
10,358,401;1,269,424;6,097,314;-0,141567112
10,378,401;1,280,148;6,102,409;-0,141587101
103,984;1,290,864;6,106,908;-0,141577107
10,418,401;1,301,588;6,111,596;-0,141607089
104,384;1,312,276;611,617;-0,141587101
10,458,401;1,322,996;612,057;-0,141607089
10,478,401;1,333,728;6,124,619;-0,141597095
10,498,401;1,344,456;6,128,908;-0,141617083
10,518,401;135,518;6,132,679;-0,141577107
105,384;13,659;6,136,277;-0,141627077
10,558,401;1,376,604;6,140,277;-0,141587101
10,578,401;1,387,336;6,143,588;-0,141597095
10,598,401;1,398,056;6,146,726;-0,141607089
10,618,401;140,878;6,150,309;-0,141587101
106,384;1,419,504;6,153,065;-0,141557118
10,658,401;1,430,216;6,155,812;-0,141577107
10,678,401;1,440,932;6,159,051;-0,141587101
10,698,401;1,451,656;6,161,455;-0,141597095
10,718,401;146,238;616,449;-0,141577107
107,384;1,473,104;6,166,869;-0,141587101
10,758,401;1,483,812;6,169,381;-0,141587101
10,778,401;1,494,532;617,186;-0,141597095
10,798,401;1,505,248;6,173,674;-0,141517142
10,818,401;1,515,976;6,175,896;-0,141617083
108,384;1,526,708;6,178,188;-0,141597095
10,858,401;1,537,432;6,179,718;-0,141597095
10,878,401;1,548,148;6,181,656;-0,141587101
10,898,401;155,884;6,183,556;-0,141547124
10,918,401;1,569,568;6,184,959;-0,141627077
109,384;1,580,292;6,186,734;-0,141577107
10,958,401;1,591,004;6,188,393;-0,141607089
10,978,401;1,601,724;6,189,272;-0,141607089
10,998,401;1,612,448;6,190,402;-0,141597095
11,018,401;1,623,188;6,191,568;-0,141577107
110,384;1,633,904;6,192,529;-0,141577107
11,058,401;164,462;6,194,182;-0,141597095
11,078,401;1,655,352;6,194,699;-0,141597095
11,098,401;1,666,052;6,195,266;-0,141557118
11,118,401;1,676,772;619,634;-0,141587101
111,384;168,748;6,196,576;-0,141587101
11,158,401;1,698,208;6,197,519;-0,141587101
11,178,401;1,708,944;6,198,182;-0,141567112
11,198,401;1,719,656;6,198,152;-0,141617083
11,218,401;1,730,368;6,198,559;-0,141597095
112,384;1,741,092;6,198,806;-0,141597095
11,258,401;1,751,828;6,199,061;-0,141597095
11,278,401;176,254;6,199,374;-0,141547124
11,298,401;1,773,248;6,198,965;-0,141587101
11,318,401;1,783,972;6,198,811;-0,141577107
113,384;1,794,672;6,198,677;-0,141577107
11,358,401;1,805,408;6,198,042;-0,141557118
11,378,401;1,816,128;619,761;-0,141587101
11,398,401;1,826,852;6,197,576;-0,141577107
11,418,401;1,837,568;6,196,656;-0,141567112
114,384;1,848,288;6,195,935;-0,141567112
11,458,401;1,859,016;6,194,948;-0,141587101
11,478,401;1,869,748;619,411;-0,141607089
11,498,401;1,880,468;6,193,389;-0,141577107
11,518,401;1,891,184;6,192,114;-0,141557118
115,384;1,901,896;6,190,557;-0,141577107
11,558,401;191,262;6,189,787;-0,141567112
11,578,401;1,923,332;6,188,562;-0,141567112
11,598,401;1,934,052;6,186,929;-0,141577107
11,618,401;194,476;6,185,406;-0,141597095
116,384;1,955,488;6,183,861;-0,141587101
11,658,401;19,662;6,181,563;-0,141587101
11,678,401;1,976,924;6,180,004;-0,141557118
11,698,401;1,987,644;6,177,912;-0,141597095
11,718,401;1,998,372;6,175,894;-0,141617083
117,384;2,009,104;6,173,762;-0,141567112
11,758,401;2,019,832;6,170,692;-0,141577107
11,778,401;203,054;6,168,219;-0,141587101
11,798,401;2,041,256;616,556;-0,141597095
11,818,401;205,198;6,162,383;-0,141587101
118,384;20,627;6,159,774;-0,141597095
11,858,401;2,073,412;6,156,077;-0,141597095
11,878,401;2,084,128;6,152,704;-0,141607089
11,898,401;2,094,852;6,149,117;-0,141587101
11,918,401;2,105,588;6,145,056;-0,141607089
119,384;2,116,304;6,141,006;-0,141547124
11,958,401;2,127,024;6,136,961;-0,141617083
11,978,401;2,137,748;6,131,696;-0,141577107
11,998,401;2,148,476;6,126,566;-0,141577107
12,018,401;2,159,184;6,121,461;-0,141607089
120,384;2,169,904;6,115,476;-0,141577107
12,058,401;218,062;6,109,398;-0,141607089
12,078,401;2,191,336;6,102,849;-0,141637071
12,098,401;2,202,076;6,095,415;-0,141587101
12,118,401;2,212,772;6,087,543;-0,141597095
121,384;2,223,504;6,079,113;-0,141607089
12,158,401;2,234,232;6,069,757;-0,141577107
12,178,401;2,244,952;6,060,337;-0,141567112
12,198,401;2,255,672;6,049,097;-0,141617083
12,218,401;2,266,392;6,037,329;-0,141587101
122,384;2,277,112;6,025,245;-0,141607089
12,258,401;2,287,832;6,011,697;-0,141577107
12,278,401;2,298,552;599,719;-0,141597095
12,298,401;2,309,276;5,981,782;-0,141607089
12,318,401;2,319,988;5,964,952;-0,141597095
123,384;2,330,732;5,947,555;-0,141617083
12,358,401;2,341,444;5,929,343;-0,141587101
12,378,201;2,352,056;5,909,334;-0,141577107
12,397,801;236,256;5,889,203;-0,141577107
12,415,801;2,372,204;5,869,072;-0,141567112
12,433,601;2,381,744;5,848,897;-0,141617083
12,450,601;239,086;5,828,799;-0,141597095
12,466,601;2,399,428;5,808,468;-0,141587101
12,482,401;2,407,912;578,809;-0,141597095
12,497,201;2,415,848;5,767,735;-0,141597095
125,118;2,423,668;5,747,392;-0,141587101
125,26;2,431,296;572,719;-0,141597095
125,396;2,438,588;5,706,816;-0,141607089
12,552,801;2,445,668;5,686,464;-0,141627077
12,565,201;2,452,308;5,666,342;-0,141577107
12,577,801;2,459,068;5,646,003;-0,141577107
125,896;2,465,388;5,625,528;-0,141587101
12,601,401;2,471,704;5,605,327;-0,141597095
12,613,001;2,477,924;5,584,984;-0,141597095
12,623,801;2,483,728;5,564,549;-0,141557118
12,634,601;248,952;5,544,264;-0,141587101
126,454;2,495,324;5,523,743;-0,141607089
12,655,401;250,068;5,503,225;-0,141607089
12,665,601;2,506,152;5,482,982;-0,141597095
12,675,401;2,511,412;5,462,428;-0,141557118
12,684,801;251,644;5,441,954;-0,141617083
12,694,401;2,521,592;5,421,458;-0,141587101
12,703,401;2,526,408;5,401,045;-0,141597095
12,712,201;2,531,128;5,380,643;-0,141577107
12,721,001;253,586;5,359,918;-0,141607089
12,729,401;2,540,364;5,339,523;-0,141557118
12,737,401;2,544,648;5,319,332;-0,141597095
127,454;254,894;5,298,895;-0,141587101
12,753,201;2,553,116;527,843;-0,141577107
12,761,001;25,573;5,257,865;-0,141567112
12,768,401;2,561,268;5,237,561;-0,141577107
127,758;2,565,236;5,216,756;-0,141577107
12,783,001;25,691;5,196,259;-0,141617083
12,790,201;2,572,964;5,175,794;-0,141587101
12,797,001;2,576,608;5,155,504;-0,141577107
12,803,801;2,580,252;5,134,503;-0,141587101
128,104;2,583,792;5,114,128;-0,141627077
12,817,002;2,587,336;5,093,518;-0,141587101
12,823,401;2,590,768;5,072,844;-0,141577107
12,829,601;25,941;5,052,234;-0,141557118
128,354;2,597,192;5,031,966;-0,141587101
128,414;2,600,408;5,011,523;-0,141577107
128,474;2,603,628;4,990,435;-0,141607089
128,53;2,606,632;4,970,054;-0,141577107
128,586;260,964;4,949,384;-0,141597095
12,864,202;2,612,652;49,28;-0,141597095
128,694;2,615,444;4,907,363;-0,141567112
128,746;2,618,228;4,886,625;-0,141587101
12,879,801;2,621,016;486,568;-0,141597095
12,884,801;2,623,708;4,845,082;-0,141597095
12,889,601;2,626,288;4,824,619;-0,141567112
128,944;262,886;4,803,406;-0,141617083
12,899,201;2,631,428;4,782,183;-0,141617083
12,903,601;2,633,788;4,762,167;-0,141617083
129,082;2,636,256;474,114;-0,141557118
12,912,601;263,862;4,720,421;-0,141577107
12,917,002;264,098;4,699,093;-0,141557118
12,921,001;264,312;4,678,829;-0,141567112
129,25;2,645,264;4,658,175;-0,141607089
12,929,001;2,647,408;4,636,783;-0,141587101
129,33;264,956;4,614,883;-0,141557118
12,936,602;26,515;459,392;-0,141577107
12,939,402;26,53;4,572,861;-0,141567112
12,940,401;2,653,544;4,520,498;-0,141567112
12,940,801;2,653,788;4,299,159;-0,141916908
129,412;2,654,052;3,908,696;-0,142846363
129,416;2,654,304;3,426,645;-0,143475995
12,942,002;2,654,536;2,910,061;-0,144555363
12,942,202;2,654,668;2,650,334;-0,145384877