File: tensile_test_ontology_TTO/data/primary_data/Zx2.csv
Time;Crosshead travel;Force;Strain
(s);(mm);(kN);(%)
0;0;0,17097;0
0,954;0,05092;0,84196;0,002791938
1,448;0,11752;196,933;0,007445168
1,832;0,18556;310,178;0,012198468
2,188;0,25856;424,419;0,016961775
2,64;0,36908;535,927;0,021735088
3,094;0,50044;648,097;0,026508402
3,404;0,60008;762,535;0,031131612
3,668;0,68916;87,577;0,035834877
3,916;0,77528;989,962;0,040598183
4,158;0,86116;1,107,005;0,045511594
4,38;0,94128;1,219,474;0,05024488
4,6;102,144;1,334,215;0,054968159
4,82;110,212;1,452,858;0,060021667
5,038;11,826;1,572,524;0,065005127
5,242;125,788;1,686,504;0,069798454
5,442;133,188;1,798,962;0,074641816
5,64;14,048;1,912,272;0,079395116
5,838;147,792;2,026,522;0,084248485
6,036;155,044;214,149;0,089322007
6,234;16,226;2,256,756;0,094285453
6,432;169,464;2,373,314;0,099439031
6,63;176,536;2,488,933;0,10465265
6,828;18,358;2,604,098;0,109886283
7,026;190,532;2,719,284;0,115300041
7,224;197,384;2,832,438;0,12074382
7,424;204,184;2,945,693;0,126367724
7,638;211,304;3,063,777;0,132532004
7,858;218,472;3,182,718;0,139056533
8,078;225,464;3,299,254;0,145771194
8,306;232,444;3,413,691;0,15299621
8,544;239,456;3,529,413;0,160891691
8,8;24,658;364,389;0,169587728
9,07;253,592;3,755,929;0,178974244
9,378;26,088;3,869,238;0,190111976
9,744;268,516;3,983,118;0,203381187
10,2;27,656;409,633;0,220012733
10,846;285,344;4,208,152;0,242058037
11,844;2,95;4,314,232;0,271968801
12,944;30,304;4,387,987;0,301369211
14,044;309,932;4,441,577;0,329518752
15,144;316,528;4,478,787;0,356987821
16,244;324,264;4,498,501;0,383606299
17,344;330,376;4,505,704;0,41447773
18,444;334,712;451,489;0,442637279
19,544;338,512;4,526,117;0,470776813
20,644;342,224;4,538,481;0,499216556
21,744;345,296;4,545,605;0,526205292
22,844;3,483;4,552,538;0,553984576
23,944;351,316;456,255;0,580823207
25,044;353,852;4,555,554;0,609443075
26,144;356,376;4,556,187;0,637402485
27,244;358,724;4,554,854;0,664711443
28,344;360,928;4,550,312;0,692110463
29,444;363,132;454,111;0,720510178
30,544;36,514;4,541,766;0,747538942
31,644;366,984;4,537,271;0,775138101
32,744;368,752;4,534,172;0,803107517
33,844;37,046;453,294;0,830346426
34,944;37,218;4,532,858;0,858045655
36,044;373,868;4,533,801;0,885374627
37,144;375,536;4,533,316;0,913083863
38,244;377,184;4,534,883;0,940212696
39,344;378,776;453,346;0,967781834
40,444;380,376;4,532,833;0,995441035
41,544;38,192;4,530,649;1,023,240,333
42,644;383,416;4,528,565;1,050,529,277
43,744;384,948;4,527,749;1,078,158,458
44,844;386,392;4,524,666;1,105,317,311
45,944;38,788;4,523,552;1,133,156,637
47,044;389,296;4,519,861;1,160,425,567
48,144;390,768;4,519,638;118,778,456
49,244;392,208;4,517,202;1,215,323,678
50,344;393,628;4,514,316;1,243,032,913
51,444;394,968;4,507,657;1,270,802,191
52,544;396,444;4,510,508;1,297,700,864
53,644;398,096;4,520,019;1,325,209,961
54,744;3,998;4,531,364;1,352,368,814
55,844;401,576;4,543,449;138,017,812
56,944;4,034;4,556,158;1,407,557,126
58,044;405,672;4,578,317;1,435,156,285
59,144;407,428;4,580,984;146,221,507
60,244;409,384;4,590,565;1,489,634,104
61,344;411,488;4,602,169;1,517,183,229
62,444;413,664;4,612,989;1,544,582,249
63,544;415,872;4,621,742;1,571,861,186
64,644;418,216;4,632,291;1,599,240,193
65,744;4,207;4,643,756;1,626,959,435
66,844;423,172;465,181;16,542,784
67,944;425,796;4,662,225;1,681,477,282
6,904,401;42,858;467,347;1,709,416,677
7,014,401;43,136;4,682,735;1,736,745,649
71,244;434,472;4,698,629;1,763,844,461
72,344;437,304;4,705,101;179,121,346
73,444;440,292;4,716,428;1,818,752,578
7,454,401;443,288;4,725,999;184,595,146
7,564,401;446,416;4,737,397;1,873,520,598
76,744;449,552;4,747,116;1,901,039,702
77,844;452,728;4,757,825;1,928,238,583
78,944;45,594;476,793;1,955,707,652
8,004,401;459,528;4,784,325;1,983,617,027
8,114,401;462,696;4,789,482;2,010,845,929
82,244;465,992;4,800,967;2,038,264,964
83,344;46,922;4,810,002;2,065,603,942
84,444;472,536;482,248;2,093,183,088
8,554,401;475,748;4,831,156;212,077,224
8,664,401;478,984;4,842,205;214,840,142
87,744;482,164;4,851,831;2,175,880,496
88,844;485,584;4,868,673;2,203,059,364
8,994,401;488,604;4,871,055;223,115,887
9,104,401;4,917;488,179;2,258,437,808
9,214,401;494,772;489,098;2,285,996,939
93,244;497,884;4,901,827;2,313,676,154
94,344;500,968;4,910,423;2,341,495,466
9,544,401;504,016;4,920,056;2,368,774,403
9,654,401;507,024;4,928,894;2,396,043,333
9,764,401;510,252;4,944,219;2,422,481,687
98,744;51,328;4,947,482;2,451,201,624
99,844;516,292;4,957,387;2,478,480,561
10,094,401;519,292;4,966,582;2,505,879,582
10,204,401;52,226;4,975,694;2,533,178,533
10,314,401;525,288;498,556;2,561,017,859
104,244;528,268;4,993,378;2,588,466,914
105,344;531,304;5,003,157;2,616,146,129
10,644,401;534,476;5,015,347;2,643,385,038
10,754,401;537,364;5,018,613;2,671,164,322
10,864,401;540,324;5,027,024;2,698,633,391
109,744;543,268;5,035,368;2,725,982,377
110,844;54,626;50,433;2,753,681,606
11,194,401;549,248;5,052,316;278,110,064
11,304,401;552,284;5,061,151;2,808,979,994
11,414,401;555,228;5,068,505;283,632,898
115,244;55,844;5,079,681;2,864,348,431
116,344;56,134;5,084,597;289,171,743
11,744,401;564,272;5,093,107;2,918,706,166
11,854,401;567,268;5,100,783;294,635,536
11,964,401;570,224;5,107,912;2,973,874,464
120,744;57,318;5,115,013;300,148,363
12,184,401;576,152;5,123,169;3,028,862,636
12,294,401;579,136;5,130,244;3,056,391,747
12,404,401;582,212;5,136,123;3,084,181,038
12,514,401;585,192;5,144,776;3,111,520,017
126,244;588,124;5,152,473;3,138,838,982
12,734,401;591,108;5,160,114;3,166,808,398
128,444;594,056;5,166,821;3,193,847,169
12,954,401;597,064;5,174,712;3,221,316,238
13,064,402;600,032;5,180,815;3,248,695,244
131,744;603,264;5,193,594;3,276,214,348
13,284,402;606,112;5,193,768;3,303,783,486
133,944;609,108;5,201,548;3,331,162,493
135,044;612,084;5,207,797;3,358,661,583
13,614,402;615,076;5,214,849;3,386,220,714
137,244;618,092;5,221,377;341,403,002
13,834,402;621,056;5,228,107;3,441,258,922
139,444;624,004;5,234,343;3,468,667,949
140,544;627,112;5,241,009;3,496,287,123
14,164,402;630,132;5,248,836;3,524,096,428
142,744;633,068;5,254,461;3,551,475,434
14,384,402;636,048;5,261,325;3,579,164,656
144,944;638,956;5,266,458;3,606,263,468
146,044;641,944;5,273,965;3,633,782,572
14,714,402;644,908;5,278,994;3,661,461,787
148,244;648,024;5,287,154;368,895,087
14,934,402;65,088;5,290,412;371,634,989
150,444;653,828;5,297,247;3,743,899,015
151,544;656,788;530,302;3,771,768,362
15,264,402;659,736;53,091;3,799,067,313
153,744;662,772;5,316,346;3,826,876,618
15,484,402;665,712;5,321,289;3,854,305,659
155,766;66,744;5,309,721;3,874,489,671
15,686,602;66,938;5,312,003;3,890,000,438
157,966;671,568;5,320,811;3,909,503,978
15,906,602;673,756;5,326,273;3,929,697,996
160,166;675,964;533,094;3,950,112,168
161,266;67,816;533,534;3,970,366,228
17,806,202;679,796;5,226,782;-0,04155885
179,162;682,004;5,303,674;-0,041578864
18,026,202;6,842;5,340,286;-0,041568857
18,136,202;686,388;5,353,728;-0,041588871
182,462;688,604;536,027;-0,041538836
18,356,202;690,804;5,363,885;-0,04155885
184,662;692,988;5,366,677;-0,041508815
18,576,202;695,184;5,370,417;-0,041548843
18,686,202;697,388;5,373,861;-0,041528829
187,962;699,584;5,376,956;-0,041468788
18,906,202;701,792;5,381,093;-0,041518822
190,162;70,398;538,474;-0,041458781
19,126,202;706,184;5,388,436;-0,041478795
19,236,202;708,404;5,392,169;-0,041408746
193,462;710,596;539,573;-0,041358711
19,456,202;712,788;5,399,103;-0,041408746
195,662;714,992;5,403,086;-0,041358711
19,676,202;717,188;5,406,659;-0,041378725
19,786,202;719,392;5,410,562;-0,041408746
198,962;721,612;541,414;-0,041398739
20,006,202;723,804;541,738;-0,041378725
201,162;725,992;5,420,635;-0,041378725
20,226,202;728,196;5,424,448;-0,041388732
20,336,202;730,396;5,427,882;-0,041398739
204,462;732,592;5,431,629;-0,041408746
20,556,202;734,808;5,435,152;-0,041418753
206,662;737,004;5,438,645;-0,041398739
20,776,202;739,192;5,441,989;-0,04142876
20,886,202;741,396;5,445,501;-0,041398739
209,962;743,604;5,449,031;-0,041438767
21,106,202;745,796;5,452,528;-0,041408746
212,162;747,996;5,455,681;-0,041388732
21,326,202;750,192;5,459,579;-0,04142876
21,436,202;752,384;5,462,787;-0,041448774
215,462;75,458;5,466,231;-0,04142876
21,656,202;756,784;5,469,788;-0,04142876
21,766,202;758,992;5,473,267;-0,041408746
21,876,202;7,612;5,476,478;-0,04142876
21,986,202;7,634;5,479,937;-0,041448774
220,962;765,596;5,483,361;-0,041418753
22,206,202;767,792;5,486,551;-0,041418753
22,316,202;769,988;5,490,022;-0,041448774
22,426,202;772,192;5,493,422;-0,041458781
22,536,202;774,388;5,496,463;-0,041418753
226,462;776,592;5,499,747;-0,04142876
22,756,202;778,784;5,503,082;-0,041468788
22,866,202;78,098;550,591;-0,04142876
22,976,202;783,176;5,509,542;-0,041438767
23,086,202;785,384;5,513,006;-0,041448774
231,962;78,758;5,515,945;-0,041448774
23,306,202;78,978;551,914;-0,041448774
23,416,202;791,984;552,265;-0,041458781
23,526,202;794,184;5,525,566;-0,041448774
23,636,202;796,388;552,863;-0,041388732
237,462;798,596;5,531,864;-0,041358711
23,856,202;80,078;5,534,381;-0,041408746
23,966,202;802,976;5,537,606;-0,041438767
24,076,202;805,184;5,541,218;-0,041418753
24,186,202;807,376;5,543,628;-0,041408746
242,962;809,572;5,546,923;-0,041408746
24,406,202;811,788;5,550,254;-0,041398739
24,516,202;813,984;5,552,938;-0,041408746
24,626,202;81,618;5,555,558;-0,041388732
24,736,202;818,384;555,905;-0,041438767
248,462;820,592;5,561,987;-0,041398739
24,956,202;822,788;5,564,712;-0,041398739
25,066,202;824,976;5,567,392;-0,041368718
25,176,202;827,168;5,570,301;-0,041418753
25,286,202;829,376;5,573,146;-0,041408746
253,962;831,584;5,576,351;-0,041448774
25,506,202;833,772;5,578,879;-0,041378725
25,616,202;835,976;5,581,789;-0,041338697
25,726,203;838,192;5,585,175;-0,041388732
258,362;840,384;5,587,589;-0,041408746
259,462;842,576;5,590,088;-0,041378725
26,056,202;844,784;5,593,363;-0,041418753
26,166,202;846,968;5,595,791;-0,041398739
26,276,203;849,176;5,598,661;-0,041398739
263,862;851,392;5,601,966;-0,04142876
264,962;853,592;5,604,349;-0,041368718
266,062;855,768;5,606,928;-0,041408746
26,716,203;85,798;5,610,049;-0,041378725
26,826,203;860,164;5,612,602;-0,041418753
269,362;862,364;5,615,043;-0,041408746
270,462;864,576;5,618,163;-0,041388732
271,562;866,776;562,039;-0,041378725
27,266,203;868,964;5,623,094;-0,041398739
27,376,203;871,176;5,625,924;-0,041378725
274,862;873,364;5,628,501;-0,041378725
275,962;875,568;5,630,831;-0,041398739
277,062;877,784;5,633,995;-0,041408746
27,816,203;87,998;5,636,052;-0,041378725
27,926,203;882,164;5,638,396;-0,041408746
280,362;884,368;564,118;-0,041378725
281,462;886,552;5,643,936;-0,041388732
282,562;888,756;5,646,747;-0,041388732
28,366,203;890,972;5,649,446;-0,041388732
28,476,203;893,168;5,651,762;-0,04142876
285,862;895,364;565,397;-0,041378725
286,962;897,572;5,656,469;-0,041358711
288,062;899,764;5,658,849;-0,041388732
28,916,203;901,956;5,661,612;-0,041368718
29,026,203;904,172;5,664,367;-0,041368718
291,362;906,376;5,666,766;-0,041408746
292,462;908,564;5,668,827;-0,041418753
293,562;910,768;5,671,229;-0,041358711
29,466,203;912,968;567,371;-0,041358711
29,576,203;915,164;5,676,095;-0,041358711
296,862;917,376;5,678,533;-0,041358711
297,962;919,576;5,680,977;-0,041368718
299,062;921,768;5,683,101;-0,041408746
30,016,203;923,972;5,685,484;-0,041408746
30,126,203;92,618;5,687,936;-0,041408746
302,362;928,376;5,690,166;-0,041398739
303,462;93,058;5,692,148;-0,04142876
304,562;932,772;569,459;-0,041388732
30,566,203;934,968;5,696,725;-0,041408746
30,676,203;937,168;5,698,981;-0,041418753
307,862;939,368;5,701,433;-0,041408746
308,962;941,564;5,703,668;-0,041398739
310,062;943,776;5,705,851;-0,041398739
31,116,203;945,972;5,708,296;-0,041368718
31,226,203;948,172;5,710,499;-0,041418753
31,336,203;95,038;5,712,862;-0,041398739
314,462;952,592;5,714,886;-0,041408746
315,562;954,768;5,716,707;-0,041388732
31,666,203;956,964;5,719,159;-0,041388732
31,776,203;959,168;5,721,693;-0,041388732
31,886,203;961,376;5,723,548;-0,041408746
319,962;963,572;5,725,503;-0,041388732
321,062;965,776;5,727,765;-0,041388732
32,216,203;96,798;5,730,218;-0,041398739
32,326,203;970,184;5,732,013;-0,041378725
32,436,203;972,376;5,734,198;-0,041368718
325,462;97,458;5,736,544;-0,041418753
326,562;976,768;5,738,044;-0,041388732
32,766,203;978,968;5,740,454;-0,041378725
32,876,203;981,188;5,742,706;-0,04142876
32,986,203;983,388;5,744,382;-0,041398739
330,962;985,576;5,745,953;-0,041408746
332,062;98,778;574,873;-0,041388732
33,316,203;98,996;5,750,343;-0,041408746
33,426,203;992,152;5,752,556;-0,041418753
33,536,203;994,368;5,754,876;-0,04142876
336,462;996,564;5,756,429;-0,041408746
337,562;998,764;5,758,239;-0,041388732
33,866,203;1,000,972;5,760,775;-0,041368718
33,976,203;100,316;57,622;-0,041358711
34,086,203;100,536;5,764,498;-0,041388732
341,962;1,007,576;5,766,928;-0,041398739
343,062;1,009,768;576,825;-0,041408746
34,416,203;1,011,968;5,769,974;-0,041378725
34,526,203;1,014,176;5,772,217;-0,041378725
34,636,203;101,636;577,359;-0,041368718
347,462;101,856;5,775,713;-0,041398739
348,562;102,078;5,778,217;-0,041388732
34,966,203;1,022,972;5,779,667;-0,041408746
35,076,203;1,025,168;5,781,384;-0,041448774
35,186,203;1,027,376;5,783,621;-0,041408746
352,962;1,029,564;5,784,831;-0,041408746
354,062;1,031,756;5,786,697;-0,04142876
35,516,203;1,033,972;5,789,284;-0,041418753
35,626,203;1,036,168;5,790,725;-0,04142876
35,736,203;103,836;5,792,437;-0,041408746
358,462;1,040,568;5,794,653;-0,041418753
359,562;1,042,752;5,796,037;-0,041448774
36,066,203;1,044,952;5,797,784;-0,041448774
36,176,203;1,047,176;5,799,958;-0,041458781
36,286,203;1,049,364;5,801,269;-0,041418753
363,962;105,156;5,803,032;-0,041438767
365,062;1,053,776;5,805,352;-0,041408746
36,616,203;1,055,972;580,687;-0,041368718
36,726,203;1,058,168;5,808,417;-0,041448774
36,836,203;1,060,384;581,034;-0,041458781
369,462;1,062,568;581,143;-0,041418753
370,562;1,064,756;5,813,239;-0,041418753
37,166,203;1,066,972;5,815,266;-0,04142876
37,276,203;1,069,164;5,816,996;-0,041418753
37,386,203;107,136;5,818,525;-0,041458781
374,962;1,073,568;5,820,643;-0,041418753
376,062;1,075,764;5,822,117;-0,04142876
37,716,203;1,077,952;5,823,495;-0,041458781
37,826,203;1,080,164;5,825,238;-0,041458781
37,936,203;108,238;5,827,342;-0,041438767
380,462;1,084,576;5,828,565;-0,041468788
381,562;1,086,752;5,830,055;-0,04142876
38,266,203;1,088,948;5,832,218;-0,041408746
38,376,203;1,091,144;583,378;-0,04142876
38,486,203;1,093,348;5,835,196;-0,041438767
385,962;1,095,548;5,836,775;-0,041408746
387,062;1,097,752;5,838,247;-0,041448774
38,816,203;109,996;5,839,841;-0,04142876
38,926,203;110,216;5,841,468;-0,041438767
39,036,203;1,104,352;5,842,972;-0,041438767
391,462;1,106,552;5,844,485;-0,041438767
392,562;1,108,748;5,846,038;-0,041418753
39,366,203;1,110,956;5,847,709;-0,041408746
39,476,203;1,113,172;5,848,892;-0,041438767
39,586,203;1,115,376;5,850,521;-0,041448774
396,962;1,117,556;5,851,618;-0,041468788
398,062;1,119,752;5,853,372;-0,041438767
39,916,203;1,121,952;5,855,076;-0,041438767
40,026,203;1,124,148;5,856,835;-0,041458781
40,136,203;1,126,356;5,857,902;-0,041388732
402,462;1,128,552;5,859,463;-0,041388732
403,562;1,130,756;586,091;-0,041468788
40,466,203;1,132,948;5,862,077;-0,041438767
40,576,203;1,135,152;586,363;-0,041418753
40,686,203;1,137,356;5,865,595;-0,041498808
407,962;1,139,564;5,866,643;-0,041438767
409,062;1,141,756;5,868,196;-0,041448774
41,016,203;114,396;586,947;-0,041478795
41,126,203;1,146,144;5,870,521;-0,041458781
41,236,203;1,148,344;587,214;-0,041408746
413,462;115,056;5,874,146;-0,041468788
414,562;1,152,764;5,875,181;-0,041458781
41,566,203;1,154,956;587,654;-0,041438767
41,676,203;1,157,168;5,878,357;-0,04142876
41,786,203;1,159,356;5,879,204;-0,041438767
418,962;1,161,556;5,880,364;-0,041388732
420,062;1,163,764;5,882,118;-0,041438767
42,116,203;1,165,964;5,883,002;-0,041468788
42,226,203;1,168,156;588,434;-0,041458781
42,336,203;1,170,364;5,886,276;-0,04142876
424,462;1,172,544;5,887,156;-0,041458781
425,562;1,174,744;5,888,502;-0,041438767
42,666,203;117,696;5,890,142;-0,041448774
42,776,203;117,916;589,097;-0,04142876
42,886,203;118,136;5,892,033;-0,041408746
429,962;1,183,572;5,893,953;-0,041418753
431,062;118,576;5,894,926;-0,041408746
43,216,203;1,187,956;5,896,206;-0,041378725
43,326,203;119,018;5,898,195;-0,04142876
43,436,203;1,192,364;5,898,707;-0,041448774
435,462;119,456;5,899,668;-0,041408746
436,562;1,196,768;5,901,445;-0,041418753
43,766,203;1,198,956;5,902,205;-0,041418753
43,876,203;1,201,156;590,347;-0,041438767
43,986,203;1,203,372;590,533;-0,041418753
44,096,203;1,205,568;5,906,284;-0,041438767
442,062;1,207,768;5,907,205;-0,041448774
44,316,203;1,209,972;5,908,582;-0,041408746
44,426,203;1,212,176;5,909,678;-0,041478795
44,536,203;121,438;5,910,825;-0,041438767
44,646,203;1,216,572;5,911,428;-0,04142876
447,562;121,876;5,913,168;-0,04142876
44,866,203;1,220,956;5,914,749;-0,041408746
44,976,203;1,223,164;5,916,117;-0,041418753
45,086,203;1,225,356;5,916,643;-0,041438767
45,196,203;1,227,556;5,917,916;-0,041418753
453,062;1,229,772;5,919,371;-0,041398739
45,416,203;123,196;5,920,129;-0,041408746
45,526,203;123,414;5,921,158;-0,041468788
45,636,203;1,236,344;5,922,705;-0,041488802
45,746,203;1,238,536;5,923,738;-0,041418753
458,562;1,240,732;5,924,886;-0,041418753
45,966,203;124,296;5,926,574;-0,041448774
46,076,203;124,516;5,927,296;-0,041438767
46,186,203;124,734;5,927,623;-0,041448774
46,296,203;1,249,544;5,929,149;-0,041438767
464,062;1,251,744;5,930,473;-0,041438767
46,516,203;125,394;5,931,775;-0,041438767
46,626,203;1,256,156;5,933,003;-0,04142876
46,736,203;1,258,356;5,933,881;-0,041468788
46,846,203;126,054;5,934,805;-0,041468788
469,562;1,262,752;5,935,782;-0,041478795
47,066,203;1,264,952;5,937,034;-0,041458781
47,176,203;1,267,152;5,937,925;-0,041458781
47,286,203;1,269,364;5,939,071;-0,041468788
47,396,203;1,271,564;5,939,936;-0,041448774
475,062;1,273,748;5,940,804;-0,041418753
47,616,203;1,275,948;5,941,516;-0,041438767
47,726,203;1,278,144;5,942,777;-0,041438767
47,836,203;1,280,352;5,943,808;-0,04142876
47,946,203;1,282,564;594,508;-0,041408746
480,562;1,284,768;5,946,003;-0,041418753
48,166,203;1,286,956;5,947,044;-0,041438767
48,276,203;128,916;5,948,117;-0,041468788
48,386,203;1,291,352;5,949,253;-0,041458781
48,496,203;1,293,552;595,031;-0,041448774
486,062;129,576;5,951,168;-0,041418753
48,716,203;1,297,956;5,951,874;-0,041398739
48,826,203;1,300,148;5,952,922;-0,041458781
48,936,203;1,302,348;5,953,815;-0,041438767
49,046,203;130,454;5,955,094;-0,041478795
491,562;1,306,752;5,956,306;-0,041438767
49,266,203;1,308,956;5,956,874;-0,04142876
49,376,203;131,116;5,957,585;-0,041438767
49,486,203;1,313,356;595,856;-0,04142876
49,596,203;1,315,552;5,959,353;-0,041418753
497,062;1,317,756;5,960,486;-0,041438767
49,816,203;1,319,968;5,961,746;-0,041418753
49,926,203;1,322,164;5,962,241;-0,041398739
50,036,203;1,324,352;5,963,023;-0,04142876
50,146,203;132,656;5,964,093;-0,041408746
502,562;1,328,752;5,964,549;-0,041438767
50,366,203;1,330,956;5,965,597;-0,04142876
50,476,203;1,333,164;596,693;-0,04142876
50,586,203;1,335,372;5,967,268;-0,041408746
50,696,203;1,337,564;5,968,106;-0,041408746
508,062;1,339,768;5,969,282;-0,041438767
50,916,203;1,341,956;5,969,773;-0,041398739
51,026,203;134,418;597,049;-0,041398739
51,136,203;1,346,396;5,971,744;-0,041378725
51,246,203;1,348,556;5,971,661;-0,041378725
513,562;1,350,748;5,972,887;-0,041408746
51,466,206;1,352,968;5,974,194;-0,041418753
51,576,203;1,355,152;597,484;-0,041458781
516,862;1,357,356;5,975,637;-0,041418753
51,796,203;1,359,572;5,976,768;-0,041448774
519,062;1,361,768;597,698;-0,041398739
52,016,206;136,396;5,977,689;-0,041398739
52,126,203;1,366,176;597,905;-0,041388732
522,362;1,368,356;5,979,269;-0,041438767
52,346,203;1,370,556;5,980,264;-0,041398739
524,562;1,372,772;598,168;-0,041388732
52,566,206;1,374,972;5,981,839;-0,041448774
526,762;1,377,164;5,982,237;-0,041388732
527,862;1,379,368;598,344;-0,041438767
52,896,206;1,381,556;5,983,763;-0,041418753
530,062;138,376;5,984,548;-0,041438767
53,116,206;1,385,968;5,985,521;-0,041438767
532,262;1,388,164;5,986,207;-0,041438767
533,362;1,390,352;5,986,791;-0,041388732
53,446,206;1,392,564;5,987,933;-0,04142876
535,562;139,476;5,988,418;-0,04142876
53,666,206;1,396,956;5,989,002;-0,04142876
537,762;1,399,176;5,990,071;-0,041438767
538,862;1,401,376;5,990,609;-0,04142876
53,996,206;1,403,564;5,990,898;-0,041418753
541,062;1,405,768;599,223;-0,041438767
54,216,206;1,407,952;5,992,574;-0,041418753
543,262;1,410,148;5,993,345;-0,041418753
544,362;1,412,368;5,994,264;-0,041418753
54,546,206;1,414,564;5,994,864;-0,041408746
546,562;1,416,752;5,995,043;-0,04142876
54,766,206;141,896;5,996,212;-0,041438767
548,762;1,421,156;5,997,072;-0,041458781
549,862;142,334;599,754;-0,041408746
55,096,206;1,425,552;5,998,693;-0,041438767
552,062;1,427,744;5,999,097;-0,041418753
55,316,206;1,429,932;5,999,289;-0,041398739
554,262;143,214;6,000,385;-0,041398739
555,362;1,434,336;6,000,936;-0,041468788
55,646,206;143,654;6,001,876;-0,041438767
557,562;1,438,756;6,002,644;-0,041438767
55,866,206;1,440,952;6,003,131;-0,041438767
559,762;1,443,144;6,003,507;-0,041438767
560,862;1,445,352;600,413;-0,04142876
56,196,206;1,447,568;6,005,009;-0,041438767
563,062;1,449,768;6,005,554;-0,041418753
56,416,206;1,451,976;6,006,125;-0,041438767
565,262;1,454,164;6,006,653;-0,041438767
566,362;1,456,348;6,007,285;-0,041478795
56,746,206;1,458,552;6,007,698;-0,041408746
568,562;1,460,756;6,008,872;-0,041468788
56,966,206;146,296;6,009,346;-0,041458781
570,762;1,465,168;6,010,066;-0,041438767
571,862;1,467,372;6,010,519;-0,041408746
57,296,206;146,956;6,011,118;-0,041478795
574,062;1,471,752;6,011,555;-0,041438767
57,516,206;1,473,968;6,013,065;-0,041448774
576,262;1,476,168;6,013,232;-0,041388732
577,362;1,478,336;601,281;-0,041408746
57,846,206;1,480,536;6,013,988;-0,041388732
579,562;148,274;6,015,015;-0,041478795
58,066,206;148,494;6,015,069;-0,041368718
581,762;148,714;6,015,995;-0,041418753
582,862;1,489,352;6,017,019;-0,041448774
58,396,206;1,491,552;6,017,194;-0,041368718
585,062;1,493,748;6,017,681;-0,041458781
58,616,206;1,495,948;6,018,263;-0,041418753
587,262;1,498,148;6,018,485;-0,041408746
588,362;150,034;6,019,202;-0,04142876
58,946,206;1,502,556;6,020,162;-0,041438767
590,562;1,504,752;6,020,316;-0,041418753
59,166,206;1,506,952;6,020,793;-0,041418753
592,762;150,914;6,021,514;-0,04142876
593,862;1,511,332;6,021,888;-0,04142876
59,496,206;1,513,532;6,022,496;-0,041458781
596,062;1,515,748;6,023,484;-0,04142876
59,716,206;1,517,944;602,354;-0,041458781
598,262;1,520,144;6,024,011;-0,041418753
599,362;1,522,348;6,024,854;-0,041448774
60,046,206;1,524,536;6,025,335;-0,041418753
601,562;152,674;6,025,667;-0,041458781
60,266,206;152,896;6,026,517;-0,041408746
603,762;1,531,156;6,026,428;-0,041418753
604,862;1,533,352;6,026,745;-0,041438767
60,596,206;1,535,564;6,027,551;-0,041438767
607,062;1,537,744;6,027,733;-0,041408746
60,816,206;153,994;6,028,255;-0,04142876
609,262;154,216;6,029,567;-0,041408746
610,362;154,436;602,924;-0,041388732
61,146,206;1,546,552;6,029,589;-0,04142876
612,562;1,548,764;6,030,389;-0,041418753
61,366,206;1,550,952;6,030,679;-0,041438767
614,762;1,553,148;6,030,932;-0,041408746
615,862;155,536;6,032,125;-0,04142876
61,696,206;1,557,552;6,032,399;-0,041458781
618,062;155,974;6,032,791;-0,041418753
61,916,206;1,561,952;603,329;-0,041418753
620,262;156,414;6,033,511;-0,041458781
621,362;156,634;6,034,029;-0,041398739
62,246,206;1,568,556;6,034,856;-0,041418753
623,562;1,570,748;6,035,004;-0,041438767
62,466,206;1,572,936;6,035,178;-0,041478795
625,762;1,575,152;6,036,177;-0,041408746
626,862;1,577,348;6,036,282;-0,041408746
62,796,206;1,579,552;6,036,537;-0,041438767
629,062;1,581,768;6,037,274;-0,041408746
63,016,206;1,583,964;6,037,365;-0,04142876
631,262;1,586,136;6,037,352;-0,041438767
63,236,206;1,588,344;6,038,292;-0,041398739
63,346,206;159,054;6,038,581;-0,041408746
634,562;1,592,736;6,039,066;-0,041458781
63,566,206;1,594,952;6,039,485;-0,041468788
636,762;1,597,152;6,039,886;-0,041448774
63,786,206;1,599,344;6,040,148;-0,041448774
63,896,206;1,601,548;6,040,667;-0,04142876
640,062;1,603,748;6,041,191;-0,041458781
64,116,206;1,605,964;6,041,842;-0,04142876
642,262;1,608,172;6,041,857;-0,041438767
64,336,206;1,610,336;6,042,199;-0,041438767
64,446,206;1,612,532;6,042,433;-0,041468788
645,562;161,474;6,042,969;-0,041448774
64,666,206;161,694;6,043,111;-0,041458781
647,762;1,619,136;604,373;-0,041438767
64,886,206;1,621,352;6,044,267;-0,041468788
64,996,206;1,623,552;6,044,776;-0,041448774
651,062;1,625,744;6,044,787;-0,041418753
65,216,206;1,627,944;6,044,989;-0,041468788
653,262;1,630,148;6,045,557;-0,04142876
65,436,206;1,632,348;6,046,027;-0,041488802
65,546,206;1,634,564;6,046,354;-0,041438767
656,562;1,636,768;6,046,888;-0,041468788
65,766,206;163,896;6,046,517;-0,041478795
658,762;1,641,148;604,695;-0,041418753
65,986,206;1,643,352;6,047,723;-0,041418753
66,096,206;1,645,552;6,048,001;-0,041418753
662,062;164,776;6,048,036;-0,041438767
66,316,206;1,649,956;604,853;-0,041448774
664,262;1,652,148;6,048,749;-0,041398739
66,536,206;165,434;6,048,993;-0,041408746
66,646,206;165,654;6,049,626;-0,041408746
667,562;1,658,744;6,050,321;-0,041468788
66,866,206;1,660,944;6,050,294;-0,041468788
669,762;1,663,148;6,050,498;-0,04142876
67,086,206;1,665,348;6,050,894;-0,04142876
67,196,206;166,754;605,078;-0,041448774
673,062;1,669,732;6,051,244;-0,041408746
67,416,206;167,194;6,051,634;-0,041448774
675,262;167,414;6,052,006;-0,041418753
67,636,206;1,676,348;6,052,086;-0,041448774
67,746,206;167,856;6,052,989;-0,04142876
678,562;1,680,748;6,052,634;-0,041408746
67,966,206;1,682,944;6,052,898;-0,041448774
680,762;1,685,152;6,053,581;-0,041448774
68,186,206;1,687,344;6,053,707;-0,041398739
68,296,206;168,954;6,053,962;-0,041408746
684,062;169,174;6,054,654;-0,041398739
68,516,206;1,693,928;6,054,252;-0,041438767
686,262;1,696,128;6,054,513;-0,041418753
68,736,206;1,698,344;6,055,454;-0,041398739
68,846,206;1,700,536;6,055,366;-0,041388732
689,562;1,702,736;6,055,441;-0,041448774
69,066,206;170,494;6,055,771;-0,041448774
691,762;1,707,136;6,056,055;-0,041398739
69,286,206;1,709,336;6,056,418;-0,041388732
69,396,206;171,156;6,057,006;-0,041468788
695,062;1,713,756;6,056,584;-0,041418753
69,616,206;171,594;6,056,491;-0,041448774
697,262;1,718,136;6,057,101;-0,041418753
69,836,206;1,720,328;6,057,093;-0,041388732
69,946,206;1,722,528;6,057,483;-0,041408746
700,562;1,724,748;6,058,233;-0,04142876
70,166,206;1,726,944;6,057,829;-0,041438767
702,762;1,729,148;6,057,777;-0,041418753
70,386,206;1,731,356;6,058,406;-0,041408746
70,496,206;173,354;6,058,315;-0,041368718
706,062;173,576;6,058,949;-0,041448774
70,716,206;173,798;6,059,251;-0,041448774
708,262;1,740,144;6,058,534;-0,041408746
70,936,206;1,742,328;6,059,095;-0,041418753
71,046,206;1,744,548;6,059,816;-0,041418753
711,562;174,674;6,059,771;-0,041418753
71,266,206;174,894;6,059,864;-0,041458781
713,762;1,751,156;6,060,576;-0,041408746
71,486,206;1,753,352;6,060,466;-0,041448774
71,596,206;175,554;6,060,532;-0,041398739
717,062;1,757,748;6,060,865;-0,04142876
71,816,206;1,759,936;6,060,847;-0,041398739
719,262;1,762,132;6,060,711;-0,04142876
72,036,206;1,764,356;6,061,407;-0,041438767
72,146,206;1,766,564;6,061,571;-0,041438767
722,562;1,768,752;6,061,524;-0,041468788
72,366,206;1,770,948;6,061,354;-0,041468788
724,762;1,773,144;6,061,973;-0,04142876
72,586,206;1,775,344;606,222;-0,041418753
72,696,206;1,777,556;6,062,155;-0,041418753
728,062;177,976;6,062,405;-0,041418753
72,916,206;1,781,948;6,062,155;-0,041438767
730,262;1,784,152;6,062,453;-0,041438767
73,136,206;1,786,352;6,062,856;-0,041438767
73,246,206;1,788,552;6,063,036;-0,041458781
733,562;179,076;6,063,088;-0,041438767
73,466,206;1,792,968;6,063,259;-0,041478795
735,762;1,795,156;6,062,905;-0,041408746
73,686,206;1,797,356;6,062,905;-0,04142876
73,796,206;1,799,552;6,063,094;-0,041388732
739,062;1,801,748;6,063,562;-0,041438767
74,016,206;180,396;6,063,741;-0,041438767
741,262;1,806,164;6,064,258;-0,041448774
74,236,206;1,808,356;6,063,873;-0,041398739
74,346,206;181,056;6,064,101;-0,041458781
744,562;181,276;6,064,107;-0,041398739
74,566,206;181,496;6,064,347;-0,041408746
746,762;181,716;6,064,234;-0,041408746
74,786,206;181,936;6,064,577;-0,041398739
74,896,206;1,821,552;6,064,512;-0,041388732
750,062;1,823,744;606,454;-0,041388732
75,116,206;182,594;6,064,606;-0,041418753
752,262;1,828,144;6,064,856;-0,041368718
75,336,206;1,830,348;6,064,609;-0,041398739
75,446,206;1,832,544;6,064,819;-0,041398739
755,562;1,834,744;6,065,012;-0,041408746
75,666,206;1,836,936;6,064,993;-0,041418753
757,762;1,839,148;6,065,533;-0,041398739
75,886,206;184,136;6,065,899;-0,041418753
75,996,206;1,843,556;6,065,296;-0,041398739
761,062;1,845,752;6,065,224;-0,041388732
76,216,206;1,847,944;6,065,473;-0,041388732
763,262;1,850,132;6,065,608;-0,041348704
76,436,206;1,852,336;6,065,668;-0,041398739
76,546,206;1,854,544;6,066,138;-0,041378725
766,562;185,674;6,065,847;-0,041388732
76,766,206;185,894;6,065,869;-0,041408746
768,762;1,861,148;6,065,983;-0,041418753
76,986,206;1,863,336;6,065,596;-0,041388732
77,096,206;1,865,544;6,065,973;-0,041408746
772,062;1,867,776;6,066,457;-0,041388732
77,316,206;1,869,956;6,065,537;-0,041418753
774,262;1,872,128;6,065,597;-0,041398739
77,536,206;187,434;606,654;-0,041398739
77,646,206;1,876,532;6,065,891;-0,041408746
777,562;1,878,736;60,659;-0,041388732
77,866,206;188,096;6,066,259;-0,04142876
779,762;1,883,152;6,065,972;-0,041408746
78,086,206;1,885,352;6,065,884;-0,041408746
78,196,206;1,887,552;6,066,437;-0,041378725
783,062;188,974;6,066,132;-0,041418753
78,416,206;1,891,936;6,066,059;-0,04142876
785,262;1,894,152;6,066,442;-0,041418753
78,636,206;1,896,352;6,066,111;-0,041418753
78,746,206;1,898,552;6,065,836;-0,041438767
788,562;1,900,752;6,066,144;-0,041408746
78,966,206;1,902,932;6,065,863;-0,04142876
790,762;1,905,132;6,066,163;-0,041418753
79,186,206;1,907,348;6,066,403;-0,041408746
79,296,206;1,909,544;6,066,117;-0,041388732
794,062;191,174;6,065,892;-0,041408746
79,516,206;1,913,944;6,066,022;-0,04142876
796,262;1,916,132;6,065,819;-0,041388732
79,736,206;1,918,336;6,065,936;-0,041418753
79,846,206;192,056;6,066,613;-0,041388732
799,562;1,922,748;6,066,105;-0,041358711
80,066,206;1,924,944;6,065,871;-0,041448774
801,762;1,927,148;6,065,985;-0,041438767
80,286,206;1,929,344;6,065,698;-0,041388732
80,396,206;193,154;6,065,484;-0,041368718
805,062;193,376;6,065,889;-0,041368718
80,616,206;193,596;6,065,634;-0,041408746
807,262;1,938,156;6,065,462;-0,041398739
80,836,206;194,036;6,065,562;-0,041378725
80,946,206;194,256;6,065,356;-0,041398739
810,562;194,476;6,065,261;-0,041368718
81,166,206;1,946,972;6,065,413;-0,041408746
812,762;1,949,168;6,065,251;-0,041408746
81,386,206;1,951,356;6,064,935;-0,041448774
81,496,206;1,953,556;6,065,102;-0,041408746
816,062;1,955,756;6,065,337;-0,041398739
81,716,206;1,957,948;6,065,077;-0,041388732
818,262;1,960,152;6,064,998;-0,041418753
81,936,206;1,962,352;6,064,686;-0,041408746
82,046,206;1,964,536;6,064,578;-0,041378725
821,562;196,674;6,064,317;-0,041398739
82,266,206;1,968,944;6,064,855;-0,04142876
823,762;1,971,152;6,064,808;-0,04142876
82,486,206;1,973,364;6,064,823;-0,041418753
82,596,206;1,975,564;6,064,482;-0,04142876
827,062;197,774;6,063,795;-0,04142876
82,816,206;1,979,944;6,063,795;-0,041458781
829,262;1,982,152;6,064,263;-0,041448774
83,036,206;1,984,348;6,063,914;-0,041388732
83,146,206;1,986,556;6,063,901;-0,041408746
832,562;198,876;6,064,034;-0,041418753
83,366,206;1,990,952;6,063,583;-0,041448774
834,762;1,993,144;6,063,083;-0,041398739
83,586,206;1,995,348;606,343;-0,04142876
83,696,206;1,997,568;6,063,911;-0,041408746
838,062;1,999,776;6,063,181;-0,041438767
83,916,206;2,001,944;6,062,387;-0,041468788
840,262;2,004,136;6,062,778;-0,04142876
84,136,206;200,634;6,062,893;-0,041398739
84,246,206;200,854;606,274;-0,04142876
843,562;2,010,752;6,063,027;-0,04142876
84,466,206;201,296;6,062,458;-0,041438767
845,762;201,516;6,062,379;-0,041448774
84,686,206;201,736;6,062,198;-0,041448774
84,796,206;2,019,552;6,061,839;-0,041478795
849,062;2,021,756;6,061,791;-0,041448774
85,016,206;2,023,964;6,062,144;-0,041458781
851,262;2,026,164;6,061,574;-0,041438767
85,236,206;2,028,368;6,061,486;-0,041478795
85,346,206;2,030,576;6,061,391;-0,041448774
854,562;2,032,748;6,060,727;-0,041438767
85,566,206;2,034,952;6,060,673;-0,041458781
856,762;2,037,168;6,061,159;-0,041478795
85,786,206;203,936;6,060,482;-0,041448774
85,896,206;2,041,552;6,060,233;-0,041468788
860,062;2,043,756;6,060,412;-0,041458781
86,116,206;204,594;6,059,926;-0,04142876
862,262;2,048,144;6,059,589;-0,041448774
86,336,206;205,036;6,060,053;-0,041438767
86,446,206;2,052,556;6,059,244;-0,041438767
865,562;2,054,756;605,925;-0,041418753
86,666,206;2,056,964;6,059,371;-0,041438767
867,762;2,059,148;605,861;-0,04142876
86,886,206;2,061,348;6,058,401;-0,04142876
86,996,206;2,063,564;6,058,714;-0,041408746
871,062;206,576;6,058,106;-0,041458781
87,216,206;206,796;6,057,963;-0,041468788
873,262;2,070,168;6,057,996;-0,041458781
87,436,206;2,072,356;6,057,433;-0,041448774
87,546,206;2,074,552;6,057,317;-0,041398739
876,562;2,076,768;6,057,312;-0,041448774
87,766,206;2,078,956;6,056,612;-0,041468788
878,762;2,081,152;6,056,404;-0,04142876
87,986,206;208,336;6,056,719;-0,041458781
88,096,206;2,085,544;6,055,939;-0,041418753
882,062;2,087,736;6,055,835;-0,04142876
88,316,206;2,089,952;6,055,965;-0,041438767
884,262;2,092,144;6,055,729;-0,041398739
88,536,206;209,434;6,055,092;-0,041418753
88,646,206;2,096,544;6,055,146;-0,041418753
887,562;2,098,736;6,054,703;-0,041408746
88,866,206;2,100,936;6,054,664;-0,041438767
889,762;2,103,156;6,054,532;-0,041408746
89,086,206;2,105,352;6,054,201;-0,041408746
89,196,206;2,107,544;6,053,532;-0,041408746
89,306,206;210,974;6,053,569;-0,041388732
89,416,206;211,194;6,053,101;-0,041478795
895,262;211,414;6,052,909;-0,041388732
89,636,206;211,636;6,052,906;-0,041418753
89,746,206;2,118,552;605,249;-0,041408746
89,856,206;2,120,756;6,052,009;-0,041408746
89,966,206;2,122,956;6,051,777;-0,041458781
900,762;2,125,152;6,051,565;-0,041418753
90,186,206;2,127,356;6,051,587;-0,041418753
90,296,206;2,129,588;605,123;-0,041478795
90,406,206;2,131,764;6,050,126;-0,04142876
90,516,206;2,133,944;6,049,889;-0,04142876
906,262;2,136,144;6,049,921;-0,041418753
90,736,206;2,138,352;6,049,891;-0,041448774
90,846,206;2,140,548;6,049,621;-0,041448774
90,956,206;214,276;6,049,344;-0,041448774
91,066,206;214,496;604,868;-0,041458781
911,762;2,147,152;6,048,171;-0,041418753
91,286,206;2,149,348;6,047,721;-0,041418753
91,396,206;2,151,552;6,047,802;-0,041418753
91,506,206;2,153,748;6,047,355;-0,041398739
91,616,206;2,155,956;6,047,274;-0,041448774
917,262;2,158,156;6,046,918;-0,041388732
91,836,206;216,036;6,046,555;-0,041388732
91,946,206;2,162,552;6,045,616;-0,041378725
92,056,206;2,164,748;6,045,691;-0,041388732
92,166,206;2,166,952;6,045,611;-0,041368718
922,762;2,169,156;6,045,167;-0,041438767
92,386,206;217,136;6,044,892;-0,041408746
92,496,206;2,173,552;6,044,737;-0,041408746
92,606,206;2,175,748;6,043,817;-0,041378725
92,716,206;2,177,952;6,043,555;-0,041388732
928,262;2,180,164;6,043,402;-0,041358711
92,936,206;2,182,364;6,042,756;-0,041388732
93,046,206;2,184,568;6,042,274;-0,041398739
93,156,206;2,186,764;6,041,999;-0,041388732
93,266,206;2,188,956;6,041,469;-0,041408746
933,762;2,191,152;6,041,288;-0,041378725
93,486,206;219,336;6,040,906;-0,041378725
93,596,206;2,195,556;6,040,061;-0,041408746
93,706,206;2,197,768;603,993;-0,041358711
93,816,206;2,199,968;603,958;-0,041398739
939,262;2,202,156;6,038,764;-0,041348704
94,036,206;2,204,344;6,038,589;-0,041388732
94,146,206;2,206,556;6,038,756;-0,041368718
94,256,206;2,208,748;6,037,671;-0,041398739
94,366,206;2,210,948;6,037,149;-0,041398739
944,762;2,213,156;6,037,006;-0,041388732
94,586,206;2,215,344;6,036,267;-0,041398739
94,696,206;221,754;6,035,573;-0,041378725
94,806,206;2,219,756;6,035,783;-0,041388732
94,916,206;2,221,944;6,034,887;-0,04142876
950,262;2,224,144;6,034,624;-0,041408746
95,136,206;2,226,352;6,034,102;-0,041418753
95,246,206;222,854;6,033,196;-0,041408746
95,356,206;2,230,744;6,032,656;-0,041378725
95,466,206;2,232,968;6,032,803;-0,041418753
955,762;2,235,164;6,031,749;-0,041388732
95,686,206;2,237,356;603,126;-0,041378725
95,796,206;2,239,552;6,030,962;-0,041418753
95,906,206;2,241,736;6,030,303;-0,041418753
96,016,206;224,394;602,953;-0,041418753
961,262;224,616;6,029,478;-0,04142876
96,236,206;2,248,352;6,028,588;-0,041418753
96,346,206;2,250,552;6,028,053;-0,041408746
96,456,206;2,252,764;6,027,851;-0,041418753
96,566,206;2,254,948;6,027,184;-0,041418753
966,762;2,257,148;6,026,468;-0,041398739
96,786,206;2,259,384;6,026,517;-0,041468788
96,896,206;226,158;6,025,215;-0,041408746
97,006,206;2,263,744;6,023,986;-0,041418753
97,116,206;2,265,952;6,024,213;-0,041448774
972,262;2,268,148;6,023,654;-0,041388732
97,336,206;2,270,348;6,022,969;-0,041418753
97,446,206;227,256;6,022,767;-0,041398739
97,556,206;2,274,752;6,022,003;-0,041418753
97,666,206;2,276,948;6,021,014;-0,041408746
977,762;2,279,152;6,020,482;-0,041438767
97,886,206;2,281,348;6,019,922;-0,041448774
97,996,206;228,354;601,916;-0,041438767
98,106,206;2,285,752;601,881;-0,041408746
98,216,206;2,287,952;6,018,128;-0,04142876
983,262;2,290,152;6,017,479;-0,041408746
98,436,206;229,236;6,016,734;-0,04142876
98,546,206;2,294,544;6,015,533;-0,041408746
98,656,206;2,296,744;601,503;-0,041378725
98,766,206;2,298,956;6,014,323;-0,041448774
988,762;2,301,152;6,013,801;-0,041418753
98,986,206;2,303,344;6,012,774;-0,041438767
99,096,206;230,554;6,012,245;-0,041438767
99,206,206;2,307,736;6,011,708;-0,041398739
99,316,206;2,309,936;601,106;-0,041468788
994,262;2,312,152;6,010,052;-0,041468788
99,536,206;2,314,352;6,009,287;-0,041418753
99,646,206;2,316,544;6,008,313;-0,041438767
99,756,206;231,874;6,007,254;-0,041408746
99,866,206;2,320,944;6,006,702;-0,041458781
999,762;2,323,132;6,005,895;-0,041418753
100,086,206;232,534;6,005,198;-0,041438767
100,196,206;2,327,548;6,004,205;-0,041418753
100,306,206;2,329,748;6,003,137;-0,041418753
100,416,206;2,331,948;6,002,024;-0,041448774
1,005,262;2,334,152;6,001,503;-0,041468788
100,636,206;2,336,356;6,000,702;-0,041418753
100,746,206;2,338,556;5,999,457;-0,041408746
100,856,206;2,340,752;5,998,891;-0,041448774
100,966,206;2,342,948;5,997,666;-0,041478795
1,010,762;2,345,144;5,996,454;-0,041398739
101,186,206;2,347,348;5,995,806;-0,041468788
101,296,206;2,349,548;5,994,938;-0,04142876
101,406,206;2,351,748;5,993,719;-0,041468788
101,516,206;2,353,952;5,992,906;-0,041488802
1,016,262;2,356,152;5,992,174;-0,041438767
101,736,206;2,358,344;5,990,801;-0,041408746
101,846,206;2,360,548;5,989,724;-0,041498808
101,956,206;2,362,768;5,989,091;-0,041448774
102,066,206;2,364,972;5,987,782;-0,041458781
1,021,762;2,367,172;5,986,459;-0,041448774
102,286,206;2,369,368;5,985,511;-0,041418753
102,396,206;2,371,552;598,415;-0,041448774
1,025,062;2,373,752;5,983,452;-0,041438767
102,616,212;2,375,964;598,255;-0,041458781
102,726,206;237,816;5,980,543;-0,041448774
102,836,206;2,380,364;5,979,429;-0,041458781
102,946,206;2,382,568;5,978,642;-0,041448774
1,030,562;2,384,756;5,977,021;-0,041438767
103,166,212;2,386,948;597,576;-0,041438767
103,276,206;2,389,176;5,975,447;-0,041448774
103,386,206;2,391,376;5,973,413;-0,04142876
103,496,206;2,393,548;5,970,917;-0,041448774
1,036,062;2,395,748;5,970,569;-0,041448774
103,716,212;2,397,944;5,969,145;-0,041468788
103,826,206;2,400,136;5,967,532;-0,041478795
103,936,206;2,402,372;5,967,155;-0,041458781
104,046,206;2,404,564;5,964,969;-0,041488802
1,041,562;2,406,772;5,963,603;-0,041448774
104,266,212;2,408,972;5,962,145;-0,041448774
104,376,206;2,411,164;5,960,194;-0,041418753
104,486,206;241,336;5,958,799;-0,04142876
104,596,206;241,558;5,957,788;-0,041448774
1,047,062;2,417,772;595,587;-0,041438767
104,816,212;2,419,976;5,954,517;-0,041488802
104,926,212;2,422,184;5,953,149;-0,041448774
1,050,362;242,436;5,950,703;-0,041438767
1,051,462;2,426,556;5,949,057;-0,041468788
1,052,562;242,878;5,947,878;-0,041498808
105,366,212;2,430,972;5,945,715;-0,041448774
105,476,212;2,433,168;5,944,123;-0,041468788
1,055,862;2,435,376;594,253;-0,041478795
1,056,962;243,756;5,940,658;-0,041468788
1,058,062;2,439,764;5,938,815;-0,041448774
105,916,212;2,441,976;5,937,254;-0,041498808
106,026,212;2,444,172;5,934,854;-0,041458781
1,061,362;244,636;5,932,728;-0,041478795
1,062,462;2,448,564;5,931,191;-0,041468788
1,063,562;2,450,756;5,929,288;-0,041488802
106,466,212;2,452,948;5,927,084;-0,041468788
106,576,212;2,455,164;5,925,858;-0,041468788
1,066,862;245,736;592,347;-0,041458781
1,067,962;2,459,556;5,921,307;-0,041448774
1,069,062;2,461,768;591,887;-0,041478795
107,016,212;246,396;5,916,892;-0,041458781
107,126,212;2,466,168;5,914,766;-0,041488802
1,072,362;246,838;5,912,597;-0,041458781
1,073,462;2,470,576;5,910,015;-0,041488802
1,074,562;2,472,764;5,907,789;-0,041448774
107,566,212;2,474,968;5,905,471;-0,041468788
107,676,212;2,477,164;5,902,913;-0,041438767
1,077,862;2,479,364;5,900,603;-0,041468788
1,078,962;2,481,572;5,898,384;-0,041488802
1,080,062;2,483,772;5,895,969;-0,041478795
108,116,212;248,596;5,893,059;-0,041448774
108,226,212;248,816;5,890,589;-0,041478795
1,083,362;2,490,356;5,888,404;-0,041478795
1,084,462;2,492,564;5,885,905;-0,041468788
1,085,562;2,494,784;5,882,859;-0,041458781
108,666,212;2,496,988;5,880,126;-0,041508815
108,776,212;2,499,172;5,877,222;-0,041448774
1,088,862;250,136;5,874,474;-0,041448774
1,089,962;2,503,568;5,872,224;-0,041458781
1,091,062;2,505,768;5,869,622;-0,041478795
109,216,212;250,798;5,866,393;-0,041468788
109,326,212;2,510,176;5,863,538;-0,04142876
1,094,362;2,512,376;5,860,335;-0,041478795
1,095,462;2,514,572;585,724;-0,041468788
1,096,562;2,516,772;5,854,628;-0,041478795
109,766,212;2,518,972;5,851,899;-0,041478795
109,876,212;2,521,196;58,488;-0,041458781
1,099,862;2,523,396;5,845,503;-0,041468788
1,100,962;252,556;5,841,904;-0,041478795
1,102,062;2,527,752;5,838,777;-0,041468788
110,316,212;2,529,968;5,835,895;-0,041488802
110,426,212;2,532,176;583,301;-0,041478795
1,105,362;2,534,384;5,829,143;-0,041468788
1,106,462;253,658;5,825,829;-0,041438767
1,107,562;2,538,788;5,822,687;-0,041468788
110,866,212;2,540,972;5,818,893;-0,041458781
110,976,212;2,543,176;5,815,574;-0,041448774
1,110,862;2,545,388;5,812,254;-0,041468788
1,111,962;2,547,588;5,808,063;-0,041458781
1,113,062;2,549,788;5,804,727;-0,041468788
111,416,212;25,52;5,801,375;-0,041478795
111,526,212;2,554,188;5,797,344;-0,041458781
1,116,362;2,556,376;5,793,634;-0,041438767
1,117,462;2,558,588;5,790,468;-0,041468788
1,118,562;2,560,784;5,785,911;-0,041448774
111,966,212;2,562,984;5,781,791;-0,041468788
112,076,212;2,565,192;5,778,411;-0,041448774
1,121,862;256,738;5,774,173;-0,041448774
1,122,962;2,569,576;5,770,307;-0,041438767
1,124,062;2,571,796;5,766,726;-0,041468788
112,516,212;2,573,988;5,762,052;-0,041458781
112,626,212;2,576,184;5,757,658;-0,041458781
1,127,362;2,578,396;5,753,797;-0,041448774
1,128,462;2,580,584;5,749,004;-0,041458781
1,129,562;2,582,776;5,744,721;-0,041438767
113,066,212;2,584,988;5,740,926;-0,041448774
113,176,212;258,718;5,736,254;-0,041418753
1,132,862;258,938;5,732,126;-0,041438767
1,133,962;2,591,592;5,727,918;-0,041478795
1,135,062;259,378;5,722,883;-0,041438767
113,616,212;2,595,984;5,718,285;-0,041468788
113,726,212;25,982;5,714,068;-0,041438767
1,138,362;2,600,388;57,091;-0,041458781
1,139,462;2,602,584;5,704,474;-0,041438767
1,140,562;2,604,792;5,700,122;-0,041468788
114,166,212;2,606,984;5,694,987;-0,041488802
114,276,212;2,609,176;5,690,072;-0,041448774
1,143,862;26,114;5,685,436;-0,041448774
1,144,962;2,613,592;5,680,036;-0,041468788
1,146,062;2,615,788;5,675,045;-0,041448774
114,716,212;2,617,996;567,036;-0,041488802
114,826,212;2,620,184;5,665,002;-0,041468788
1,149,362;262,238;5,659,739;-0,041468788
1,150,462;2,624,604;5,654,786;-0,041468788
1,151,562;26,268;5,649,307;-0,041478795
115,266,212;2,628,996;5,643,631;-0,041488802
115,376,212;2,631,192;5,638,193;-0,041458781
1,154,862;263,338;5,632,952;-0,041448774
1,155,962;2,635,584;5,627,588;-0,041438767
1,157,062;2,637,804;5,622,237;-0,041488802
115,816,212;26,4;5,616,174;-0,041498808
115,926,212;2,642,184;5,610,245;-0,041458781
1,160,362;26,444;5,604,742;-0,041448774
1,161,462;2,646,596;5,598,609;-0,041478795
1,162,562;2,648,792;5,592,801;-0,041468788
116,366,212;265,102;5,587,443;-0,041488802
116,476,212;2,653,224;5,580,993;-0,041498808
1,165,862;2,655,384;5,573,887;-0,041498808
1,166,962;2,657,588;5,568,434;-0,041478795
1,168,062;2,659,796;5,562,541;-0,041498808
116,916,212;26,62;5,555,849;-0,041478795
117,026,212;2,664,216;5,549,566;-0,041448774
1,171,362;2,666,424;554,306;-0,041488802
1,172,462;2,668,612;5,536,455;-0,041488802
1,173,562;2,670,812;5,529,785;-0,041458781
117,466,212;2,673,016;5,523,578;-0,041478795
117,576,212;2,675,212;5,516,772;-0,041478795
1,176,862;2,677,424;5,509,676;-0,041438767
1,177,962;2,679,628;5,502,801;-0,041518822
1,179,062;2,681,828;5,495,761;-0,041478795
118,016,212;2,684,032;5,488,561;-0,041478795
118,126,212;2,686,212;5,481,511;-0,041458781
1,182,362;26,884;5,474,501;-0,041458781
1,183,462;2,690,604;5,467,357;-0,041468788
1,184,562;2,692,804;546,014;-0,041478795
118,566,212;26,95;5,452,397;-0,041478795
118,676,212;2,697,204;5,444,682;-0,041508815
1,187,862;26,994;5,437,214;-0,041458781
1,188,962;2,701,608;5,429,927;-0,041488802
1,190,062;2,703,812;5,421,777;-0,041478795
119,116,212;2,706,012;5,413,904;-0,041488802
119,226,212;2,708,208;5,406,016;-0,041488802
1,193,362;2,710,408;5,397,682;-0,041468788
1,194,462;2,712,608;5,389,508;-0,041508815
1,195,562;2,714,812;5,381,588;-0,041508815
119,666,212;2,717,012;5,372,726;-0,041528829
119,776,212;2,719,212;5,364,563;-0,041458781
1,198,862;272,142;5,356,281;-0,041498808
1,199,962;2,723,612;5,347,365;-0,041508815
1,201,062;2,725,812;5,338,474;-0,041478795
120,216,212;2,728,028;5,329,801;-0,041468788
120,326,212;2,730,224;532,021;-0,041478795
1,204,362;2,732,416;5,311,254;-0,041468788
1,205,462;2,734,628;5,302,637;-0,041488802
1,206,562;2,736,812;5,292,948;-0,041518822
120,766,212;2,739,016;5,283,595;-0,041478795
120,876,212;2,741,228;527,464;-0,041458781
1,209,862;2,743,424;5,263,841;-0,041458781
1,210,962;2,745,628;525,417;-0,041458781
1,212,062;274,784;5,244,596;-0,041458781
121,316,212;2,750,028;5,234,171;-0,041488802
121,426,212;2,752,228;5,223,938;-0,041468788
1,215,362;2,754,452;5,214,309;-0,041488802
1,216,462;2,756,648;5,202,998;-0,041508815
1,217,562;2,758,848;5,192,449;-0,041508815
121,866,212;2,761,052;5,181,862;-0,041508815
121,976,212;2,763,236;5,170,606;-0,04142876
1,220,862;276,544;5,159,845;-0,041478795
1,221,962;2,767,656;5,148,916;-0,041458781
1,223,062;2,769,848;5,137,061;-0,041468788
122,416,212;2,772,048;5,125,815;-0,041478795
122,526,212;2,774,256;5,114,471;-0,041478795
1,226,362;2,776,448;5,102,065;-0,041468788
1,227,462;277,864;5,089,871;-0,041458781
1,228,562;2,780,864;5,078,144;-0,041448774
122,966,212;2,783,072;5,065,507;-0,041488802
123,076,212;2,785,268;5,052,709;-0,041458781
1,231,862;2,787,444;5,040,497;-0,041468788
1,232,962;278,964;5,027,434;-0,041468788
1,234,062;279,184;5,014,386;-0,041518822
123,516,212;2,794,064;5,000,974;-0,041498808
123,626,212;279,626;4,987,014;-0,041438767
1,237,362;279,846;497,305;-0,041488802
1,238,462;2,800,668;4,959,512;-0,041518822
1,239,562;2,802,856;4,945,036;-0,041488802
124,066,212;2,805,052;4,930,549;-0,041498808
124,176,212;2,807,272;4,916,058;-0,041448774
1,242,862;2,809,464;4,900,661;-0,041478795
1,243,962;2,811,668;4,885,159;-0,041478795
1,245,062;2,813,884;4,869,665;-0,041498808
124,616,212;2,816,076;4,853,857;-0,041478795
124,726,212;2,818,264;4,837,721;-0,041468788
1,248,362;282,048;4,821,403;-0,041468788
1,249,462;2,822,676;4,804,366;-0,041448774
1,250,562;2,824,868;4,787,092;-0,041478795
125,166,212;2,827,076;4,769,438;-0,041498808
125,276,212;2,829,268;4,751,488;-0,041468788
1,253,862;2,831,472;4,733,327;-0,041448774
1,254,962;2,833,688;4,714,806;-0,04142876
1,256,062;2,835,892;4,695,256;-0,04142876
125,716,212;2,838,084;4,675,276;-0,041478795
125,826,212;2,840,292;4,654,779;-0,041448774
1,259,362;2,842,488;463,394;-0,041418753
1,260,462;2,844,696;4,611,755;-0,041458781
1,261,562;2,846,904;4,587,577;-0,041458781
126,215,212;2,848,104;4,445,394;-0,041448774
1262,17;2,848,296;2,513,275;-0,03739596