File: tensile_test_ontology_TTO/data/primary_data/Zx3.csv
Time;Crosshead travel;Force;Strain
(s);(mm);(kN);(%)
0;0;0,20536;0
0,986;0,0554;0,79908;0,003110716
1,474;0,12568;192,312;0,007441712
1,864;0,19828;306,121;0,012182803
2,18;0,26688;354,755;0,014793404
2,818;0,441;467,428;0,019954592
3,22;0,57468;581,023;0,024635669
3,512;0,67916;694,829;0,029296741
3,766;0,77316;809,084;0,033947811
4,008;0,86488;927,184;0,038838937
4,228;0,94928;1,040,682;0,043580028
4,448;103,432;1,158,173;0,048401137
4,66;111,692;1,274,972;0,053342274
4,862;119,576;1,387,895;0,058013349
5,06;127,336;1,501,452;0,062714431
5,258;135,032;1,615,624;0,067515535
5,456;142,692;1,731,296;0,072406661
5,654;150,324;1,848,265;0,077287784
5,852;157,956;196,626;0,082378955
6,05;165,524;2,084,639;0,08744012
6,248;17,306;2,203,212;0,09261131
6,446;180,536;2,323,505;0,097862518
6,644;18,796;2,443,151;0,103183743
6,842;195,276;2,562,466;0,108634997
7,04;202,496;2,680,827;0,114136263
7,238;2,096;2,798,226;0,119697542
7,436;216,556;2,913,479;0,125498877
7,634;22,336;3,026,474;0,131260203
7,834;230,048;3,138,856;0,137421621
8,054;237,204;3,258,228;0,144213183
8,274;244,112;3,374,034;0,151384834
8,51;25,116;3,490,567;0,159216636
8,752;25,806;3,604,158;0,167588562
9,022;265,188;3,719,736;0,177240783
9,316;2,723;3,832,273;0,187773207
9,656;279,636;39,461;0,200326095
10,066;287,256;4,059,232;0,215379559
10,614;295,356;4,172,557;0,234694003
11,442;304,224;4,284,032;0,261120084
12,54;312,364;4,375,421;0,292377276
13,64;318,428;4,434,394;0,320763808
14,736;324,244;4,486,015;0,349930519
15,836;328,616;4,516,875;0,377686906
16,936;332,464;4,537,892;0,405793373
18,036;335,952;4,552,809;0,433979859
19,136;339,072;4,562,731;0,461466183
20,236;34,194;4,566,694;0,489592655
21,336;34,456;4,567,744;0,517299031
22,436;3,47;4,565,823;0,544765351
23,536;349,288;4,555,884;0,572611758
24,636;351,508;4,540,728;0,600228112
25,736;353,708;4,522,848;0,627564403
26,836;355,904;4,506,729;0,654900693
27,936;358,496;4,506,386;0,68200693
29,036;360,472;4,486,437;0,710143404
30,136;362,536;4,478,257;0,737859782
31,236;364,564;4,473,535;0,765346106
32,336;366,596;4,470,917;0,792832431
33,436;368,568;4,468,318;0,820298751
34,536;37,054;4,466,918;0,847695055
35,636;372,516;446,768;0,875071354
36,736;374,488;44,67;0,902817738
37,836;376,544;4,464,015;0,930554121
38,936;378,488;4,467,427;0,957600344
40,036;380,412;4,467,179;0,985416744
41,136;38,222;4,465,352;1,012,753,034
42,236;384,048;4,465,322;1,040,379,391
43,336;38,584;4,465,216;1,068,045,757
44,436;387,576;4,464,265;1,095,842,153
45,536;389,372;4,467,722;112,320,845
46,636;391,124;4,470,194;1,150,444,717
47,736;392,952;4,474,916;1,177,941,044
48,836;394,808;4,480,965;12,051,273
49,936;396,716;448,771;1,232,403,576
51,036;398,696;4,494,685;1,259,899,903
52,136;400,688;4,500,706;1,287,536,262
53,236;402,784;4,509,567;1,314,762,527
54,336;404,888;4,516,842;1,341,998,794
55,436;407,332;4,526,031;1,370,295,305
56,536;409,552;4,535,049;1,396,761,395
57,636;411,912;454,405;1,424,177,703
58,736;414,344;4,552,113;1,451,894,081
59,836;416,892;4,562,374;1,479,350,399
60,936;4,195;4,572,366;1,506,776,709
62,036;42,212;4,580,996;1,533,802,928
63,136;424,884;4,592,603;1,561,069,202
64,236;42,768;4,601,581;1,588,825,589
6,533,601;430,532;4,612,485;161,621,189
6,643,601;433,444;4,623,318;1,643,628,199
67,536;436,712;464,157;1,670,714,431
68,636;439,604;4,645,653;1,698,730,878
69,736;442,624;4,658,103;1,726,387,242
7,083,601;445,612;4,668,023;1,753,883,569
7,193,601;4,486;467,966;1,780,579,711
73,036;45,172;4,691,551;1,808,316,094
74,136;454,788;4,701,208;1,835,832,425
75,236;457,916;4,713,311;1,863,328,752
7,633,601;460,984;4,723,153;189,065,504
7,743,601;46,414;4,735,041;1,918,261,392
78,536;467,524;4,752,252;1,944,967,537
79,636;470,604;4,756,603;197,314,402
80,736;473,732;4,767,387;2,000,840,393
8,183,601;476,832;4,777,857;2,028,256,702
8,293,601;479,972;4,789,136;2,055,683,013
84,036;48,306;4,799,434;208,304,931
85,136;486,188;481,008;2,110,715,676
8,623,601;489,276;4,820,734;2,137,881,927
8,733,601;492,388;4,830,856;2,165,808,353
8,843,601;495,464;4,840,878;2,193,144,643
89,536;498,836;4,853,786;2,220,971,045
90,636;50,182;4,861,216;2,248,007,266
9,173,601;504,944;4,871,744;2,275,833,669
9,283,601;507,964;488,159;23,029,099
9,393,601;511,008;4,891,647;2,330,536,256
95,036;514,008;4,900,628;2,357,772,523
96,136;517,104;4,911,864;2,385,558,917
9,723,601;520,124;4,920,033;2,413,185,274
9,833,601;523,112;4,928,897;2,440,471,553
9,943,601;526,392;4,944,156;2,467,687,815
100,536;529,312;4,947,917;2,495,354,181
101,636;532,316;4,956,091;2,523,060,556
10,273,601;53,532;4,965,461;2,550,476,865
10,383,601;538,328;4,974,416;2,578,113,224
10,493,601;541,304;4,983,391;2,605,419,507
106,036;544,352;4,992,992;2,633,295,921
107,136;547,324;5,001,172;2,660,822,255
10,823,601;550,308;5,009,618;2,688,288,575
10,933,601;553,528;502,416;2,715,024,727
11,043,601;556,436;5,027,525;2,742,951,153
111,536;55,938;5,034,834;2,770,547,503
112,636;56,234;5,043,804;2,797,943,807
11,373,601;565,268;505,114;2,825,360,115
11,483,601;568,208;505,919;2,852,706,408
11,593,601;571,208;5,067,106;288,070,285
117,036;574,192;5,075,619;2,908,609,271
11,813,601;577,032;5,080,894;2,935,585,478
11,923,601;580,252;5,095,552;2,962,871,757
12,033,601;583,136;5,099,295;2,990,638,146
12,143,601;586,056;5,106,694;301,812,447
122,536;58,902;5,115,181;3,045,610,795
12,363,601;591,924;5,121,511;3,072,817,055
12,473,601;594,904;5,130,051;3,100,503,426
12,583,601;597,836;5,135,731;3,128,009,755
12,693,601;6,008;5,143,516;3,155,246,022
12,803,601;603,824;515,099;3,183,012,411
129,136;606,968;5,156,891;3,210,728,789
13,023,601;609,976;5,165,349;3,238,015,067
13,133,602;612,952;5,171,475;3,265,271,339
132,436;616,004;5,179,743;3,292,727,657
13,353,602;6,19;5,186,771;3,319,983,928
134,636;622,068;519,432;3,347,860,343
135,736;62,506;5,200,544;3,375,456,693
13,683,602;628,044;5,207,492;3,402,772,978
137,936;631,268;5,217,869;3,430,359,326
13,903,602;634,164;5,221,099;3,457,855,653
140,136;63,712;5,226,305;3,485,411,993
141,236;640,052;5,233,036;3,512,838,304
14,233,602;642,996;5,239,409;3,540,494,668
143,436;645,904;5,246,002;356,771,093
14,453,602;648,892;5,252,913;3,595,657,361
145,636;651,812;5,258,704;3,623,083,672
146,736;654,896;5,269,183;36,488,496
14,783,602;65,784;5,270,613;367,770,624
148,936;6,608;5,278,971;3,705,392,611
15,003,602;663,672;5,283,267;3,732,728,901
151,136;666,604;5,290,164;376,023,523
152,236;669,492;5,295,346;3,787,761,564
15,333,602;672,396;5,301,602;3,815,267,893
15,428,002;67,368;5,277,914;3,832,121,771
155,38;675,876;5,296,131;3,850,345,965
15,648,002;678,072;5,302,372;3,870,430,586
157,58;68,028;5,307,904;3,890,725,256
15,868,002;68,246;5,312,251;3,909,189,505
159,722;684,528;5,316,188;3,928,633,979
182,772;686,196;5,221,874;-0,089780659
18,387,202;688,396;5,291,682;-0,089760654
18,497,202;6,906;5,324,681;-0,089790661
186,072;6,928;5,337,793;-0,089740649
18,717,202;694,984;5,343,432;-0,089810665
188,272;69,718;534,757;-0,089790661
18,937,202;699,388;5,351,618;-0,089760654
19,047,202;701,592;5,354,698;-0,089760654
191,572;703,812;5,358,638;-0,089750652
19,267,202;70,602;5,362,323;-0,089800663
193,772;708,172;5,365,049;-0,089790661
19,487,202;710,368;5,369,598;-0,089750652
19,597,202;712,588;5,374,107;-0,089770656
197,072;714,788;5,377,407;-0,089760654
19,817,202;716,984;5,380,906;-0,089780659
199,272;719,196;5,384,888;-0,089790661
20,037,202;721,384;5,388,326;-0,089770656
20,147,202;723,572;5,392,081;-0,089750652
202,572;725,796;539,679;-0,089760654
20,367,202;727,984;5,400,298;-0,089810665
204,772;73,018;5,403,764;-0,089750652
20,587,202;732,392;5,407,819;-0,089780659
20,697,202;734,588;5,410,975;-0,089750652
208,072;736,784;5,414,813;-0,089750652
20,917,202;738,992;5,418,838;-0,089760654
210,272;74,118;5,422,441;-0,089800663
21,137,202;74,338;5,425,755;-0,089750652
21,247,202;745,584;5,430,007;-0,089800663
213,572;747,768;5,432,846;-0,089750652
21,467,202;74,996;543,649;-0,089810665
215,772;752,184;5,440,528;-0,089770656
21,687,202;754,376;5,443,791;-0,089770656
21,797,202;756,572;5,447,299;-0,089800663
219,072;75,878;5,451,208;-0,089780659
22,017,202;760,976;5,454,726;-0,089770656
221,272;763,168;5,458,108;-0,089800663
22,237,202;765,384;5,461,882;-0,089780659
22,347,202;767,576;5,464,966;-0,089800663
224,572;769,776;5,468,236;-0,089750652
22,567,202;771,984;5,472,016;-0,089740649
226,772;77,418;5,475,195;-0,089820668
22,787,202;776,372;5,478,665;-0,089790661
22,897,202;778,592;5,482,401;-0,089800663
230,072;780,792;5,485,331;-0,089740649
23,117,202;78,298;5,488,402;-0,089760654
23,227,202;785,184;5,491,421;-0,089760654
23,337,202;787,376;5,494,722;-0,089790661
23,447,202;789,576;5,498,037;-0,089760654
235,572;791,788;5,501,555;-0,089720645
23,667,202;79,398;5,504,831;-0,089780659
23,777,202;796,168;5,508,054;-0,089780659
23,887,202;79,838;5,511,076;-0,089760654
23,997,202;800,576;5,514,187;-0,089740649
241,072;802,772;551,715;-0,089720645
24,217,202;804,988;5,520,759;-0,089760654
24,327,202;807,192;5,523,889;-0,089770656
24,437,202;809,384;5,526,735;-0,089720645
24,547,202;811,584;5,529,936;-0,089770656
246,572;813,776;5,532,581;-0,089740649
24,767,202;815,968;5,535,683;-0,089770656
24,877,202;818,184;553,881;-0,089780659
24,987,202;820,384;5,541,779;-0,089780659
25,097,202;822,576;5,544,434;-0,089760654
252,072;824,776;5,547,559;-0,089750652
25,317,202;82,698;5,550,824;-0,089760654
25,427,202;82,918;5,553,811;-0,089750652
25,537,202;831,384;5,556,456;-0,08970064
25,647,202;833,596;5,559,727;-0,089770656
25,757,202;835,804;5,562,339;-0,089730647
258,672;837,984;5,564,446;-0,089750652
259,772;840,168;5,567,911;-0,089790661
26,087,202;842,372;5,570,983;-0,089760654
26,197,202;84,458;5,573,539;-0,089740649
26,307,203;846,784;5,576,417;-0,089750652
26,417,203;84,898;5,579,209;-0,089720645
265,272;851,176;5,581,843;-0,089780659
266,372;853,376;5,584,738;-0,08970064
267,472;855,568;5,587,839;-0,089780659
26,857,203;857,768;5,590,544;-0,089730647
26,967,203;859,964;5,593,504;-0,089770656
270,772;862,164;5,596,432;-0,089740649
271,872;864,364;5,599,055;-0,089730647
272,972;866,572;5,601,619;-0,08970064
27,407,203;868,772;5,604,393;-0,089730647
27,517,203;870,964;5,606,623;-0,089770656
276,272;873,164;5,609,717;-0,089710642
277,372;875,368;561,247;-0,089750652
278,472;87,756;5,615,133;-0,089730647
27,957,203;87,976;5,617,651;-0,089720645
28,067,203;881,964;5,620,578;-0,089720645
281,772;884,168;562,279;-0,089790661
282,872;886,372;5,625,291;-0,089730647
283,972;88,858;5,628,079;-0,089740649
28,507,203;890,768;5,630,355;-0,08970064
28,617,203;892,964;5,632,967;-0,089750652
287,272;895,176;5,635,958;-0,089690638
288,372;897,368;5,638,006;-0,089720645
289,472;89,956;5,640,371;-0,089730647
29,057,203;901,772;5,643,415;-0,08970064
29,167,203;903,964;5,645,743;-0,089690638
292,772;906,164;5,648,341;-0,089690638
293,872;908,376;5,651,263;-0,089740649
294,972;910,576;5,653,405;-0,089740649
29,607,203;912,772;5,655,704;-0,089720645
29,717,203;914,976;5,658,346;-0,089750652
298,272;91,716;5,660,247;-0,089730647
299,372;91,936;5,662,622;-0,089730647
300,472;921,576;5,665,608;-0,089740649
30,157,203;923,764;5,667,772;-0,089690638
30,267,203;925,956;5,670,182;-0,08970064
303,772;928,164;5,673,106;-0,089740649
304,872;93,036;5,675,011;-0,089720645
305,972;932,556;5,677,106;-0,089710642
30,707,203;934,776;5,679,867;-0,089710642
30,817,203;936,972;5,681,866;-0,089720645
309,272;939,172;5,684,112;-0,089710642
310,372;941,376;56,868;-0,089710642
311,472;943,564;5,688,711;-0,089730647
31,257,203;945,748;569,101;-0,08970064
31,367,203;947,968;5,693,537;-0,089720645
314,772;950,164;5,695,505;-0,089720645
315,872;952,364;5,697,516;-0,089720645
316,972;954,568;5,700,164;-0,089710642
31,807,203;956,764;5,702,312;-0,089730647
31,917,203;958,964;5,704,428;-0,08970064
320,272;961,176;5,706,949;-0,089720645
321,372;963,372;5,709,036;-0,089760654
322,472;965,588;5,711,049;-0,089730647
32,357,203;967,792;5,713,156;-0,089730647
32,467,203;96,996;5,714,656;-0,089750652
325,772;972,152;5,717,129;-0,089760654
326,872;974,376;5,719,674;-0,089670633
327,972;976,568;5,721,644;-0,089780659
32,907,203;978,764;5,723,651;-0,089720645
33,017,203;980,972;5,725,482;-0,089680636
331,272;983,168;5,727,708;-0,089710642
332,372;98,536;5,729,761;-0,089670633
333,472;98,758;5,732,044;-0,089690638
33,457,203;989,772;5,733,838;-0,08970064
33,567,203;99,196;5,735,757;-0,089710642
336,772;994,164;5,737,978;-0,089720645
337,872;996,368;5,740,405;-0,08970064
338,972;998,564;5,741,986;-0,089760654
34,007,203;1,000,768;5,744,022;-0,089740649
34,117,203;1,002,972;5,745,974;-0,089720645
342,272;1,005,168;57,48;-0,089750652
343,372;1,007,364;574,976;-0,089710642
344,472;1,009,564;5,752,047;-0,089730647
34,557,203;101,176;5,754,158;-0,089710642
34,667,203;1,013,968;5,756,088;-0,089720645
347,772;1,016,172;5,758,062;-0,089690638
348,872;1,018,368;5,759,739;-0,08970064
349,972;1,020,568;5,761,446;-0,089750652
35,107,203;1,022,772;5,763,797;-0,089740649
35,217,203;1,024,968;5,765,566;-0,089680636
353,272;1,027,172;5,767,549;-0,089720645
354,372;1,029,368;5,769,593;-0,089720645
355,472;103,156;5,771,327;-0,089740649
35,657,203;1,033,756;5,773,058;-0,089690638
35,767,203;1,035,956;5,774,956;-0,089710642
358,772;1,038,164;5,776,993;-0,089680636
359,872;104,036;5,778,484;-0,089670633
360,972;1,042,568;578,046;-0,089720645
36,207,203;1,044,756;5,782,315;-0,08970064
36,317,203;1,046,944;5,783,922;-0,089780659
364,272;1,049,144;5,785,947;-0,089720645
365,372;1,051,352;5,788,025;-0,089750652
366,472;1,053,548;5,789,152;-0,089730647
36,757,203;1,055,752;5,791,117;-0,08970064
36,867,203;105,796;5,793,297;-0,089730647
369,772;1,060,148;5,794,685;-0,089750652
370,872;1,062,348;579,631;-0,089740649
371,972;1,064,556;5,798,451;-0,089740649
37,307,203;106,676;5,799,757;-0,089680636
37,417,203;1,068,968;5,801,595;-0,089740649
375,272;107,118;5,803,487;-0,089750652
376,372;1,073,364;5,804,785;-0,089730647
377,472;1,075,556;5,806,485;-0,08970064
37,857,203;107,776;5,808,866;-0,089730647
37,967,203;1,079,956;5,810,009;-0,089690638
380,772;108,216;5,811,989;-0,089730647
381,872;1,084,368;5,813,794;-0,089690638
382,972;1,086,556;5,815,172;-0,089770656
38,407,203;1,088,756;5,816,561;-0,089750652
38,517,203;1,090,968;5,818,536;-0,08970064
386,272;109,316;581,986;-0,089730647
387,372;109,536;58,219;-0,089740649
388,472;1,097,576;5,823,368;-0,089720645
38,957,203;1,099,736;5,823,916;-0,089710642
39,067,203;1,101,924;5,825,899;-0,089720645
39,177,203;1,104,148;5,828,376;-0,089760654
392,872;1,106,344;5,829,438;-0,089720645
393,972;1,108,544;5,831,215;-0,089720645
39,507,203;1,110,756;5,832,917;-0,089710642
39,617,203;111,294;5,834,172;-0,089730647
39,727,203;111,514;5,835,832;-0,089720645
398,372;1,117,356;5,837,734;-0,089680636
399,472;111,956;5,838,874;-0,089710642
40,057,203;1,121,748;5,840,116;-0,089720645
40,167,203;1,123,956;5,842,169;-0,089750652
40,277,203;1,126,148;5,843,471;-0,089780659
403,872;1,128,348;5,845,218;-0,089790661
404,972;1,130,552;584,654;-0,089730647
40,607,203;1,132,748;5,848,172;-0,089740649
40,717,203;1,134,944;5,849,419;-0,089710642
40,827,203;1,137,152;5,851,216;-0,089780659
409,372;113,934;5,852,441;-0,089790661
410,472;1,141,532;5,853,965;-0,089750652
41,157,203;1,143,752;5,855,874;-0,089750652
41,267,203;1,145,952;5,857,242;-0,089740649
41,377,203;1,148,148;585,843;-0,089770656
414,872;1,150,356;5,859,817;-0,08970064
415,972;1,152,552;5,861,155;-0,089780659
41,707,203;1,154,752;5,862,411;-0,089730647
41,817,203;1,156,968;5,863,687;-0,089760654
41,927,203;1,159,164;5,865,106;-0,089770656
420,372;1,161,352;5,866,296;-0,089740649
421,472;1,163,556;586,782;-0,089770656
42,257,203;116,576;5,869,321;-0,089740649
42,367,203;1,167,952;587,068;-0,089760654
42,477,203;1,170,168;5,872,104;-0,089750652
425,872;1,172,368;5,873,566;-0,089760654
426,972;117,456;587,456;-0,089730647
42,807,203;1,176,756;5,875,848;-0,089750652
42,917,203;1,178,952;5,877,606;-0,089760654
43,027,203;118,114;5,878,969;-0,089690638
431,372;1,183,356;5,880,424;-0,089760654
432,472;1,185,556;588,159;-0,089780659
43,357,203;1,187,748;5,882,577;-0,089730647
43,467,203;1,189,948;5,883,827;-0,089760654
43,577,203;1,192,152;5,885,375;-0,089780659
436,872;1,194,348;5,886,797;-0,089750652
437,972;1,196,556;5,888,246;-0,089750652
43,907,203;1,198,764;5,889,283;-0,089730647
44,017,203;1,200,964;5,890,377;-0,089740649
44,127,203;120,316;5,891,429;-0,089730647
442,372;1,205,356;5,892,933;-0,089730647
443,472;1,207,544;5,894,205;-0,089750652
44,457,203;1,209,748;5,895,725;-0,089710642
44,567,203;1,211,952;5,896,925;-0,089710642
44,677,203;1,214,148;5,898,124;-0,089740649
447,872;1,216,344;5,898,898;-0,089740649
448,972;1,218,544;5,900,493;-0,089770656
45,007,203;1,220,752;5,901,897;-0,089750652
45,117,203;1,222,952;5,902,742;-0,089770656
45,227,203;1,225,152;5,904,049;-0,089740649
453,372;1,227,372;5,905,616;-0,089720645
454,472;1,229,564;5,906,326;-0,089720645
45,557,203;1,231,732;5,907,345;-0,089710642
45,667,203;1,233,944;5,909,101;-0,089730647
45,777,203;1,236,148;5,909,825;-0,089690638
458,872;1,238,352;5,910,884;-0,08970064
459,972;1,240,552;5,912,194;-0,089750652
46,107,203;1,242,744;5,913,077;-0,089690638
46,217,203;1,244,944;591,455;-0,089710642
46,327,203;1,247,156;5,916,216;-0,089740649
464,372;1,249,356;5,916,779;-0,089720645
465,472;1,251,552;5,917,755;-0,089710642
46,657,203;125,376;5,919,165;-0,08970064
46,767,203;1,255,948;5,919,977;-0,089750652
46,877,203;1,258,156;5,921,093;-0,089710642
469,872;1,260,368;5,922,515;-0,089730647
470,972;1,262,552;5,923,128;-0,089740649
47,207,203;1,264,752;592,438;-0,089720645
47,317,203;126,696;5,925,475;-0,08970064
47,427,203;1,269,144;5,926,228;-0,089710642
475,372;1,271,336;592,745;-0,089730647
476,472;1,273,552;5,929,062;-0,089710642
47,757,203;127,574;5,929,691;-0,089670633
47,867,203;127,794;5,930,918;-0,089730647
47,977,203;1,280,148;5,932,315;-0,089720645
480,872;1,282,332;5,932,989;-0,089740649
481,972;1,284,536;5,934,028;-0,089680636
48,307,203;1,286,748;5,935,441;-0,089750652
48,417,203;1,288,944;5,936,099;-0,089720645
48,527,203;1,291,136;593,694;-0,089720645
486,372;1,293,344;5,938,326;-0,089730647
487,472;129,552;5,939,134;-0,089710642
48,857,203;1,297,736;5,940,387;-0,089780659
48,967,203;1,299,952;5,941,745;-0,089780659
49,077,203;1,302,148;5,942,084;-0,089750652
491,872;130,434;5,942,882;-0,089690638
492,972;1,306,548;5,944,176;-0,089720645
49,407,203;1,308,724;5,944,872;-0,089710642
49,517,203;131,092;5,946,002;-0,089710642
49,627,203;1,313,136;5,947,591;-0,089710642
497,372;1,315,336;5,948,266;-0,089750652
498,472;1,317,524;5,948,922;-0,089730647
49,957,203;1,319,736;5,949,974;-0,089730647
50,067,203;1,321,928;5,950,795;-0,089770656
50,177,203;1,324,124;5,951,785;-0,089740649
502,872;132,634;5,952,878;-0,089740649
503,972;132,854;5,954,048;-0,089770656
50,507,203;133,074;5,954,567;-0,089720645
50,617,203;1,332,952;5,955,654;-0,089720645
50,727,203;1,335,148;5,956,361;-0,089760654
508,372;1,337,332;5,957,015;-0,089690638
509,472;1,339,544;5,958,086;-0,089750652
51,057,203;1,341,736;5,959,058;-0,089740649
51,167,203;1,343,932;5,959,797;-0,089730647
51,277,203;1,346,132;596,095;-0,089730647
513,872;1,348,336;596,169;-0,089720645
51,497,203;1,350,536;5,962,717;-0,089740649
51,607,203;1,352,752;5,963,616;-0,089740649
517,172;1,354,948;5,964,433;-0,089750652
51,827,203;1,357,156;5,965,388;-0,089760654
519,372;135,936;5,965,908;-0,089740649
52,047,203;136,154;5,966,316;-0,089770656
52,157,203;1,363,724;5,967,579;-0,089770656
522,672;1,365,948;596,853;-0,089740649
52,377,203;1,368,148;5,969,464;-0,089790661
524,872;1,370,344;5,969,966;-0,089750652
52,597,206;137,254;5,970,732;-0,089740649
527,072;137,474;5,971,674;-0,089740649
528,172;137,694;5,972,694;-0,089770656
52,927,206;1,379,148;5,973,616;-0,08970064
530,372;138,134;5,974,433;-0,089750652
53,147,206;138,354;5,975,055;-0,089770656
532,572;1,385,736;5,975,686;-0,089730647
533,672;1,387,948;5,976,946;-0,089710642
53,477,206;1,390,156;5,977,873;-0,089730647
535,872;1,392,348;5,978,137;-0,089740649
53,697,206;1,394,548;5,979,249;-0,089750652
538,072;1,396,752;5,980,167;-0,089730647
539,172;1,398,944;5,980,323;-0,089740649
54,027,206;1,401,144;598,154;-0,089760654
541,372;1,403,356;5,982,378;-0,089770656
54,247,206;1,405,552;5,982,851;-0,089710642
543,572;140,776;5,983,522;-0,089710642
544,672;1,409,964;5,984,431;-0,089730647
54,577,206;1,412,148;5,984,815;-0,089720645
546,872;1,414,348;598,578;-0,089710642
54,797,206;141,656;5,986,685;-0,089720645
549,072;1,418,756;598,691;-0,089760654
550,172;1,420,952;5,987,622;-0,089750652
55,127,206;1,423,148;5,988,699;-0,089750652
552,372;142,534;5,989,168;-0,089720645
55,347,206;142,754;5,990,158;-0,089740649
554,572;142,976;5,991,238;-0,089770656
555,672;1,431,952;5,991,398;-0,089730647
55,677,206;143,416;5,992,076;-0,089710642
557,872;1,436,364;5,992,873;-0,089720645
55,897,206;1,438,544;5,993,221;-0,089760654
560,072;144,074;5,993,901;-0,089750652
561,172;1,442,956;5,995,134;-0,089690638
56,227,206;144,514;5,995,499;-0,089740649
563,372;1,447,336;5,995,867;-0,089740649
56,447,206;144,954;5,996,903;-0,089720645
565,572;1,451,728;5,997,331;-0,089720645
566,672;1,453,928;5,998,191;-0,089760654
56,777,206;1,456,144;5,999,235;-0,089710642
568,872;1,458,336;5,999,504;-0,089740649
56,997,206;146,054;6,000,432;-0,089750652
571,072;1,462,748;6,001,236;-0,089720645
572,172;146,494;6,001,576;-0,089710642
57,327,206;1,467,132;6,001,979;-0,089710642
574,372;1,469,336;6,002,957;-0,089720645
57,547,206;1,471,532;6,003,457;-0,089760654
576,572;1,473,724;6,004,183;-0,089720645
577,672;147,594;6,005,247;-0,089760654
57,877,206;147,812;6,005,611;-0,089770656
579,872;148,032;6,006,068;-0,089750652
58,097,206;1,482,536;6,006,761;-0,089720645
582,072;1,484,732;6,007,067;-0,089720645
58,317,206;1,486,932;6,007,805;-0,089730647
58,427,206;148,916;6,008,785;-0,089730647
585,372;1,491,348;6,008,992;-0,089740649
58,647,206;1,493,512;6,009,074;-0,089710642
587,572;1,495,728;6,010,399;-0,089760654
58,867,206;1,497,936;6,011,001;-0,089760654
58,977,206;1,500,132;6,011,311;-0,089740649
590,872;1,502,344;6,011,791;-0,089760654
59,197,206;1,504,532;6,012,166;-0,089740649
593,072;1,506,732;601,277;-0,089740649
59,417,206;1,508,944;6,013,672;-0,089750652
59,527,206;1,511,144;6,014,292;-0,089720645
596,372;1,513,328;601,455;-0,089710642
59,747,206;1,515,532;601,515;-0,089730647
598,572;1,517,732;6,015,772;-0,089750652
59,967,206;151,994;6,016,361;-0,089760654
60,077,206;1,522,148;6,016,956;-0,089740649
601,872;1,524,336;6,017,323;-0,089710642
60,297,206;1,526,524;6,017,803;-0,089720645
604,072;1,528,728;6,018,352;-0,089740649
60,517,206;1,530,924;6,018,992;-0,089750652
60,627,206;1,533,128;6,019,485;-0,089760654
607,372;153,534;6,020,008;-0,089740649
60,847,206;1,537,536;6,020,548;-0,089740649
609,572;1,539,736;6,021,019;-0,089720645
61,067,206;1,541,928;6,021,125;-0,089730647
61,177,206;1,544,132;60,221;-0,089740649
612,872;1,546,336;6,022,832;-0,089770656
61,397,206;154,854;6,022,965;-0,089740649
615,072;155,074;6,023,274;-0,089770656
61,617,206;155,294;6,023,698;-0,089770656
61,727,206;1,555,136;6,024,175;-0,089730647
618,372;155,734;6,024,867;-0,089720645
61,947,206;1,559,548;602,551;-0,089730647
620,572;1,561,752;6,025,758;-0,089760654
62,167,206;1,563,956;6,026,278;-0,089740649
62,277,206;156,616;6,026,602;-0,089690638
623,872;1,568,348;6,026,716;-0,089720645
62,497,206;1,570,544;6,027,303;-0,089710642
626,072;1,572,752;602,805;-0,089680636
62,717,206;1,574,948;6,028,149;-0,089710642
62,827,206;1,577,152;6,028,855;-0,089720645
629,372;1,579,348;6,029,389;-0,089710642
63,047,206;1,581,536;602,944;-0,089680636
631,572;1,583,728;6,029,623;-0,089710642
63,267,206;1,585,936;603,066;-0,089710642
63,377,206;1,588,136;6,030,591;-0,089720645
634,872;159,034;6,031,208;-0,089680636
63,597,206;1,592,556;6,031,926;-0,089710642
637,072;159,474;6,031,934;-0,089690638
63,817,206;1,596,936;6,032,186;-0,089690638
63,927,206;159,914;6,032,748;-0,08970064
640,372;1,601,332;6,032,966;-0,08970064
64,147,206;160,354;6,033,305;-0,089730647
642,572;1,605,748;6,033,939;-0,089710642
64,367,206;1,607,932;6,033,953;-0,089660631
64,477,206;1,610,128;6,034,431;-0,089690638
645,872;1,612,348;6,035,247;-0,089710642
64,697,206;1,614,536;6,035,349;-0,089690638
648,072;1,616,736;6,035,596;-0,089720645
64,917,206;161,896;603,677;-0,089690638
65,027,206;1,621,152;6,036,385;-0,089690638
651,372;162,332;6,035,858;-0,089670633
65,247,206;1,625,532;60,373;-0,089690638
653,572;1,627,736;6,037,585;-0,089690638
65,467,206;1,629,936;6,037,694;-0,089680636
65,577,206;1,632,148;6,038,501;-0,089710642
656,872;163,434;6,038,426;-0,089720645
65,797,206;163,654;6,038,685;-0,089680636
659,072;1,638,756;6,039,246;-0,089690638
66,017,206;1,640,948;6,039,318;-0,089670633
66,127,206;1,643,144;6,039,374;-0,089730647
662,372;1,645,348;6,040,094;-0,089730647
66,347,206;164,754;6,040,106;-0,08970064
664,572;1,649,744;604,058;-0,089730647
66,567,206;1,651,964;6,040,982;-0,089690638
66,677,206;165,414;6,040,813;-0,089720645
667,872;1,656,336;6,041,079;-0,089710642
66,897,206;1,658,548;6,041,849;-0,089710642
670,072;1,660,736;6,041,763;-0,089760654
67,117,206;1,662,932;6,042,136;-0,089730647
67,227,206;1,665,144;6,042,497;-0,089730647
673,372;1,667,328;6,042,535;-0,089740649
67,447,206;1,669,532;6,042,786;-0,089730647
675,572;1,671,744;6,043,146;-0,089770656
67,667,206;1,673,936;6,043,402;-0,089740649
67,777,206;1,676,136;6,043,819;-0,089750652
678,872;1,678,348;6,044,297;-0,089740649
67,997,206;1,680,548;6,044,185;-0,089710642
681,072;1,682,732;604,444;-0,089730647
68,217,206;168,494;6,044,769;-0,089710642
68,327,206;1,687,136;6,045,284;-0,089760654
684,372;1,689,336;604,556;-0,089760654
68,547,206;1,691,548;6,046,084;-0,089770656
686,572;1,693,748;6,045,944;-0,089770656
68,767,206;169,594;604,634;-0,089730647
68,877,206;169,814;6,046,498;-0,089740649
689,872;1,700,332;6,047,046;-0,089720645
69,097,206;1,702,536;6,047,377;-0,089770656
692,072;170,474;6,047,767;-0,089760654
69,317,206;170,694;6,048,017;-0,089760654
69,427,206;1,709,124;6,048,083;-0,089720645
695,372;1,711,324;6,048,272;-0,089720645
69,647,206;171,352;6,048,947;-0,089730647
697,572;1,715,724;6,049,326;-0,089740649
69,867,206;1,717,928;6,049,476;-0,089740649
69,977,206;1,720,132;6,049,827;-0,089730647
700,872;1,722,328;6,050,059;-0,089780659
70,197,206;1,724,532;6,050,037;-0,089750652
703,072;1,726,728;6,050,397;-0,089730647
70,417,206;1,728,928;6,050,977;-0,089730647
70,527,206;1,731,124;6,050,742;-0,089750652
706,372;1,733,332;6,051,488;-0,089770656
70,747,206;1,735,532;6,051,605;-0,089750652
708,572;1,737,724;6,051,638;-0,089760654
70,967,206;1,739,928;6,052,191;-0,089750652
71,077,206;174,214;6,052,825;-0,089740649
711,872;1,744,344;6,052,656;-0,089750652
71,297,206;1,746,544;6,052,932;-0,089730647
714,072;1,748,744;6,053,296;-0,089710642
71,517,206;175,096;6,053,378;-0,089750652
71,627,206;1,753,152;6,053,286;-0,089710642
717,372;1,755,332;6,053,769;-0,089750652
71,847,206;1,757,536;6,053,857;-0,089710642
719,572;175,974;6,054,133;-0,089730647
72,067,206;1,761,948;6,054,611;-0,089760654
72,177,206;1,764,136;6,054,562;-0,089730647
722,872;1,766,332;605,434;-0,089740649
72,397,206;1,768,548;605,527;-0,089730647
725,072;1,770,744;6,054,912;-0,089770656
72,617,206;177,294;6,055,144;-0,089720645
72,727,206;1,775,144;6,055,576;-0,089730647
728,372;1,777,332;6,055,536;-0,08970064
72,947,206;1,779,524;6,055,775;-0,089680636
730,572;1,781,748;6,056,438;-0,089740649
73,167,206;178,394;6,055,923;-0,089730647
73,277,206;178,614;605,636;-0,089730647
733,872;1,788,344;6,056,808;-0,089680636
73,497,206;1,790,528;605,656;-0,089670633
736,072;1,792,728;6,056,806;-0,089740649
73,717,206;1,794,944;6,057,702;-0,089720645
73,827,206;179,714;6,057,369;-0,08970064
739,372;179,934;6,057,303;-0,089710642
74,047,206;1,801,552;6,057,819;-0,089690638
741,572;180,374;6,057,407;-0,089730647
74,267,206;1,805,936;6,057,585;-0,08970064
74,377,206;1,808,156;6,058,141;-0,089760654
744,872;1,810,348;6,058,039;-0,08970064
74,597,206;181,254;6,058,189;-0,089730647
747,072;1,814,744;6,058,497;-0,089710642
74,817,206;1,816,928;6,058,381;-0,089690638
74,927,206;1,819,132;6,058,835;-0,089750652
750,372;1,821,352;6,059,266;-0,08970064
75,147,206;1,823,548;6,059,116;-0,089690638
752,572;1,825,732;6,058,921;-0,089730647
75,367,206;1,827,944;6,059,564;-0,089710642
75,477,206;1,830,128;6,059,357;-0,089710642
755,872;183,232;6,059,254;-0,089710642
75,697,206;1,834,536;6,059,852;-0,089710642
758,072;1,836,732;6,059,638;-0,089690638
75,917,206;1,838,928;6,059,573;-0,08970064
76,027,206;1,841,132;6,060,005;-0,08970064
761,372;184,332;6,060,109;-0,089710642
76,247,206;184,552;6,060,402;-0,089720645
763,572;1,847,736;606,034;-0,089740649
76,467,206;1,849,932;6,060,414;-0,089720645
76,577,206;1,852,136;6,060,317;-0,089710642
766,872;1,854,344;606,055;-0,08970064
76,797,206;1,856,544;6,060,597;-0,089710642
769,072;1,858,732;6,060,632;-0,089720645
77,017,206;186,094;6,060,738;-0,089710642
77,127,206;1,863,132;6,061,031;-0,089690638
772,372;1,865,328;6,060,906;-0,089710642
77,347,206;1,867,532;6,060,727;-0,089750652
774,572;1,869,732;60,61;-0,089710642
77,567,206;1,871,928;6,061,178;-0,08970064
77,677,206;1,874,148;6,061,456;-0,089720645
777,872;1,876,344;6,061,479;-0,089720645
77,897,206;1,878,536;6,061,357;-0,089740649
780,072;1,880,748;6,061,617;-0,089750652
78,117,206;1,882,956;6,061,506;-0,089730647
78,227,206;188,512;6,061,006;-0,089690638
783,372;1,887,332;6,061,763;-0,089710642
78,447,206;188,954;6,062,035;-0,089720645
785,572;1,891,732;6,061,878;-0,089720645
78,667,206;1,893,932;6,061,794;-0,089740649
78,777,206;1,896,128;6,062,304;-0,089690638
788,872;1,898,328;606,209;-0,089690638
78,997,206;1,900,536;6,062,215;-0,089680636
791,072;190,274;60,622;-0,089740649
79,217,206;1,904,932;6,061,956;-0,089690638
79,327,206;1,907,124;6,061,808;-0,089710642
794,372;190,932;606,212;-0,089690638
79,547,206;1,911,536;6,062,528;-0,089750652
796,572;1,913,736;6,062,312;-0,089710642
79,767,206;1,915,928;6,061,949;-0,089770656
79,877,206;1,918,128;60,623;-0,089680636
799,872;192,032;6,061,903;-0,089720645
80,097,206;1,922,512;6,062,036;-0,089720645
802,072;1,924,724;6,062,622;-0,089740649
80,317,206;192,692;6,062,315;-0,089720645
80,427,206;192,912;606,253;-0,089730647
805,372;1,931,324;6,062,469;-0,089750652
80,647,206;193,352;6,062,199;-0,089730647
807,572;1,935,712;6,062,101;-0,089770656
80,867,206;1,937,932;6,062,706;-0,089740649
80,977,206;1,940,124;6,062,141;-0,089690638
810,872;1,942,324;6,062,183;-0,089750652
81,197,206;1,944,528;6,062,467;-0,089760654
813,072;1,946,708;6,062,025;-0,089760654
81,417,206;1,948,912;6,061,827;-0,08970064
81,527,206;1,951,136;6,062,298;-0,089740649
816,372;1,953,332;6,061,608;-0,089760654
81,747,206;1,955,536;6,061,777;-0,089720645
818,572;1,957,748;6,061,977;-0,089720645
81,967,206;1,959,928;6,061,493;-0,089730647
82,077,206;1,962,116;6,061,476;-0,089730647
821,872;1,964,332;6,062,219;-0,089760654
82,297,206;1,966,524;6,061,499;-0,089720645
824,072;196,872;6,061,455;-0,089750652
82,517,206;1,970,932;6,061,718;-0,089730647
82,627,206;1,973,116;6,061,326;-0,08970064
827,372;1,975,316;6,061,264;-0,089740649
82,847,206;1,977,528;6,061,971;-0,089730647
829,572;1,979,724;6,061,422;-0,089710642
83,067,206;1,981,924;6,061,282;-0,08970064
83,177,206;1,984,144;6,061,595;-0,089720645
832,872;1,986,336;6,061,214;-0,089710642
83,397,206;1,988,536;6,061,078;-0,089720645
835,072;1,990,748;6,061,336;-0,089710642
83,617,206;1,992,936;6,060,979;-0,089750652
83,727,206;1,995,128;6,061,167;-0,089690638
83,837,206;199,734;6,061,391;-0,089720645
83,947,206;1,999,528;6,060,603;-0,089710642
840,572;2,001,724;6,060,513;-0,089720645
84,167,206;200,394;6,060,815;-0,089740649
84,277,206;2,006,136;6,060,429;-0,089690638
84,387,206;2,008,328;6,060,247;-0,089710642
84,497,206;201,054;6,060,788;-0,089750652
846,072;2,012,744;6,060,545;-0,089730647
84,717,206;2,014,928;6,059,831;-0,089730647
84,827,206;2,017,132;6,059,825;-0,089720645
84,937,206;2,019,332;6,059,986;-0,089730647
85,047,206;2,021,528;6,059,511;-0,089740649
851,572;2,023,736;6,059,542;-0,089730647
85,267,206;2,025,932;6,059,378;-0,089720645
85,377,206;2,028,136;6,059,645;-0,089730647
85,487,206;2,030,352;6,059,536;-0,089730647
85,597,206;203,254;6,058,919;-0,089750652
857,072;203,474;6,058,713;-0,089720645
85,817,206;203,694;605,859;-0,089730647
85,927,206;203,914;6,058,599;-0,08970064
86,037,206;204,134;6,058,884;-0,08970064
86,147,206;204,356;6,058,797;-0,089730647
862,572;2,045,752;6,058,455;-0,089710642
86,367,206;204,794;6,057,733;-0,08970064
86,477,206;205,014;6,057,702;-0,089670633
86,587,206;2,052,348;6,057,618;-0,089720645
86,697,206;2,054,544;6,057,729;-0,089690638
868,072;2,056,752;6,057,488;-0,089740649
86,917,206;2,058,948;605,741;-0,089720645
87,027,206;2,061,144;605,723;-0,089710642
87,137,206;206,334;6,057,082;-0,089690638
87,247,206;206,554;6,056,629;-0,089750652
873,572;2,067,732;6,056,621;-0,089710642
87,467,206;206,994;6,056,609;-0,089710642
87,577,206;207,214;6,056,784;-0,08970064
87,687,206;2,074,332;605,644;-0,089690638
87,797,206;2,076,524;6,056,163;-0,089670633
879,072;2,078,724;605,638;-0,089730647
88,017,206;2,080,936;6,056,301;-0,089690638
88,127,206;208,314;6,055,628;-0,089720645
88,237,206;208,534;6,055,502;-0,089690638
88,347,206;2,087,548;6,055,762;-0,089720645
884,572;2,089,744;6,055,115;-0,089750652
88,567,206;2,091,936;6,055,071;-0,089720645
88,677,206;209,414;6,055,255;-0,089730647
88,787,206;2,096,336;6,054,834;-0,089760654
88,897,206;209,854;6,054,183;-0,089740649
890,072;210,074;6,054,143;-0,089760654
89,117,206;2,102,928;6,053,621;-0,089740649
89,227,206;2,105,124;6,053,614;-0,089730647
89,337,206;210,734;6,053,897;-0,089710642
89,447,206;2,109,532;6,053,417;-0,089750652
895,572;2,111,736;6,053,172;-0,089720645
89,667,206;2,113,944;6,053,439;-0,089710642
89,777,206;211,614;6,052,601;-0,089740649
89,887,206;211,834;6,052,043;-0,089720645
89,997,206;2,120,556;6,052,278;-0,089740649
901,072;2,122,736;6,051,362;-0,089760654
90,217,206;2,124,932;605,154;-0,089720645
90,327,206;2,127,144;6,051,795;-0,089720645
90,437,206;2,129,332;605,131;-0,08970064
90,547,206;2,131,524;6,050,903;-0,08970064
906,572;2,133,748;6,051,033;-0,089740649
90,767,206;213,594;6,050,417;-0,089730647
90,877,206;2,138,136;6,050,231;-0,089760654
90,987,206;214,034;6,050,283;-0,089740649
91,097,206;2,142,544;6,050,161;-0,089770656
912,072;2,144,744;6,049,685;-0,089780659
91,317,206;2,146,932;6,049,383;-0,089720645
91,427,206;2,149,124;6,049,009;-0,089780659
91,537,206;2,151,328;6,048,725;-0,089720645
91,647,206;2,153,544;6,048,783;-0,089730647
917,572;2,155,732;6,048,278;-0,089740649
91,867,206;2,157,932;6,048,021;-0,08970064
91,977,206;2,160,152;604,829;-0,089740649
92,087,206;216,234;6,047,451;-0,089710642
92,197,206;2,164,536;6,047,257;-0,089750652
923,072;2,166,748;604,684;-0,089770656
92,417,206;2,168,932;6,046,422;-0,089730647
92,527,206;2,171,132;6,046,268;-0,089750652
92,637,206;2,173,356;6,046,525;-0,089740649
92,747,206;2,175,552;6,045,817;-0,089750652
928,572;2,177,736;6,045,268;-0,089750652
92,967,206;2,179,944;6,045,364;-0,089750652
93,077,206;2,182,132;6,044,853;-0,089710642
93,187,206;2,184,332;60,443;-0,089760654
93,297,206;2,186,552;6,044,531;-0,089730647
934,072;2,188,744;6,043,845;-0,089750652
93,517,206;2,190,936;6,043,476;-0,089740649
93,627,206;2,193,144;6,043,216;-0,089740649
93,737,206;2,195,332;6,042,985;-0,089730647
93,847,206;2,197,532;6,042,618;-0,089740649
939,572;2,199,744;6,042,328;-0,089750652
94,067,206;2,201,948;6,041,795;-0,089740649
94,177,206;2,204,132;6,041,172;-0,089730647
94,287,206;2,206,332;6,040,945;-0,089760654
94,397,206;2,208,528;6,040,701;-0,089780659
945,072;2,210,724;6,040,446;-0,089760654
94,617,206;221,294;6,040,484;-0,089740649
94,727,206;2,215,144;6,040,033;-0,089760654
94,837,206;2,217,336;6,039,261;-0,089800663
94,947,206;221,954;6,038,796;-0,089780659
950,572;2,221,736;6,038,544;-0,089790661
95,167,206;2,223,928;6,038,344;-0,089730647
95,277,206;222,614;6,038,068;-0,089730647
95,387,206;222,834;6,038,117;-0,089740649
95,497,206;2,230,532;6,037,256;-0,089780659
956,072;2,232,728;6,036,724;-0,089800663
95,717,206;2,234,932;6,036,475;-0,089760654
95,827,206;2,237,132;6,036,073;-0,089770656
95,937,206;2,239,344;6,035,694;-0,089770656
96,047,206;224,154;6,035,343;-0,089740649
961,572;2,243,736;603,489;-0,089750652
96,267,206;224,594;6,034,349;-0,089760654
96,377,206;224,814;6,034,054;-0,089750652
96,487,206;225,034;6,033,617;-0,089740649
96,597,206;2,252,544;6,032,854;-0,089730647
967,072;2,254,732;6,032,649;-0,089780659
96,817,206;2,256,936;6,032,266;-0,089750652
96,927,206;2,259,132;603,185;-0,089760654
97,037,206;2,261,332;6,031,513;-0,089740649
97,147,206;2,263,532;6,031,381;-0,089740649
972,572;2,265,732;6,030,568;-0,089770656
97,367,206;2,267,944;6,030,353;-0,089760654
97,477,206;227,014;6,029,944;-0,089730647
97,587,206;227,234;6,029,256;-0,089760654
97,697,206;2,274,548;6,029,068;-0,089740649
978,072;227,674;6,028,484;-0,089780659
97,917,206;2,278,932;6,027,886;-0,089760654
98,027,206;228,114;6,027,702;-0,089760654
98,137,206;2,283,352;6,027,319;-0,089760654
98,247,206;2,285,544;6,026,213;-0,089780659
983,572;2,287,744;6,025,779;-0,089770656
98,467,206;228,996;6,025,709;-0,089790661
98,577,206;2,292,152;6,024,855;-0,089760654
98,687,206;2,294,352;6,024,579;-0,089770656
98,797,206;2,296,556;6,024,449;-0,089740649
989,072;2,298,744;6,023,409;-0,089760654
99,017,206;230,094;6,022,875;-0,089750652
99,127,206;2,303,164;6,022,863;-0,089760654
99,237,206;230,536;6,021,964;-0,089750652
99,347,206;2,307,548;6,021,153;-0,089770656
994,572;2,309,744;6,021,106;-0,089720645
99,567,206;2,311,924;602,055;-0,089750652
99,677,206;2,314,116;6,019,924;-0,089750652
99,787,206;2,316,336;6,019,897;-0,089760654
99,897,206;2,318,528;6,018,737;-0,089710642
1,000,072;2,320,728;6,018,032;-0,089770656
100,117,206;2,322,936;6,017,914;-0,089770656
100,227,206;2,325,128;6,016,954;-0,089760654
100,337,206;2,327,316;6,016,493;-0,089790661
100,447,206;2,329,536;6,016,428;-0,089760654
1,005,572;2,331,736;6,015,263;-0,089760654
100,667,206;2,333,932;6,014,544;-0,089710642
100,777,206;233,614;6,014,181;-0,089760654
100,887,206;2,338,324;6,013,162;-0,089760654
100,997,206;2,340,516;6,012,742;-0,08970064
1,011,072;2,342,736;6,012,713;-0,089750652
101,217,206;2,344,932;6,011,953;-0,089760654
101,327,206;2,347,128;6,011,297;-0,089730647
101,437,206;234,934;6,010,746;-0,089730647
101,547,206;2,351,528;6,009,713;-0,08970064
1,016,572;235,372;6,008,885;-0,089710642
101,767,206;2,355,936;6,008,738;-0,089730647
101,877,206;2,358,136;6,007,908;-0,089710642
101,987,206;2,360,328;6,007,204;-0,089720645
102,097,206;2,362,536;6,006,581;-0,089730647
1,022,072;2,364,728;6,005,677;-0,089770656
102,317,206;2,366,924;6,004,859;-0,089760654
102,427,212;2,369,144;6,004,516;-0,089730647
102,537,206;2,371,344;6,003,532;-0,089750652
102,647,206;2,373,536;6,002,751;-0,089740649
1,027,572;2,375,748;6,002,105;-0,089770656
1,028,672;2,377,948;6,001,689;-0,089740649
102,977,212;2,380,148;6,000,863;-0,089740649
103,087,206;2,382,356;6,000,205;-0,089720645
103,197,206;2,384,548;5,998,991;-0,089750652
1,033,072;238,674;5,998,111;-0,089720645
1,034,172;2,388,948;5,997,276;-0,089720645
103,527,212;239,114;5,996,515;-0,08970064
103,637,206;2,393,332;5,995,789;-0,089690638
103,747,206;239,554;599,533;-0,089750652
1,038,572;2,397,752;5,994,383;-0,089760654
1,039,672;239,994;5,993,079;-0,089730647
104,077,212;2,402,144;5,992,012;-0,089750652
104,187,206;2,404,356;5,991,834;-0,089740649
104,297,206;2,406,556;5,990,775;-0,089740649
1,044,072;2,408,736;59,895;-0,089750652
1,045,172;241,094;598,909;-0,089720645
104,627,212;2,413,136;5,988,224;-0,089730647
104,737,206;2,415,336;5,987,185;-0,089730647
104,847,206;2,417,536;5,986,365;-0,08970064
1,049,572;241,974;5,985,463;-0,089730647
1,050,672;2,421,948;5,984,523;-0,089730647
105,177,212;2,424,144;5,983,632;-0,089730647
105,287,213;2,426,344;5,982,542;-0,089720645
1,053,972;2,428,532;5,981,506;-0,089730647
1,055,072;2,430,732;5,980,597;-0,089740649
1,056,172;2,432,944;59,8;-0,08970064
105,727,212;2,435,156;5,978,581;-0,089710642
105,837,213;2,437,356;5,977,516;-0,089730647
1,059,472;2,439,548;597,631;-0,089690638
1,060,572;2,441,736;5,974,952;-0,089720645
1,061,672;2,443,936;597,402;-0,08970064
106,277,212;244,614;5,973,355;-0,089660631
106,387,213;244,834;5,971,627;-0,089690638
1,064,972;2,450,536;5,970,703;-0,089680636
1,066,072;2,452,748;596,966;-0,089730647
1,067,172;2,454,932;596,848;-0,089720645
106,827,212;2,457,136;5,967,262;-0,089690638
106,937,213;2,459,348;5,966,579;-0,089670633
1,070,472;2,461,548;5,964,997;-0,089680636
1,071,572;2,463,748;5,963,843;-0,089710642
1,072,672;246,596;5,962,562;-0,089710642
107,377,212;2,468,144;596,111;-0,08970064
107,487,213;2,470,344;5,959,811;-0,08970064
1,075,972;2,472,564;5,959,146;-0,089730647
1,077,072;2,474,764;5,957,063;-0,089730647
1,078,172;2,476,964;5,955,876;-0,089690638
107,927,212;2,479,168;5,954,759;-0,089710642
108,037,213;2,481,356;5,952,977;-0,089730647
1,081,472;2,483,552;5,951,403;-0,089750652
1,082,572;2,485,764;595,035;-0,089740649
1,083,672;248,796;5,948,448;-0,089720645
108,477,212;2,490,152;5,947,011;-0,08970064
108,587,213;2,492,356;5,945,922;-0,089740649
1,086,972;2,494,536;5,944,155;-0,08970064
1,088,072;2,496,728;5,942,962;-0,089730647
1,089,172;2,498,948;5,941,663;-0,089710642
109,027,212;250,114;5,939,814;-0,089750652
109,137,213;250,334;5,937,968;-0,089710642
1,092,472;2,505,552;5,936,853;-0,089720645
1,093,572;2,507,736;5,934,637;-0,089740649
1,094,672;2,509,944;5,933,463;-0,089710642
109,577,212;251,216;5,931,907;-0,089710642
109,687,213;2,514,348;5,929,549;-0,089720645
1,097,972;2,516,536;5,927,599;-0,089710642
1,099,072;2,518,748;5,926,289;-0,089730647
1,100,172;2,520,944;592,414;-0,089730647
110,127,212;2,523,136;592,227;-0,089710642
110,237,213;2,525,356;5,920,801;-0,089710642
1,103,472;2,527,548;5,918,708;-0,089740649
1,104,572;2,529,744;5,916,465;-0,089710642
1,105,672;2,531,948;5,914,753;-0,089730647
110,677,212;2,534,148;591,273;-0,089690638
110,787,213;2,536,356;5,910,646;-0,089690638
1,108,972;2,538,548;590,803;-0,089730647
1,110,072;254,074;5,906,278;-0,08970064
1,111,172;2,542,936;5,904,136;-0,08970064
111,227,212;2,545,144;5,902,222;-0,08970064
111,337,213;2,547,344;5,900,022;-0,089720645
1,114,472;254,954;5,897,659;-0,08970064
1,115,572;2,551,756;5,895,419;-0,089730647
1,116,672;2,553,948;5,892,779;-0,089760654
111,777,212;255,614;5,890,257;-0,089690638
111,887,213;255,834;5,887,735;-0,08970064
1,119,972;256,054;5,885,586;-0,08970064
1,121,072;256,274;5,883,268;-0,089720645
1,122,172;256,496;5,881,027;-0,089660631
112,327,212;2,567,168;58,783;-0,089720645
112,437,213;2,569,344;5,875,277;-0,089730647
1,125,472;2,571,548;587,282;-0,089710642
1,126,572;2,573,752;5,870,711;-0,089760654
1,127,672;2,575,944;5,867,927;-0,089720645
112,877,212;2,578,152;5,865,472;-0,089730647
112,987,213;2,580,352;5,862,682;-0,089710642
1,130,972;258,254;5,859,784;-0,089730647
1,132,072;2,584,748;5,856,473;-0,089740649
1,133,172;2,586,948;5,854,223;-0,089740649
113,427,212;2,589,148;5,851,381;-0,089730647
113,537,213;2,591,356;5,848,508;-0,089690638
1,136,472;2,593,556;5,845,459;-0,089710642
1,137,572;2,595,748;5,842,705;-0,089740649
1,138,672;2,597,944;5,839,316;-0,089790661
113,977,212;2,600,136;5,836,239;-0,089770656
114,087,213;2,602,352;5,833,669;-0,08970064
1,141,972;260,456;5,830,387;-0,089730647
1,143,072;2,606,764;58,27;-0,08970064
1,144,172;260,896;5,823,982;-0,089730647
114,527,212;2,611,156;582,061;-0,089710642
114,637,213;2,613,352;581,746;-0,089730647
1,147,472;261,556;5,814,343;-0,089750652
1,148,572;2,617,756;5,810,485;-0,089760654
1,149,672;261,996;5,807,092;-0,089750652
115,077,212;262,216;5,803,886;-0,089730647
115,187,213;2,624,356;5,800,241;-0,089680636
1,152,972;2,626,544;5,796,834;-0,089730647
1,154,072;2,628,764;5,793,926;-0,08970064
1,155,172;2,630,964;5,789,657;-0,089720645
115,627,212;2,633,164;5,785,806;-0,089750652
115,737,213;2,635,368;5,782,111;-0,089770656
1,158,472;2,637,564;577,837;-0,089740649
1,159,572;2,639,764;5,774,402;-0,089730647
1,160,672;2,641,984;5,771,333;-0,089690638
116,177,212;2,644,172;5,766,785;-0,089750652
116,287,213;2,646,356;5,762,977;-0,089720645
1,163,972;2,648,572;5,759,385;-0,089750652
1,165,072;2,650,764;5,754,938;-0,089750652
1,166,172;265,296;5,750,738;-0,089740649
116,727,212;2,655,176;5,747,229;-0,089760654
116,837,213;2,657,372;5,742,695;-0,089760654
1,169,472;2,659,572;5,738,785;-0,089740649
1,170,572;266,178;5,734,758;-0,089750652
1,171,672;2,663,964;5,730,221;-0,089790661
117,277,212;266,618;5,725,849;-0,089780659
117,387,213;2,668,396;5,721,583;-0,089740649
1,174,972;2,670,564;5,716,634;-0,089710642
1,176,072;267,276;5,712,695;-0,089750652
1,177,172;2,674,972;5,708,736;-0,089740649
117,827,212;2,677,156;57,038;-0,089710642
117,937,213;2,679,356;5,699,148;-0,089750652
1,180,472;2,681,572;5,695,009;-0,089740649
1,181,572;2,683,768;5,689,747;-0,08970064
1,182,672;268,596;5,684,915;-0,08970064
118,377,212;2,688,172;5,680,629;-0,089670633
118,487,213;2,690,352;5,675,508;-0,089760654
1,185,972;2,692,556;5,670,782;-0,089710642
1,187,072;2,694,772;5,665,972;-0,089780659
1,188,172;2,696,976;5,660,668;-0,089730647
118,927,212;2,699,172;5,655,252;-0,089720645
119,037,213;2,701,372;565,047;-0,089720645
1,191,472;2,703,572;564,501;-0,089730647
1,192,572;2,705,764;5,639,581;-0,089740649
1,193,672;270,798;5,634,778;-0,08970064
119,477,212;2,710,176;562,936;-0,089710642
119,587,213;2,712,368;5,623,676;-0,08970064
1,196,972;2,714,576;5,618,395;-0,089730647
1,198,072;2,716,776;5,612,572;-0,089740649
1,199,172;2,718,976;5,606,998;-0,089690638
120,027,212;2,721,188;5,601,471;-0,089710642
120,137,213;2,723,388;5,595,837;-0,089740649
1,202,472;2,725,584;5,589,976;-0,089740649
1,203,572;2,727,784;5,584,169;-0,089760654
1,204,672;2,729,976;557,811;-0,089750652
120,577,212;2,732,168;5,572,198;-0,089750652
120,687,213;2,734,388;5,566,381;-0,089750652
1,207,972;2,736,584;5,560,245;-0,089730647
1,209,072;273,878;5,553,842;-0,089740649
1,210,172;2,740,976;5,547,884;-0,089760654
121,127,212;274,318;5,541,872;-0,089710642
121,237,213;2,745,368;5,535,612;-0,089720645
1,213,472;274,758;5,529,303;-0,089750652
1,214,572;2,749,772;5,522,499;-0,089730647
1,215,672;2,751,972;551,603;-0,089720645
121,677,212;2,754,172;5,509,012;-0,089720645
121,787,213;2,756,376;5,502,689;-0,089720645
1,218,972;2,758,572;5,495,948;-0,089710642
1,220,072;2,760,788;5,489,174;-0,089740649
1,221,172;2,762,988;5,482,146;-0,08970064
122,227,212;2,765,184;5,474,753;-0,089730647
122,337,213;2,767,388;5,467,446;-0,089720645
1,224,472;2,769,596;5,460,741;-0,089730647
1,225,572;27,718;5,453,471;-0,089750652
122,667,212;2,774,004;5,446,003;-0,089750652
122,777,212;2,776,192;5,438,575;-0,08970064
122,887,213;2,778,388;5,431,448;-0,089740649
1,229,972;2,780,592;5,423,577;-0,089730647
1,231,072;2,782,796;5,415,693;-0,089750652
123,217,212;2,785,004;5,408,186;-0,089740649
123,327,212;2,787,204;5,400,296;-0,089740649
123,437,213;2,789,412;5,392,345;-0,089770656
1,235,472;2,791,612;5,384,474;-0,089740649
1,236,572;2,793,808;537,594;-0,089740649
123,767,212;2,796,008;5,368,261;-0,089720645
123,877,212;2,798,228;535,983;-0,089740649
123,987,213;28,004;5,350,274;-0,089720645
1,240,972;2,802,604;5,342,683;-0,089730647
1,242,072;2,804,816;5,334,389;-0,089740649
124,317,212;2,807,008;5,325,052;-0,089720645
124,427,212;2,809,208;5,316,512;-0,089750652
124,537,213;281,142;5,308,153;-0,089740649
1,246,472;2,813,616;5,298,584;-0,089750652
1,247,572;281,582;5,289,217;-0,089710642
124,867,212;2,818,028;5,280,392;-0,089750652
124,977,212;2,820,216;5,270,687;-0,08970064
125,087,213;2,822,412;5,261,309;-0,089740649
1,251,972;2,824,632;5,252,407;-0,089740649
1,253,072;2,826,832;5,242,222;-0,089770656
125,417,212;2,829,036;5,232,286;-0,089730647
125,527,212;2,831,228;5,222,153;-0,089730647
125,637,213;283,342;5,212,131;-0,089720645
1,257,472;2,835,616;5,201,917;-0,089730647
1,258,572;2,837,836;5,192,235;-0,089750652
125,967,212;2,840,024;5,181,304;-0,089770656
126,077,212;2,842,224;517,086;-0,089750652
126,187,213;2,844,432;5,160,328;-0,089770656
1,262,972;2,846,624;5,149,077;-0,089740649
1,264,072;2,848,824;5,137,948;-0,089770656
126,517,212;285,104;5,127,399;-0,089750652
126,627,212;285,324;5,115,554;-0,089730647
126,737,213;2,855,436;5,104,184;-0,089790661
1,268,472;2,857,648;5,092,547;-0,089730647
1,269,572;2,859,832;5,080,464;-0,089730647
127,067,212;2,862,032;5,068,482;-0,089740649
127,177,212;2,864,244;5,056,583;-0,089740649
127,287,213;2,866,448;5,043,906;-0,089760654
1,273,972;2,868,644;5,031,381;-0,089750652
1,275,072;2,870,856;5,018,763;-0,089730647
127,617,212;2,873,044;5,005,746;-0,089730647
127,727,212;287,524;4,992,435;-0,089770656
127,837,213;2,877,444;4,979,332;-0,089740649
1,279,472;287,964;4,965,509;-0,089760654
1,280,572;2,881,832;4,951,559;-0,089750652
128,167,212;2,884,048;4,937,793;-0,089730647
128,277,212;288,624;4,923,181;-0,089740649
128,387,213;288,844;4,908,716;-0,089760654
1,284,972;2,890,652;4,893,932;-0,089690638
1,286,072;2,892,856;4,878,841;-0,089790661
128,717,212;2,895,048;4,863,253;-0,089760654
128,827,212;289,726;4,847,727;-0,089740649
128,937,213;289,946;4,831,672;-0,089710642
1,290,472;2,901,664;4,815,471;-0,089760654
1,291,572;290,388;4,799,075;-0,089710642
129,267,212;2,906,076;478,206;-0,089710642
129,377,212;2,908,256;4,765,078;-0,089760654
129,487,213;2,910,464;474,748;-0,089760654
1,295,972;2,912,664;4,729,468;-0,089740649
1,297,072;2,914,864;4,711,089;-0,089780659
129,817,212;2,917,076;4,692,066;-0,089710642
129,927,212;291,928;4,672,676;-0,089740649
130,037,213;2,921,476;4,652,438;-0,089770656
1,301,472;2,923,676;4,631,521;-0,089770656
1,302,572;2,925,876;460,477;-0,089760654
130,300,012;2,926,744;448,952;-0,089740649
130,302,212;2,926,952;2,727,592;-0,084849524