File: tensile_test_ontology_TTO/data/primary_data/Zx4.csv
Time;Crosshead travel;Force;Strain
(s);(mm);(kN);(%)
0;0;0,1972;0
0,978;0,05188;0,74793;0,002550198
1,476;0,12384;187,284;0,007550587
1,884;0,19984;300,848;0,012450967
2,336;0,30176;413,301;0,017171334
2,696;0,39676;527,664;0,021981708
3,048;0,49916;641,365;0,026942093
3,426;0,61908;755,017;0,031772469
3,712;0,71608;868,929;0,036572842
3,962;0,80372;983,894;0,041433219
4,198;0,88796;1,100,711;0,046403606
4,418;0,9676;121,439;0,051163975
4,638;104,776;1,330,945;0,056204367
4,856;11,274;1,449,415;0,061204756
5,06;120,208;1,563,084;0,066035131
5,26;12,754;167,594;0,070895509
5,458;134,772;1,789,164;0,075795889
5,656;141,964;1,903,052;0,080796278
5,854;149,112;2,018,044;0,085856671
6,052;156,216;2,132,836;0,09099707
6,25;163,208;2,247,454;0,096207475
6,448;17,016;2,361,772;0,101467884
6,646;177,044;247,614;0,106888305
6,844;183,828;2,589,775;0,112398733
7,042;190,528;2,701,593;0,117989168
7,248;197,316;2,816,794;0,123969632
7,468;204,424;2,936,687;0,130400132
7,688;21,134;3,055,246;0,137100653
7,908;21,804;3,169,129;0,143811174
8,134;224,692;3,282,219;0,151031735
8,376;231,508;3,398,495;0,158792338
8,636;238,444;3,514,264;0,167262996
8,91;245,288;3,628,298;0,176403707
9,212;252,264;3,742,319;0,186554495
9,546;259,304;3,856,522;0,197955381
9,938;26,652;3,969,589;0,211346422
10,404;273,912;4,081,872;0,226887629
11,002;28,168;4,193,569;0,24606912
11,844;29,012;4,305,001;0,271031059
12,926;298,336;4,405,697;0,300833375
14,026;305,012;4,478,278;0,329805626
15,126;310,628;4,532,334;0,358307841
16,226;315,596;4,573,798;0,386840057
17,326;31,998;4,605,283;0,414432201
18,426;323,932;4,625,636;0,442244362
19,526;327,736;4,644,678;0,470046523
20,626;331,416;4,650,536;0,497148628
21,726;335,312;465,632;0,521910552
22,826;338,924;4,653,656;0,553172982
23,926;342,032;4,654,964;0,580905136
25,026;34,496;4,651,216;0,608467278
26,126;347,728;4,645,514;0,636009418
27,226;350,592;4,645,813;0,662451472
28,326;35,292;4,628,883;0,691873759
29,426;355,132;4,623,231;0,719475903
30,526;35,708;4,612,864;0,747198057
31,626;358,932;4,605,358;0,774910211
32,726;3,607;46,014;0,802152327
33,826;3,625;4,601,815;0,829514453
34,926;364,224;460,141;0,856716567
36,026;365,988;4,602,308;0,884748745
37,126;36,766;460,236;0,91197086
38,226;36,934;460,228;0,939392991
39,326;37,108;4,594,951;0,967335162
40,426;372,828;460,328;0,994657285
41,526;374,444;4,604,284;1,021,899,402
42,626;376,072;4,605,841;1,049,331,533
43,726;377,732;4,608,909;107,683,367
44,826;379,344;4,608,597;1,104,675,833
45,926;380,956;4,610,086;1,132,127,966
47,026;382,568;46,117;1,159,570,099
48,126;384,316;4,618,648;1,186,892,222
49,226;38,606;4,624,306;1,214,534,369
50,326;387,908;4,633,026;1,241,966,501
51,426;389,792;464,061;1,269,398,632
52,526;391,764;4,649,999;1,297,180,791
53,626;39,372;4,657,219;132,407,288
54,726;395,796;4,666,184;1,351,415,005
55,826;398,016;4,677,069;137,888,714
56,926;40,022;4,684,603;1,406,029,248
58,026;402,928;4,703,234;1,432,531,308
59,126;405,284;4,703,696;1,461,163,532
60,226;40,782;4,714,086;1,488,555,661
61,326;410,408;4,723,778;1,515,727,772
62,426;413,096;4,733,415;1,543,209,907
63,526;415,904;4,743,902;1,570,812,052
64,626;418,744;4,753,515;1,597,974,163
6,572,601;421,712;4,765,107;1,625,336,289
6,682,601;424,764;4,776,306;1,652,868,428
67,926;427,812;4,786,617;1,680,120,545
69,026;430,976;4,798,793;1,707,742,692
7,012,601;434,084;4,808,884;1,735,054,814
7,122,601;43,764;482,112;1,762,956,982
7,232,601;440,748;4,831,589;1,789,789,067
73,426;443,988;4,844,328;1,817,591,227
74,526;44,714;4,854,664;1,844,923,351
7,562,601;450,312;4,866,343;1,872,245,473
7,672,601;453,472;4,876,364;1,899,837,617
7,782,601;456,636;4,889,104;1,926,829,715
78,926;459,768;4,898,748;1,954,491,864
80,026;462,948;4,911,087;198,211,401
8,112,601;466,044;4,920,323;2,009,616,147
8,222,601;469,168;4,932,271;2,036,948,271
8,332,601;472,316;4,942,755;2,064,790,434
84,426;475,796;4,954,349;20,926,626
85,526;478,792;4,964,325;2,119,494,685
8,662,601;481,868;4,975,502;2,146,936,817
8,772,601;484,972;4,985,339;2,174,688,973
8,882,601;48,804;4,995,944;2,202,121,105
89,926;491,112;5,005,959;2,229,903,263
91,026;49,412;5,016,309;2,256,905,362
9,212,601;497,192;502,726;2,284,647,517
9,322,601;5,002;5,036,952;2,312,069,648
9,432,601;503,244;5,046,865;2,339,551,783
95,426;506,216;5,056,162;2,366,693,892
96,526;5,097;5,076,399;2,394,226,031
9,762,601;51,252;5,075,934;2,422,028,192
9,872,601;515,524;5,086,895;2,449,700,342
9,982,601;518,484;5,095,289;2,477,152,475
100,926;5,215;5,105,426;2,504,704,616
10,202,601;524,432;5,112,932;2,532,256,756
10,312,601;527,392;5,122,967;2,559,558,878
10,422,601;530,388;513,215;2,587,141,021
10,532,601;533,344;5,140,937;2,614,353,135
106,426;536,364;5,150,225;2,642,265,304
10,752,601;539,336;5,159,128;266,975,744
10,862,601;542,672;517,375;2,697,389,587
10,972,601;545,472;5,176,813;2,724,561,698
11,082,601;548,404;518,532;2,752,213,847
111,926;551,316;5,194,443;2,779,255,948
11,302,601;554,276;5,203,168;2,806,888,095
11,412,601;557,192;5,210,412;2,834,390,232
11,522,601;560,132;5,219,152;2,861,802,362
11,632,601;563,108;5,227,598;2,889,404,507
117,426;566,072;5,235,362;2,916,866,641
11,852,601;569,028;5,242,769;2,944,448,784
11,962,601;57,204;5,252,007;2,970,120,778
12,072,601;575,276;5,259,202;2,999,993,099
12,182,601;578,232;5,267,811;3,027,215,215
122,926;581,212;5,276,466;3,054,707,351
12,402,601;584,136;528,245;3,081,879,462
12,512,601;587,152;5,291,844;3,109,101,577
12,622,601;590,188;5,298,797;3,136,833,732
12,732,601;593,196;5,306,335;3,164,295,866
12,842,601;59,618;5,312,719;3,191,808,003
129,526;59,918;5,320,668;3,219,080,123
13,062,601;602,284;5,329,015;3,244,732,116
13,172,602;605,392;5,333,449;3,274,494,428
132,826;608,364;5,342,373;3,301,766,547
13,392,602;611,296;5,349,669;3,328,928,658
135,026;614,296;5,357,651;3,356,830,826
136,126;617,248;5,364,184;3,384,342,963
13,722,602;62,024;5,371,814;341,196,511
138,326;623,184;5,377,949;3,439,107,219
13,942,602;626,168;5,385,361;3,466,659,359
140,526;629,104;5,391,126;3,494,241,503
141,626;63,234;5,406,473;3,520,823,568
14,272,602;635,128;5,403,215;3,548,965,755
143,826;63,806;5,411,326;357,631,788
14,492,602;641,016;5,417,702;3,604,150,042
146,026;643,932;5,424,417;3,631,582,174
147,126;646,884;543,151;3,659,244,323
14,822,602;649,796;5,437,432;3,686,576,447
149,326;652,796;5,445,204;3,714,308,602
15,042,602;655,688;5,449,753;3,741,690,729
151,526;658,644;5,457,414;3,768,952,848
152,626;661,736;5,461,441;3,796,885,018
15,358,802;66,306;5,434,808;3,814,696,402
154,688;665,252;5,456,519;3,832,097,754
15,578,802;667,448;546,386;3,852,089,307
156,888;669,652;546,906;3,872,600,901
157,988;671,856;5,474,201;3,893,042,489
15,898,002;673,832;5,478,227;3,911,593,931
18,453,202;67,564;5,385,984;-0,025301966
185,632;67,784;5,453,977;-0,025241961
18,673,202;680,024;5,486,235;-0,025281964
18,783,202;682,224;5,499,836;-0,025311967
188,932;684,436;5,506,333;-0,025291965
19,003,202;686,624;5,510,246;-0,025241961
191,132;688,816;5,513,779;-0,025271964
19,223,202;691,024;5,518,083;-0,025271964
19,333,202;693,224;5,521,497;-0,025281964
194,432;695,428;5,525,522;-0,025281964
19,553,202;697,632;55,291;-0,025301966
196,632;69,982;5,532,438;-0,025291965
19,773,202;702,008;5,536,149;-0,025281964
19,883,202;70,422;5,540,808;-0,025301966
199,932;706,428;5,544,214;-0,025261963
20,103,202;708,628;5,548,187;-0,025291965
202,132;710,828;5,552,153;-0,025281964
20,323,202;71,302;5,556,071;-0,025261963
20,433,202;715,208;5,559,652;-0,025301966
205,432;717,404;5,564,151;-0,025281964
20,653,202;719,608;5,567,809;-0,025301966
207,632;721,812;5,571,644;-0,025311967
20,873,202;72,402;5,575,605;-0,025251962
20,983,202;726,212;5,579,083;-0,025261963
210,932;728,404;5,583,155;-0,025301966
21,203,202;730,616;5,587,286;-0,025291965
213,132;732,816;5,590,908;-0,025281964
21,423,202;73,502;5,594,375;-0,025251962
21,533,202;737,224;5,598,273;-0,025271964
216,432;739,408;5,601,394;-0,025261963
21,753,202;741,596;5,605,195;-0,025321968
218,632;743,816;5,609,346;-0,025301966
21,973,202;746,016;5,612,962;-0,025271964
22,083,202;748,208;5,616,251;-0,025291965
221,932;750,416;5,620,189;-0,025321968
22,303,202;752,612;5,623,317;-0,025291965
224,132;754,804;5,626,891;-0,025311967
22,523,202;757,016;5,630,685;-0,025281964
22,633,202;759,212;5,633,915;-0,025311967
227,432;761,408;5,637,209;-0,025321968
22,853,202;763,616;5,641,087;-0,025261963
229,632;765,804;5,644,295;-0,025301966
23,073,202;767,996;5,647,774;-0,025261963
23,183,202;77,022;5,651,469;-0,025301966
232,932;772,416;5,654,546;-0,025331968
23,403,202;774,612;5,657,751;-0,025331968
235,132;77,682;5,661,327;-0,025281964
23,623,202;77,902;5,664,662;-0,025261963
23,733,202;781,216;5,667,992;-0,025291965
238,432;783,428;5,671,669;-0,025321968
23,953,202;785,616;5,674,658;-0,025301966
24,063,202;787,804;567,776;-0,025291965
24,173,202;790,012;5,681,316;-0,025281964
24,283,202;792,208;5,684,485;-0,025311967
243,932;7,944;5,687,714;-0,025291965
24,503,202;796,616;569,132;-0,025301966
24,613,202;798,816;5,694,413;-0,025301966
24,723,202;801,012;5,697,108;-0,025261963
24,833,202;803,208;5,700,321;-0,025311967
249,432;805,408;5,703,796;-0,025261963
25,053,202;807,612;5,706,846;-0,025311967
25,163,202;80,982;5,709,925;-0,025301966
25,273,202;812,004;5,712,852;-0,025251962
25,383,202;814,196;5,716,097;-0,025301966
254,932;816,404;5,719,027;-0,025271964
25,603,202;8,186;5,722,306;-0,025301966
25,713,202;820,804;5,725,521;-0,025311967
25,823,203;823,012;5,728,595;-0,025271964
259,332;825,216;5,731,506;-0,025261963
260,432;827,412;5,734,555;-0,025311967
26,153,202;829,612;5,737,178;-0,025291965
26,263,203;831,808;5,740,224;-0,025261963
26,373,203;834,008;5,743,303;-0,025281964
264,832;836,224;5,746,326;-0,025231961
265,932;838,432;5,749,316;-0,025301966
267,032;840,616;5,751,739;-0,025311967
26,813,203;84,282;5,754,694;-0,025271964
26,923,203;845,016;5,757,535;-0,025281964
270,332;8,472;5,760,319;-0,025281964
271,432;849,388;5,763,002;-0,025261963
272,532;8,516;5,766,369;-0,025281964
27,363,203;8,538;5,769,317;-0,025321968
27,473,203;856,004;577,198;-0,025261963
275,832;858,196;5,774,583;-0,025301966
276,932;8,604;5,777,643;-0,025361971
278,032;862,596;5,780,182;-0,025251962
27,913,203;864,808;5,783,346;-0,025291965
28,023,203;867,004;5,786,225;-0,025251962
281,332;8,692;5,788,624;-0,025291965
282,432;871,388;5,791,214;-0,025271964
283,532;8,736;5,794,452;-0,025301966
28,463,203;8,758;5,796,668;-0,02535197
28,573,203;878,004;5,799,437;-0,025271964
286,832;880,208;5,802,218;-0,025311967
287,932;8,824;5,804,715;-0,025311967
289,032;884,588;5,807,083;-0,025251962
29,013,203;886,796;5,810,103;-0,025271964
29,123,203;888,992;5,812,227;-0,025301966
292,332;891,192;5,815,169;-0,025301966
293,432;893,396;5,817,748;-0,025301966
294,532;895,584;5,820,174;-0,025311967
29,563,203;897,772;5,822,607;-0,025301966
29,673,203;899,988;5,825,836;-0,025301966
297,832;902,188;5,827,983;-0,025341969
298,932;904,388;5,830,542;-0,025301966
300,032;906,596;5,833,368;-0,025331968
30,113,203;908,792;5,835,541;-0,025311967
30,223,203;910,996;5,838,068;-0,025311967
303,332;913,208;5,841,003;-0,025291965
304,432;9,154;5,842,804;-0,025241961
305,532;917,584;5,845,199;-0,025331968
30,663,203;919,796;5,847,975;-0,025321968
30,773,203;921,988;5,850,221;-0,025301966
308,832;924,184;5,852,501;-0,025321968
309,932;9,264;5,855,408;-0,025281964
311,032;9,286;5,857,367;-0,025311967
31,213,203;930,796;5,859,587;-0,025321968
31,323,203;9,33;5,862,135;-0,025271964
314,332;935,188;5,864,162;-0,025301966
315,432;9,374;5,866,786;-0,025331968
316,532;939,616;5,869,137;-0,025291965
31,763,203;941,796;5,870,997;-0,025301966
31,873,203;943,984;587,328;-0,025281964
319,832;946,196;5,876,299;-0,025291965
320,932;948,384;5,878,235;-0,025321968
322,032;950,584;5,880,383;-0,025301966
32,313,203;952,796;5,882,784;-0,025281964
32,423,203;954,996;5,884,719;-0,025291965
325,332;957,188;5,886,648;-0,025321968
326,432;959,396;5,889,189;-0,025321968
327,532;961,584;5,891,287;-0,025301966
32,863,203;96,378;5,893,785;-0,025321968
32,973,203;965,996;5,896,043;-0,025321968
330,832;9,682;589,812;-0,025301966
331,932;970,396;5,899,924;-0,025311967
333,032;972,592;5,902,135;-0,025271964
33,413,203;974,792;5,904,215;-0,025331968
33,523,203;976,972;5,906,098;-0,025291965
336,332;97,918;590,876;-0,025291965
337,432;981,376;5,911,039;-0,025311967
338,532;983,576;5,912,729;-0,025291965
33,963,203;985,776;5,914,876;-0,025271964
34,073,203;98,798;5,916,901;-0,025291965
34,183,203;990,172;5,918,898;-0,025321968
342,932;992,384;5,921,146;-0,025281964
344,032;994,592;5,923,274;-0,025291965
34,513,203;996,792;5,925,041;-0,025321968
34,623,203;998,988;5,926,906;-0,025291965
34,733,203;1,001,184;5,928,758;-0,025341969
348,432;1,003,384;5,930,907;-0,025301966
349,532;1,005,604;5,932,959;-0,025291965
35,063,203;1,007,808;5,934,955;-0,025291965
35,173,203;1,010,004;5,936,748;-0,025261963
35,283,203;1,012,204;593,864;-0,025311967
353,932;1,014,396;5,940,653;-0,025281964
355,032;1,016,592;5,942,454;-0,025301966
35,613,203;1,018,792;5,944,443;-0,025241961
35,723,203;10,21;5,946,386;-0,025281964
35,833,203;1,023,196;594,833;-0,025291965
359,432;1,025,392;5,949,964;-0,025291965
360,532;1,027,584;5,951,895;-0,025271964
36,163,203;1,029,784;5,954,155;-0,025281964
36,273,203;1,031,988;5,955,911;-0,025271964
36,383,203;1,034,196;5,957,595;-0,025291965
364,932;1,036,392;5,959,458;-0,025291965
366,032;1,038,592;5,960,894;-0,025311967
36,713,203;1,040,792;5,962,906;-0,025321968
36,823,203;10,43;5,965,058;-0,025301966
36,933,203;1,045,188;5,966,303;-0,025271964
370,432;104,738;5,968,242;-0,025291965
371,532;1,049,576;5,970,106;-0,025321968
37,263,203;1,051,776;5,971,885;-0,025281964
37,373,203;1,053,968;5,973,403;-0,025251962
37,483,203;1,056,176;5,975,606;-0,025291965
375,932;1,058,376;5,977,072;-0,025271964
377,032;1,060,584;5,979,035;-0,025271964
37,813,203;1,062,792;5,981,109;-0,025321968
37,923,203;1,064,976;5,982,357;-0,025271964
38,033,203;106,718;5,984,138;-0,025291965
381,432;1,069,408;5,986,242;-0,025301966
382,532;1,071,592;5,986,829;-0,025291965
38,363,203;1,073,784;5,988,874;-0,025341969
38,473,203;1,075,996;5,990,883;-0,025301966
38,583,203;107,818;5,992,185;-0,025281964
386,932;108,038;5,993,959;-0,025321968
388,032;1,082,592;599,611;-0,025291965
38,913,203;1,084,784;599,712;-0,025271964
39,023,203;1,086,988;599,873;-0,025261963
39,133,203;1,089,196;600,058;-0,025291965
392,432;1,091,372;6,001,443;-0,025291965
393,532;1,093,568;6,003,274;-0,025311967
39,463,203;1,095,784;6,005,561;-0,025291965
39,573,203;1,097,988;6,006,729;-0,025241961
39,683,203;1,100,184;6,008,114;-0,025271964
397,932;1,102,388;6,009,555;-0,025281964
399,032;110,458;6,011,273;-0,025311967
40,013,203;1,106,776;6,012,668;-0,025281964
40,123,203;1,108,968;6,014,546;-0,025281964
40,233,203;1,111,168;6,016,105;-0,025291965
403,432;1,113,372;6,017,911;-0,025261963
404,532;111,558;6,019,528;-0,025261963
40,563,203;1,117,768;602,067;-0,025301966
40,673,203;1,119,968;6,022,006;-0,025281964
40,783,203;1,122,184;6,023,828;-0,025291965
408,932;1,124,384;602,509;-0,025341969
410,032;1,126,584;6,026,496;-0,025321968
41,113,203;1,128,788;6,028,113;-0,025291965
41,223,203;1,130,972;602,939;-0,025271964
41,333,203;113,316;6,030,602;-0,025311967
414,432;113,538;6,032,498;-0,025261963
415,532;1,137,588;6,033,771;-0,025281964
41,663,203;1,139,784;6,034,992;-0,025301966
41,773,203;1,141,992;6,036,634;-0,025291965
41,883,203;1,144,184;603,799;-0,025321968
419,932;114,638;6,039,319;-0,025271964
421,032;1,148,588;604,098;-0,025261963
42,213,203;1,150,788;6,042,183;-0,025291965
42,323,203;1,152,976;604,319;-0,025301966
42,433,203;1,155,184;6,044,654;-0,025301966
425,432;115,738;604,587;-0,025301966
426,532;1,159,568;6,047,345;-0,025311967
42,763,203;1,161,784;6,048,926;-0,025311967
42,873,203;1,163,984;6,050,498;-0,025291965
42,983,203;116,618;6,051,356;-0,025321968
430,932;1,168,384;6,052,645;-0,025271964
432,032;1,170,592;6,054,059;-0,025291965
43,313,203;1,172,784;605,536;-0,025321968
43,423,203;1,174,996;6,056,638;-0,025311967
43,533,203;1,177,192;6,057,944;-0,025331968
436,432;1,179,376;6,058,905;-0,025341969
437,532;1,181,576;6,060,331;-0,025321968
43,863,203;118,378;606,176;-0,025321968
43,973,203;1,185,976;6,062,924;-0,025291965
44,083,203;1,188,188;6,064,305;-0,025301966
441,932;1,190,392;606,567;-0,025331968
443,032;1,192,592;6,066,645;-0,025321968
44,413,203;1,194,788;6,067,641;-0,025301966
44,523,203;119,698;6,069,074;-0,025301966
44,633,203;11,992;6,070,822;-0,025321968
447,432;1,201,404;6,071,506;-0,025311967
448,532;1,203,584;6,072,586;-0,02535197
44,963,203;1,205,784;6,073,856;-0,025331968
45,073,203;1,207,984;607,509;-0,025301966
45,183,203;1,210,176;6,076,395;-0,025341969
452,932;1,212,384;6,077,961;-0,025341969
454,032;1,214,588;6,078,925;-0,025291965
45,513,203;1,216,788;6,080,039;-0,025301966
45,623,203;1,218,984;6,081,416;-0,025301966
45,733,203;1,221,184;6,082,173;-0,025291965
458,432;1,223,376;6,083,551;-0,025331968
459,532;1,225,584;6,084,936;-0,025271964
46,063,203;1,227,784;6,085,882;-0,025281964
46,173,203;1,229,996;6,086,989;-0,025291965
46,283,203;1,232,196;6,088,277;-0,025281964
463,932;123,438;6,089,012;-0,025331968
465,032;1,236,576;6,090,163;-0,025281964
46,613,203;1,238,784;6,091,197;-0,025301966
46,723,203;1,240,976;6,092,038;-0,025281964
46,833,203;124,318;6,093,388;-0,025301966
46,943,203;1,245,388;6,094,874;-0,025301966
470,532;1,247,572;6,095,659;-0,025271964
47,163,203;1,249,768;6,096,951;-0,025341969
47,273,203;1,251,984;6,098,281;-0,025321968
47,383,203;125,418;6,098,799;-0,025301966
47,493,203;1,256,388;6,100,082;-0,025301966
476,032;12,586;6,101,343;-0,025311967
47,713,203;126,078;6,101,769;-0,025301966
47,823,203;1,262,968;6,102,837;-0,02535197
47,933,203;1,265,188;6,104,562;-0,025311967
48,043,203;1,267,384;6,105,098;-0,025301966
481,532;1,269,584;6,106,099;-0,025291965
48,263,203;1,271,792;6,107,174;-0,025321968
48,373,203;1,273,984;6,107,827;-0,025301966
48,483,203;1,276,172;6,108,691;-0,025311967
48,593,203;1,278,384;6,110,202;-0,025311967
487,032;1,280,568;6,110,985;-0,025291965
48,813,203;1,282,764;6,111,993;-0,025291965
48,923,203;1,284,976;6,113,204;-0,025321968
49,033,203;128,716;6,113,858;-0,025281964
49,143,203;1,289,344;6,114,627;-0,025271964
492,532;1,291,572;6,116,386;-0,025291965
49,363,203;1,293,776;6,117,061;-0,025311967
49,473,203;1,295,968;6,117,765;-0,025291965
49,583,203;1,298,176;6,118,875;-0,025301966
49,693,203;1,300,364;6,119,779;-0,025281964
498,032;1,302,568;6,120,695;-0,025331968
49,913,203;1,304,792;6,122,053;-0,025331968
50,023,203;1,306,984;6,122,407;-0,025291965
50,133,203;1,309,168;6,123,065;-0,025271964
50,243,203;1,311,368;6,124,376;-0,025301966
503,532;131,356;6,125,476;-0,025271964
50,463,203;131,576;6,126,381;-0,025291965
50,573,203;1,317,976;6,127,686;-0,025291965
50,683,203;1,320,172;6,128,225;-0,025361971
50,793,203;1,322,372;6,128,923;-0,025341969
509,032;132,458;6,129,687;-0,025321968
51,013,203;132,676;6,130,235;-0,025311967
51,123,203;1,328,968;6,131,794;-0,025301966
51,233,203;1,331,184;6,132,967;-0,02535197
513,432;133,336;6,132,901;-0,025261963
51,453,203;1,335,548;6,134,065;-0,025331968
51,563,203;133,776;6,135,163;-0,025261963
516,732;1,339,956;6,135,726;-0,025291965
51,783,203;1,342,156;613,666;-0,025281964
518,932;1,344,372;6,137,612;-0,025291965
52,003,203;1,346,576;6,138,427;-0,025261963
52,113,203;1,348,764;6,138,771;-0,025331968
522,232;1,350,968;6,140,065;-0,025321968
52,333,203;1,353,164;6,140,519;-0,025341969
524,432;1,355,372;6,141,652;-0,025311967
52,553,206;135,758;6,142,278;-0,025301966
526,632;1,359,792;6,143,198;-0,025301966
527,732;1,361,984;6,143,652;-0,025301966
528,832;1,364,172;6,144,221;-0,025311967
529,932;1,366,372;6,145,173;-0,025301966
53,103,206;1,368,576;6,146,242;-0,025291965
532,132;1,370,764;6,146,536;-0,025341969
53,323,206;1,372,968;6,147,628;-0,025311967
534,332;1,375,168;6,148,236;-0,025311967
535,432;137,736;614,869;-0,025311967
53,653,206;137,956;6,149,892;-0,025321968
537,632;1,381,768;6,150,951;-0,025331968
53,873,206;1,383,968;6,151,332;-0,025311967
539,832;1,386,176;6,152,469;-0,025291965
540,932;1,388,384;6,152,977;-0,025291965
54,203,206;1,390,576;6,153,383;-0,025281964
543,132;1,392,768;6,153,999;-0,025281964
54,423,206;1,394,976;6,155,205;-0,025311967
545,332;139,718;6,155,894;-0,025311967
546,432;1,399,384;6,156,847;-0,025291965
54,753,206;1,401,588;6,157,289;-0,025311967
548,632;140,378;6,157,633;-0,025321968
54,973,206;1,405,976;6,158,176;-0,025331968
550,832;1,408,184;6,159,196;-0,025291965
551,932;1,410,376;6,159,509;-0,025291965
55,303,206;141,258;6,160,604;-0,025311967
554,132;1,414,776;6,161,369;-0,025291965
55,523,206;1,416,956;616,156;-0,025301966
556,332;1,419,152;6,162,508;-0,025301966
557,432;1,421,372;6,163,474;-0,025291965
55,853,206;1,423,572;6,163,762;-0,025301966
559,632;1,425,776;6,164,324;-0,025281964
56,073,206;1,427,976;6,165,032;-0,025311967
561,832;143,016;6,165,248;-0,025301966
562,932;143,236;6,166,634;-0,025291965
56,403,206;1,434,584;616,732;-0,025281964
565,132;1,436,776;6,167,517;-0,025311967
56,623,206;1,438,976;6,167,826;-0,025291965
567,332;1,441,168;6,168,792;-0,025311967
568,432;144,336;6,169,181;-0,025321968
56,953,206;1,445,556;6,169,888;-0,025331968
570,632;1,447,776;6,170,917;-0,025311967
57,173,206;1,449,968;617,105;-0,025281964
572,832;1,452,172;6,171,766;-0,025341969
573,932;1,454,376;6,172,425;-0,025291965
57,503,206;1,456,568;617,258;-0,025311967
576,132;1,458,756;6,173,355;-0,02535197
57,723,206;1,460,992;6,174,554;-0,025311967
578,332;1,463,184;6,174,592;-0,025311967
579,432;146,536;6,174,864;-0,025291965
58,053,206;1,467,568;6,176,043;-0,025341969
581,632;146,976;617,624;-0,025301966
58,273,206;1,471,956;6,176,649;-0,025281964
583,832;1,474,176;6,177,579;-0,025311967
584,932;1,476,368;6,177,862;-0,025301966
58,603,206;147,856;6,178,322;-0,025271964
587,132;1,480,768;617,942;-0,025291965
58,823,206;148,296;6,179,849;-0,025271964
589,332;1,485,156;6,180,444;-0,025361971
590,432;1,487,372;618,125;-0,025301966
59,153,206;1,489,576;6,181,644;-0,02535197
592,632;149,178;6,182,029;-0,025311967
59,373,206;149,398;6,182,299;-0,025311967
594,832;1,496,168;6,182,728;-0,025321968
595,932;1,498,368;6,183,755;-0,025331968
59,703,206;1,500,568;6,184,009;-0,025301966
598,132;1,502,764;6,184,538;-0,025291965
59,923,206;150,496;6,185,053;-0,025311967
600,332;150,716;6,185,577;-0,025311967
601,432;1,509,356;6,186,234;-0,025301966
60,253,206;1,511,556;6,186,741;-0,025331968
603,632;151,376;6,187,548;-0,025291965
60,473,206;151,596;6,187,982;-0,025281964
605,832;1,518,152;6,188,653;-0,025321968
606,932;152,036;61,887;-0,025341969
60,803,206;1,522,552;6,189,239;-0,025301966
609,132;1,524,752;61,897;-0,025301966
61,023,206;1,526,956;619,028;-0,025331968
611,332;1,529,164;6,190,867;-0,02535197
612,432;1,531,348;6,191,021;-0,025301966
61,353,206;1,533,564;6,191,754;-0,025301966
614,632;153,576;6,192,299;-0,025331968
61,573,206;1,537,964;6,192,672;-0,025281964
616,832;154,016;6,192,914;-0,025271964
617,932;154,236;6,193,444;-0,025291965
61,903,206;1,544,552;6,193,784;-0,025301966
620,132;1,546,756;6,194,081;-0,025321968
62,123,206;1,548,952;6,194,413;-0,025321968
622,332;1,551,156;6,195,441;-0,025301966
623,432;1,553,356;6,195,525;-0,025251962
62,453,206;1,555,568;6,195,998;-0,025271964
625,632;1,557,764;6,196,382;-0,025361971
62,673,206;1,559,956;6,196,801;-0,025301966
627,832;1,562,156;6,197,307;-0,025291965
628,932;1,564,376;6,198,407;-0,025331968
63,003,206;1,566,572;6,197,982;-0,025291965
631,132;1,568,772;6,198,612;-0,025301966
63,223,206;1,570,968;6,198,972;-0,025301966
633,332;1,573,156;6,199,231;-0,025271964
634,432;1,575,352;6,199,547;-0,025331968
63,553,206;157,756;620,046;-0,025321968
636,632;1,579,756;6,200,384;-0,025331968
63,773,206;158,196;6,201,108;-0,025321968
638,832;1,584,168;6,201,633;-0,025341969
639,932;158,636;6,201,653;-0,025261963
64,103,206;1,588,552;6,201,835;-0,025301966
642,132;159,078;6,203,228;-0,025311967
64,323,206;159,298;6,202,883;-0,025341969
644,332;159,516;6,202,735;-0,025271964
645,432;1,597,364;6,203,729;-0,02535197
64,653,206;1,599,556;6,203,817;-0,025321968
647,632;1,601,752;6,204,202;-0,025321968
64,873,206;1,603,972;6,205,058;-0,025311967
649,832;1,606,168;6,204,847;-0,025301966
650,932;1,608,368;6,205,148;-0,025331968
65,203,206;1,610,572;6,205,767;-0,025341969
653,132;161,276;6,205,769;-0,025321968
65,423,206;1,614,952;6,206,053;-0,025291965
655,332;1,617,164;6,206,732;-0,025321968
656,432;1,619,368;6,206,887;-0,025301966
65,753,206;1,621,576;6,207,354;-0,025321968
658,632;1,623,788;6,207,905;-0,025371971
65,973,206;1,625,964;6,207,573;-0,025311967
660,832;1,628,164;6,208,228;-0,025331968
661,932;1,630,384;6,208,767;-0,025301966
66,303,206;1,632,568;6,208,753;-0,025261963
664,132;1,634,764;6,209,007;-0,025321968
66,523,206;1,636,976;6,209,777;-0,025321968
666,332;1,639,172;6,209,601;-0,025311967
667,432;1,641,368;6,209,945;-0,025341969
66,853,206;1,643,588;6,210,344;-0,025361971
669,632;1,645,776;621,034;-0,025311967
67,073,206;1,647,972;6,210,688;-0,025301966
671,832;1,650,176;6,211,243;-0,025291965
672,932;1,652,364;6,211,365;-0,025321968
67,403,206;165,456;6,211,529;-0,02535197
675,132;1,656,768;6,212,186;-0,025331968
67,623,206;165,896;6,212,344;-0,025341969
677,332;166,116;6,212,669;-0,025321968
678,432;166,336;6,212,924;-0,025341969
67,953,206;166,556;6,213,521;-0,025371971
680,632;1,667,756;6,213,658;-0,025321968
68,173,206;1,669,968;6,213,827;-0,025331968
682,832;167,216;6,213,971;-0,025321968
683,932;1,674,352;621,411;-0,025301966
68,503,206;1,676,552;6,214,502;-0,025341969
686,132;1,678,752;6,214,691;-0,025321968
68,723,206;1,680,944;6,215,062;-0,02535197
688,332;1,683,156;6,215,591;-0,025291965
689,432;168,536;6,215,703;-0,02535197
69,053,206;1,687,556;6,215,584;-0,025301966
691,632;168,976;6,215,776;-0,025361971
69,273,206;169,196;6,216,055;-0,02535197
693,832;1,694,164;6,216,556;-0,02535197
694,932;169,638;6,216,835;-0,025301966
69,603,206;1,698,576;6,216,835;-0,025291965
697,132;1,700,764;6,216,801;-0,025361971
69,823,206;1,702,956;6,216,864;-0,025361971
699,332;1,705,156;6,217,494;-0,025311967
700,432;170,736;6,217,879;-0,025311967
70,153,206;1,709,568;6,218,015;-0,025301966
702,632;1,711,764;6,218,053;-0,025321968
70,373,206;171,396;6,218,475;-0,025321968
704,832;171,616;6,218,408;-0,025321968
705,932;1,718,348;6,218,302;-0,025291965
70,703,206;1,720,556;6,219,088;-0,025331968
708,132;1,722,776;6,219,279;-0,025331968
70,923,206;1,724,972;6,219,217;-0,025331968
710,332;1,727,152;6,219,437;-0,025331968
711,432;1,729,348;6,219,649;-0,025331968
71,253,206;1,731,544;6,220,093;-0,025301966
713,632;173,376;6,220,427;-0,025281964
71,473,206;1,735,964;6,220,235;-0,025341969
715,832;1,738,168;6,220,427;-0,025281964
716,932;1,740,372;6,220,667;-0,025321968
71,803,206;1,742,564;622,062;-0,025311967
719,132;1,744,756;6,220,761;-0,025341969
72,023,206;1,746,968;622,144;-0,025311967
721,332;1,749,164;6,221,247;-0,025291965
722,432;1,751,376;6,221,345;-0,025301966
72,353,206;1,753,584;6,221,674;-0,025311967
724,632;1,755,772;6,221,094;-0,025321968
72,573,206;1,757,964;6,221,281;-0,025301966
726,832;176,018;6,221,982;-0,025301966
727,932;1,762,352;6,221,259;-0,025301966
72,903,206;1,764,552;6,221,932;-0,025281964
730,132;176,676;6,222,268;-0,025341969
73,123,206;1,768,952;6,221,832;-0,025281964
732,332;1,771,152;6,222,089;-0,025311967
733,432;1,773,364;622,258;-0,025261963
73,453,206;177,556;6,222,305;-0,025311967
735,632;177,776;622,245;-0,025251962
73,673,206;1,779,976;6,222,897;-0,025311967
737,832;1,782,156;6,222,681;-0,025281964
738,932;1,784,348;6,222,629;-0,025311967
74,003,206;1,786,564;622,323;-0,025281964
741,132;178,876;6,222,855;-0,025311967
74,223,206;1,790,964;6,223,104;-0,025311967
743,332;1,793,172;6,223,332;-0,025291965
744,432;179,536;6,223,143;-0,025301966
74,553,206;179,756;6,223,356;-0,025301966
746,632;179,978;6,223,853;-0,025291965
74,773,206;1,801,972;6,223,428;-0,025281964
748,832;1,804,168;6,223,481;-0,025301966
749,932;1,806,372;6,223,649;-0,025341969
75,103,206;180,856;6,223,496;-0,025301966
752,132;1,810,752;6,223,478;-0,025291965
75,323,206;1,812,968;6,224,024;-0,025321968
754,332;181,516;6,224,105;-0,025271964
755,432;1,817,356;622,396;-0,025281964
75,653,206;181,956;6,224,067;-0,025281964
757,632;1,821,748;6,223,944;-0,025291965
75,873,206;1,823,952;6,224,273;-0,025321968
759,832;1,826,172;6,224,613;-0,025281964
760,932;1,828,372;6,224,496;-0,025301966
76,203,206;183,056;6,224,443;-0,025311967
763,132;1,832,752;6,224,222;-0,025281964
76,423,206;1,834,944;6,224,236;-0,025301966
765,332;1,837,148;6,224,638;-0,025281964
766,432;1,839,368;6,224,709;-0,025291965
76,753,206;1,841,564;6,224,408;-0,025281964
768,632;1,843,756;622,429;-0,025291965
76,973,206;184,596;6,224,345;-0,025301966
770,832;1,848,156;6,224,516;-0,025291965
771,932;1,850,348;622,472;-0,025301966
77,303,206;1,852,576;6,225,175;-0,025281964
774,132;1,854,776;6,224,694;-0,025291965
77,523,206;1,856,952;6,224,009;-0,025301966
776,332;1,859,152;6,224,245;-0,025341969
777,432;1,861,352;6,224,579;-0,025341969
77,853,206;1,863,552;6,224,817;-0,025281964
779,632;1,865,768;6,224,985;-0,025251962
78,073,206;1,867,972;6,224,813;-0,025311967
781,832;1,870,168;6,224,566;-0,025311967
782,932;1,872,372;6,224,415;-0,025301966
78,403,206;1,874,572;6,224,567;-0,025321968
785,132;1,876,772;6,224,583;-0,025241961
78,623,206;187,898;6,224,485;-0,025321968
787,332;1,881,184;6,224,694;-0,025281964
78,843,206;1,883,392;6,224,673;-0,025321968
78,953,206;1,885,588;6,224,375;-0,025281964
790,632;1,887,772;6,223,956;-0,025291965
79,173,206;1,889,984;6,224,413;-0,025281964
792,832;1,892,176;6,224,005;-0,025321968
79,393,206;1,894,372;6,224,306;-0,025311967
79,503,206;1,896,576;6,224,411;-0,025321968
796,132;1,898,772;622,394;-0,025331968
79,723,206;1,900,964;6,223,931;-0,025361971
798,332;1,903,176;6,224,449;-0,025301966
79,943,206;1,905,372;622,393;-0,025321968
80,053,206;1,907,576;6,224,054;-0,025341969
801,632;190,978;6,224,367;-0,025311967
80,273,206;1,911,972;6,223,693;-0,025331968
803,832;1,914,156;62,238;-0,025291965
80,493,206;1,916,368;6,224,188;-0,025321968
80,603,206;1,918,556;6,223,882;-0,025331968
807,132;1,920,768;6,223,823;-0,025301966
80,823,206;1,922,976;6,224,067;-0,025371971
809,332;1,925,164;6,223,367;-0,025311967
81,043,206;192,736;6,223,613;-0,025291965
81,153,206;192,958;6,223,633;-0,025301966
812,632;1,931,764;6,223,033;-0,02535197
81,373,206;1,933,968;622,314;-0,025311967
814,832;1,936,168;6,223,421;-0,025271964
81,593,206;193,836;6,222,758;-0,025301966
81,703,206;1,940,552;6,222,666;-0,025321968
818,132;1,942,768;6,222,984;-0,025341969
81,923,206;1,944,956;6,222,434;-0,025321968
820,332;194,716;6,222,681;-0,025321968
82,143,206;194,936;622,259;-0,025301966
82,253,206;1,951,552;6,222,292;-0,025321968
823,632;1,953,744;6,222,208;-0,025341969
82,473,206;1,955,972;6,222,592;-0,025341969
825,832;1,958,168;6,221,939;-0,025321968
82,693,206;1,960,368;6,221,591;-0,025341969
82,803,206;1,962,564;6,221,474;-0,025291965
829,132;1,964,748;6,221,302;-0,025311967
83,023,206;1,966,948;6,221,209;-0,025321968
831,332;1,969,176;6,221,625;-0,025341969
83,243,206;1,971,372;6,220,853;-0,025311967
83,353,206;1,973,568;6,220,676;-0,025321968
834,632;1,975,784;6,220,877;-0,025311967
83,573,206;1,977,972;6,220,403;-0,02535197
836,832;1,980,168;6,220,184;-0,025281964
83,793,206;1,982,388;622,075;-0,025321968
83,903,206;1,984,592;6,220,232;-0,025301966
840,132;1,986,776;6,219,664;-0,025321968
84,123,206;1,988,972;6,219,671;-0,025321968
842,332;1,991,164;6,219,745;-0,025381972
84,343,206;1,993,364;6,219,498;-0,025291965
84,453,206;199,558;6,219,798;-0,025311967
845,632;1,997,776;6,219,369;-0,025321968
84,673,206;1,999,964;6,219,127;-0,025331968
847,832;2,002,172;6,218,967;-0,025331968
84,893,206;2,004,364;6,218,692;-0,025311967
85,003,206;200,656;6,218,425;-0,025321968
851,132;2,008,772;6,218,672;-0,025341969
85,223,206;2,010,972;6,218,293;-0,025311967
853,332;2,013,168;6,218,169;-0,025291965
85,443,206;2,015,372;6,217,901;-0,025371971
85,553,206;201,756;6,217,642;-0,025311967
856,632;2,019,764;6,217,626;-0,025341969
85,773,206;2,021,988;6,217,568;-0,02535197
858,832;2,024,168;621,675;-0,025341969
85,993,206;2,026,356;6,216,581;-0,025281964
86,103,206;2,028,564;6,216,437;-0,025341969
862,132;2,030,764;6,216,465;-0,02535197
86,323,206;2,032,968;6,216,226;-0,025311967
864,332;2,035,176;6,216,018;-0,025341969
86,543,206;2,037,376;6,215,689;-0,025311967
86,653,206;2,039,568;6,215,243;-0,025341969
867,632;2,041,772;6,214,902;-0,025321968
86,873,206;2,043,964;6,214,601;-0,025331968
869,832;2,046,168;6,214,706;-0,025311967
87,093,206;2,048,368;6,214,461;-0,025341969
87,203,206;2,050,568;6,214,511;-0,025311967
873,132;2,052,772;6,214,167;-0,025311967
87,423,206;2,054,972;6,213,788;-0,025331968
875,332;2,057,168;6,213,508;-0,025371971
87,643,206;2,059,376;6,213,647;-0,025311967
87,753,206;2,061,568;6,212,663;-0,025301966
878,632;2,063,764;6,212,918;-0,025341969
87,973,206;2,065,964;6,212,926;-0,025311967
880,832;206,816;6,212,291;-0,025291965
88,193,206;2,070,352;6,211,931;-0,025301966
88,303,206;207,256;6,212,082;-0,025311967
884,132;207,476;6,211,429;-0,025321968
88,523,206;2,076,964;6,211,157;-0,025331968
886,332;2,079,168;6,211,221;-0,025331968
88,743,206;2,081,356;6,210,434;-0,025331968
88,853,206;2,083,556;6,210,244;-0,02535197
889,632;2,085,772;621,051;-0,025311967
89,073,206;2,087,976;6,209,467;-0,025361971
891,832;2,090,172;620,931;-0,025321968
89,293,206;2,092,376;6,209,298;-0,025341969
89,403,206;2,094,548;6,208,507;-0,025311967
895,132;2,096,744;6,208,661;-0,025321968
89,623,206;209,896;6,208,761;-0,025291965
897,332;210,116;6,208,045;-0,025271964
89,843,206;2,103,364;6,207,739;-0,025321968
89,953,206;2,105,572;6,207,597;-0,025341969
900,632;2,107,764;6,206,918;-0,025341969
90,173,206;210,996;6,206,466;-0,025301966
902,832;2,112,172;6,206,768;-0,025271964
90,393,206;2,114,376;6,206,458;-0,025261963
90,503,206;2,116,576;6,205,694;-0,025311967
906,132;2,118,764;6,205,265;-0,025321968
90,723,206;2,120,948;6,204,744;-0,02535197
908,332;2,123,148;6,204,962;-0,025301966
90,943,206;2,125,368;6,204,785;-0,025341969
91,053,206;2,127,564;6,204,084;-0,025321968
911,632;2,129,764;6,203,706;-0,025311967
91,273,206;2,131,968;6,203,644;-0,025331968
913,832;2,134,152;6,202,704;-0,025321968
91,493,206;2,136,348;620,244;-0,025281964
91,603,206;2,138,572;6,202,376;-0,025301966
917,132;2,140,764;6,201,642;-0,025321968
91,823,206;214,296;6,201,162;-0,025331968
919,332;2,145,172;6,201,217;-0,025321968
92,043,206;214,736;6,200,652;-0,025311967
92,153,206;2,149,548;6,200,122;-0,025331968
922,632;2,151,772;6,200,148;-0,025341969
92,373,206;215,396;6,199,067;-0,02535197
924,832;2,156,148;6,198,324;-0,025311967
92,593,206;2,158,356;6,198,282;-0,025321968
92,703,206;2,160,548;6,197,984;-0,025311967
928,132;2,162,748;6,197,395;-0,025321968
92,923,206;2,164,968;6,197,309;-0,025331968
930,332;2,167,156;6,196,277;-0,025301966
93,143,206;2,169,352;6,195,931;-0,025301966
93,253,206;217,156;6,195,534;-0,02535197
933,632;2,173,756;6,195,108;-0,025331968
93,473,206;2,175,952;6,194,654;-0,025281964
935,832;217,816;6,194,488;-0,025311967
93,693,206;2,180,356;619,402;-0,025321968
93,803,206;2,182,548;6,193,599;-0,025301966
939,132;2,184,756;6,192,964;-0,025291965
94,023,206;2,186,956;6,192,414;-0,025341969
941,332;218,916;6,192,027;-0,025281964
94,243,206;2,191,372;6,191,647;-0,025331968
94,353,206;2,193,568;6,190,847;-0,025321968
944,632;2,195,752;6,190,328;-0,025331968
94,573,206;2,197,952;6,189,655;-0,02535197
946,832;2,200,148;6,189,431;-0,025331968
94,793,206;2,202,348;6,188,877;-0,025331968
94,903,206;2,204,556;6,188,498;-0,025331968
950,132;220,676;6,187,823;-0,025321968
95,123,206;2,208,952;61,872;-0,025371971
952,332;221,116;6,186,499;-0,025341969
95,343,206;2,213,352;6,186,453;-0,025301966
95,453,206;221,556;6,186,184;-0,02535197
955,632;2,217,772;6,185,346;-0,025321968
95,673,206;2,219,984;6,184,677;-0,025331968
957,832;222,218;6,184,043;-0,025331968
95,893,206;2,224,376;6,183,006;-0,025301966
96,003,206;2,226,564;618,265;-0,025331968
961,132;2,228,776;6,182,563;-0,025311967
96,223,206;2,230,976;6,181,685;-0,025331968
963,332;223,318;6,181,114;-0,025331968
96,443,206;2,235,376;6,180,472;-0,025291965
96,553,206;2,237,576;617,956;-0,025331968
966,632;2,239,768;6,178,959;-0,025341969
96,773,206;2,241,976;6,178,763;-0,025291965
968,832;224,418;6,178,028;-0,025301966
96,993,206;2,246,388;6,177,589;-0,025361971
97,103,206;2,248,576;6,176,515;-0,025321968
972,132;225,076;6,175,455;-0,02535197
97,323,206;2,252,956;6,174,954;-0,025341969
974,332;2,255,176;6,174,892;-0,025321968
97,543,206;2,257,372;6,173,687;-0,025331968
97,653,206;2,259,572;6,173,213;-0,025331968
977,632;226,178;6,172,723;-0,025321968
97,873,206;2,263,976;6,171,787;-0,025331968
979,832;2,266,164;6,170,835;-0,025341969
98,093,206;2,268,376;6,170,492;-0,025341969
98,203,206;2,270,568;6,169,226;-0,025371971
983,132;2,272,772;6,168,874;-0,025301966
98,423,206;2,274,988;6,168,339;-0,025331968
985,332;2,277,172;6,167,349;-0,025311967
98,643,206;2,279,356;6,166,182;-0,025311967
98,753,206;2,281,576;6,166,457;-0,025321968
988,632;2,283,772;616,479;-0,025331968
98,973,206;2,285,956;6,163,557;-0,025321968
990,832;2,288,172;6,163,263;-0,025291965
99,193,206;229,036;6,162,284;-0,025341969
99,303,206;229,256;6,161,326;-0,025321968
994,132;229,478;6,160,964;-0,025331968
99,523,206;2,296,976;6,159,646;-0,025341969
996,332;2,299,172;6,158,835;-0,025341969
99,743,206;2,301,384;6,158,098;-0,025321968
99,853,206;2,303,568;6,156,768;-0,025311967
999,632;230,576;6,155,786;-0,02535197
100,073,206;2,307,976;6,155,316;-0,025341969
1,001,832;2,310,168;6,154,113;-0,025331968
100,293,206;2,312,364;6,153,284;-0,025361971
100,403,206;231,458;6,152,676;-0,025321968
1,005,132;2,316,768;615,118;-0,025321968
100,623,206;2,318,964;6,150,021;-0,02535197
1,007,332;2,321,188;6,149,325;-0,025341969
100,843,206;2,323,384;6,148,061;-0,025321968
100,953,206;2,325,576;614,692;-0,025331968
1,010,632;2,327,776;6,146,105;-0,025361971
101,173,206;2,329,968;6,144,845;-0,025331968
1,012,832;233,216;614,405;-0,02535197
101,393,206;2,334,372;6,143,063;-0,025311967
101,503,206;233,656;6,141,543;-0,025321968
1,016,132;233,876;6,140,366;-0,025331968
101,723,206;2,340,964;6,139,327;-0,025341969
1,018,332;2,343,156;6,138,092;-0,025341969
101,943,206;2,345,348;6,137,136;-0,02535197
102,053,206;2,347,576;6,136,351;-0,025311967
1,021,632;2,349,776;6,134,787;-0,025341969
102,273,206;2,351,976;6,132,987;-0,025321968
1,023,832;2,354,172;613,142;-0,025341969
1,024,932;235,636;6,130,111;-0,025331968
102,603,212;235,856;6,129,194;-0,025321968
102,713,206;236,078;6,128,058;-0,025321968
102,823,206;2,362,976;6,126,503;-0,02535197
1,029,332;2,365,172;612,496;-0,025311967
1,030,432;2,367,376;6,123,257;-0,025311967
103,153,212;236,958;6,121,812;-0,025341969
103,263,206;237,178;6,120,315;-0,025321968
103,373,206;2,373,988;6,118,844;-0,025361971
1,034,832;2,376,196;6,117,623;-0,025311967
1,035,932;2,378,392;6,115,876;-0,025321968
103,703,212;2,380,568;6,114,066;-0,025341969
103,813,206;2,382,768;611,298;-0,025301966
103,923,206;2,384,972;6,111,326;-0,025361971
1,040,332;2,387,176;6,109,859;-0,025311967
1,041,432;2,389,376;6,108,083;-0,025301966
104,253,212;239,158;6,106,485;-0,025341969
104,363,206;239,378;6,104,422;-0,02535197
104,473,206;2,395,976;6,102,749;-0,02535197
1,045,832;2,398,184;6,101,265;-0,025321968
1,046,932;240,038;6,099,174;-0,025321968
104,803,212;2,402,584;6,097,168;-0,025291965
104,913,213;2,404,788;6,095,469;-0,025321968
1,050,232;2,406,988;6,093,232;-0,025341969
1,051,332;2,409,184;609,162;-0,025341969
1,052,432;2,411,388;6,089,845;-0,02535197
105,353,212;2,413,584;60,877;-0,025331968
105,463,213;241,578;6,085,528;-0,025311967
1,055,732;241,798;6,083,689;-0,025371971
1,056,832;242,018;6,081,501;-0,025361971
1,057,932;2,422,376;6,079,443;-0,02535197
105,903,212;2,424,592;6,077,728;-0,025321968
106,013,213;2,426,788;6,074,994;-0,02535197
1,061,232;2,428,988;6,072,747;-0,025311967
1,062,332;2,431,188;6,070,805;-0,025341969
1,063,432;2,433,384;6,068,139;-0,025281964
106,453,212;2,435,576;6,065,668;-0,02535197
106,563,213;2,437,792;6,063,898;-0,025321968
1,066,732;2,439,976;6,060,914;-0,02535197
1,067,832;2,442,176;6,058,672;-0,025341969
1,068,932;2,444,384;6,056,561;-0,025341969
107,003,212;2,446,572;605,374;-0,02535197
107,113,213;244,876;605,139;-0,025311967
1,072,232;2,450,988;6,049,468;-0,025341969
1,073,332;2,453,184;6,046,134;-0,025321968
1,074,432;245,538;6,043,358;-0,02535197
107,553,212;2,457,584;6,041,034;-0,025341969
107,663,213;2,459,772;6,038,111;-0,025311967
1,077,732;2,461,964;6,035,262;-0,025371971
1,078,832;2,464,184;6,033,314;-0,025301966
1,079,932;2,466,376;6,029,611;-0,025341969
108,103,212;2,468,572;6,026,832;-0,025321968
108,213,213;2,470,784;6,024,014;-0,025321968
1,083,232;2,472,972;6,020,846;-0,02535197
1,084,332;2,475,172;6,017,925;-0,025321968
1,085,432;2,477,388;6,015,465;-0,025311967
108,653,212;2,479,588;6,012,039;-0,025311967
108,763,213;2,481,784;6,008,864;-0,02535197
1,088,732;2,483,992;6,005,553;-0,025371971
1,089,832;2,486,172;6,001,868;-0,025331968
1,090,932;2,488,368;5,998,647;-0,025311967
109,203,212;2,490,592;5,995,978;-0,025301966
109,313,213;2,492,788;5,992,248;-0,025331968
1,094,232;2,494,988;5,988,714;-0,02535197
1,095,332;2,497,192;5,985,698;-0,025321968
1,096,432;2,499,384;5,981,985;-0,025331968
109,753,212;2,501,576;5,978,372;-0,025361971
109,863,213;2,503,796;5,975,151;-0,025341969
1,099,732;25,06;5,971,641;-0,025331968
1,100,832;2,508,204;5,967,729;-0,025361971
1,101,932;2,510,388;5,963,769;-0,025331968
110,303,212;2,512,568;5,960,469;-0,025341969
110,413,213;2,514,776;5,957,251;-0,025301966
1,105,232;2,516,996;595,336;-0,025301966
1,106,332;2,519,196;5,949,231;-0,025341969
1,107,432;2,521,392;5,945,004;-0,025311967
110,853,212;25,236;5,941,136;-0,025311967
110,963,213;2,525,792;5,937,216;-0,025371971
1,110,732;2,527,992;5,933,583;-0,025331968
1,111,832;25,302;5,929,678;-0,025321968
1,112,932;25,324;592,546;-0,025291965
111,403,212;2,534,596;5,920,917;-0,025321968
111,513,213;25,368;5,916,563;-0,025321968
1,116,232;25,39;5,912,203;-0,025341969
1,117,332;2,541,192;5,907,821;-0,025331968
1,118,432;25,434;5,903,752;-0,025331968
111,953,212;25,456;5,899,423;-0,025321968
112,063,213;2,547,776;5,894,779;-0,025331968
1,121,732;2,549,972;5,890,215;-0,025341969
1,122,832;2,552,172;5,885,714;-0,025331968
1,123,932;2,554,376;5,881,171;-0,02535197
112,503,212;2,556,592;5,876,515;-0,02535197
112,613,213;2,558,788;5,871,755;-0,025331968
1,127,232;2,560,984;5,866,818;-0,025341969
1,128,332;256,318;5,861,984;-0,025331968
1,129,432;256,538;5,857,183;-0,025331968
113,053,212;2,567,588;5,852,405;-0,025301966
113,163,213;2,569,792;5,846,961;-0,025331968
1,132,732;2,571,992;584,192;-0,025321968
1,133,832;2,574,196;5,837,001;-0,025311967
1,134,932;2,576,392;5,831,671;-0,025341969
113,603,212;2,578,588;5,826,371;-0,025311967
113,713,213;25,808;5,821,766;-0,025341969
1,138,232;2,583,004;5,815,952;-0,025341969
1,139,332;2,585,204;5,810,354;-0,025341969
1,140,432;2,587,404;5,804,973;-0,025321968
114,153,212;25,896;5,799,305;-0,025331968
114,263,213;2,591,796;5,793,959;-0,025331968
1,143,732;2,594,008;5,788,577;-0,025331968
1,144,832;2,596,204;57,824;-0,025331968
1,145,932;2,598,404;5,776,651;-0,025331968
114,703,212;2,600,608;5,771,177;-0,025341969
114,813,213;2,602,804;5,764,738;-0,025311967
1,149,232;2,604,996;5,758,802;-0,02535197
1,150,332;2,607,216;5,753,326;-0,025321968
1,151,432;260,942;574,711;-0,025311967
115,253,212;2,611,624;5,740,739;-0,025381972
115,363,213;2,613,828;5,734,717;-0,025331968
1,154,732;2,616,016;5,727,892;-0,025321968
1,155,832;2,618,196;5,721,534;-0,025321968
1,156,932;2,620,424;5,715,659;-0,025341969
115,803,212;262,262;5,708,865;-0,025341969
115,913,213;2,624,824;5,702,035;-0,025341969
1,160,232;2,627,024;5,695,558;-0,02535197
1,161,332;2,629,216;568,875;-0,025341969
1,162,432;2,631,408;5,682,023;-0,025361971
116,353,212;2,633,628;5,675,312;-0,025311967
116,463,213;2,635,824;5,667,827;-0,025311967
1,165,732;2,638,036;5,660,648;-0,025301966
1,166,832;2,640,236;565,344;-0,02535197
1,167,932;2,642,404;5,646,241;-0,02535197
116,903,212;26,446;5,639,147;-0,025321968
117,013,213;2,646,824;5,632,352;-0,025341969
1,171,232;2,649,012;5,624,487;-0,025361971
1,172,332;2,651,216;5,616,913;-0,02535197
1,173,432;2,653,424;5,609,462;-0,02535197
117,453,212;2,655,616;5,601,335;-0,025321968
117,563,213;2,657,812;5,593,525;-0,025331968
1,176,732;2,660,028;5,586,206;-0,025381972
1,177,832;2,662,224;5,577,606;-0,025291965
1,178,932;266,442;5,569,786;-0,025311967
118,003,212;2,666,628;5,561,634;-0,025331968
118,113,213;2,668,828;5,552,927;-0,02535197
1,182,232;2,671,028;554,471;-0,025331968
1,183,332;267,324;5,536,681;-0,025361971
1,184,432;267,544;5,527,995;-0,025331968
118,553,212;267,762;5,518,988;-0,025291965
118,663,213;2,679,828;5,510,532;-0,025331968
1,187,732;2,682,024;5,501,903;-0,025371971
1,188,832;2,684,224;5,492,378;-0,025321968
1,189,932;268,644;5,483,814;-0,025331968
119,103,212;2,688,644;5,474,154;-0,025331968
119,213,213;2,690,832;5,464,963;-0,025361971
1,193,232;2,693,044;5,455,495;-0,025381972
1,194,332;269,524;5,446,181;-0,025361971
1,195,432;2,697,444;5,436,422;-0,025361971
119,653,212;2,699,652;5,426,739;-0,025311967
119,763,213;2,701,848;5,416,511;-0,025321968
1,198,732;270,404;5,406,574;-0,025331968
1,199,832;2,706,248;5,396,546;-0,02535197
1,200,932;2,708,448;5,386,428;-0,025311967
120,203,212;2,710,652;5,375,994;-0,025331968
120,313,213;2,712,868;5,365,602;-0,025331968
1,204,232;2,715,064;5,354,551;-0,025311967
1,205,332;2,717,252;5,343,819;-0,025331968
1,206,432;2,719,456;5,332,482;-0,025301966
120,753,212;2,721,652;5,321,321;-0,025341969
120,863,213;2,723,852;5,310,128;-0,02535197
1,209,732;2,726,056;5,298,512;-0,025301966
1,210,832;2,728,252;5,287,027;-0,025321968
1,211,932;2,730,448;5,275,463;-0,025321968
121,303,212;2,732,648;5,263,198;-0,025321968
121,413,213;2,734,844;5,250,803;-0,025321968
1,215,232;2,737,044;5,238,565;-0,025311967
1,216,332;273,926;5,225,909;-0,025301966
1,217,432;2,741,464;5,213,333;-0,025341969
121,853,212;274,366;5,200,236;-0,025321968
121,963,213;274,586;5,187,306;-0,025361971
1,220,732;2,748,048;5,173,724;-0,025361971
1,221,832;2,750,252;5,160,522;-0,025321968
1,222,932;275,246;5,146,202;-0,02535197
122,403,212;2,754,664;5,132,031;-0,025341969
122,513,213;2,756,868;5,118,134;-0,025361971
1,226,232;2,759,064;510,334;-0,025361971
1,227,332;2,761,268;5,088,857;-0,025321968
1,228,432;2,763,476;5,074,103;-0,025361971
122,953,212;2,765,676;50,583;-0,025341969
123,063,213;2,767,888;5,042,952;-0,025311967
1,231,732;27,701;5,027,194;-0,025361971
1,232,832;2,772,272;5,010,557;-0,025321968
1,233,932;2,774,468;4,994,753;-0,025341969
123,503,212;2,776,688;4,978,594;-0,025311967
123,613,213;2,778,888;4,961,153;-0,02535197
1,237,232;2,781,088;4,944,105;-0,025331968
1,238,332;27,833;4,926,691;-0,02535197
1,239,432;2,785,488;4,908,308;-0,025341969
124,053,212;2,787,684;4,889,986;-0,025311967
124,163,213;2,789,896;4,871,913;-0,025331968
1,242,732;2,792,092;4,852,413;-0,025331968
1,243,832;2,794,288;4,832,885;-0,025361971
1,244,932;2,796,496;4,813,241;-0,025341969
124,603,212;27,987;4,792,601;-0,02535197
124,713,213;2,800,896;4,771,233;-0,025371971
1,248,232;2,803,112;4,749,711;-0,025341969
1,249,332;2,805,308;472,748;-0,025371971
1,250,432;2,807,512;4,704,641;-0,025321968
125,153,212;2,809,708;4,681,707;-0,025311967
125,263,213;2,811,904;4,657,177;-0,02535197
1,253,732;28,141;4,628,107;-0,02535197
1,254,086;2,814,892;4,104,604;-0,025621991
1,254,098;2,815,012;2,632,115;-0,027812161