File: tensile_test_ontology_TTO/data/primary_data/Zy1.csv
Time;Crosshead travel;Force;Strain
(s);(mm);(kN);(%)
0;0;0,26954;0
0,912;0,04632;0,88486;0,00277176
1,436;0,11796;190,293;0,006944409
1,898;0,20552;292,717;0,011097046
2,276;0,2932;39,555;0,015249682
2,578;0,37236;498,085;0,019402319
2,846;0,44752;601,986;0,023614993
3,09;0,51952;70,592;0,027777636
3,326;0,59168;811,688;0,032000317
3,56;0,66572;917,562;0,036172966
3,78;0,73752;1,021,477;0,040355622
4,006;0,8132;1,125,372;0,044478239
4,238;0,89336;1,230,304;0,048580844
4,448;0,96736;1,335,692;0,052773506
4,648;103,904;1,440,801;0,056836085
4,848;111,152;1,549,086;0,061078779
5,04;118,196;1,655,427;0,065261434
5,22;124,812;1,757,364;0,069314007
5,4;131,464;1,861,029;0,073346568
5,58;138,136;1,966,143;0,077369122
5,76;144,836;2,073,499;0,081721885
5,94;151,524;2,180,545;0,085894534
6,12;158,232;229,057;0,090087196
6,3;164,928;2,401,124;0,094479985
6,468;171,192;2,505,673;0,098622615
6,64;177,532;2,612,492;0,102875316
6,814;18,396;2,720,451;0,10719806
6,974;18,984;2,821,718;0,111260639
7,142;19,596;2,926,999;0,115573378
7,31;202,072;3,032,121;0,11984609
7,478;208,112;3,137,501;0,124408987
7,652;214,328;3,245,611;0,128911846
7,832;220,692;3,357,248;0,133754921
8,01;22,692;3,467,102;0,138608002
8,19;23,314;3,575,633;0,143621185
8,37;239,288;3,684,187;0,148714419
8,55;245,328;3,790,256;0,153847678
8,73;251,264;3,894,046;0,158940912
8,912;257,132;3,997,402;0,16440438
9,108;263,324;4,104,517;0,170027951
9,308;26,948;4,209,139;0,175981731
9,52;275,832;4,313,663;0,182786051
9,756;28,258;4,418,991;0,190200758
10,024;289,952;4,523,557;0,198315911
10,396;29,968;4,626,624;0,210753808
11,268;31,754;4,669,252;0,248127536
12,268;327,716;4,693,024;0,283049708
13,268;333,884;4,715,622;0,311257617
14,268;339,208;4,741,492;0,337284142
15,268;343,436;4,759,278;0,362760317
16,268;3,476;4,781,115;0,388196466
17,268;350,892;47,887;0,413572577
18,268;35,412;4,802,087;0,438758568
19,268;357,356;4,812,166;0,46462499
20,268;359,988;4,813,797;0,489700911
21,268;362,468;4,815,503;0,514576705
22,268;365,016;4,813,471;0,540403102
23,268;367,176;4,812,929;0,564978705
24,268;369,272;4,811,849;0,590114664
25,268;371,524;4,814,794;0,61586101
26,268;373,228;4,806,556;0,640546683
27,268;37,502;4,804,999;0,665802718
28,268;37,668;4,802,604;0,690638486
29,268;378,356;480,197;0,715914534
30,268;379,936;4,800,673;0,740580194
31,268;381,528;4,801,958;0,765636102
32,268;383,084;4,802,378;0,790651985
33,268;384,624;4,803,393;0,815948045
34,268;386,032;4,799,818;0,841114023
35,268;38,752;4,802,197;0,86567962
36,268;388,996;4,803,469;0,890795566
37,268;390,368;4,800,737;0,915741404
38,268;391,808;480,096;0,941197566
39,268;393,136;4,798,078;0,965783176
40,268;3,945;4,796,604;0,990839084
41,268;39,584;4,794,782;1,015,774,915
42,268;39,722;4,794,918;1,040,780,792
43,268;398,568;4,793,293;1,066,226,947
44,268;399,888;4,791,563;109,102,269
45,268;401,564;480,208;1,112,866,559
46,268;402,624;4,780,509;114,134,464
47,268;404,244;4,795,092;1,166,620,687
48,268;405,468;4,789,969;1,191,126,246
49,268;406,808;4,790,168;1,216,182,154
50,268;408,156;4,791,548;1,240,927,865
51,268;409,492;4,792,045;1,265,603,532
52,268;410,864;4,792,143;1,291,059,694
53,268;412,196;4,792,446;1,316,075,576
54,268;413,532;4,792,954;1,341,001,402
55,268;414,896;4,793,541;136,627,745
56,268;416,224;4,793,732;1,390,933,103
57,268;417,604;4,795,331;1,416,259,183
58,268;418,944;4,795,822;144,112,497
59,268;420,284;4,796,178;146,601,077
60,268;421,576;4,794,189;1,491,206,767
61,268;422,756;4,786,335;1,516,482,815
62,268;423,824;4,772,976;154,206,906
63,268;424,812;475,801;156,695,486
64,268;425,952;4,751,925;1,591,540,469
65,268;427,304;475,634;1,616,296,186
6,626,801;428,824;4,768,517;1,641,262,037
6,726,801;430,472;4,785,817;1,666,397,996
6,826,801;432,144;4,802,829;1,691,143,707
6,926,801;433,864;4,820,499;1,715,349,075
7,026,801;435,632;4,836,281;174,019,485
7,126,801;437,524;4,852,029;1,765,731,063
7,226,801;439,336;4,863,254;1,790,446,755
7,326,801;441,264;4,875,462;1,815,582,713
7,426,801;443,236;488,732;1,840,358,444
7,526,801;445,204;4,895,926;1,865,184,205
7,626,801;44,726;4,906,217;1,890,009,967
7,726,801;449,344;4,915,307;1,914,725,659
7,826,801;451,604;492,456;193,788,036
7,926,801;453,936;4,930,634;1,965,107,647
8,026,801;456,208;4,942,053;1,989,673,244
8,126,801;4,585;4,949,325;2,014,609,075
8,226,801;46,088;4,958,172;2,039,664,983
8,326,801;463,292;4,966,804;2,064,520,764
8,426,801;465,752;497,478;2,089,586,679
8,526,801;46,826;4,983,383;2,114,612,568
8,626,801;470,804;4,991,819;2,139,538,393
8,726,801;473,604;5,002,286;2,164,744,396
8,826,801;476,124;5,009,605;2,189,330,006
8,926,801;478,704;5,016,487;2,214,495,983
9,026,801;481,304;5,024,304;2,239,551,891
9,126,801;483,948;5,033,088;2,264,657,831
9,226,801;486,576;5,041,627;2,289,493,599
9,326,801;489,256;5,050,865;2,314,519,488
9,426,801;49,198;5,059,019;2,337,684,196
9,526,801;494,716;5,064,064;2,364,571,266
9,626,801;497,388;50,732;2,389,517,104
9,726,801;500,052;5,081,323;2,414,522,981
9,826,801;502,768;5,090,392;2,439,658,939
9,926,801;505,408;5,096,746;2,464,614,784
10,026,801;508,032;5,103,887;2,489,350,489
10,126,801;510,716;5,112,024;2,514,066,181
10,226,801;513,636;5,126,335;253,769,118
10,326,801;516,352;5,126,839;2,564,338,098
10,426,801;519,032;5,135,223;2,589,033,778
10,526,801;5,217;514,274;2,613,989,622
10,626,801;524,348;5,149,159;2,638,875,422
10,726,801;527,004;5,156,556;2,663,901,311
10,826,801;529,752;5,164,664;2,689,267,416
10,926,801;532,488;5,172,738;2,714,373,356
11,026,801;53,548;5,185,503;2,739,389,238
11,126,801;538,012;5,184,879;2,764,285,045
11,226,801;540,652;5,192,436;2,789,050,768
11,326,801;543,348;5,199,299;2,814,376,848
11,426,801;54,602;5,206,581;283,942,275
11,526,801;548,708;5,213,742;286,449,867
11,626,801;55,136;5,220,447;2,889,244,381
11,726,801;55,406;5,227,855;2,914,340,315
11,826,801;556,936;523,421;2,939,976,591
11,926,801;55,954;5,240,519;2,964,862,391
12,026,801;562,192;5,246,503;2,990,188,471
12,126,801;564,732;5,252,471;3,014,493,902
12,226,801;567,404;5,261,146;3,039,509,785
12,326,801;570,028;5,265,791;3,064,815,852
12,426,801;572,664;5,272,272;3,089,691,645
12,526,801;575,552;5,285,162;3,113,897,013
12,626,801;57,812;5,284,202;3,139,793,455
12,726,801;580,796;5,292,533;316,471,928
12,826,801;58,342;5,297,239;318,982,522
12,926,801;58,604;5,303,238;321,471,102
13,026,801;588,676;5,309,396;3,239,736,909
131,268;591,296;5,315,679;3,264,682,747
132,268;59,396;5,322,665;3,289,638,592
133,268;596,832;533,156;3,314,834,588
134,268;599,336;533,326;333,947,023
135,268;601,956;5,338,616;336,454,615
136,268;604,552;5,344,977;3,389,391,925
137,268;60,718;535,173;3,414,517,877
138,268;609,768;5,356,708;3,439,593,798
139,268;612,372;5,362,226;3,464,449,579
140,268;615,224;5,374,157;3,488,664,953
141,268;617,764;5,372,284;3,514,641,446
142,268;620,404;5,379,825;3,539,837,443
143,268;622,944;538,455;3,564,733,249
144,268;625,468;5,389,335;3,589,549,005
145,268;628,036;5,394,804;3,614,654,944
146,268;630,612;5,400,393;3,639,530,738
147,268;6,333;5,407,723;3,664,726,735
148,268;636,024;5,410,835;3,690,112,853
149,268;638,544;5,415,808;3,714,798,526
150,268;641,084;5,420,519;3,739,694,332
151,268;643,648;5,426,217;3,764,560,119
152,268;646,288;5,432,814;3,789,736,103
153,268;648,832;5,436,189;3,814,671,935
154,268;651,448;5,441,844;3,839,507,703
155,268;654,244;5,447,416;386,492,384
15,611,402;655,052;5,424,973;3,876,871,426
15,711,402;657,048;5,440,235;3,894,212,435
15,811,402;659,068;5,446,918;3,913,064,405
15,911,402;661,056;545,086;3,932,236,577
16,011,402;663,064;545,468;3,951,448,775
16,111,402;66,508;5,458,468;3,970,460,846
18,544,802;666,424;5,333,068;-0,035472522
18,644,802;668,408;5,409,017;-0,035502541
18,744,802;670,392;5,453,686;-0,035502541
18,844,802;672,408;5,472,915;-0,035542566
18,944,802;674,404;5,480,394;-0,035572585
19,044,802;676,404;5,484,559;-0,035582591
19,144,802;678,408;5,487,368;-0,03553256
19,244,802;6,804;5,489,659;-0,035562579
19,344,802;6,824;5,492,641;-0,035572585
19,444,802;684,404;5,495,881;-0,035562579
19,544,802;686,408;5,498,787;-0,035552572
19,644,802;688,404;5,502,025;-0,035522553
19,744,802;690,416;5,505,037;-0,035562579
19,844,802;69,242;5,507,796;-0,035512547
19,944,802;694,392;5,509,914;-0,035522553
20,044,802;69,638;5,513,126;-0,035572585
20,144,802;6,984;5,516,489;-0,035512547
20,244,802;7,004;5,517,286;-0,035512547
20,344,802;7,024;5,521,052;-0,035562579
20,444,802;704,404;5,524,399;-0,035562579
20,544,802;706,392;5,527,116;-0,035552572
20,644,802;708,392;5,530,116;-0,035552572
20,744,802;7,104;5,532,834;-0,035592598
20,844,802;712,404;5,535,409;-0,03553256
20,944,802;714,404;5,538,716;-0,035562579
21,044,802;716,396;5,541,399;-0,035562579
21,144,802;718,404;5,544,369;-0,035582591
21,244,802;720,404;5,547,327;-0,035572585
21,344,802;722,404;5,550,084;-0,035572585
21,444,802;724,416;5,553,146;-0,035552572
21,544,802;7,264;555,555;-0,035582591
21,644,802;728,404;5,558,504;-0,035582591
21,744,802;730,408;5,562,111;-0,035552572
21,844,802;732,404;5,564,598;-0,035562579
21,944,802;7,344;5,567,822;-0,035542566
22,044,802;736,404;5,570,752;-0,035582591
22,144,802;738,408;5,573,564;-0,03553256
22,244,802;740,412;5,576,645;-0,035552572
22,344,802;742,404;5,579,084;-0,03553256
22,444,802;744,404;5,582,061;-0,035522553
22,544,802;7,464;558,481;-0,035552572
22,644,802;748,396;5,587,841;-0,035512547
22,744,802;750,404;5,590,876;-0,03553256
22,844,802;752,396;5,593,475;-0,035592598
22,944,802;754,392;5,596,308;-0,03553256
23,044,802;756,392;5,599,539;-0,035552572
23,144,802;758,388;5,602,195;-0,035542566
23,244,802;760,392;5,605,333;-0,035552572
23,344,802;762,392;5,608,263;-0,035502541
23,444,802;764,404;5,610,884;-0,035522553
23,544,802;766,408;5,613,901;-0,035512547
23,644,802;7,684;5,616,295;-0,035552572
23,744,802;770,396;5,619,116;-0,03553256
23,844,802;772,388;5,621,841;-0,035522553
23,944,802;774,384;5,624,697;-0,03553256
24,044,802;7,764;5,627,943;-0,035562579
24,144,802;778,396;5,630,285;-0,035542566
24,244,802;780,388;563,287;-0,035562579
24,344,802;782,392;5,635,504;-0,035542566
24,444,802;78,438;5,638,101;-0,035512547
24,544,802;78,638;5,640,914;-0,03553256
24,644,802;78,838;564,373;-0,03553256
24,744,802;790,388;5,646,412;-0,035512547
24,844,802;792,388;5,649,347;-0,035482528
24,944,802;794,388;5,651,689;-0,035492534
25,044,802;796,396;5,654,472;-0,035522553
25,144,802;798,384;5,656,773;-0,035542566
25,244,802;80,038;5,659,074;-0,035502541
25,344,802;802,388;5,662,266;-0,03553256
25,444,802;804,384;5,664,592;-0,035512547
25,544,802;806,384;5,667,347;-0,035492534
256,448;808,388;5,670,319;-0,035512547
257,448;810,384;5,672,157;-0,035482528
258,448;812,384;5,675,308;-0,035502541
259,448;814,388;5,677,544;-0,035522553
260,448;8,164;5,680,131;-0,035492534
261,448;818,392;5,682,264;-0,03553256
262,448;820,388;5,684,951;-0,035512547
263,448;822,408;5,687,741;-0,035492534
264,448;824,396;5,689,695;-0,035472522
265,448;826,368;5,692,024;-0,035502541
266,448;828,388;5,695,094;-0,035502541
267,448;830,388;5,697,287;-0,035542566
268,448;832,388;5,699,423;-0,035522553
269,448;834,388;570,217;-0,035512547
270,448;836,384;5,704,192;-0,035542566
271,448;83,838;5,706,894;-0,035562579
272,448;84,038;5,709,288;-0,035522553
273,448;842,392;5,711,914;-0,035552572
274,448;844,384;5,713,908;-0,035452509
275,448;84,638;5,715,873;-0,035512547
276,448;848,384;571,865;-0,035482528
277,448;85,038;5,720,663;-0,035522553
278,448;85,238;5,723,099;-0,035562579
279,448;854,396;5,725,795;-0,03553256
28,044,803;856,376;5,727,614;-0,035452509
28,144,803;858,376;5,730,384;-0,03553256
28,244,803;860,384;5,732,878;-0,035522553
28,344,803;862,372;5,734,699;-0,035502541
28,444,803;864,376;5,737,056;-0,035522553
28,544,803;866,372;5,739,223;-0,035572585
28,644,803;86,838;5,741,391;-0,035512547
28,744,803;870,376;5,743,631;-0,035502541
28,844,803;872,372;5,745,793;-0,035542566
28,944,803;87,438;5,748,207;-0,035482528
29,044,803;876,368;5,750,437;-0,035512547
29,144,803;878,372;5,752,404;-0,035472522
29,244,803;88,038;575,516;-0,035512547
29,344,803;882,376;5,756,549;-0,035542566
29,444,803;884,376;5,758,944;-0,035552572
29,544,803;886,368;576,102;-0,035512547
29,644,803;88,836;5,762,821;-0,035552572
29,744,803;890,368;5,765,539;-0,035552572
29,844,803;89,236;576,753;-0,035472522
29,944,803;894,372;5,770,048;-0,035542566
30,044,803;896,376;5,771,814;-0,035552572
30,144,803;898,376;5,773,766;-0,035502541
30,244,803;90,038;5,775,899;-0,035512547
30,344,803;902,364;5,777,532;-0,03553256
30,444,803;904,368;5,779,822;-0,03553256
30,544,803;906,376;5,782,236;-0,035542566
30,644,803;908,372;5,784,057;-0,035552572
30,744,803;91,038;5,786,117;-0,035522553
30,844,803;912,372;5,788,048;-0,035562579
30,944,803;914,372;5,789,674;-0,035512547
31,044,803;916,372;579,196;-0,03553256
31,144,803;918,368;5,793,814;-0,035512547
31,244,803;92,038;5,795,938;-0,035512547
31,344,803;92,238;5,797,827;-0,03553256
31,444,803;92,438;57,998;-0,035542566
31,544,803;926,388;5,801,959;-0,035542566
31,644,803;928,376;5,803,366;-0,035522553
31,744,803;930,368;5,805,259;-0,035512547
31,844,803;932,376;5,807,452;-0,03553256
31,944,803;934,368;5,809,149;-0,035482528
32,044,803;936,376;5,811,412;-0,035522553
32,144,803;938,372;581,331;-0,035512547
32,244,803;940,368;5,815,075;-0,035512547
32,344,803;942,372;5,817,108;-0,035492534
32,444,803;944,368;5,818,863;-0,035492534
32,544,803;94,638;5,820,791;-0,035512547
32,644,803;948,368;5,822,485;-0,035482528
32,744,803;950,376;5,824,255;-0,03553256
32,844,803;9,524;5,826,765;-0,035492534
32,944,803;954,392;582,765;-0,035492534
33,044,803;956,356;5,828,925;-0,035542566
33,144,803;958,368;5,832,091;-0,035512547
33,244,803;960,372;5,833,797;-0,035512547
33,344,803;962,376;5,835,648;-0,03553256
33,444,803;964,376;5,837,313;-0,035512547
33,544,803;966,376;5,838,995;-0,035512547
33,644,803;968,376;5,840,799;-0,035502541
33,744,803;970,368;5,842,537;-0,035522553
33,844,803;97,238;5,844,531;-0,035502541
33,944,803;97,438;5,846,184;-0,03553256
34,044,803;976,372;5,847,608;-0,035542566
34,144,803;978,384;5,849,714;-0,035542566
34,244,803;980,372;5,851,319;-0,035492534
34,344,803;982,376;5,853,052;-0,035492534
34,444,803;984,392;5,855,201;-0,035522553
34,544,803;98,638;5,856,043;-0,035502541
34,644,803;988,384;5,858,055;-0,035522553
34,744,803;990,376;5,859,569;-0,035502541
34,844,803;992,368;5,860,929;-0,035522553
34,944,803;99,436;586,279;-0,035462515
35,044,803;996,356;5,864,567;-0,035502541
35,144,803;998,372;586,657;-0,035472522
35,244,803;1,000,372;5,868,012;-0,035492534
35,344,803;1,002,372;5,869,631;-0,035502541
35,444,803;100,438;5,871,617;-0,03553256
35,544,803;1,006,368;5,872,893;-0,035522553
35,644,803;1,008,364;5,874,598;-0,035492534
35,744,803;1,010,372;587,675;-0,035542566
35,844,803;1,012,376;5,878,065;-0,035472522
35,944,803;101,438;5,879,599;-0,035502541
36,044,803;1,016,364;5,880,733;-0,035522553
36,144,803;1,018,368;5,882,261;-0,035452509
36,244,803;1,020,364;5,883,948;-0,035522553
36,344,803;1,022,364;5,885,429;-0,035472522
36,444,803;1,024,376;588,724;-0,035502541
36,544,803;1,026,368;5,888,698;-0,035492534
36,644,803;1,028,372;5,890,252;-0,035472522
36,744,803;1,030,376;5,892,174;-0,035452509
36,844,803;103,236;5,892,983;-0,035492534
36,944,803;1,034,352;5,894,738;-0,035482528
37,044,803;1,036,364;5,896,648;-0,035492534
37,144,803;103,836;5,898,114;-0,035472522
37,244,803;1,040,364;5,899,966;-0,035472522
37,344,803;104,236;5,901,073;-0,035472522
37,444,803;104,436;5,902,691;-0,035482528
37,544,803;104,636;5,904,012;-0,035482528
37,644,803;1,048,356;5,905,457;-0,035472522
37,744,803;1,050,372;5,907,296;-0,035452509
37,844,803;1,052,364;5,908,481;-0,035512547
37,944,803;1,054,372;5,910,074;-0,035482528
38,044,803;1,056,388;5,911,934;-0,035442502
38,144,803;1,058,376;5,913,023;-0,035482528
38,244,803;1,060,368;59,144;-0,035472522
38,344,803;1,062,364;5,916,189;-0,035482528
38,444,803;106,436;5,917,245;-0,035502541
38,544,803;1,066,368;5,918,927;-0,035472522
38,644,803;106,836;5,920,023;-0,035472522
38,744,803;107,036;5,921,464;-0,035492534
38,844,803;1,072,356;592,297;-0,035442502
38,944,803;1,074,348;5,924,239;-0,035512547
39,044,803;107,636;592,626;-0,035472522
39,144,803;1,078,356;5,927,165;-0,035452509
39,244,803;1,080,356;5,928,547;-0,035502541
39,344,803;108,238;5,930,445;-0,035512547
39,444,803;1,084,376;5,931,156;-0,035472522
39,544,803;1,086,364;5,932,302;-0,035462515
39,644,803;1,088,344;5,933,911;-0,035522553
39,744,803;1,090,356;5,935,736;-0,035432496
39,844,803;1,092,364;5,937,145;-0,035452509
39,944,803;109,436;5,938,016;-0,035492534
40,044,803;1,096,364;5,938,988;-0,035472522
40,144,803;109,836;5,940,384;-0,035482528
40,244,803;110,036;5,941,525;-0,035472522
40,344,803;1,102,372;5,943,086;-0,035492534
40,444,803;1,104,364;5,944,043;-0,035472522
40,544,803;1,106,364;5,945,476;-0,035482528
40,644,803;1,108,372;5,947,194;-0,035482528
40,744,803;1,110,356;5,947,832;-0,035522553
40,844,803;1,112,364;5,949,172;-0,035522553
40,944,803;1,114,368;5,950,571;-0,035472522
41,044,803;1,116,376;5,951,884;-0,035492534
41,144,803;1,118,368;5,953,044;-0,035472522
41,244,803;1,120,356;5,954,168;-0,035472522
41,344,803;1,122,364;5,955,757;-0,035492534
41,444,803;1,124,348;5,956,908;-0,03553256
41,544,803;112,634;5,958,163;-0,035502541
41,644,803;1,128,356;5,959,716;-0,035462515
41,744,803;1,130,344;596,036;-0,035472522
41,844,803;1,132,356;5,961,697;-0,035482528
41,944,803;113,436;5,963,248;-0,035512547
42,044,803;1,136,344;596,399;-0,035452509
42,144,803;1,138,344;5,965,375;-0,035472522
42,244,803;1,140,348;5,966,919;-0,035472522
42,344,803;114,236;5,968,027;-0,035492534
42,444,803;1,144,356;5,969,065;-0,035492534
42,544,803;1,146,352;5,969,779;-0,035462515
42,644,803;1,148,352;5,971,122;-0,035462515
42,744,803;1,150,352;5,972,338;-0,035472522
42,844,803;1,152,352;5,973,583;-0,035482528
42,944,803;1,154,372;5,975,065;-0,035462515
43,044,803;1,156,364;5,975,839;-0,035432496
43,144,803;1,158,368;5,977,259;-0,035432496
43,244,803;116,038;5,978,316;-0,035452509
43,344,803;1,162,356;5,979,034;-0,035462515
43,444,803;116,436;5,980,375;-0,035432496
43,544,803;1,166,364;5,981,662;-0,035442502
43,644,803;1,168,368;5,982,633;-0,035462515
43,744,803;1,170,364;5,983,804;-0,035472522
43,844,803;117,236;5,984,748;-0,035452509
43,944,803;117,436;598,608;-0,035492534
44,044,803;1,176,348;5,986,987;-0,035482528
44,144,803;1,178,348;598,789;-0,035412483
44,244,803;1,180,364;5,989,397;-0,035472522
44,344,803;118,236;5,990,081;-0,03542249
44,444,803;1,184,368;5,991,335;-0,035442502
44,544,803;1,186,376;5,992,653;-0,035462515
44,644,803;1,188,372;5,993,381;-0,035482528
44,744,803;1,190,356;5,994,298;-0,035452509
44,844,803;1,192,364;599,558;-0,035442502
44,944,803;119,436;5,996,321;-0,035492534
45,044,803;1,196,364;5,997,458;-0,035452509
45,144,803;1,198,356;5,998,186;-0,035442502
45,244,803;120,036;5,999,533;-0,035432496
45,344,803;1,202,348;600,044;-0,035492534
45,444,803;1,204,348;6,001,516;-0,035442502
45,544,803;1,206,368;6,003,268;-0,035462515
45,644,803;1,208,364;6,003,861;-0,03542249
45,744,803;1,210,364;6,004,568;-0,035442502
45,844,803;1,212,368;6,005,979;-0,035462515
45,944,803;1,214,376;6,006,793;-0,035442502
46,044,803;1,216,376;6,007,712;-0,035482528
46,144,803;1,218,348;6,008,182;-0,035482528
46,244,803;122,036;6,009,689;-0,035452509
46,344,803;1,222,364;6,010,922;-0,035442502
46,444,803;1,224,356;6,011,592;-0,03542249
46,544,803;1,226,364;6,012,587;-0,035462515
46,644,803;1,228,356;6,013,376;-0,035502541
46,744,803;1,230,352;6,014,251;-0,035432496
46,844,803;1,232,368;6,015,673;-0,035402477
46,944,803;1,234,356;6,016,141;-0,035452509
47,044,803;1,236,356;60,172;-0,035482528
47,144,803;1,238,352;6,018,353;-0,035472522
47,244,803;124,034;6,019,071;-0,035452509
47,344,803;1,242,344;6,020,198;-0,035492534
47,444,803;1,244,348;6,021,289;-0,035462515
47,544,803;1,246,368;6,022,379;-0,035442502
47,644,803;1,248,356;6,022,649;-0,035482528
47,744,803;1,250,348;6,023,399;-0,035482528
47,844,803;1,252,356;6,024,724;-0,035482528
47,944,803;1,254,348;6,025,326;-0,035482528
48,044,803;125,634;6,026,273;-0,035442502
48,144,803;125,836;6,027,727;-0,035432496
48,244,803;1,260,352;6,028,026;-0,035452509
48,344,803;1,262,356;6,028,996;-0,035462515
48,444,803;126,436;6,029,727;-0,035432496
48,544,803;1,266,352;6,030,499;-0,035462515
48,644,803;1,268,352;6,031,421;-0,035482528
48,744,803;1,270,348;6,032,175;-0,035462515
48,844,803;1,272,364;603,339;-0,035492534
48,944,803;127,436;6,034,054;-0,035452509
49,044,803;1,276,348;6,034,951;-0,035522553
49,144,803;1,278,352;6,035,782;-0,035462515
49,244,803;128,034;603,636;-0,035482528
49,344,803;1,282,344;6,037,281;-0,035472522
49,444,803;1,284,364;6,038,662;-0,035452509
49,544,803;128,636;6,039,041;-0,035442502
49,644,803;1,288,364;6,040,136;-0,035472522
49,744,803;1,290,368;6,041,098;-0,035462515
49,844,803;1,292,356;6,041,481;-0,035452509
49,944,803;1,294,356;6,042,472;-0,035492534
50,044,803;1,296,352;6,043,058;-0,035442502
50,144,803;1,298,364;6,044,065;-0,035472522
50,244,803;130,036;604,442;-0,035472522
50,344,803;1,302,356;6,045,088;-0,035472522
50,444,803;130,436;6,046,153;-0,035452509
50,544,803;1,306,348;6,046,718;-0,035462515
50,644,803;1,308,344;6,047,668;-0,035482528
50,744,803;1,310,364;6,048,869;-0,035472522
50,844,803;131,236;604,894;-0,035502541
50,944,803;1,314,368;604,986;-0,035482528
51,044,803;1,316,364;6,050,594;-0,035492534
51,144,803;1,318,364;6,051,082;-0,035472522
512,448;132,036;6,052,073;-0,035472522
513,448;1,322,352;6,052,866;-0,035492534
514,448;132,436;6,053,824;-0,035492534
515,448;1,326,352;6,054,559;-0,035482528
516,448;1,328,356;6,054,949;-0,035452509
517,448;1,330,368;6,056,068;-0,035442502
518,448;1,332,356;6,056,195;-0,035472522
519,448;1,334,352;6,057,073;-0,035512547
520,448;1,336,372;6,058,336;-0,035452509
521,448;1,338,372;6,058,526;-0,035472522
522,448;1,340,368;6,059,426;-0,035482528
523,448;134,236;6,059,949;-0,035482528
524,448;1,344,372;6,060,994;-0,035452509
525,448;134,638;6,061,403;-0,035512547
526,448;1,348,352;6,061,334;-0,035482528
527,448;1,350,364;6,062,734;-0,035512547
528,448;135,236;6,063,412;-0,035482528
529,448;1,354,364;6,063,997;-0,035502541
530,448;1,356,372;6,065,065;-0,035462515
531,448;1,358,356;6,065,468;-0,035452509
532,448;1,360,356;6,065,964;-0,035492534
533,448;1,362,372;6,066,993;-0,035492534
534,448;1,364,368;6,067,096;-0,035502541
535,448;1,366,368;6,067,888;-0,035492534
536,448;1,368,368;6,068,326;-0,035512547
537,448;1,370,356;6,068,792;-0,035452509
538,448;1,372,356;6,069,703;-0,035462515
539,448;1,374,356;6,070,435;-0,035452509
540,448;1,376,372;6,071,395;-0,035452509
541,448;1,378,368;6,071,538;-0,035442502
542,448;1,380,356;607,205;-0,035492534
543,448;1,382,368;607,326;-0,035562579
544,448;1,384,356;607,344;-0,035442502
545,448;1,386,356;6,074,076;-0,035492534
546,448;1,388,364;6,075,206;-0,035462515
547,448;139,036;607,544;-0,035502541
548,448;139,236;6,076,128;-0,035482528
549,448;1,394,356;607,686;-0,035522553
550,448;1,396,356;6,077,292;-0,035512547
551,448;1,398,352;6,077,845;-0,035492534
552,448;1,400,352;6,078,339;-0,035462515
553,448;1,402,372;6,079,382;-0,035472522
554,448;1,404,364;6,079,449;-0,035512547
555,448;1,406,356;6,080,062;-0,035472522
556,448;140,836;608,128;-0,035472522
557,448;1,410,344;6,081,429;-0,035492534
558,448;141,234;6,082,156;-0,035462515
559,448;1,414,356;6,083,078;-0,035442502
560,448;1,416,352;6,083,152;-0,035442502
561,448;1,418,356;6,083,923;-0,035482528
562,448;1,420,348;6,084,191;-0,035452509
563,448;1,422,352;6,084,648;-0,035472522
564,448;142,434;6,085,157;-0,035492534
565,448;1,426,332;6,085,736;-0,035492534
566,448;1,428,352;6,086,652;-0,035462515
567,448;1,430,344;608,687;-0,035492534
568,448;143,234;6,087,064;-0,035472522
569,448;1,434,352;6,088,182;-0,035492534
570,448;143,634;6,088,135;-0,035432496
571,448;1,438,344;6,088,942;-0,035472522
572,448;1,440,352;6,089,725;-0,035522553
573,448;1,442,352;6,089,782;-0,035432496
574,448;1,444,356;6,090,711;-0,035502541
575,448;1,446,356;6,090,859;-0,03553256
576,448;1,448,364;6,091,394;-0,035442502
577,448;1,450,364;6,091,812;-0,035482528
578,448;1,452,356;6,092,145;-0,035492534
579,448;1,454,368;6,093,068;-0,035462515
580,448;1,456,352;6,093,301;-0,035492534
581,448;1,458,356;6,093,875;-0,035432496
582,448;146,036;609,475;-0,03553256
583,448;1,462,348;6,094,974;-0,035462515
584,448;1,464,348;6,095,424;-0,035482528
585,448;1,466,356;6,096,141;-0,035472522
586,448;1,468,364;6,096,437;-0,035442502
587,448;147,036;6,096,823;-0,035452509
588,448;1,472,352;609,698;-0,035462515
589,448;147,436;6,097,904;-0,035452509
590,448;147,636;6,098,624;-0,035462515
591,448;1,478,344;6,098,534;-0,035432496
592,448;1,480,336;609,929;-0,035492534
593,448;1,482,336;6,099,393;-0,035482528
594,448;1,484,344;6,100,138;-0,035472522
595,448;1,486,356;6,100,745;-0,035462515
596,448;1,488,344;6,100,622;-0,035452509
597,448;1,490,348;6,101,466;-0,035472522
598,448;1,492,348;6,102,028;-0,035482528
599,448;1,494,352;6,102,478;-0,035452509
600,448;1,496,356;6,102,818;-0,035492534
60,144,806;1,498,344;610,288;-0,035432496
60,244,806;1,500,352;6,103,189;-0,035492534
60,344,806;1,502,344;6,103,617;-0,035452509
60,444,806;150,434;6,104,097;-0,035472522
60,544,806;1,506,368;6,105,029;-0,035482528
60,644,806;1,508,364;6,105,093;-0,035462515
60,744,806;1,510,344;6,105,041;-0,035482528
60,844,806;1,512,352;6,106,137;-0,035462515
60,944,806;1,514,344;6,106,031;-0,035472522
61,044,806;1,516,344;6,106,558;-0,035482528
61,144,806;1,518,344;6,106,996;-0,035432496
61,244,806;1,520,352;6,107,354;-0,035442502
61,344,806;1,522,352;6,107,817;-0,035462515
61,444,806;1,524,344;6,108,025;-0,035472522
61,544,806;1,526,352;6,108,698;-0,035502541
61,644,806;1,528,344;6,108,769;-0,035452509
61,744,806;1,530,336;6,109,103;-0,035462515
61,844,806;1,532,364;6,109,924;-0,035502541
61,944,806;153,436;6,109,878;-0,035502541
62,044,806;153,636;6,110,036;-0,035492534
62,144,806;1,538,364;611,064;-0,035462515
62,244,806;1,540,348;6,110,799;-0,035462515
62,344,806;1,542,348;6,111,459;-0,035542566
62,444,806;1,544,352;6,112,118;-0,035472522
62,544,806;1,546,364;6,111,907;-0,035482528
62,644,806;154,836;6,112,382;-0,035482528
62,744,806;1,550,352;6,112,528;-0,035482528
62,844,806;1,552,364;611,313;-0,035482528
62,944,806;1,554,352;6,113,208;-0,035492534
63,044,806;1,556,344;6,113,495;-0,035482528
63,144,806;155,836;6,114,507;-0,035482528
63,244,806;1,560,348;6,114,221;-0,035472522
63,344,806;1,562,348;6,114,863;-0,035442502
63,444,806;1,564,356;6,115,195;-0,03542249
63,544,806;1,566,348;611,534;-0,035482528
63,644,806;1,568,348;6,115,714;-0,035462515
63,744,806;1,570,348;6,116,079;-0,035502541
63,844,806;157,236;6,116,346;-0,035452509
63,944,806;1,574,356;611,643;-0,035492534
64,044,806;1,576,348;6,116,819;-0,035502541
64,144,806;1,578,364;6,117,221;-0,035492534
64,244,806;1,580,352;6,117,376;-0,035472522
64,344,806;1,582,348;6,117,542;-0,035492534
64,444,806;158,436;6,118,289;-0,035462515
64,544,806;1,586,348;6,118,011;-0,035492534
64,644,806;1,588,344;61,184;-0,035512547
64,744,806;1,590,348;6,119,207;-0,035462515
64,844,806;159,234;6,118,832;-0,035462515
64,944,806;159,434;6,119,441;-0,035482528
65,044,806;159,634;6,119,789;-0,035502541
65,144,806;1,598,352;6,120,138;-0,035502541
65,244,806;1,600,356;6,120,055;-0,035442502
65,344,806;1,602,348;6,120,021;-0,035512547
65,444,806;1,604,356;612,069;-0,035442502
65,544,806;160,636;6,120,955;-0,035472522
65,644,806;1,608,356;612,096;-0,035502541
65,744,806;1,610,348;6,121,029;-0,035462515
65,844,806;161,234;6,121,531;-0,035432496
65,944,806;1,614,348;6,121,935;-0,035462515
66,044,806;1,616,352;612,223;-0,035512547
66,144,806;1,618,344;6,121,961;-0,035472522
66,244,806;162,034;6,122,476;-0,035452509
66,344,806;162,234;6,122,842;-0,035502541
66,444,806;1,624,356;6,123,285;-0,035482528
66,544,806;1,626,348;6,123,508;-0,035472522
66,644,806;1,628,348;6,123,574;-0,035482528
66,744,806;1,630,352;6,123,844;-0,035482528
66,844,806;1,632,344;6,123,595;-0,035492534
66,944,806;1,634,344;6,123,976;-0,03542249
67,044,806;1,636,368;6,124,692;-0,035432496
67,144,806;1,638,364;6,124,424;-0,035502541
67,244,806;1,640,356;6,124,561;-0,035462515
67,344,806;1,642,352;612,515;-0,035452509
67,444,806;1,644,344;6,125,198;-0,03542249
67,544,806;1,646,344;6,125,366;-0,035462515
67,644,806;164,834;6,125,622;-0,035472522
67,744,806;1,650,352;6,125,958;-0,035472522
67,844,806;1,652,344;6,126,166;-0,035452509
67,944,806;165,434;6,126,184;-0,035442502
68,044,806;1,656,348;6,126,696;-0,035432496
68,144,806;1,658,336;6,126,714;-0,035452509
68,244,806;1,660,332;6,126,651;-0,035452509
68,344,806;1,662,348;6,127,403;-0,035492534
68,444,806;1,664,348;6,127,125;-0,035452509
68,544,806;1,666,348;6,127,408;-0,035442502
68,644,806;1,668,348;6,127,524;-0,035472522
68,744,806;1,670,332;6,127,422;-0,035442502
68,844,806;1,672,336;6,128,011;-0,035492534
68,944,806;1,674,328;6,127,999;-0,035482528
69,044,806;167,634;6,128,771;-0,035452509
69,144,806;167,834;6,128,474;-0,035432496
69,244,806;168,034;6,128,901;-0,035472522
69,344,806;1,682,356;6,128,986;-0,035472522
69,444,806;1,684,336;6,128,675;-0,035492534
69,544,806;1,686,332;6,128,864;-0,035482528
69,644,806;1,688,344;6,129,628;-0,035482528
69,744,806;1,690,336;6,129,093;-0,035482528
69,844,806;1,692,344;6,129,563;-0,035452509
69,944,806;1,694,336;6,129,714;-0,035482528
70,044,806;1,696,328;6,129,448;-0,035512547
70,144,806;1,698,328;6,129,914;-0,035472522
70,244,806;1,700,328;6,129,919;-0,035462515
70,344,806;1,702,344;613,028;-0,035462515
70,444,806;1,704,344;6,130,172;-0,035472522
70,544,806;1,706,336;6,129,984;-0,035512547
70,644,806;1,708,356;6,130,691;-0,035492534
70,744,806;1,710,348;6,130,241;-0,035462515
70,844,806;1,712,352;6,130,474;-0,035512547
70,944,806;1,714,364;6,130,797;-0,035462515
71,044,806;1,716,352;6,130,447;-0,035492534
71,144,806;1,718,352;6,130,702;-0,035512547
71,244,806;172,034;6,130,757;-0,035502541
71,344,806;1,722,336;613,077;-0,035502541
71,444,806;1,724,336;6,131,205;-0,035472522
71,544,806;1,726,328;6,131,461;-0,035482528
71,644,806;1,728,348;6,131,776;-0,035502541
71,744,806;1,730,348;6,131,586;-0,035492534
71,844,806;1,732,348;6,131,424;-0,035492534
71,944,806;1,734,352;6,131,842;-0,035462515
72,044,806;1,736,356;6,131,859;-0,035472522
72,144,806;173,836;6,131,796;-0,035492534
72,244,806;1,740,356;6,131,781;-0,035512547
72,344,806;174,234;6,131,584;-0,035482528
72,444,806;1,744,344;6,131,912;-0,035492534
72,544,806;1,746,348;6,132,004;-0,035462515
72,644,806;1,748,348;6,131,974;-0,035512547
72,744,806;1,750,344;6,132,164;-0,035452509
72,844,806;175,234;6,132,178;-0,035442502
72,944,806;1,754,356;6,132,625;-0,035472522
73,044,806;1,756,344;6,132,278;-0,035432496
73,144,806;1,758,344;6,132,428;-0,035462515
73,244,806;1,760,348;6,132,327;-0,035462515
73,344,806;1,762,332;6,132,362;-0,035462515
73,444,806;1,764,336;6,132,504;-0,035482528
73,544,806;1,766,352;6,133,093;-0,035432496
73,644,806;1,768,364;6,132,681;-0,035462515
73,744,806;1,770,368;6,132,825;-0,035462515
73,844,806;1,772,352;6,132,525;-0,035492534
73,944,806;1,774,348;6,132,405;-0,035472522
74,044,806;1,776,352;613,273;-0,035432496
74,144,806;1,778,348;6,132,486;-0,035472522
74,244,806;1,780,364;6,132,852;-0,035462515
74,344,806;178,236;613,251;-0,035512547
74,444,806;1,784,356;6,132,414;-0,035472522
74,544,806;1,786,372;6,132,885;-0,035452509
74,644,806;1,788,356;6,132,442;-0,035462515
74,744,806;1,790,352;6,132,606;-0,035472522
74,844,806;1,792,356;6,132,881;-0,035472522
74,944,806;179,436;6,132,809;-0,035472522
75,044,806;1,796,368;6,132,734;-0,035492534
75,144,806;179,836;6,132,597;-0,035482528
75,244,806;1,800,352;6,132,445;-0,035452509
75,344,806;1,802,344;6,132,671;-0,035472522
75,444,806;180,434;613,276;-0,035442502
75,544,806;180,636;613,306;-0,035462515
75,644,806;1,808,356;6,132,869;-0,035482528
75,744,806;1,810,352;6,132,631;-0,035442502
75,844,806;1,812,368;6,133,001;-0,035492534
75,944,806;1,814,356;6,132,435;-0,035432496
76,044,806;1,816,344;6,132,429;-0,035472522
76,144,806;1,818,352;6,132,969;-0,035482528
76,244,806;1,820,352;6,132,696;-0,035492534
76,344,806;1,822,356;6,132,851;-0,035432496
76,444,806;182,434;6,132,569;-0,035452509
76,544,806;1,826,336;6,132,343;-0,035482528
76,644,806;1,828,332;613,239;-0,035462515
76,744,806;1,830,328;6,132,396;-0,035432496
76,844,806;1,832,348;6,132,589;-0,035462515
76,944,806;1,834,344;6,132,212;-0,035452509
77,044,806;1,836,348;6,132,207;-0,035442502
77,144,806;1,838,356;6,132,511;-0,035462515
77,244,806;1,840,348;6,132,262;-0,035462515
77,344,806;1,842,348;6,132,321;-0,035452509
77,444,806;1,844,356;6,132,565;-0,035472522
77,544,806;1,846,356;6,131,992;-0,035462515
77,644,806;1,848,352;6,132,098;-0,035472522
77,744,806;1,850,344;6,131,843;-0,035432496
77,844,806;185,234;6,131,871;-0,035462515
77,944,806;1,854,336;6,131,874;-0,035452509
78,044,806;1,856,328;6,131,672;-0,035482528
78,144,806;1,858,348;6,132,249;-0,03542249
78,244,806;1,860,348;6,131,715;-0,035452509
78,344,806;1,862,344;6,131,479;-0,035472522
78,444,806;1,864,348;6,131,401;-0,035472522
78,544,806;186,634;6,131,203;-0,035512547
78,644,806;186,836;6,131,436;-0,035472522
78,744,806;1,870,364;6,131,338;-0,035482528
78,844,806;1,872,344;6,130,617;-0,035462515
78,944,806;1,874,344;6,130,916;-0,035452509
79,044,806;187,634;6,130,844;-0,035452509
79,144,806;1,878,344;6,130,445;-0,035432496
79,244,806;188,034;6,130,478;-0,035472522
79,344,806;1,882,344;6,130,304;-0,035482528
79,444,806;1,884,352;6,130,594;-0,035472522
79,544,806;1,886,352;6,130,138;-0,035502541
79,644,806;1,888,344;6,130,043;-0,035492534
79,744,806;1,890,352;6,130,431;-0,035492534
79,844,806;189,234;6,129,813;-0,035502541
79,944,806;189,434;6,129,827;-0,035482528
80,044,806;1,896,348;6,129,767;-0,035492534
80,144,806;189,836;6,129,599;-0,035472522
80,244,806;1,900,364;612,932;-0,035472522
80,344,806;190,234;6,128,674;-0,035472522
80,444,806;1,904,344;6,128,899;-0,035482528
80,544,806;1,906,336;6,128,818;-0,035522553
80,644,806;1,908,332;612,879;-0,035462515
80,744,806;1,910,348;6,128,865;-0,035512547
80,844,806;1,912,344;6,128,196;-0,035492534
80,944,806;1,914,344;6,128,115;-0,035502541
81,044,806;1,916,352;6,128,332;-0,035472522
81,144,806;191,834;6,127,661;-0,035492534
81,244,806;1,920,344;6,127,756;-0,035492534
81,344,806;1,922,348;6,127,815;-0,035482528
81,444,806;1,924,356;6,127,607;-0,035522553
81,544,806;1,926,356;6,127,343;-0,035462515
81,644,806;1,928,344;6,126,773;-0,035462515
81,744,806;1,930,352;6,126,649;-0,035522553
81,844,806;1,932,344;6,126,233;-0,035512547
81,944,806;193,434;612,626;-0,035492534
82,044,806;193,636;6,126,648;-0,035512547
82,144,806;193,836;6,125,926;-0,035542566
82,244,806;194,036;6,125,952;-0,035492534
82,344,806;1,942,372;6,125,844;-0,035522553
82,444,806;1,944,364;6,125,311;-0,035502541
82,544,806;1,946,364;6,125,078;-0,035492534
82,644,806;194,836;6,124,852;-0,035482528
82,744,806;1,950,372;6,124,586;-0,035472522
82,844,806;1,952,368;6,124,439;-0,035482528
82,944,806;195,436;61,239;-0,035482528
83,044,806;195,636;6,123,967;-0,035502541
83,144,806;1,958,352;6,123,695;-0,035482528
83,244,806;1,960,344;6,123,572;-0,035492534
83,344,806;1,962,356;6,123,584;-0,035492534
83,444,806;1,964,348;6,122,757;-0,035562579
83,544,806;1,966,352;6,122,762;-0,035502541
83,644,806;196,836;6,122,675;-0,035472522
83,744,806;1,970,352;6,122,101;-0,035492534
83,844,806;197,236;6,122,012;-0,035502541
83,944,806;197,436;6,121,742;-0,035482528
84,044,806;1,976,364;6,121,604;-0,035472522
84,144,806;1,978,352;6,120,754;-0,035442502
84,244,806;198,034;6,120,608;-0,035482528
84,344,806;1,982,356;6,120,412;-0,035472522
84,444,806;1,984,344;6,120,002;-0,035482528
84,544,806;198,634;6,119,649;-0,035482528
84,644,806;1,988,356;6,119,937;-0,035472522
84,744,806;1,990,352;6,119,456;-0,035502541
84,844,806;1,992,356;6,119,292;-0,035472522
84,944,806;1,994,356;6,119,018;-0,035482528
85,044,806;1,996,344;6,118,338;-0,035482528
85,144,806;1,998,364;6,118,742;-0,035462515
85,244,806;2,000,368;611,806;-0,035462515
85,344,806;2,002,356;6,117,188;-0,035512547
85,444,806;2,004,348;611,702;-0,035522553
85,544,806;200,634;6,116,739;-0,035412483
85,644,806;2,008,356;6,116,832;-0,035482528
85,744,806;2,010,344;6,116,349;-0,035482528
85,844,806;2,012,344;6,115,984;-0,035492534
85,944,806;2,014,368;6,116,121;-0,035482528
86,044,806;201,636;6,115,212;-0,035482528
86,144,806;201,836;6,114,901;-0,035512547
86,244,806;2,020,364;6,114,722;-0,035442502
86,344,806;2,022,352;6,113,966;-0,035502541
86,444,806;2,024,352;6,113,992;-0,035442502
86,544,806;2,026,352;6,113,744;-0,035472522
86,644,806;2,028,372;6,113,436;-0,035472522
86,744,806;2,030,372;6,112,829;-0,035482528
86,844,806;2,032,364;6,111,915;-0,035462515
86,944,806;203,436;611,165;-0,035492534
87,044,806;2,036,352;6,111,078;-0,035482528
87,144,806;2,038,356;6,110,997;-0,035492534
87,244,806;2,040,372;6,110,992;-0,035522553
87,344,806;2,042,364;6,110,038;-0,035502541
87,444,806;204,436;6,109,734;-0,035482528
87,544,806;204,636;610,931;-0,035472522
87,644,806;2,048,356;6,108,763;-0,035462515
87,744,806;2,050,356;6,108,438;-0,035492534
87,844,806;2,052,352;6,108,029;-0,035472522
87,944,806;2,054,368;6,107,704;-0,035482528
88,044,806;205,636;6,107,283;-0,035522553
88,144,806;2,058,356;6,106,814;-0,035522553
88,244,806;206,036;6,106,266;-0,035502541
88,344,806;2,062,348;6,105,726;-0,035482528
88,444,806;2,064,348;6,105,415;-0,035492534
88,544,806;2,066,364;6,105,431;-0,035502541
88,644,806;2,068,364;61,045;-0,035482528
88,744,806;2,070,364;610,406;-0,035502541
88,844,806;2,072,364;6,103,619;-0,035472522
88,944,806;207,436;6,102,957;-0,035472522
89,044,806;207,636;6,102,921;-0,035492534
89,144,806;2,078,352;6,101,946;-0,035492534
89,244,806;2,080,356;6,101,729;-0,035492534
89,344,806;2,082,356;6,100,882;-0,035492534
89,444,806;2,084,348;6,100,225;-0,035512547
89,544,806;2,086,356;6,099,965;-0,035492534
89,644,806;208,834;6,099,114;-0,035482528
89,744,806;2,090,332;6,098,687;-0,035502541
89,844,806;2,092,348;6,098,526;-0,035462515
89,944,806;2,094,344;6,097,606;-0,035462515
90,044,806;2,096,348;6,097,135;-0,035492534
90,144,806;2,098,344;6,096,443;-0,035452509
90,244,806;2,100,344;6,095,652;-0,035542566
90,344,806;2,102,348;6,095,394;-0,035512547
90,444,806;2,104,348;6,094,669;-0,035522553
90,544,806;2,106,356;6,094,057;-0,035492534
90,644,806;2,108,348;609,325;-0,035522553
90,744,806;2,110,336;6,092,249;-0,035512547
90,844,806;2,112,352;609,242;-0,035512547
90,944,806;2,114,344;609,132;-0,035482528
91,044,806;211,634;6,090,759;-0,035512547
91,144,806;211,836;6,090,565;-0,035512547
91,244,806;2,120,356;608,923;-0,035512547
91,344,806;2,122,368;608,903;-0,03553256
91,444,806;2,124,364;6,087,872;-0,035542566
91,544,806;2,126,356;6,087,101;-0,035492534
91,644,806;2,128,368;608,669;-0,035502541
91,744,806;2,130,376;6,085,924;-0,035492534
91,844,806;2,132,384;6,084,917;-0,035492534
91,944,806;213,436;6,083,868;-0,035492534
92,044,806;213,636;6,083,351;-0,035522553
92,144,806;2,138,372;6,082,917;-0,035552572
92,244,806;2,140,356;6,081,728;-0,035522553
92,344,806;2,142,352;6,080,939;-0,035552572
92,444,806;2,144,364;6,080,749;-0,035512547
92,544,806;214,636;6,079,129;-0,035552572
92,644,806;2,148,364;6,078,517;-0,035542566
92,744,806;215,036;6,077,625;-0,035442502
92,844,806;2,152,352;6,076,563;-0,035552572
92,944,806;2,154,352;6,075,956;-0,035492534
93,044,806;2,156,344;6,075,168;-0,035492534
93,144,806;2,158,364;6,074,717;-0,035502541
93,244,806;2,160,356;6,073,521;-0,035462515
93,344,806;2,162,364;60,725;-0,035522553
93,444,806;216,436;607,138;-0,035502541
93,544,806;2,166,352;6,070,356;-0,035492534
93,644,806;2,168,352;6,069,449;-0,03553256
93,744,806;217,036;6,068,826;-0,035452509
93,844,806;217,236;6,067,536;-0,035492534
93,944,806;2,174,364;6,066,741;-0,035512547
94,044,806;2,176,356;6,065,706;-0,035482528
94,144,806;2,178,356;6,064,155;-0,035472522
94,244,806;2,180,356;6,063,375;-0,035502541
94,344,806;2,182,356;6,062,254;-0,035512547
94,444,806;2,184,368;6,061,504;-0,035482528
94,544,806;2,186,368;606,021;-0,035472522
94,644,806;2,188,364;6,058,798;-0,035482528
94,744,806;2,190,372;6,058,181;-0,035492534
94,844,806;2,192,356;605,663;-0,035492534
94,944,806;2,194,352;6,055,508;-0,035522553
95,044,806;219,636;6,054,552;-0,035522553
95,144,806;2,198,364;6,053,251;-0,035502541
95,244,806;2,200,372;6,052,103;-0,035502541
95,344,806;2,202,364;6,050,574;-0,035482528
95,444,806;2,204,364;6,049,178;-0,035502541
95,544,806;2,206,356;6,047,971;-0,035462515
95,644,806;2,208,344;6,046,873;-0,035482528
95,744,806;2,210,356;6,045,573;-0,035502541
95,844,806;2,212,352;6,044,211;-0,035442502
95,944,806;2,214,348;6,042,778;-0,035472522
96,044,806;221,636;6,041,748;-0,035472522
96,144,806;2,218,352;6,040,039;-0,035482528
96,244,806;2,220,344;6,038,637;-0,035462515
96,344,806;2,222,356;6,037,584;-0,035482528
96,444,806;222,436;6,036,026;-0,035452509
96,544,806;2,226,364;6,034,602;-0,035482528
96,644,806;2,228,356;6,032,536;-0,035492534
96,744,806;2,230,356;6,031,175;-0,035452509
96,844,806;223,236;6,029,695;-0,035472522
96,944,806;223,436;6,028,203;-0,035502541
97,044,806;223,638;6,026,874;-0,035502541
97,144,806;2,238,368;6,024,683;-0,035512547
97,244,806;2,240,356;6,023,138;-0,035472522
97,344,806;2,242,364;6,021,835;-0,035492534
97,444,806;2,244,348;6,019,945;-0,035452509
97,544,806;2,246,352;6,018,278;-0,035502541
97,644,806;2,248,356;6,016,952;-0,035482528
97,744,806;2,250,364;6,014,987;-0,035492534
97,844,806;2,252,368;6,013,401;-0,035482528
97,944,806;225,436;6,011,292;-0,035472522
98,044,806;225,636;600,949;-0,035472522
98,144,806;2,258,356;600,774;-0,035472522
98,244,806;2,260,364;600,615;-0,035512547
98,344,806;2,262,384;6,004,142;-0,035502541
98,444,806;2,264,352;6,001,354;-0,035492534
98,544,806;2,266,352;6,000,047;-0,035512547
98,644,806;2,268,372;5,998,592;-0,035472522
98,744,806;2,270,356;5,996,034;-0,035482528
98,844,806;227,236;5,994,048;-0,035482528
98,944,806;2,274,364;5,992,289;-0,035482528
99,044,806;2,276,368;5,989,851;-0,035482528
99,144,806;2,278,368;598,787;-0,035482528
99,244,806;2,280,356;5,985,521;-0,035482528
99,344,806;228,236;5,983,449;-0,035482528
99,444,806;2,284,352;5,981,368;-0,035472522
99,544,806;2,286,344;5,978,984;-0,035472522
99,644,806;228,836;5,977,225;-0,035492534
99,744,806;2,290,364;597,482;-0,035502541
99,844,806;2,292,364;5,972,382;-0,035452509
99,944,806;229,436;5,969,973;-0,035472522
100,044,806;2,296,348;596,741;-0,035452509
100,144,806;2,298,356;5,965,404;-0,035502541
100,244,806;230,036;5,962,867;-0,035492534
100,344,806;230,236;5,960,425;-0,035482528
100,444,806;2,304,364;5,958,155;-0,035442502
100,544,806;2,306,352;5,955,199;-0,035492534
100,644,806;2,308,352;5,952,845;-0,035482528
100,744,806;2,310,348;5,950,169;-0,035472522
100,844,806;2,312,344;5,947,545;-0,035472522
100,944,806;2,314,364;5,945,312;-0,035452509
101,044,806;231,636;594,226;-0,035452509
101,144,806;2,318,364;5,939,716;-0,035462515
101,244,806;2,320,372;5,937,294;-0,035512547
101,344,806;232,236;5,933,997;-0,035502541
101,444,806;2,324,356;5,931,569;-0,035472522
101,544,806;2,326,356;592,909;-0,035482528
101,644,806;2,328,372;5,925,876;-0,035452509
101,744,806;2,330,372;5,923,149;-0,035492534
101,844,806;2,332,364;591,976;-0,035482528
101,944,806;2,334,372;5,917,261;-0,035482528
102,044,806;2,336,368;5,914,227;-0,035512547
102,144,806;233,836;5,911,213;-0,035462515
102,244,806;2,340,372;5,908,663;-0,035472522
102,344,806;234,236;5,905,446;-0,035492534
1,024,448;234,436;5,902,419;-0,035462515
1,025,448;2,346,372;5,899,448;-0,035452509
1,026,448;2,348,356;5,895,984;-0,035502541
1,027,448;2,350,356;5,892,785;-0,035472522
1,028,448;2,352,356;5,889,857;-0,035472522
1,029,448;2,354,372;5,886,432;-0,035492534
1,030,448;2,356,372;5,883,194;-0,035442502
1,031,448;235,836;5,879,883;-0,035472522
1,032,448;2,360,368;5,876,656;-0,035472522
1,033,448;2,362,364;5,873,207;-0,035492534
1,034,448;2,364,376;5,869,631;-0,035482528
1,035,448;2,366,396;5,866,764;-0,035482528
1,036,448;2,368,388;5,862,736;-0,035512547
1,037,448;237,038;5,859,262;-0,035452509
1,038,448;237,238;5,856,272;-0,035452509
1,039,448;2,374,372;5,852,509;-0,035482528
1,040,448;2,376,372;5,848,975;-0,035462515
1,041,448;2,378,376;5,845,272;-0,035452509
1,042,448;2,380,384;5,841,383;-0,035472522
1,043,448;2,382,388;5,837,746;-0,035472522
1,044,448;238,438;5,833,867;-0,035472522
1,045,448;2,386,388;5,830,026;-0,035502541
1,046,448;2,388,372;5,825,942;-0,035452509
1,047,448;2,390,388;5,822,763;-0,035472522
1,048,448;2,392,408;5,819,089;-0,035482528
1,049,448;2,394,384;5,813,822;-0,035462515
1,050,448;239,638;5,810,317;-0,035522553
1,051,448;2,398,384;5,806,732;-0,035482528
1,052,448;2,400,384;5,802,428;-0,035492534
1,053,448;2,402,372;5,798,608;-0,035462515
1,054,448;2,404,384;579,507;-0,035512547
1,055,448;2,406,392;5,790,678;-0,035512547
1,056,448;2,408,396;5,786,636;-0,035472522
1,057,448;2,410,384;5,781,673;-0,035472522
1,058,448;2,412,392;5,777,684;-0,035472522
1,059,448;2,414,384;5,773,101;-0,035452509
1,060,448;2,416,384;5,768,941;-0,035492534
1,061,448;2,418,404;5,764,859;-0,035492534
1,062,448;24,204;5,760,165;-0,035492534
1,063,448;2,422,408;5,755,984;-0,035482528
1,064,448;2,424,408;5,751,602;-0,035462515
1,065,448;2,426,388;5,746,436;-0,035492534
1,066,448;2,428,388;5,741,956;-0,035492534
1,067,448;2,430,388;573,743;-0,035522553
1,068,448;24,324;5,732,723;-0,035472522
1,069,448;2,434,396;5,727,962;-0,035492534
1,070,448;2,436,392;5,722,935;-0,035452509
1,071,448;2,438,396;5,718,652;-0,035492534
1,072,448;2,440,388;5,713,784;-0,035452509
1,073,448;2,442,384;5,708,897;-0,035492534
1,074,448;2,444,396;5,703,971;-0,035462515
1,075,448;2,446,388;5,698,547;-0,035432496
1,076,448;2,448,388;5,693,765;-0,035482528
1,077,448;2,450,392;5,688,818;-0,035472522
1,078,448;2,452,388;5,683,581;-0,035492534
1,079,448;2,454,384;567,841;-0,035482528
1,080,448;245,638;5,673,352;-0,035452509
1,081,448;2,458,396;5,668,169;-0,035452509
1,082,448;24,604;5,662,448;-0,035512547
1,083,448;2,462,396;5,656,622;-0,035452509
1,084,448;2,464,408;5,651,445;-0,03542249
1,085,448;24,664;5,645,768;-0,035452509
1,086,448;24,684;5,640,217;-0,035492534
1,087,448;2,470,412;5,634,974;-0,035482528
1,088,448;24,724;5,628,972;-0,035492534
1,089,448;2,474,404;5,623,485;-0,035482528
1,090,448;24,764;5,617,777;-0,035482528
1,091,448;24,784;5,611,505;-0,035462515
1,092,448;2,480,396;5,605,813;-0,035482528
1,093,448;2,482,392;5,599,685;-0,035472522
1,094,448;2,484,404;5,594,032;-0,035492534
1,095,448;2,486,404;5,587,913;-0,035472522
1,096,448;2,488,392;5,581,471;-0,035452509
1,097,448;2,490,404;5,575,729;-0,035502541
1,098,448;2,492,392;5,569,387;-0,035482528
1,099,448;2,494,396;5,563,318;-0,035502541
1,100,448;2,496,416;5,556,903;-0,035502541
1,101,448;2,498,416;5,549,875;-0,035462515
1,102,448;2,500,416;5,543,547;-0,035522553
1,103,448;25,024;5,537,099;-0,035492534
1,104,448;25,044;5,530,505;-0,035492534
1,105,448;25,064;5,524,077;-0,035492534
1,106,448;25,084;5,517,219;-0,035442502
1,107,448;2,510,416;551,043;-0,035452509
1,108,448;2,512,412;5,503,312;-0,035502541
1,109,448;2,514,416;5,496,064;-0,035482528
1,110,448;2,516,424;5,489,438;-0,035492534
1,111,448;2,518,408;5,482,177;-0,035472522
1,112,448;2,520,412;5,475,239;-0,035492534
1,113,448;2,522,436;5,468,628;-0,035482528
1,114,448;2,524,436;5,460,644;-0,035492534
1,115,448;2,526,416;545,308;-0,035462515
1,116,448;2,528,408;5,445,658;-0,035482528
1,117,448;2,530,412;54,379;-0,035452509
1,118,448;2,532,416;5,430,484;-0,035492534
1,119,448;2,534,412;5,422,878;-0,035502541
1,120,448;2,536,436;541,504;-0,035482528
1,121,448;2,538,432;5,407,097;-0,035502541
1,122,448;2,540,428;5,399,252;-0,035452509
1,123,448;2,542,436;5,391,293;-0,035482528
1,124,448;254,442;5,383,036;-0,035542566
1,125,448;254,642;5,374,659;-0,035512547
1,126,448;2,548,432;5,366,996;-0,035492534
1,127,448;255,044;5,358,143;-0,035512547
1,128,448;2,552,444;5,349,958;-0,035502541
1,129,448;2,554,444;534,126;-0,035482528
1,130,448;2,556,428;5,331,955;-0,035492534
1,131,448;2,558,428;5,323,592;-0,035502541
1,132,448;2,560,428;5,314,764;-0,035482528
1,133,448;2,562,444;5,305,851;-0,035482528
1,134,448;2,564,444;5,296,399;-0,035492534
1,135,448;256,644;5,287,426;-0,035502541
1,136,448;2,568,448;527,855;-0,03553256
1,137,448;2,570,436;5,268,827;-0,035462515
1,138,448;2,572,436;525,969;-0,035482528
1,139,448;2,574,448;5,250,389;-0,035482528
1,140,448;2,576,444;5,240,146;-0,035512547
1,141,448;2,578,448;5,230,229;-0,035482528
1,142,448;2,580,444;522,024;-0,035482528
1,143,448;2,582,448;5,209,827;-0,035512547
1,144,448;258,444;5,199,808;-0,035472522
1,145,448;2,586,436;5,189,651;-0,035492534
1,146,448;2,588,448;5,179,496;-0,035492534
1,147,448;2,590,444;5,168,653;-0,035462515
1,148,448;2,592,444;5,157,921;-0,035472522
1,149,448;2,594,452;5,147,315;-0,035442502
1,150,448;2,596,444;5,135,857;-0,035452509
1,151,448;2,598,448;5,125,074;-0,035472522
1,152,448;2,600,456;5,114,009;-0,035472522
1,153,448;2,602,452;5,102,334;-0,035512547
1,154,448;2,604,456;5,090,896;-0,035472522
1,155,448;2,606,448;5,078,664;-0,035472522
1,156,448;2,608,452;5,066,626;-0,035462515
1,157,448;2,610,448;5,054,137;-0,035462515
1,158,448;2,612,444;5,041,574;-0,035482528
1,159,448;2,614,464;5,029,055;-0,035482528
1,160,448;2,616,456;50,157;-0,035472522
1,161,448;261,846;5,002,255;-0,035482528
1,162,448;2,620,468;498,855;-0,035452509
1,163,448;262,246;4,969,289;-0,035522553
1,164,448;2,624,468;4,912,992;-0,035462515
116,496,012;2,625,496;4,809,724;-0,035492534
116,503,212;2,625,652;4,649,922;-0,035482528
1165,05;262,586;2,670,422;-0,031159783