File: tensile_test_ontology_TTO/data/primary_data/Zy2.csv
Time;Crosshead travel;Force;Strain
(s);(mm);(kN);(%)
0;0;0,19004;0
0,976;0,05184;0,84711;0,002827494
1,506;0,12852;197,398;0,00732351
2,028;0,2336;310,434;0,012039331
2,392;0,321;317,301;0,016485391
3,132;0,55388;428,374;0,020361955
3,564;0,71996;541,849;0,025077776
3,858;0,84216;65,453;0,02938396
4,1;0,94624;769,443;0,033939922
4,318;104,108;886,696;0,03845592
4,516;112,764;1,000,706;0,042921963
4,714;121,456;1,119,854;0,047467934
4,9;129,648;1,236,054;0,052033888
5,08;137,512;1,349,336;0,056449974
5,256;145,208;1,462,352;0,060716193
5,432;152,892;1,576,825;0,065162253
5,608;160,508;1,692,298;0,069598322
5,784;1,681;1,808,945;0,074124311
5,96;17,566;1,926,696;0,078600344
6,136;183,148;2,045,796;0,083246227
6,312;190,596;2,165,451;0,08780219
6,488;19,798;22,855;0,092528002
6,664;205,316;2,406,099;0,097183876
6,84;212,592;2,527,104;0,101879714
7,016;219,808;2,647,556;0,106745402
7,192;22,694;2,767,989;0,111451232
7,368;2,34;2,887,152;0,116326911
7,544;240,976;3,005,731;0,121222573
7,72;247,864;3,123,965;0,126128225
7,896;254,668;3,239,544;0,131023887
8,072;26,138;3,355,347;0,136179318
8,25;268,004;3,468,328;0,141124935
8,428;274,564;3,580,883;0,146350304
8,62;281,516;3,699,689;0,151905381
8,818;28,854;3,816,886;0,157580352
9,016;295,436;3,931,389;0,163155412
9,232;302,824;4,049,178;0,169389887
9,456;310,316;4,163,965;0,17595407
9,71;318,596;4,278,477;0,183007818
10,036;329,008;4,392,247;0,192339549
10,524;344,692;4,505,481;0,205028304
11,59;367,504;4,592,108;0,258301094
12,69;376,276;4,615,983;0,295887784
13,79;382,548;4,649,922;0,324722231
14,89;387,776;4,678,265;0,352327767
15,99;39,286;4,703,768;0,380752577
17,09;397,048;4,725,747;0,407918503
18,19;401,516;4,750,182;0,43632333
19,29;4,05;4,762,203;0,463539212
20,39;408,436;4,775,883;0,491714243
21,49;411,892;4,790,512;0,519869292
22,59;414,672;4,796,771;0,546765456
23,69;417,324;4,800,954;0,574690709
24,79;41,984;4,806,353;0,602605971
25,89;42,218;4,808,539;0,628363145
26,99;424,172;4,797,042;0,658126768
28,09;426,208;4,800,381;0,685742295
29,19;428,016;4,797,023;0,713038106
30,29;429,796;4,794,852;0,740623659
31,39;431,508;479,313;0,76800939
32,49;433,212;4,791,525;0,795974607
33,59;434,908;4,792,842;0,823310382
34,69;436,544;4,791,808;0,850945892
35,79;438,132;4,791,155;0,878161773
36,89;439,692;4,791,043;0,905347681
37,99;441,236;4,790,139;0,932763385
39,09;44,276;4,789,319;0,96018908
40,19;444,264;4,787,997;0,987774634
41,29;445,804;4,787,934;1,015,649,931
42,39;447,232;4,783,875;1,042,805,865
43,49;448,748;4,784,662;1,070,471,348
44,59;450,196;4,782,827;1,097,627,283
45,69;451,708;4,782,634;1,125,472,606
46,79;453,168;4,781,531;1,152,698,479
47,89;454,724;4,774,383;1,180,823,554
48,99;456,368;4,783,993;1,207,749,692
50,09;457,832;4,783,267;1,235,115,441
51,19;459,268;4,780,842;1,262,880,835
52,29;460,756;4,782,495;1,290,036,769
53,39;462,244;4,783,155;1,317,672,279
54,49;463,764;4,785,529;1,345,087,983
55,59;46,526;478,529;137,279,343
56,69;46,676;4,786,946;1,400,219,126
57,79;46,828;4,789,016;1,427,524,927
58,89;469,764;4,789,398;1,454,670,871
59,99;471,244;4,787,847;1,482,805,937
61,09;47,256;477,982;151,029,158
62,19;473,756;4,767,014;1,537,907,107
63,29;474,828;4,749,023;1,565,592,572
64,39;476,072;4,742,059;1,592,418,798
65,49;477,568;4,746,953;1,619,684,635
6,659,001;479,248;4,761,042;1,646,790,614
67,69;481,088;4,781,372;1,673,986,513
68,79;483,008;4,802,019;1,701,262,341
6,989,001;484,992;4,820,381;1,729,117,656
7,099,001;4,87;4,836,685;1,755,893,927
7,209,001;489,072;485,087;1,783,349,596
73,19;491,284;4,865,209;1,811,035,061
74,29;49,346;4,875,725;1,838,210,977
7,539,001;49,572;4,885,937;1,865,586,717
7,649,001;498,332;4,903,908;1,891,513,741
7,759,001;500,612;4,903,812;1,920,138,373
78,69;503,072;4,914,602;1,947,723,927
79,79;50,556;4,922,722;1,975,359,436
8,089,001;508,076;4,931,923;2,002,575,318
8,199,001;510,724;4,942,372;2,030,300,747
8,309,001;513,308;4,949,385;20,574,367
84,19;516,032;4,958,696;2,084,772,475
85,29;519,088;4,973,629;211,219,817
8,639,001;521,732;4,975,762;2,139,603,883
8,749,001;524,548;4,984,942;2,167,099,516
8,859,001;527,352;4,994,684;2,194,355,362
89,69;530,216;5,004,046;2,221,850,996
90,79;533,044;501,193;2,249,076,868
9,189,001;535,944;5,021,539;2,276,612,466
9,299,001;539,132;5,033,799;2,304,647,621
9,409,001;5,419;5,038,082;23,317,536
95,19;544,744;5,045,962;2,359,109,357
96,29;547,612;505,567;2,386,255,301
9,739,001;550,524;5,064,809;2,414,200,535
9,849,001;553,388;5,073,203;2,441,476,364
9,959,001;55,628;5,082,064;2,469,011,962
100,69;559,384;5,092,651;2,496,717,409
10,179,001;562,156;5,097,869;2,523,823,388
10,289,001;565,036;5,106,019;2,551,618,755
10,399,001;567,876;5,113,171;2,579,194,318
10,509,001;570,704;5,121,009;2,606,180,403
106,19;573,584;5,130,414;2,633,506,187
10,729,001;576,484;5,138,417;2,661,301,555
10,839,001;57,956;5,146,086;2,688,997,011
10,949,001;582,356;5,154,124;2,716,122,972
11,059,001;585,152;516,082;2,743,408,791
111,69;588,012;5,169,416;277,069,461
11,279,001;59,082;5,175,396;2,798,340,111
11,389,001;593,692;5,183,988;2,825,785,789
11,499,001;596,596;5,191,718;2,853,451,271
11,609,001;59,958;5,196,719;2,880,856,985
117,19;602,504;5,207,762;2,908,472,512
11,829,001;605,348;5,214,554;2,935,848,251
11,939,001;60,818;5,221,075;2,963,233,982
12,049,001;611,044;5,227,597;299,050,981
12,159,001;613,964;5,235,703;301,797,547
122,69;617,088;5,247,439;3,044,491,971
12,379,001;61,998;5,247,713;3,073,176,551
12,489,001;62,292;5,255,764;3,100,772,096
12,599,001;625,804;5,262,532;312,809,788
12,709,001;628,748;5,270,286;3,155,873,265
128,19;631,624;5,276,511;3,182,929,288
12,929,001;634,596;528,423;3,210,554,806
130,39;637,808;5,296,427;3,237,740,714
131,49;640,636;5,296,634;3,265,506,108
13,259,002;643,504;530,205;3,293,041,706
133,69;646,344;5,308,302;3,320,097,729
13,479,002;649,268;5,314,729;3,347,543,407
135,89;652,212;5,321,307;3,374,979,094
136,99;655,196;5,327,852;3,402,554,656
13,809,002;658,392;5,336,404;3,430,100,245
139,19;661,288;5,340,726;3,457,485,976
14,029,002;66,422;5,346,538;3,484,681,875
141,39;667,248;5,353,495;3,512,507,216
142,49;670,248;535,871;3,540,122,743
14,359,002;673,248;5,364,791;3,567,488,492
144,69;676,336;5,373,005;3,593,155,745
14,579,002;67,942;5,375,783;3,622,239,971
146,89;682,444;5,381,376;3,649,895,463
147,99;685,448;5,387,154;3,677,271,202
14,909,002;688,492;5,392,506;3,704,886,729
150,026;689,596;5,370,555;3,718,574,599
151,126;691,788;5,385,048;3,736,388,812
15,222,602;6,94;5,391,622;3,755,761,644
153,326;696,212;5,396,519;3,775,374,263
15,442,602;698,408;5,400,433;3,794,497,316
155,526;700,592;5,403,753;3,811,981,822
17,236,602;702,116;5,275,691;-0,181718961
173,466;704,296;5,360,087;-0,18170897
17,456,602;706,512;5,405,044;-0,181698978
17,566,602;708,708;5,420,951;-0,181718961
176,766;710,908;542,687;-0,181718961
17,786,602;713,108;5,430,971;-0,181738943
178,966;715,296;5,433,813;-0,181669005
18,006,602;717,492;5,437,196;-0,181738943
18,116,602;719,708;5,440,892;-0,181678996
182,266;7,219;5,444,123;-0,181688987
18,336,602;724,096;5,447,053;-0,18170897
184,466;726,304;5,450,828;-0,181718961
18,556,602;728,496;5,453,632;-0,181678996
18,666,602;730,672;5,456,734;-0,181669005
187,766;732,888;5,460,939;-0,181748934
18,886,602;735,084;5,464,423;-0,181688987
189,966;737,284;5,467,753;-0,181768916
19,106,602;739,484;5,471,354;-0,181738943
19,216,602;741,676;5,474,889;-0,181688987
193,266;743,872;5,477,931;-0,181738943
19,436,602;746,092;5,482,043;-0,181718961
195,466;748,284;5,485,051;-0,181698978
19,656,602;750,484;5,488,507;-0,181718961
19,766,602;752,692;5,491,933;-0,181698978
198,766;754,892;5,495,206;-0,181698978
19,986,602;757,084;549,855;-0,181738943
200,966;7,593;550,207;-0,181698978
20,206,602;761,484;5,505,351;-0,181748934
20,316,602;76,368;5,508,946;-0,181688987
204,266;765,888;5,512,079;-0,181678996
20,536,602;768,088;5,515,531;-0,181728952
206,466;770,288;5,518,872;-0,181678996
20,756,602;772,504;5,522,547;-0,181718961
20,866,602;7,747;5,525,658;-0,181698978
209,766;776,884;552,907;-0,181738943
21,086,602;779,084;5,532,055;-0,181698978
211,966;78,128;5,535,783;-0,181718961
21,306,602;783,484;5,538,747;-0,181688987
21,416,602;78,568;5,541,975;-0,181718961
215,266;78,788;5,545,482;-0,181698978
21,636,602;790,072;554,896;-0,18170897
217,466;79,228;5,552,108;-0,181698978
21,856,602;794,476;5,555,219;-0,181678996
21,966,602;796,676;5,558,421;-0,181698978
220,766;798,888;5,561,762;-0,181718961
22,186,602;8,011;5,564,943;-0,181688987
222,966;803,296;5,567,994;-0,18170897
22,406,602;805,492;5,570,844;-0,181698978
22,516,602;807,676;5,573,851;-0,181659014
226,266;809,884;5,577,505;-0,18170897
22,736,602;812,088;5,580,615;-0,181698978
228,466;814,288;5,583,631;-0,181688987
22,956,602;816,488;558,675;-0,181669005
23,066,602;818,688;5,589,464;-0,181659014
231,766;820,884;5,592,431;-0,181688987
23,286,602;823,092;5,595,799;-0,181718961
23,396,602;825,284;5,598,601;-0,18170897
23,506,602;8,275;5,602,034;-0,18170897
23,616,602;829,696;5,604,877;-0,181718961
237,266;831,872;5,607,221;-0,18170897
23,836,602;834,064;5,610,455;-0,181718961
23,946,602;836,284;5,613,834;-0,181669005
24,056,602;83,848;5,616,241;-0,181718961
24,166,602;84,068;5,619,144;-0,181718961
242,766;84,288;5,622,374;-0,181728952
24,386,602;845,076;5,625,284;-0,181659014
24,496,602;847,272;5,627,996;-0,181728952
24,606,602;849,484;5,631,106;-0,181678996
24,716,602;851,676;5,633,388;-0,181678996
248,266;853,876;5,636,361;-0,181698978
24,936,602;856,092;5,639,596;-0,181718961
25,046,602;858,284;5,642,128;-0,181698978
25,156,602;86,048;5,644,887;-0,181698978
25,266,602;862,684;5,648,183;-0,181688987
253,766;864,876;5,650,393;-0,181678996
25,486,602;86,708;5,653,285;-0,181698978
25,596,602;869,292;565,601;-0,181738943
25,706,602;87,148;565,829;-0,181718961
25,816,602;873,676;5,660,947;-0,18170897
25,926,602;875,892;5,664,265;-0,181678996
260,366;878,084;5,666,342;-0,181688987
261,466;880,276;5,669,112;-0,18170897
262,566;882,484;5,672,107;-0,181748934
263,666;88,468;5,674,506;-0,181688987
26,476,603;886,872;5,676,796;-0,181688987
26,586,603;88,908;5,679,778;-0,181678996
266,966;891,272;5,681,982;-0,181698978
268,066;893,464;5,684,598;-0,181649023
269,166;895,676;5,687,466;-0,181688987
27,026,603;897,872;5,689,824;-0,181678996
27,136,603;900,068;569,236;-0,181728952
272,466;902,284;5,695,302;-0,181698978
273,566;904,484;5,697,627;-0,18170897
274,666;906,676;5,699,847;-0,181669005
27,576,603;90,888;5,702,817;-0,18170897
27,686,603;911,072;5,704,841;-0,181659014
277,966;913,264;5,707,593;-0,181718961
279,066;91,548;5,710,254;-0,18170897
280,166;917,668;5,712,382;-0,181659014
28,126,603;919,864;5,714,563;-0,18170897
28,236,603;922,072;5,717,334;-0,181688987
283,466;924,264;5,719,408;-0,181678996
284,566;92,646;5,721,927;-0,181698978
285,666;928,676;5,724,723;-0,181678996
28,676,603;930,872;5,726,846;-0,181678996
28,786,603;933,072;5,729,077;-0,181688987
288,966;935,276;5,731,505;-0,181659014
290,066;937,464;5,733,502;-0,181718961
291,166;939,656;5,735,821;-0,181659014
29,226,603;941,876;5,738,498;-0,181698978
29,336,603;944,076;5,740,684;-0,181678996
294,466;946,268;5,742,614;-0,18170897
295,566;948,472;5,745,088;-0,181639031
296,666;950,676;574,748;-0,181659014
29,776,603;952,872;5,749,614;-0,181678996
29,886,603;95,508;5,751,891;-0,181669005
299,966;957,292;5,754,451;-0,181649023
301,066;959,488;5,756,415;-0,181649023
302,166;961,664;5,757,779;-0,181639031
30,326,603;96,386;5,760,792;-0,181688987
30,436,603;966,068;5,763,304;-0,18170897
305,466;968,272;5,765,206;-0,181659014
306,566;970,476;5,767,351;-0,181649023
307,666;972,668;5,769,516;-0,181669005
30,876,603;974,868;5,771,173;-0,181669005
30,986,603;977,064;5,773,584;-0,181669005
310,966;979,268;5,775,939;-0,181669005
312,066;981,468;5,777,771;-0,181649023
313,166;983,668;5,780,123;-0,181678996
31,426,603;985,868;5,782,308;-0,181688987
31,536,603;988,072;5,784,208;-0,181639031
316,466;990,268;5,786,492;-0,18162904
317,566;992,464;5,788,478;-0,181678996
318,666;994,656;579,053;-0,181639031
31,976,603;996,868;5,792,717;-0,18162904
32,086,603;999,064;5,795,014;-0,181659014
321,966;100,126;5,796,542;-0,181639031
323,066;1,003,456;5,798,503;-0,181639031
324,166;1,005,668;5,800,863;-0,18162904
32,526,603;1,007,864;5,802,417;-0,181659014
32,636,603;1,010,064;580,441;-0,181678996
327,466;1,012,264;5,806,683;-0,18162904
328,566;101,446;580,862;-0,181649023
329,666;1,016,656;5,810,358;-0,18170897
33,076,603;1,018,872;5,812,598;-0,181649023
33,186,603;102,106;5,813,924;-0,181649023
332,966;1,023,256;5,815,839;-0,181678996
334,066;1,025,456;5,818,183;-0,181659014
335,166;1,027,656;5,820,047;-0,181649023
33,626,603;1,029,848;582,168;-0,181669005
33,736,603;1,032,068;5,823,984;-0,181678996
338,466;1,034,264;5,825,517;-0,181639031
339,566;1,036,468;5,827,175;-0,181649023
340,666;1,038,668;5,829,102;-0,181669005
34,176,603;104,086;5,831,019;-0,181649023
34,286,603;1,043,056;5,832,663;-0,181619049
343,966;1,045,272;5,835,114;-0,18162904
345,066;104,746;5,836,192;-0,181649023
346,166;1,049,656;5,837,886;-0,181659014
34,726,603;1,051,872;58,401;-0,18162904
34,836,603;105,406;5,841,621;-0,181619049
349,466;1,056,252;584,314;-0,181659014
350,566;1,058,468;5,845,653;-0,181688987
351,666;1,060,668;5,847,074;-0,181678996
35,276,603;1,062,868;5,848,802;-0,181619049
35,386,603;1,065,076;5,850,714;-0,181639031
354,966;106,726;58,52;-0,181669005
356,066;1,069,448;5,853,513;-0,181669005
357,166;107,166;5,855,699;-0,181669005
35,826,603;1,073,864;5,857,236;-0,181659014
35,936,603;1,076,056;5,858,758;-0,181688987
360,466;1,078,272;5,860,627;-0,181659014
361,566;1,080,456;5,862,139;-0,181639031
362,666;1,082,652;5,863,587;-0,181669005
36,376,603;108,486;586,552;-0,181639031
36,486,603;1,087,068;5,867,345;-0,181669005
365,966;1,089,276;5,869,108;-0,18162904
367,066;109,148;5,870,675;-0,181669005
368,166;1,093,644;5,871,869;-0,181649023
36,926,603;1,095,844;587,388;-0,18162904
37,036,603;1,098,064;5,875,906;-0,181678996
371,466;1,100,264;5,877,317;-0,181678996
372,566;1,102,464;5,878,524;-0,181659014
373,666;1,104,672;5,880,097;-0,181649023
37,476,603;1,106,864;588,153;-0,181678996
37,586,603;1,109,056;5,883,206;-0,181678996
376,966;1,111,272;5,884,998;-0,181659014
378,066;1,113,468;5,886,573;-0,181688987
379,166;111,566;5,887,657;-0,181649023
38,026,603;1,117,872;5,889,615;-0,18162904
38,136,603;1,120,076;589,105;-0,181669005
382,466;1,122,268;5,892,497;-0,181659014
383,566;1,124,476;5,894,107;-0,181649023
384,666;1,126,672;589,578;-0,181659014
38,576,603;112,886;5,897,164;-0,181669005
38,686,603;1,131,052;589,867;-0,18162904
387,966;1,133,252;5,900,366;-0,181649023
389,066;1,135,456;5,901,791;-0,181659014
390,166;1,137,668;59,034;-0,181639031
39,126,603;1,139,868;5,904,774;-0,181609058
39,236,603;114,206;5,905,987;-0,181649023
39,346,603;1,144,256;5,907,543;-0,181659014
394,566;114,646;5,909,161;-0,181639031
395,666;114,866;5,910,771;-0,181649023
39,676,603;1,150,872;5,912,267;-0,181609058
39,786,603;1,153,064;5,913,325;-0,181609058
39,896,603;1,155,256;5,914,755;-0,181639031
400,066;1,157,456;5,916,176;-0,181639031
401,166;1,159,656;5,917,725;-0,181659014
40,226,603;1,161,856;5,919,212;-0,181639031
40,336,603;1,164,064;5,920,805;-0,181609058
40,446,603;116,626;5,921,973;-0,181678996
405,566;116,846;592,329;-0,181669005
406,666;1,170,648;592,451;-0,181649023
40,776,603;1,172,848;5,925,971;-0,181669005
40,886,603;1,175,056;5,927,702;-0,181669005
40,996,603;1,177,252;5,928,825;-0,181639031
411,066;1,179,448;5,930,369;-0,181659014
412,166;1,181,648;5,931,904;-0,181649023
41,326,603;1,183,848;5,933,008;-0,181688987
41,436,603;1,186,044;5,934,346;-0,18162904
41,546,603;1,188,256;5,936,097;-0,181639031
416,566;1,190,452;5,937,164;-0,181669005
417,666;1,192,664;5,938,513;-0,181678996
41,876,603;1,194,864;5,940,161;-0,181639031
41,986,603;1,197,052;5,940,864;-0,181639031
42,096,603;1,199,232;594,213;-0,181649023
422,066;1,201,448;5,943,915;-0,181639031
423,166;1,203,644;5,944,884;-0,181659014
42,426,603;1,205,848;5,946,146;-0,181649023
42,536,603;1,208,056;5,947,726;-0,181669005
42,646,603;1,210,244;5,948,722;-0,181659014
427,566;1,212,436;594,999;-0,18162904
428,666;1,214,648;595,167;-0,181649023
42,976,603;121,684;5,952,501;-0,181649023
43,086,603;121,906;5,954,108;-0,181639031
43,196,603;1,221,276;5,955,401;-0,181639031
433,066;122,344;595,561;-0,181639031
434,166;1,225,628;5,957,239;-0,181678996
43,526,603;1,227,856;5,959,532;-0,181639031
43,636,603;1,230,048;5,960,066;-0,181678996
43,746,603;1,232,248;596,103;-0,181659014
438,566;1,234,456;5,962,502;-0,181639031
439,666;1,236,648;5,963,209;-0,181639031
44,076,603;123,884;5,964,162;-0,181678996
44,186,603;124,106;596,607;-0,181639031
44,296,603;1,243,248;5,966,867;-0,181678996
444,066;1,245,448;5,968,101;-0,181659014
445,166;1,247,652;5,969,388;-0,181678996
44,626,603;1,249,848;5,970,323;-0,181659014
44,736,603;1,252,048;5,971,327;-0,181698978
44,846,603;1,254,252;5,972,789;-0,181678996
449,566;1,256,448;5,973,732;-0,181688987
450,666;1,258,644;5,974,991;-0,181649023
45,176,603;1,260,852;5,976,369;-0,181659014
45,286,603;1,263,036;5,977,359;-0,181659014
45,396,603;1,265,228;5,978,144;-0,181619049
455,066;1,267,444;5,979,908;-0,181669005
456,166;1,269,648;5,980,707;-0,181669005
45,726,603;1,271,836;598,156;-0,18162904
45,836,603;1,274,044;5,982,792;-0,181649023
45,946,603;127,624;5,983,989;-0,181688987
460,566;127,844;598,496;-0,181669005
461,666;1,280,656;5,986,246;-0,181639031
46,276,603;1,282,852;5,986,812;-0,181639031
46,386,603;1,285,036;5,987,804;-0,181688987
46,496,603;1,287,248;5,989,205;-0,181639031
466,066;1,289,452;5,990,635;-0,181688987
467,166;1,291,648;5,991,377;-0,181659014
46,826,603;1,293,868;5,992,903;-0,181659014
46,936,603;1,296,072;5,993,688;-0,181649023
47,046,603;1,298,256;5,994,287;-0,181609058
471,566;1,300,456;5,995,433;-0,181678996
472,666;1,302,652;5,996,643;-0,181619049
47,376,603;1,304,852;5,997,834;-0,181669005
47,486,603;1,307,064;599,894;-0,181599067
47,596,603;1,309,256;5,999,917;-0,181688987
477,066;131,144;6,000,949;-0,181659014
478,166;1,313,644;6,001,744;-0,181649023
47,926,603;1,315,844;6,002,664;-0,181639031
48,036,603;1,318,044;6,003,857;-0,181678996
48,146,603;132,026;6,004,803;-0,181649023
482,566;1,322,464;600,594;-0,18162904
483,666;132,466;6,006,594;-0,181639031
48,476,603;1,326,848;600,738;-0,181639031
48,586,603;1,329,048;600,884;-0,181688987
48,696,603;133,124;6,009,729;-0,181688987
488,066;1,333,452;6,010,709;-0,181609058
489,166;1,335,652;6,011,478;-0,181609058
49,026,603;1,337,848;6,012,433;-0,181639031
49,136,603;1,340,044;601,311;-0,181639031
49,246,603;1,342,244;6,014,272;-0,181609058
493,566;1,344,448;6,015,754;-0,181688987
494,666;1,346,648;6,016,276;-0,181669005
49,576,603;1,348,852;6,017,373;-0,181659014
49,686,603;1,351,072;6,018,517;-0,181678996
49,796,603;1,353,256;601,864;-0,181619049
499,066;1,355,436;6,019,577;-0,181619049
500,166;1,357,648;6,021,183;-0,18162904
50,126,603;1,359,852;6,021,788;-0,18162904
50,236,603;1,362,052;6,022,703;-0,181619049
50,346,603;136,426;6,023,619;-0,181619049
504,566;1,366,452;6,023,961;-0,181639031
505,666;1,368,648;6,024,717;-0,181688987
50,676,603;1,370,856;6,026,102;-0,181659014
50,786,603;1,373,044;6,026,332;-0,181669005
50,896,603;1,375,244;6,027,431;-0,181678996
510,066;1,377,448;6,028,777;-0,181639031
511,166;137,964;6,028,896;-0,181669005
51,226,606;1,381,844;6,029,901;-0,181649023
51,336,603;1,384,056;6,030,934;-0,181639031
514,466;1,386,244;6,031,262;-0,181669005
51,556,603;138,844;6,032,224;-0,18162904
516,666;1,390,652;6,033,536;-0,181669005
51,776,606;1,392,836;6,034,057;-0,181659014
51,886,603;1,395,028;6,035,053;-0,181669005
519,966;1,397,248;6,036,476;-0,181639031
52,106,603;1,399,444;6,036,834;-0,181659014
522,166;1,401,644;6,037,263;-0,181669005
52,326,606;1,403,848;6,038,516;-0,181639031
524,366;1,406,036;6,038,893;-0,18162904
525,466;1,408,236;6,039,779;-0,18162904
52,656,606;1,410,456;6,041,073;-0,181639031
527,666;1,412,644;6,041,431;-0,181639031
52,876,606;141,484;6,041,982;-0,181669005
529,866;1,417,044;6,042,995;-0,181619049
530,966;141,924;6,043,527;-0,181619049
53,206,606;1,421,436;6,044,312;-0,181669005
533,166;142,366;6,045,374;-0,18162904
53,426,606;1,425,856;6,046,047;-0,181659014
535,366;1,428,052;6,046,622;-0,181649023
536,466;1,430,252;6,047,352;-0,181639031
53,756,606;143,244;6,047,777;-0,181639031
538,666;143,464;6,048,527;-0,181649023
53,976,606;143,686;6,049,393;-0,18162904
540,866;1,439,048;6,049,768;-0,181639031
541,966;144,124;6,050,441;-0,18162904
54,306,606;1,443,444;6,051,453;-0,18162904
544,166;1,445,636;6,052,086;-0,181639031
54,526,606;1,447,836;605,262;-0,181669005
546,366;1,450,056;6,053,599;-0,181639031
547,466;1,452,256;6,054,171;-0,181649023
54,856,606;1,454,448;605,466;-0,181659014
549,666;1,456,652;6,055,365;-0,18162904
55,076,606;145,884;6,056,186;-0,181669005
551,866;1,461,032;6,056,662;-0,181619049
552,966;1,463,244;6,057,807;-0,181609058
55,406,606;1,465,448;6,058,151;-0,181659014
555,166;1,467,636;6,058,606;-0,181649023
55,626,606;1,469,844;6,059,368;-0,181639031
557,366;1,472,044;6,060,272;-0,181659014
558,466;1,474,248;6,060,916;-0,18162904
55,956,606;1,476,456;606,173;-0,18162904
560,666;1,478,656;6,062,254;-0,181599067
56,176,606;148,086;6,063,061;-0,181619049
562,866;1,483,068;60,631;-0,181619049
563,966;1,485,244;6,063,535;-0,181659014
56,506,606;1,487,444;6,064,286;-0,181609058
566,166;1,489,656;6,065,195;-0,18162904
56,726,606;1,491,856;6,065,697;-0,181649023
568,366;1,494,048;6,066,204;-0,181659014
569,466;1,496,248;6,066,681;-0,181649023
57,056,606;1,498,444;6,067,322;-0,181619049
571,666;1,500,648;6,068,052;-0,181609058
57,276,606;1,502,852;6,068,472;-0,181619049
573,866;1,505,052;606,905;-0,181639031
574,966;1,507,244;6,069,593;-0,181669005
57,606,606;1,509,444;6,070,081;-0,181619049
577,166;1,511,648;6,071,011;-0,181649023
57,826,606;1,513,852;6,071,714;-0,181649023
579,366;151,604;6,071,812;-0,181649023
580,466;1,518,248;6,072,797;-0,181659014
58,156,606;1,520,452;6,073,243;-0,181669005
582,666;1,522,648;6,073,507;-0,181619049
58,376,606;1,524,844;6,074,148;-0,181619049
584,866;1,527,048;6,075,188;-0,18162904
585,966;1,529,248;6,075,462;-0,181619049
58,706,606;1,531,452;6,076,198;-0,181609058
588,166;1,533,652;6,076,615;-0,181639031
58,926,606;1,535,844;6,076,749;-0,181619049
590,366;1,538,044;607,754;-0,181599067
591,466;1,540,256;6,078,478;-0,181639031
59,256,606;1,542,448;6,078,375;-0,181639031
593,666;1,544,648;6,079,144;-0,181639031
59,476,606;154,684;6,079,913;-0,18162904
595,866;1,549,028;6,080,053;-0,181639031
596,966;1,551,232;6,080,602;-0,18162904
59,806,606;1,553,448;6,081,473;-0,181639031
599,166;1,555,644;608,136;-0,181659014
60,026,606;1,557,848;6,081,908;-0,181639031
601,366;1,560,052;6,082,596;-0,181639031
602,466;1,562,232;6,082,787;-0,181678996
60,356,606;1,564,432;6,083,267;-0,181678996
604,666;1,566,648;6,084,207;-0,181659014
60,576,606;1,568,836;6,083,991;-0,181678996
606,866;1,571,032;6,084,648;-0,181669005
607,966;1,573,244;6,085,355;-0,181649023
60,906,606;1,575,436;6,085,609;-0,181659014
610,166;1,577,628;6,085,827;-0,181678996
61,126,606;1,579,844;6,087,017;-0,181589076
612,366;158,204;6,087,174;-0,181619049
613,466;1,584,248;6,087,517;-0,181669005
61,456,606;1,586,464;6,088,107;-0,181659014
615,666;1,588,648;6,088,014;-0,181688987
61,676,606;1,590,836;608,862;-0,181678996
617,866;1,593,048;6,089,363;-0,181669005
618,966;159,524;6,089,901;-0,181669005
62,006,606;1,597,436;6,090,278;-0,181669005
621,166;1,599,644;6,090,827;-0,181649023
62,226,606;160,184;6,090,888;-0,181639031
623,366;1,604,036;6,091,409;-0,181649023
624,466;1,606,252;6,091,906;-0,181619049
62,556,606;1,608,444;6,091,943;-0,181639031
626,666;1,610,644;6,092,489;-0,18162904
62,776,606;161,286;6,093,335;-0,181639031
628,866;1,615,032;609,271;-0,181609058
629,966;1,617,216;6,093,372;-0,181639031
63,106,606;161,944;6,094,377;-0,181609058
632,166;1,621,636;6,094,368;-0,18162904
63,326,606;1,623,836;60,947;-0,181639031
634,366;162,604;6,095,268;-0,181639031
635,466;1,628,232;6,095,774;-0,181649023
63,656,606;1,630,428;6,096,121;-0,181639031
637,666;1,632,648;609,682;-0,181639031
63,876,606;163,484;609,683;-0,181649023
639,866;163,704;6,096,879;-0,181639031
640,966;163,924;6,097,258;-0,181649023
64,206,606;1,641,444;6,097,801;-0,181659014
643,166;164,364;6,098,011;-0,181619049
64,426,606;1,645,848;6,098,453;-0,18162904
645,366;164,804;6,098,632;-0,181639031
646,466;1,650,236;6,099,041;-0,181669005
64,756,606;1,652,436;6,099,049;-0,181669005
648,666;1,654,636;6,099,634;-0,181639031
64,976,606;1,656,828;61;-0,181659014
650,866;165,904;6,100,377;-0,181639031
651,966;1,661,248;6,100,968;-0,181639031
65,306,606;1,663,436;610,105;-0,181659014
654,166;1,665,632;6,101,093;-0,181659014
65,526,606;1,667,832;6,101,647;-0,181649023
656,366;167,004;6,102,014;-0,181649023
657,466;1,672,248;610,234;-0,181609058
65,856,606;1,674,452;61,026;-0,181609058
659,666;1,676,636;6,102,706;-0,181619049
66,076,606;1,678,832;6,102,982;-0,181639031
661,866;1,681,036;6,103,722;-0,181639031
662,966;1,683,244;610,388;-0,181609058
66,406,606;1,685,448;6,103,991;-0,181649023
665,166;1,687,656;6,104,169;-0,181639031
66,626,606;1,689,852;6,104,503;-0,181639031
667,366;1,692,044;6,104,461;-0,18162904
668,466;1,694,236;6,104,882;-0,181649023
66,956,606;169,644;6,105,515;-0,181678996
670,666;1,698,636;610,557;-0,181688987
67,176,606;1,700,836;6,105,711;-0,18162904
672,866;1,703,036;6,106,277;-0,181659014
673,966;1,705,232;610,612;-0,181659014
67,506,606;1,707,432;6,106,635;-0,181609058
676,166;170,964;6,107,025;-0,18162904
67,726,606;1,711,832;6,107,041;-0,181659014
678,366;1,714,044;610,733;-0,181649023
679,466;1,716,256;6,107,888;-0,181649023
68,056,606;1,718,444;610,743;-0,181619049
681,666;1,720,636;6,107,532;-0,181669005
68,276,606;172,284;6,108,245;-0,181678996
683,866;1,725,032;6,108,108;-0,181659014
684,966;1,727,232;6,108,643;-0,181659014
68,606,606;1,729,444;6,108,966;-0,181659014
687,166;1,731,628;6,108,879;-0,181649023
68,826,606;1,733,828;6,109,174;-0,181649023
689,366;1,736,044;6,109,695;-0,181639031
690,466;173,824;6,109,317;-0,181649023
69,156,606;174,044;6,109,627;-0,181649023
692,666;1,742,664;6,110,304;-0,181659014
69,376,606;1,744,848;6,110,132;-0,181599067
694,866;174,702;6,109,814;-0,181599067
695,966;1,749,236;6,110,872;-0,181649023
69,706,606;175,144;6,110,494;-0,181659014
698,166;175,364;6,110,738;-0,181659014
69,926,606;1,755,848;6,110,772;-0,18162904
700,366;1,758,032;6,110,812;-0,181659014
701,466;1,760,228;6,110,973;-0,181678996
70,256,606;1,762,444;6,111,899;-0,181649023
703,666;1,764,644;6,111,531;-0,181659014
70,476,606;1,766,836;6,111,404;-0,181659014
705,866;1,769,048;611,174;-0,18162904
706,966;1,771,236;6,111,802;-0,181609058
70,806,606;177,344;6,111,966;-0,181639031
709,166;1,775,656;6,112,525;-0,181649023
71,026,606;177,784;6,112,388;-0,181619049
711,366;1,780,032;6,112,677;-0,181619049
712,466;1,782,248;6,113,091;-0,181609058
71,356,606;1,784,436;6,112,725;-0,181619049
714,666;1,786,632;6,112,846;-0,181659014
71,576,606;1,788,844;611,324;-0,181609058
716,866;179,104;6,113,195;-0,18162904
71,796,606;1,793,232;6,113,152;-0,18162904
71,906,606;1,795,432;6,113,515;-0,18162904
720,166;1,797,624;611,349;-0,181639031
72,126,606;1,799,824;6,114,164;-0,181609058
722,366;1,802,044;6,114,203;-0,181639031
72,346,606;1,804,236;6,114,241;-0,18162904
72,456,606;1,806,428;6,114,004;-0,181579085
725,666;1,808,624;6,114,292;-0,181619049
72,676,606;181,082;6,114,338;-0,181619049
727,866;1,813,012;6,114,968;-0,181659014
72,896,606;1,815,236;6,115,177;-0,181619049
73,006,606;1,817,444;6,115,207;-0,181639031
731,166;181,964;6,114,493;-0,181669005
73,226,606;1,821,828;6,114,598;-0,181609058
733,366;1,824,024;611,481;-0,181589076
73,446,606;182,622;611,508;-0,18162904
73,556,606;1,828,436;6,115,335;-0,18162904
736,666;1,830,636;6,115,329;-0,181609058
73,776,606;1,832,824;611,496;-0,181639031
738,866;1,835,024;6,114,997;-0,181649023
73,996,606;1,837,228;6,115,243;-0,181599067
74,106,606;1,839,428;611,538;-0,181639031
742,166;184,164;6,115,491;-0,181609058
74,326,606;1,843,844;6,115,617;-0,181589076
744,366;1,846,048;6,115,661;-0,181639031
74,546,606;1,848,248;6,115,298;-0,181599067
74,656,606;185,044;6,115,489;-0,18162904
747,666;185,264;6,115,572;-0,181639031
74,876,606;1,854,844;6,115,677;-0,181619049
749,866;1,857,036;6,115,835;-0,181609058
75,096,606;1,859,236;6,115,943;-0,18162904
75,206,606;1,861,428;611,568;-0,181619049
753,166;1,863,628;611,586;-0,181589076
75,426,606;186,584;6,116,146;-0,181609058
755,366;1,868,044;6,115,916;-0,181579085
75,646,606;1,870,244;6,115,901;-0,181619049
75,756,606;1,872,452;6,116,359;-0,181599067
758,666;1,874,652;6,115,817;-0,181609058
75,976,606;1,876,832;6,115,382;-0,181659014
760,866;1,879,036;611,616;-0,181639031
76,196,606;1,881,236;6,115,952;-0,181619049
76,306,606;188,344;6,115,787;-0,181589076
764,166;1,885,648;6,116,152;-0,181639031
76,526,606;188,784;6,115,909;-0,181599067
766,366;1,890,028;6,115,751;-0,18162904
76,746,606;1,892,248;6,116,257;-0,181649023
76,856,606;189,444;6,115,954;-0,181619049
769,666;1,896,636;6,115,813;-0,181639031
77,076,606;189,884;6,116,071;-0,181659014
771,866;1,901,032;6,115,704;-0,181619049
77,296,606;1,903,236;6,116,048;-0,181609058
77,406,606;1,905,464;6,116,512;-0,18162904
775,166;1,907,644;6,115,277;-0,181609058
77,626,606;1,909,852;6,115,583;-0,181589076
777,366;1,912,056;6,116,008;-0,181599067
77,846,606;1,914,244;611,531;-0,181599067
77,956,606;1,916,436;6,115,149;-0,181609058
780,666;1,918,656;6,115,747;-0,181639031
78,176,606;1,920,848;6,115,228;-0,181579085
782,866;1,923,052;6,115,419;-0,181609058
78,396,606;1,925,256;6,115,381;-0,18162904
78,506,606;192,744;6,115,119;-0,18162904
786,166;1,929,632;6,115,103;-0,181609058
78,726,606;1,931,852;6,115,723;-0,18162904
788,366;1,934,048;6,114,937;-0,181589076
78,946,606;1,936,252;6,114,879;-0,181599067
79,056,606;1,938,444;6,114,772;-0,181639031
791,666;1,940,628;6,114,653;-0,181649023
79,276,606;1,942,828;6,114,798;-0,181609058
793,866;1,945,048;611,524;-0,181589076
79,496,606;1,947,244;6,114,721;-0,181639031
79,606,606;1,949,448;6,114,647;-0,181609058
797,166;1,951,652;6,114,383;-0,181619049
79,826,606;1,953,832;6,114,146;-0,181619049
799,366;1,956,028;6,114,168;-0,181619049
80,046,606;1,958,244;6,114,523;-0,181619049
80,156,606;1,960,436;6,114,054;-0,18162904
802,666;196,262;6,113,796;-0,181609058
80,376,606;1,964,828;6,114,043;-0,181649023
804,866;1,967,024;6,113,799;-0,181619049
80,596,606;1,969,224;611,366;-0,181619049
80,706,606;197,144;6,113,879;-0,181619049
808,166;197,364;6,113,399;-0,181599067
80,926,606;197,584;6,113,424;-0,18162904
810,366;1,978,052;6,113,378;-0,181649023
81,146,606;198,024;6,113,131;-0,181609058
81,256,606;1,982,432;6,112,761;-0,18162904
813,666;198,464;6,112,783;-0,18162904
81,476,606;198,684;61,128;-0,181589076
815,866;1,989,032;6,112,559;-0,181649023
81,696,606;1,991,236;611,228;-0,181649023
81,806,606;1,993,428;6,112,369;-0,181589076
819,166;1,995,628;611,235;-0,181599067
82,026,606;1,997,844;6,112,317;-0,18162904
821,366;2,000,036;6,111,991;-0,181599067
82,246,606;2,002,232;6,111,539;-0,181619049
82,356,606;2,004,452;6,111,699;-0,18162904
824,666;2,006,652;6,111,382;-0,181639031
82,576,606;2,008,824;6,111,069;-0,18162904
826,866;2,011,032;611,129;-0,181659014
82,796,606;201,324;611,149;-0,181599067
82,906,606;2,015,432;6,110,827;-0,181639031
830,166;2,017,636;6,110,412;-0,181649023
83,126,606;2,019,836;6,110,424;-0,18162904
832,366;2,022,036;6,110,406;-0,181609058
83,346,606;2,024,244;6,110,106;-0,18162904
83,456,606;202,644;6,110,074;-0,181609058
835,666;202,864;6,109,814;-0,18162904
83,676,606;2,030,832;6,109,203;-0,181599067
837,866;2,033,036;6,109,399;-0,181609058
83,896,606;2,035,248;6,109,271;-0,181589076
84,006,606;2,037,452;6,108,587;-0,181619049
841,166;203,964;6,108,195;-0,181639031
84,226,606;204,184;6,108,443;-0,18162904
843,366;2,044,032;6,108,141;-0,181639031
84,446,606;2,046,228;6,108,151;-0,181609058
84,556,606;204,844;6,108,172;-0,181619049
846,666;2,050,636;6,107,383;-0,181609058
84,776,606;205,284;6,107,221;-0,181589076
848,866;205,504;6,107,048;-0,181619049
84,996,606;2,057,232;6,106,666;-0,181599067
85,106,606;2,059,428;6,106,527;-0,181589076
852,166;2,061,644;6,106,812;-0,181599067
85,326,606;2,063,836;6,106,113;-0,181599067
854,366;206,604;6,105,956;-0,181599067
85,546,606;2,068,244;6,105,801;-0,181609058
85,656,606;2,070,428;6,105,205;-0,181639031
857,666;2,072,632;6,105,129;-0,181589076
85,876,606;2,074,856;6,105,419;-0,181609058
859,866;2,077,048;6,104,673;-0,181599067
86,096,606;2,079,256;6,104,441;-0,18162904
86,206,606;2,081,464;6,104,285;-0,181589076
863,166;2,083,648;6,103,436;-0,181639031
86,426,606;208,584;6,103,137;-0,181579085
865,366;208,806;6,103,473;-0,181619049
86,646,606;2,090,256;6,102,734;-0,181609058
86,756,606;2,092,452;6,102,456;-0,181579085
868,666;2,094,656;6,102,652;-0,181649023
86,976,606;209,684;6,102,009;-0,181589076
870,866;2,099,032;6,101,642;-0,181609058
87,196,606;2,101,248;6,101,751;-0,181619049
87,306,606;210,344;6,101,118;-0,181609058
874,166;2,105,644;6,100,719;-0,181609058
87,526,606;2,107,856;6,100,854;-0,181589076
876,366;2,110,048;6,100,172;-0,18162904
87,746,606;2,112,236;6,099,868;-0,181619049
87,856,606;2,114,448;6,099,544;-0,18162904
879,666;2,116,636;6,099,137;-0,18162904
88,076,606;211,884;6,098,818;-0,181599067
881,866;2,121,052;6,098,711;-0,18162904
88,296,606;2,123,236;6,098,008;-0,181609058
88,406,606;2,125,432;6,097,692;-0,181619049
885,166;2,127,652;6,097,935;-0,181599067
88,626,606;2,129,848;6,097,189;-0,181639031
887,366;213,204;6,096,907;-0,181639031
88,846,606;213,426;6,097,016;-0,181619049
88,956,606;2,136,456;6,096,277;-0,181619049
890,666;2,138,632;6,095,124;-0,181589076
89,176,606;2,140,848;6,095,688;-0,181579085
892,866;2,143,044;6,095,267;-0,181589076
89,396,606;2,145,236;6,094,899;-0,181599067
89,506,606;2,147,448;6,094,409;-0,181559102
896,166;214,964;609,418;-0,181619049
89,726,606;215,184;6,093,661;-0,181589076
898,366;2,154,056;6,093,696;-0,181609058
89,946,606;2,156,256;6,092,975;-0,181599067
90,056,606;2,158,444;6,092,378;-0,181589076
901,666;2,160,644;6,091,951;-0,181619049
90,276,606;2,162,844;609,181;-0,181609058
903,866;2,165,048;6,091,438;-0,181589076
90,496,606;2,167,268;6,091,136;-0,181609058
90,606,606;2,169,456;60,901;-0,181589076
907,166;2,171,648;6,089,602;-0,181619049
90,826,606;2,173,852;6,089,072;-0,181599067
909,366;2,176,052;6,088,971;-0,181599067
91,046,606;2,178,252;6,088,671;-0,181599067
91,156,606;2,180,456;6,088,176;-0,181609058
912,666;2,182,652;6,087,642;-0,18162904
91,376,606;2,184,848;6,087,351;-0,18162904
914,866;2,187,044;6,086,518;-0,181619049
91,596,606;2,189,236;6,086,535;-0,181609058
91,706,606;2,191,444;6,086,408;-0,181569093
918,166;2,193,656;6,085,865;-0,181599067
91,926,606;2,195,852;6,085,453;-0,181619049
920,366;2,198,048;6,084,619;-0,181589076
92,146,606;2,200,236;608,395;-0,181609058
92,256,606;220,244;608,377;-0,18162904
923,666;2,204,648;6,083,602;-0,181659014
92,476,606;2,206,852;6,082,762;-0,181639031
925,866;2,209,052;6,082,418;-0,181589076
92,696,606;2,211,256;6,082,081;-0,181589076
92,806,606;221,344;6,081,243;-0,181589076
929,166;2,215,636;6,080,893;-0,181619049
93,026,606;2,217,844;6,080,734;-0,181589076
931,366;2,220,044;6,079,632;-0,181599067
93,246,606;2,222,244;6,079,342;-0,181639031
93,356,606;222,444;6,078,672;-0,181639031
934,666;2,226,624;6,077,834;-0,181589076
93,576,606;2,228,824;6,077,514;-0,181619049
936,866;2,231,036;6,077,406;-0,18162904
93,796,606;2,233,232;6,076,357;-0,18162904
93,906,606;2,235,436;6,075,965;-0,181599067
940,166;2,237,648;6,075,569;-0,18162904
94,126,606;2,239,836;6,074,709;-0,181599067
942,366;2,242,032;6,073,908;-0,18162904
94,346,606;224,424;6,073,923;-0,18162904
94,456,606;2,246,432;6,072,628;-0,181599067
945,666;2,248,632;6,072,219;-0,181589076
94,676,606;2,250,848;6,071,933;-0,181619049
947,866;2,253,032;6,070,859;-0,181599067
94,896,606;2,255,232;6,070,188;-0,181589076
95,006,606;2,257,456;6,070,231;-0,18162904
951,166;2,259,652;6,068,998;-0,18162904
95,226,606;2,261,852;6,068,335;-0,181589076
953,366;226,406;6,067,918;-0,181619049
95,446,606;2,266,264;6,067,218;-0,181579085
95,556,606;2,268,456;6,066,138;-0,181589076
956,666;2,270,656;6,065,788;-0,181609058
95,776,606;2,272,848;6,064,879;-0,181599067
958,866;2,275,052;6,064,348;-0,181609058
95,996,606;227,726;6,063,956;-0,181599067
96,106,606;2,279,444;6,062,922;-0,181589076
962,166;2,281,636;606,217;-0,181599067
96,326,606;2,283,856;6,061,534;-0,181619049
964,366;2,286,048;606,053;-0,181589076
96,546,606;2,288,244;6,059,753;-0,181579085
96,656,606;2,290,448;6,059,315;-0,181569093
967,666;2,292,636;6,058,138;-0,181649023
96,876,606;2,294,832;605,768;-0,181569093
969,866;2,297,052;605,712;-0,181609058
97,096,606;2,299,252;6,056,291;-0,181589076
97,206,606;2,301,444;6,055,089;-0,181599067
97,316,606;2,303,652;6,054,503;-0,181649023
97,426,606;230,584;6,053,367;-0,181609058
975,366;2,308,036;6,052,735;-0,181589076
97,646,606;2,310,256;6,052,319;-0,181599067
97,756,606;2,312,448;6,051,356;-0,181569093
97,866,606;2,314,648;6,050,264;-0,181569093
97,976,606;2,316,856;604,927;-0,181599067
980,866;2,319,044;6,048,322;-0,181639031
98,196,606;232,124;6,047,347;-0,181609058
98,306,606;2,323,464;6,046,893;-0,181619049
98,416,606;232,566;6,045,686;-0,181609058
98,526,606;2,327,852;6,044,777;-0,181609058
986,366;2,330,044;6,043,749;-0,181599067
98,746,606;233,224;6,042,908;-0,181549111
98,856,606;2,334,436;6,042,027;-0,181609058
98,966,606;2,336,664;6,041,293;-0,18162904
99,076,606;2,338,856;604,008;-0,181589076
991,866;2,341,052;6,038,985;-0,181579085
99,296,606;2,343,244;6,037,662;-0,181609058
99,406,606;234,544;6,037,099;-0,181639031
99,516,606;2,347,632;6,035,772;-0,181619049
99,626,606;2,349,852;6,034,856;-0,181609058
997,366;2,352,052;6,033,673;-0,181609058
99,846,606;2,354,244;6,032,314;-0,181619049
99,956,606;235,644;6,030,949;-0,181559102
100,066,606;2,358,636;6,030,192;-0,181599067
100,176,606;236,084;6,029,277;-0,181609058
1,002,866;2,363,052;6,028,103;-0,181609058
100,396,606;2,365,252;6,026,769;-0,181619049
100,506,606;2,367,452;6,025,587;-0,181619049
100,616,606;236,966;6,024,185;-0,181599067
100,726,606;2,371,856;6,023,192;-0,181589076
1,008,366;2,374,056;6,021,959;-0,181599067
100,946,606;2,376,252;6,020,479;-0,181619049
101,056,606;2,378,448;6,019,527;-0,181609058
101,166,606;2,380,648;6,018,149;-0,181609058
101,276,606;238,284;6,016,472;-0,181569093
1,013,866;2,385,036;6,015,412;-0,181579085
101,496,606;2,387,248;6,014,534;-0,181579085
101,606,606;2,389,452;6,012,892;-0,181589076
101,716,606;2,391,656;6,011,471;-0,181589076
101,826,606;2,393,848;601,024;-0,181599067
1,019,366;239,606;6,008,694;-0,181609058
102,046,606;239,826;6,006,939;-0,181599067
102,156,606;2,400,452;6,005,162;-0,181619049
102,266,606;2,402,644;6,003,529;-0,181639031
102,376,606;2,404,856;6,002,356;-0,181609058
102,486,606;2,407,056;6,000,945;-0,181589076
102,596,606;2,409,248;5,999,209;-0,181619049
102,706,606;241,144;5,997,695;-0,181619049
1,028,166;2,413,652;5,996,598;-0,181599067
1,029,266;241,584;5,994,185;-0,181609058
103,036,606;2,418,044;5,992,727;-0,181569093
103,146,606;2,420,252;5,991,225;-0,181619049
103,256,606;2,422,436;5,989,159;-0,181609058
1,033,666;2,424,628;5,987,393;-0,18162904
1,034,766;2,426,848;5,986,548;-0,181589076
103,586,606;2,429,048;5,984,053;-0,181599067
103,696,606;243,124;5,981,896;-0,181579085
103,806,606;2,433,448;5,980,315;-0,181619049
1,039,166;2,435,636;5,978,048;-0,181599067
1,040,266;2,437,832;5,975,977;-0,181609058
104,136,606;2,440,052;597,478;-0,181609058
104,246,606;2,442,244;5,972,257;-0,181619049
104,356,606;244,444;5,970,402;-0,181609058
1,044,666;2,446,648;5,968,568;-0,181609058
1,045,766;2,448,832;5,966,109;-0,18162904
104,686,606;2,451,032;5,964,065;-0,181599067
104,796,606;2,453,252;5,962,631;-0,181619049
1,049,066;2,455,452;5,959,955;-0,181599067
1,050,166;2,457,652;5,957,722;-0,181599067
1,051,266;2,459,856;5,955,777;-0,181589076
105,236,612;2,462,032;5,953,333;-0,181619049
105,346,612;2,464,232;5,951,101;-0,181589076
1,054,566;246,646;5,949,268;-0,181609058
1,055,666;2,468,656;5,946,355;-0,181599067
1,056,766;2,470,852;5,943,948;-0,181609058
105,786,612;2,473,064;5,941,876;-0,181599067
105,896,612;2,475,248;5,939,329;-0,18162904
1,060,066;2,477,436;5,936,987;-0,18162904
1,061,166;2,479,652;5,935,094;-0,181619049
1,062,266;2,481,852;5,932,233;-0,181599067
106,336,612;2,484,044;5,929,469;-0,181599067
106,446,612;2,486,248;5,926,991;-0,181609058
1,065,566;2,488,436;5,924,395;-0,181579085
1,066,666;2,490,636;5,921,854;-0,181599067
1,067,766;249,286;5,919,567;-0,181599067
106,886,612;2,495,052;5,916,775;-0,181609058
106,996,612;2,497,248;591,399;-0,181589076
1,071,066;2,499,464;5,911,116;-0,181599067
1,072,166;2,501,668;590,807;-0,181589076
1,073,266;250,386;5,905,346;-0,181569093
107,436,612;2,506,076;5,902,678;-0,181589076
107,546,612;2,508,264;5,899,871;-0,181559102
1,076,566;2,510,456;5,896,798;-0,181569093
1,077,666;2,512,656;589,398;-0,181609058
1,078,766;251,486;589,072;-0,181579085
107,986,612;2,517,056;5,887,836;-0,181599067
108,096,612;251,928;5,884,835;-0,18162904
1,082,066;2,521,476;588,156;-0,181569093
1,083,166;2,523,664;5,878,342;-0,181579085
1,084,266;2,525,864;5,875,298;-0,181599067
108,536,612;252,808;5,872,607;-0,181609058
108,646,612;2,530,272;5,868,978;-0,181569093
1,087,566;2,532,468;586,543;-0,181579085
1,088,666;2,534,664;5,862,299;-0,181589076
1,089,766;2,536,868;5,858,887;-0,181599067
109,086,612;253,906;5,855,271;-0,181549111
109,196,612;2,541,268;5,852,515;-0,181609058
1,093,066;2,543,468;5,849,078;-0,181579085
1,094,166;2,545,684;5,845,469;-0,181579085
1,095,266;2,547,876;5,841,592;-0,181579085
109,636,612;2,550,076;5,838,242;-0,181609058
109,746,612;2,552,272;5,834,298;-0,181619049
1,098,566;2,554,468;583,106;-0,181639031
1,099,666;255,668;5,827,394;-0,181599067
110,076,613;2,558,884;582,363;-0,181589076
110,186,612;2,561,084;5,819,729;-0,181589076
110,296,612;2,563,272;5,816,277;-0,181589076
1,104,066;2,565,468;5,812,097;-0,181619049
1,105,166;256,766;5,808,145;-0,181579085
110,626,613;2,569,876;5,804,657;-0,181619049
110,736,612;2,572,072;5,800,433;-0,181579085
110,846,612;2,574,272;5,796,569;-0,181609058
1,109,566;257,648;5,793,222;-0,181619049
1,110,666;2,578,668;5,788,579;-0,181589076
111,176,613;258,086;5,784,261;-0,181569093
111,286,612;258,308;5,780,606;-0,181609058
111,396,612;2,585,268;5,775,812;-0,181579085
1,115,066;2,587,476;5,771,744;-0,181589076
1,116,166;258,968;5,767,825;-0,181589076
111,726,613;2,591,864;576,306;-0,181609058
111,836,612;2,594,056;5,758,992;-0,181599067
111,946,612;259,628;5,755,066;-0,181619049
1,120,566;2,598,476;5,750,114;-0,181589076
1,121,666;2,600,684;5,745,053;-0,181599067
112,276,613;2,602,892;5,740,945;-0,181589076
112,386,612;2,605,084;5,735,935;-0,181619049
112,496,612;2,607,276;5,731,342;-0,181589076
1,126,066;2,609,492;5,727,217;-0,181599067
1,127,166;2,611,688;5,721,906;-0,181619049
112,826,613;2,613,884;5,717,129;-0,181599067
112,936,612;2,616,088;5,712,316;-0,181599067
113,046,612;2,618,276;5,707,276;-0,181609058
1,131,566;2,620,468;5,702,231;-0,181599067
1,132,666;2,622,688;5,697,832;-0,181599067
113,376,613;2,624,876;5,692,263;-0,181579085
113,486,612;2,627,076;5,687,531;-0,18162904
113,596,612;2,629,288;5,682,455;-0,181599067
1,137,066;263,148;5,677,249;-0,181609058
1,138,166;263,368;567,153;-0,181589076
113,926,613;2,635,896;5,666,577;-0,181599067
114,036,612;2,638,084;566,038;-0,181609058
114,146,612;2,640,276;5,655,279;-0,181569093
1,142,566;2,642,488;5,650,205;-0,181649023
1,143,666;2,644,676;5,644,509;-0,181579085
114,476,613;2,646,872;5,638,598;-0,181609058
114,586,612;2,649,096;5,633,344;-0,181589076
114,696,612;2,651,296;5,627,181;-0,181589076
1,148,066;2,653,492;5,621,346;-0,181599067
1,149,166;2,655,696;5,615,653;-0,181609058
115,026,613;2,657,896;5,610,287;-0,181619049
115,136,612;26,601;5,604,143;-0,181569093
115,246,612;2,662,296;5,597,904;-0,181559102
1,153,566;2,664,488;5,591,844;-0,181619049
1,154,666;2,666,688;5,585,592;-0,181619049
115,576,613;2,668,896;5,579,218;-0,181579085
115,686,612;2,671,088;5,572,994;-0,181579085
115,796,612;2,673,292;5,567,059;-0,181599067
1,159,066;2,675,508;5,560,684;-0,181599067
1,160,166;2,677,704;5,553,921;-0,18162904
116,126,613;2,679,896;5,547,271;-0,181609058
116,236,612;2,682,096;5,540,687;-0,181569093
116,346,612;2,684,296;5,534,041;-0,181599067
1,164,566;26,865;5,527,501;-0,181559102
1,165,666;268,872;5,520,809;-0,18162904
116,676,613;269,092;5,513,893;-0,181589076
116,786,612;26,931;5,506,666;-0,181569093
116,896,612;26,953;5,499,578;-0,181599067
1,170,066;26,975;5,492,514;-0,181609058
1,171,166;26,997;5,485,284;-0,181549111
117,226,613;2,701,916;5,478,083;-0,181589076
117,336,612;2,704,116;5,470,855;-0,181609058
117,446,612;2,706,312;5,463,383;-0,181619049
1,175,566;2,708,512;5,455,776;-0,181589076
1,176,666;2,710,708;5,448,297;-0,181569093
117,776,613;2,712,908;5,440,904;-0,181569093
117,886,612;2,715,124;5,432,776;-0,181589076
117,996,612;271,732;5,425,045;-0,181619049
1,181,066;271,952;5,416,842;-0,181569093
1,182,166;2,721,708;5,408,667;-0,181609058
118,326,613;2,723,896;540,085;-0,181609058
118,436,612;27,261;5,393,096;-0,181599067
118,546,612;2,728,312;5,384,634;-0,18162904
1,186,566;2,730,512;5,376,217;-0,181589076
1,187,666;273,272;536,782;-0,18162904
118,876,613;2,734,916;5,358,841;-0,181589076
118,986,612;2,737,108;5,350,221;-0,181589076
119,096,612;2,739,312;5,342,141;-0,181609058
1,192,066;2,741,516;5,332,885;-0,181579085
1,193,166;2,743,716;5,324,025;-0,181589076
119,426,613;274,592;531,516;-0,181589076
119,536,612;2,748,108;5,305,461;-0,181579085
119,646,612;2,750,308;5,296,184;-0,181609058
1,197,566;275,252;5,287,083;-0,18162904
1,198,666;2,754,724;5,277,134;-0,181639031
119,976,613;2,756,924;5,267,581;-0,181599067
120,086,612;2,759,128;525,806;-0,181579085
120,196,612;2,761,324;5,247,865;-0,181609058
1,203,066;276,352;5,237,765;-0,181619049
1,204,166;2,765,732;5,227,642;-0,181619049
120,526,613;276,792;5,216,975;-0,18162904
120,636,612;277,012;5,206,513;-0,181579085
120,746,612;2,772,324;5,196,576;-0,18162904
1,208,566;277,452;5,185,573;-0,181589076
1,209,666;2,776,716;517,489;-0,181639031
121,076,613;2,778,936;5,164,188;-0,181599067
121,186,612;2,781,128;5,152,416;-0,181639031
121,296,612;2,783,336;5,141,099;-0,181619049
1,214,066;2,785,544;5,129,893;-0,18162904
1,215,166;2,787,744;5,118,158;-0,181619049
121,626,613;2,789,948;5,106,459;-0,181589076
121,736,612;2,792,148;5,094,739;-0,18162904
121,846,612;2,794,336;5,082,341;-0,18162904
1,219,566;2,796,544;5,070,062;-0,181609058
1,220,666;2,798,752;5,057,801;-0,181619049
122,176,613;2,800,948;5,044,763;-0,181599067
122,286,612;280,314;5,032,055;-0,181599067
122,396,612;2,805,364;5,019,289;-0,181609058
1,225,066;280,756;5,005,454;-0,181609058
1,226,166;280,976;4,991,838;-0,181649023
122,726,613;2,811,964;4,978,022;-0,181609058
122,836,612;2,814,152;4,963,872;-0,18162904
122,946,612;2,816,352;4,949,395;-0,18162904
1,230,566;2,818,576;4,934,998;-0,181619049
1,231,666;2,820,776;4,918,917;-0,181619049
123,276,613;2,822,964;4,901,946;-0,181609058
123,386,612;2,825,164;4,883,696;-0,18162904
123,495,412;2,827,328;4,827,734;-0,181639031
1,235,224;2,827,876;4,711,126;-0,181619049
1235,25;28,281;2,847,769;-0,178781564