File: tensile_test_ontology_TTO/data/primary_data/Zy3.csv
Time;Crosshead travel;Force;Strain
(s);(mm);(kN);(%)
0;0;0,1937;0
0,978;0,05108;0,74712;0,002651231
1,47;0,12256;188,192;0,007503485
1,85;0,192;301,483;0,012375747
2,198;0,26584;415,231;0,017157968
2,46;0,32204;369,882;0,024351309
3,052;0,47568;481,845;0,028733344
3,502;0,61844;593,843;0,033395509
3,842;0,73796;706,751;0,037997646
4,118;0,84004;82,126;0,042729844
4,36;0,93224;937,262;0,047452037
4,58;101,728;1,052,109;0,05217423
4,794;110,068;116,985;0,056896423
4,992;117,812;1,282,769;0,061418523
5,19;125,548;1,397,752;0,066120706
5,388;133,308;1,516,927;0,070782872
5,586;141,064;1,637,681;0,07564513
5,782;148,728;175,922;0,080537402
5,968;15,598;1,875,428;0,085209571
6,148;16,298;1,988,965;0,089681648
6,324;169,796;2,101,481;0,094203748
6,512;17,696;2,219,048;0,098905932
6,688;183,636;2,331,214;0,103357999
6,864;190,256;2,442,337;0,107910113
7,04;19,686;2,555,245;0,112452223
7,216;203,408;2,668,052;0,117114388
7,392;209,896;2,780,218;0,121666502
7,568;216,336;2,893,598;0,126338672
7,744;222,716;3,006,291;0,131000837
7,92;229,048;3,119,702;0,135823076
8,096;235,292;3,231,821;0,140595292
8,276;241,628;3,345,344;0,145617625
8,462;248,072;3,461,504;0,150679976
8,654;25,464;3,580,053;0,156022457
8,852;261,292;3,700,392;0,161685087
9,038;26,762;3,816,649;0,164516401
9,234;27,424;3,936,184;0,170849342
9,432;280,668;4,052,385;0,177232307
9,632;286,928;4,165,491;0,183675299
9,85;293,484;4,282,708;0,190918663
10,07;299,828;4,396,327;0,198222054
10,312;306,404;4,511,231;0,206075702
10,566;31,298;4,625,222;0,214359549
10,846;319,828;4,739,252;0,223223665
11,178;327,484;4,852,659;0,234068702
11,834;34,018;4,878,412;0,263172217
12,814;346,928;4,795,882;0,302530495
13,914;350,596;4,780,886;0,330143319
15,014;354,356;4,777,559;0,358676569
16,114;357,732;4,782,663;0,384468547
17,214;360,736;477,142;0,413712128
18,314;3,636;4,772,141;0,440974789
19,414;366,488;476,854;0,469387984
20,514;369,004;4,769,756;0,496270468
21,614;3,714;4,767,358;0,52407338
22,714;373,836;4,762,358;0,552916775
23,814;37,592;4,762,595;0,57947911
24,914;377,964;4,760,979;0,606651729
26,014;380,048;4,760,151;0,634534678
27,114;382,124;476,266;0,661777329
28,214;384,536;4,775,066;0,688599786
29,314;386,284;476,021;0,716862911
30,414;38,826;4,762,424;0,744515753
31,514;390,172;4,762,635;0,772128577
32,614;392,056;4,763,426;0,799831442
33,714;393,788;4,760,552;0,826984051
34,814;395,548;4,759,361;0,854616884
35,914;397,264;4,758,529;0,881909559
37,014;399,024;4,757,792;0,91001261
38,114;400,792;4,751,349;0,937975596
39,214;4,026;4,758,034;0,965178229
40,314;40,424;4,756,866;0,99229082
41,414;405,864;4,753,886;1,020,063,718
42,514;407,488;475,374;1,047,156,299
43,614;40,912;4,753,643;1,074,689,086
44,714;410,784;4,755,221;110,213,183
45,814;412,392;4,753,715;1,130,094,816
46,914;413,984;4,754,237;1,157,247,426
48,014;4,156;4,754,649;11,849,703
49,114;41,714;4,753,754;1,212,142,919
50,214;41,866;4,751,425;1,239,945,831
51,314;4,202;4,751,199;1,267,378,571
52,414;421,672;4,748,622;1,294,791,301
53,514;42,316;4,747,771;1,322,164,013
54,614;424,736;474,999;1,350,147,008
55,714;426,192;4,748,099;1,377,659,785
56,814;427,672;4,747,514;1,405,392,664
57,914;429,176;4,748,501;1,432,925,451
59,014;430,628;4,748,965;1,460,008,028
60,114;432,096;4,749,552;14,875,108
61,214;433,488;4,746,278;1,515,003,568
62,314;434,736;4,736,663;1,542,686,424
63,414;435,948;4,725,883;1,570,379,284
64,514;437,084;4,711,742;1,597,882,056
6,561,401;438,428;4,708,516;1,625,324,801
6,671,401;440,016;4,719,003;1,652,397,373
67,814;44,178;4,736,193;1,679,980,183
68,914;443,604;4,755,407;1,707,102,779
70,014;445,432;4,772,796;1,734,725,607
7,111,401;447,336;4,790,281;1,761,888,221
7,221,401;449,636;4,817,911;1,787,119,938
73,314;451,452;4,817,428;1,816,813,728
74,414;453,536;483,253;1,844,126,412
75,514;455,652;4,844,032;1,871,549,147
7,661,401;457,872;4,855,677;1,899,452,106
7,771,401;460,104;4,865,673;1,926,504,669
78,814;462,384;4,874,941;1,953,477,195
79,914;464,836;4,885,374;1,981,480,199
8,101,401;467,324;4,894,941;2,008,682,832
8,211,401;469,888;490,423;2,035,995,516
8,321,401;472,508;4,912,826;2,063,388,237
84,314;475,236;4,922,268;2,090,670,908
85,414;47,842;4,939,117;2,118,593,875
8,651,401;481,088;4,941,215;2,145,896,554
8,761,401;483,996;4,951,198;2,173,419,336
8,871,401;486,876;4,959,729;2,200,611,964
89,814;489,852;4,970,135;2,228,054,709
90,914;492,812;497,768;2,255,587,495
9,201,401;4,958;4,987,355;2,283,030,239
9,311,401;498,772;4,995,505;2,310,482,988
9,421,401;501,792;5,005,434;2,337,815,682
95,314;50,516;5,021,729;2,365,188,393
96,414;508,056;5,021,937;2,393,201,403
9,751,401;511,068;5,031,536;2,420,644,147
9,861,401;51,402;5,040,161;2,447,836,775
9,971,401;517,056;5,049,515;2,475,639,687
100,814;520,048;5,058,236;2,502,902,348
101,914;523,072;5,067,066;2,530,675,246
10,301,401;525,988;5,074,281;2,557,817,851
10,411,401;529,008;5,084,658;2,585,560,734
10,521,401;532,224;5,098,516;2,612,803,386
106,314;535,052;5,098,569;2,640,726,353
107,414;537,932;510,622;2,668,059,047
10,851,401;540,852;5,115,278;2,695,361,726
10,961,401;54,382;512,349;2,723,334,717
11,071,401;54,672;513,174;2,750,697,424
111,814;549,596;5,138,958;2,778,290,238
11,291,401;552,456;5,146,433;2,805,552,899
11,401,401;555,364;5,155,662;2,833,085,685
11,511,401;558,544;5,168,824;2,860,878,592
11,621,401;561,244;5,168,763;2,888,391,369
117,314;564,036;517,676;2,915,483,951
11,841,401;56,686;518,436;2,942,966,714
11,951,401;569,716;5,192,024;2,970,859,667
12,061,401;572,544;5,199,168;2,998,382,449
12,171,401;575,392;5,206,582;3,026,075,309
122,814;57,818;5,213,338;3,053,227,919
12,391,401;58,102;5,221,196;3,080,810,729
12,501,401;584,024;5,227,919;3,108,603,636
12,611,401;586,784;5,234,023;313,576,625
12,721,401;5,896;5,240,122;3,163,539,148
12,831,401;592,388;5,246,805;3,190,581,706
129,414;595,252;5,255,268;3,218,364,609
13,051,401;598,044;526,141;3,245,857,376
13,161,402;60,086;5,268,983;3,273,190,069
132,714;6,036;5,274,045;3,300,432,721
13,381,402;606,604;5,286,947;332,689,501
134,914;60,936;5,285,748;3,355,828,447
136,014;612,104;5,292,528;3,383,041,084
13,711,402;61,494;530,045;3,410,944,042
138,214;617,712;5,306,656;3,438,126,666
13,931,402;620,508;5,313,382;3,465,639,443
140,414;623,264;5,318,351;3,493,022,159
141,514;626,076;5,324,876;3,520,574,955
14,261,402;62,888;5,330,358;3,548,267,816
143,714;63,178;5,335,787;3,575,870,634
14,481,402;634,584;5,343,283;3,603,533,481
145,914;637,312;5,348,847;3,630,826,156
147,014;640,068;535,501;3,658,328,928
14,811,402;642,788;5,359,671;3,685,631,607
149,214;645,532;5,365,863;3,713,084,356
15,031,402;64,828;537,127;3,740,847,249
151,414;651,024;5,377,566;3,768,289,994
152,514;65,394;5,383,148;3,796,313,008
15,361,402;656,596;5,387,875;3,823,145,469
15,462,202;659,116;5,394,325;3,848,247,126
15,562,402;660,252;5,378,169;3,862,953,956
15,672,402;662,452;5,391,049;3,883,453,476
157,824;664,648;5,396,817;3,905,133,544
15,892,402;666,848;5,401,284;3,926,963,682
160,024;669,028;5,405,656;3,948,733,792
18,319,802;670,604;5,285,665;-0,032355026
184,298;672,816;5,367,983;-0,032335016
18,539,802;675,016;5,409,959;-0,032355026
18,649,802;677,216;5,425,888;-0,03236503
187,598;679,428;5,432,187;-0,03236503
18,869,802;681,616;5,435,861;-0,032355026
189,798;683,804;5,439,171;-0,032325012
19,089,802;686,016;5,443,033;-0,032345021
19,199,802;688,216;5,446,113;-0,032345021
193,098;69,042;5,449,513;-0,032345021
19,419,802;692,608;5,452,784;-0,032355026
195,298;694,796;5,456,755;-0,032355026
19,639,802;696,992;5,460,598;-0,032335016
19,749,802;699,208;5,464,638;-0,032335016
198,598;701,408;5,468,071;-0,03236503
19,969,802;703,608;5,471,748;-0,032335016
200,798;705,816;5,475,595;-0,032325012
20,189,802;708,004;547,869;-0,032375035
20,299,802;710,204;5,481,977;-0,03238504
204,098;712,416;5,486,312;-0,032375035
20,519,802;714,612;5,489,869;-0,032355026
206,298;716,812;5,493,523;-0,032315007
20,739,802;719,024;5,497,344;-0,03238504
20,849,802;721,216;5,500,593;-0,03236503
209,598;723,404;550,331;-0,032355026
21,069,802;725,616;5,507,468;-0,032355026
211,798;727,812;551,127;-0,032325012
21,289,802;7,3;5,514,558;-0,032375035
21,399,802;732,204;5,518,216;-0,032345021
215,098;734,396;5,521,616;-0,032325012
21,619,802;736,596;5,524,818;-0,032335016
217,298;738,804;552,834;-0,032355026
21,839,802;741,004;5,531,349;-0,032335016
21,949,802;743,196;5,534,655;-0,03238504
220,598;745,404;5,538,051;-0,03236503
22,169,802;747,604;5,541,359;-0,032335016
222,798;7,498;5,544,474;-0,032345021
22,389,802;752,004;5,547,733;-0,032325012
22,499,802;7,542;5,551,046;-0,032375035
226,098;7,564;5,553,212;-0,03238504
22,719,802;758,604;5,555,812;-0,032395044
228,298;7,608;5,559,228;-0,032345021
22,939,802;7,63;5,562,396;-0,032375035
23,049,802;765,212;556,548;-0,03236503
231,598;767,408;5,569,031;-0,03236503
23,269,802;769,604;5,571,676;-0,032355026
233,798;7,718;5,574,808;-0,03236503
23,489,802;773,996;5,577,711;-0,032355026
23,599,802;776,196;5,580,907;-0,03236503
237,098;778,396;5,583,743;-0,03238504
23,819,802;780,596;5,586,994;-0,03238504
239,298;7,828;5,589,925;-0,032345021
24,039,802;784,988;5,592,551;-0,032345021
24,149,802;787,184;5,595,571;-0,03236503
242,598;789,388;5,598,633;-0,032325012
24,369,802;791,596;5,601,436;-0,032345021
244,798;7,938;5,604,513;-0,03236503
24,589,802;7,96;5,607,572;-0,03238504
24,699,802;798,184;5,610,045;-0,032375035
248,098;800,368;561,284;-0,03236503
24,919,802;802,576;5,616,125;-0,03236503
25,029,802;804,784;5,618,607;-0,03236503
25,139,802;806,992;5,621,546;-0,032345021
25,249,802;809,196;5,624,536;-0,03236503
253,598;811,388;5,626,875;-0,03238504
25,469,802;81,358;5,629,522;-0,032425058
25,579,802;815,792;5,632,412;-0,03238504
25,689,802;817,988;5,634,865;-0,032435063
25,799,802;820,204;5,637,451;-0,03238504
25,909,802;822,404;5,640,045;-0,032375035
260,198;824,576;5,641,995;-0,032395044
261,298;826,764;5,645,153;-0,03238504
262,398;828,984;5,648,038;-0,03236503
26,349,803;83,118;5,650,625;-0,03238504
26,459,803;833,384;5,653,287;-0,03238504
265,698;835,588;5,656,312;-0,032405049
266,798;837,772;5,658,388;-0,032405049
267,898;83,996;5,660,887;-0,032425058
26,899,803;84,218;5,664,061;-0,032405049
27,009,803;844,364;5,666,372;-0,032375035
271,198;846,572;5,669,025;-0,032395044
272,298;848,788;5,672,195;-0,032375035
273,398;85,098;5,674,012;-0,032375035
27,449,803;853,164;5,676,606;-0,032405049
27,559,803;855,376;5,679,612;-0,03238504
276,698;857,576;568,179;-0,03238504
277,798;85,978;5,684,116;-0,03238504
278,898;86,198;568,678;-0,032405049
27,999,803;864,172;5,688,954;-0,032395044
28,109,803;866,364;5,691,608;-0,032395044
28,219,803;868,584;5,694,497;-0,03238504
283,298;87,078;569,672;-0,032315007
284,398;872,976;5,698,941;-0,03236503
28,549,803;875,188;5,701,512;-0,03238504
28,659,803;877,384;5,703,847;-0,032405049
28,769,803;87,958;5,706,202;-0,032395044
288,798;881,788;5,708,967;-0,032425058
289,898;883,984;5,711,169;-0,03238504
29,099,803;886,176;5,713,406;-0,03238504
29,209,803;888,388;5,715,832;-0,032405049
29,319,803;89,058;5,718,011;-0,032415054
294,298;892,772;5,720,173;-0,032375035
295,398;894,992;5,722,836;-0,03236503
29,649,803;897,184;5,725,025;-0,032435063
29,759,803;899,368;5,727,046;-0,032405049
29,869,803;901,568;5,729,309;-0,032435063
299,798;903,756;5,731,805;-0,032375035
300,898;905,956;5,733,991;-0,03238504
30,199,803;908,168;5,736,505;-0,03236503
30,309,803;910,368;5,738,722;-0,032425058
30,419,803;91,256;5,740,716;-0,032405049
305,298;914,768;5,742,797;-0,03238504
306,398;916,956;5,744,957;-0,03236503
30,749,803;919,156;5,746,976;-0,03236503
30,859,803;921,376;5,749,792;-0,03238504
30,969,803;923,588;5,751,955;-0,032415054
310,798;925,788;5,753,854;-0,03236503
311,898;927,984;5,755,776;-0,032375035
31,299,803;930,172;5,757,921;-0,032445067
31,409,803;932,364;5,760,044;-0,032375035
31,519,803;93,458;5,762,597;-0,032355026
316,298;936,784;5,764,594;-0,032375035
317,398;938,984;5,766,768;-0,032405049
31,849,803;941,184;5,768,692;-0,032395044
31,959,803;94,338;5,770,865;-0,032375035
32,069,803;94,558;5,772,971;-0,032405049
321,798;947,788;5,775,089;-0,032395044
322,898;950,004;5,777,525;-0,032395044
32,399,803;952,208;577,922;-0,032405049
32,509,803;954,384;578,041;-0,032445067
32,619,803;956,576;5,782,815;-0,032405049
327,298;958,784;5,785,263;-0,032375035
328,398;960,992;5,787,031;-0,032415054
32,949,803;963,192;5,789,273;-0,032395044
33,059,803;9,654;5,791,349;-0,032395044
33,169,803;967,584;5,793,235;-0,032405049
332,798;969,776;5,795,066;-0,03236503
333,898;97,198;5,797,333;-0,032415054
33,499,803;97,418;5,799,018;-0,032435063
33,609,803;97,638;5,801,181;-0,032445067
33,719,803;978,584;5,803,249;-0,032415054
338,298;980,776;5,804,796;-0,032405049
339,398;982,972;580,686;-0,032395044
34,049,803;985,164;5,808,982;-0,032405049
34,159,803;987,364;581,046;-0,032405049
34,269,803;989,572;5,812,618;-0,032375035
343,798;99,178;5,814,609;-0,03236503
344,898;993,964;5,816,182;-0,032405049
34,599,803;996,156;5,818,237;-0,03238504
34,709,803;998,372;5,820,563;-0,032405049
34,819,803;1,000,572;5,822,193;-0,032405049
349,298;1,002,772;5,823,613;-0,032425058
350,398;100,498;5,825,845;-0,032375035
35,149,803;1,007,172;5,827,182;-0,03236503
35,259,803;1,009,368;5,828,971;-0,032415054
35,369,803;101,158;5,831,059;-0,032415054
354,798;1,013,772;5,832,515;-0,032395044
355,898;1,015,968;583,439;-0,032405049
35,699,803;1,018,172;5,836,642;-0,032395044
35,809,803;1,020,368;5,837,748;-0,032355026
35,919,803;102,256;5,839,384;-0,032405049
360,298;1,024,784;5,841,494;-0,032415054
361,398;102,698;5,843,072;-0,032415054
36,249,803;1,029,172;5,844,565;-0,032395044
36,359,803;1,031,372;5,846,748;-0,03238504
36,469,803;103,356;5,848,048;-0,03238504
365,798;1,035,748;5,849,838;-0,032395044
366,898;1,037,968;585,192;-0,03238504
36,799,803;1,040,156;5,853,354;-0,032415054
36,909,803;1,042,356;585,482;-0,03238504
37,019,803;1,044,564;5,857,115;-0,032445067
371,298;1,046,756;5,858,458;-0,032395044
372,398;1,048,948;5,860,264;-0,032435063
37,349,803;1,051,172;5,862,156;-0,032395044
37,459,803;1,053,372;5,863,473;-0,032445067
37,569,803;105,558;5,864,857;-0,032455072
376,798;1,057,784;5,866,485;-0,032415054
377,898;1,059,976;5,867,833;-0,032375035
37,899,803;1,062,156;5,869,438;-0,032425058
38,009,803;106,438;5,871,598;-0,032425058
38,119,803;106,658;5,873,218;-0,032435063
382,298;1,068,776;587,431;-0,032405049
383,398;107,098;5,876,024;-0,032425058
38,449,803;1,073,176;5,877,423;-0,03236503
38,559,803;1,075,368;58,789;-0,032405049
38,669,803;1,077,584;5,880,787;-0,032375035
387,798;1,079,776;5,882,269;-0,03238504
388,898;1,081,984;5,883,915;-0,032405049
38,999,803;1,084,176;5,884,828;-0,03238504
39,109,803;1,086,356;5,886,382;-0,032415054
39,219,803;1,088,552;5,887,873;-0,03238504
393,298;1,090,772;5,889,753;-0,032415054
394,398;1,092,976;5,891,194;-0,032455072
39,549,803;1,095,172;5,892,645;-0,032405049
39,659,803;1,097,364;5,893,848;-0,03238504
39,769,803;1,099,568;5,895,803;-0,032405049
398,798;1,101,764;589,722;-0,032415054
399,898;1,103,976;5,898,685;-0,032405049
40,099,803;1,106,176;5,899,959;-0,032395044
40,209,803;1,108,372;5,901,455;-0,032415054
40,319,803;111,058;5,902,742;-0,032435063
404,298;111,278;5,904,395;-0,032375035
405,398;1,114,976;5,905,641;-0,032415054
40,649,803;111,718;5,907,117;-0,032375035
40,759,803;1,119,384;5,908,498;-0,032395044
40,869,803;1,121,576;5,909,716;-0,032395044
40,979,803;1,123,776;5,910,813;-0,032375035
410,898;1,125,972;5,912,474;-0,032415054
41,199,803;112,818;5,913,987;-0,032415054
41,309,803;1,130,384;591,537;-0,032455072
41,419,803;1,132,584;5,916,746;-0,032415054
41,529,803;113,478;5,918,054;-0,032395044
416,398;113,698;5,919,158;-0,03238504
41,749,803;1,139,176;5,920,651;-0,032415054
41,859,803;114,138;5,922,126;-0,032375035
41,969,803;1,143,572;5,923,157;-0,032405049
42,079,803;1,145,772;5,924,692;-0,032415054
421,898;1,147,972;5,926,121;-0,032405049
42,299,803;1,150,168;5,927,206;-0,032405049
42,409,803;1,152,364;5,928,574;-0,03238504
42,519,803;1,154,576;5,930,258;-0,032395044
42,629,803;115,678;5,931,122;-0,032405049
427,398;1,158,984;5,932,491;-0,032345021
42,849,803;1,161,184;5,933,787;-0,032375035
42,959,803;1,163,368;5,934,739;-0,032345021
43,069,803;1,165,564;5,936,087;-0,03238504
43,179,803;1,167,772;5,937,867;-0,032415054
432,898;1,169,964;5,938,568;-0,032375035
43,399,803;1,172,164;5,939,857;-0,032375035
43,509,803;1,174,376;5,941,316;-0,032405049
43,619,803;1,176,564;594,218;-0,032405049
43,729,803;1,178,752;5,943,105;-0,032415054
438,398;1,180,964;5,944,886;-0,03238504
43,949,803;1,183,164;5,945,883;-0,03238504
44,059,803;1,185,372;5,946,822;-0,03238504
44,169,803;1,187,584;5,948,289;-0,032355026
44,279,803;1,189,768;5,949,036;-0,03238504
443,898;1,191,956;5,949,983;-0,032375035
44,499,803;1,194,172;5,951,685;-0,032395044
44,609,803;1,196,372;595,265;-0,03238504
44,719,803;1,198,572;5,953,913;-0,032415054
44,829,803;1,200,784;5,955,305;-0,032375035
449,398;1,202,968;5,956,045;-0,032405049
45,049,803;1,205,168;5,957,165;-0,032425058
45,159,803;120,738;5,958,716;-0,032435063
45,269,803;1,209,568;5,959,513;-0,03238504
45,379,803;1,211,776;5,960,883;-0,032425058
454,898;1,213,988;5,962,176;-0,032405049
45,599,803;1,216,152;596,226;-0,03238504
45,709,803;1,218,344;5,963,883;-0,032375035
45,819,803;1,220,572;5,965,564;-0,03236503
45,929,803;1,222,764;5,966,198;-0,032405049
460,398;122,496;5,967,017;-0,03236503
46,149,803;1,227,168;596,845;-0,032375035
46,259,803;122,936;5,969,142;-0,032435063
46,369,803;1,231,548;5,970,206;-0,032345021
46,479,803;1,233,772;5,971,465;-0,032415054
465,898;123,596;5,972,353;-0,032415054
46,699,803;1,238,156;5,973,312;-0,03238504
46,809,803;1,240,364;597,471;-0,032395044
46,919,803;1,242,564;597,556;-0,032445067
47,029,803;1,244,756;5,976,678;-0,03238504
471,398;1,246,964;5,977,733;-0,032415054
47,249,803;1,249,156;5,978,956;-0,032375035
47,359,803;1,251,356;5,979,813;-0,032405049
47,469,803;1,253,556;5,980,762;-0,03238504
47,579,803;1,255,752;5,981,599;-0,03238504
476,898;1,257,944;5,982,873;-0,032445067
47,799,803;1,260,164;5,983,991;-0,032395044
47,909,803;1,262,364;5,984,918;-0,032415054
48,019,803;1,264,552;5,985,692;-0,032395044
48,129,803;1,266,752;5,986,631;-0,032425058
482,398;1,268,956;5,987,855;-0,032425058
48,349,803;1,271,152;5,988,593;-0,032345021
48,459,803;1,273,368;5,989,482;-0,032415054
48,569,803;127,556;5,990,323;-0,032395044
48,679,803;1,277,748;5,990,997;-0,032395044
487,898;1,279,948;5,991,998;-0,032415054
48,899,803;1,282,156;5,993,479;-0,032375035
49,009,803;1,284,344;5,994,201;-0,032425058
49,119,803;1,286,564;5,995,353;-0,032435063
49,229,803;1,288,772;5,996,047;-0,03236503
493,398;1,290,964;5,996,627;-0,032405049
49,449,803;129,316;5,997,257;-0,03238504
49,559,803;1,295,356;5,998,623;-0,032375035
49,669,803;1,297,556;5,999,641;-0,032395044
49,779,803;1,299,768;6,000,686;-0,032405049
498,898;1,301,964;6,001,416;-0,03238504
49,999,803;130,416;6,002,216;-0,032425058
50,109,803;130,636;6,002,831;-0,032395044
50,219,803;130,856;6,003,875;-0,032395044
50,329,803;131,076;6,004,943;-0,032415054
504,398;1,312,968;600,573;-0,032405049
50,549,803;131,518;6,006,671;-0,032415054
50,659,803;131,738;6,007,577;-0,032415054
50,769,803;1,319,568;600,799;-0,032425058
50,879,803;1,321,756;6,008,783;-0,032405049
509,898;132,396;600,996;-0,032425058
51,099,803;132,616;6,010,656;-0,03236503
51,209,803;1,328,368;6,011,539;-0,032405049
513,198;1,330,568;6,012,467;-0,032435063
51,429,803;133,276;6,013,007;-0,032425058
515,398;1,334,956;6,013,742;-0,032435063
51,649,806;1,337,168;601,513;-0,032415054
51,759,803;1,339,352;6,015,134;-0,03238504
518,698;1,341,572;6,016,649;-0,03238504
51,979,803;1,343,784;6,017,421;-0,032405049
520,898;1,345,964;6,017,354;-0,032375035
52,199,806;1,348,144;6,018,189;-0,03236503
52,309,803;1,350,364;601,999;-0,032395044
524,198;135,256;6,020,066;-0,03238504
52,529,806;1,354,764;6,020,864;-0,032415054
526,398;1,356,976;6,022,005;-0,032455072
52,749,806;1,359,164;6,022,232;-0,03238504
528,598;136,136;6,022,917;-0,032405049
529,698;1,363,576;6,024,283;-0,03238504
53,079,806;1,365,768;6,024,452;-0,032375035
531,898;1,367,964;6,025,553;-0,032395044
53,299,806;137,018;602,633;-0,032415054
534,098;1,372,372;6,026,804;-0,032415054
535,198;1,374,576;6,027,246;-0,03238504
53,629,806;137,678;6,028,092;-0,032435063
537,398;1,378,972;6,028,458;-0,032405049
53,849,806;1,381,168;6,029,177;-0,03238504
539,598;1,383,372;6,029,672;-0,032405049
540,698;1,385,548;6,030,267;-0,03236503
54,179,806;1,387,744;6,031,241;-0,03236503
542,898;1,389,964;6,032,389;-0,032425058
54,399,806;1,392,164;6,032,777;-0,032395044
545,098;139,436;6,033,348;-0,032415054
546,198;1,396,568;6,034,116;-0,032355026
54,729,806;1,398,752;6,034,394;-0,03238504
548,398;1,400,952;6,035,331;-0,032405049
54,949,806;1,403,168;6,036,332;-0,03238504
550,598;1,405,364;6,036,764;-0,032445067
551,698;1,407,552;6,036,981;-0,032395044
55,279,806;140,976;6,037,949;-0,032405049
553,898;1,411,956;603,857;-0,032375035
55,499,806;1,414,152;6,039,081;-0,03238504
556,098;1,416,364;6,040,079;-0,03238504
557,198;141,856;6,040,975;-0,032405049
55,829,806;1,420,752;6,041,166;-0,032395044
559,398;1,422,956;6,041,929;-0,032395044
56,049,806;1,425,148;6,042,292;-0,032375035
561,598;142,734;6,043,011;-0,032405049
562,698;1,429,556;6,043,838;-0,03236503
56,379,806;1,431,748;6,044,475;-0,032375035
564,898;143,394;6,045,024;-0,032425058
56,599,806;1,436,148;6,045,744;-0,03238504
567,098;1,438,348;6,046,214;-0,032415054
568,198;144,054;6,046,761;-0,032375035
56,929,806;1,442,752;6,047,447;-0,032405049
570,398;144,496;6,048,304;-0,032415054
57,149,806;1,447,156;6,048,563;-0,032395044
572,598;1,449,352;6,049,081;-0,032395044
573,698;1,451,556;6,049,743;-0,032405049
57,479,806;1,453,732;6,050,085;-0,032405049
575,898;1,455,948;6,050,805;-0,03238504
57,699,806;1,458,156;6,051,522;-0,032435063
578,098;1,460,352;6,051,764;-0,032395044
579,198;1,462,552;6,052,204;-0,032425058
58,029,806;1,464,748;6,052,934;-0,032415054
581,398;146,694;6,053,491;-0,03236503
58,249,806;1,469,148;6,053,963;-0,03238504
583,598;1,471,344;6,054,333;-0,032425058
584,698;1,473,568;6,055,267;-0,03238504
58,579,806;1,475,764;6,055,031;-0,032445067
586,898;1,477,944;605,541;-0,032405049
58,799,806;148,014;6,056,416;-0,032395044
589,098;1,482,356;6,057,199;-0,032435063
590,198;1,484,556;6,057,727;-0,032425058
59,129,806;148,676;6,058,066;-0,032405049
592,398;1,488,952;6,058,081;-0,032395044
59,349,806;1,491,152;6,058,772;-0,032405049
594,598;1,493,356;6,059,479;-0,032425058
595,698;149,556;6,059,703;-0,032395044
59,679,806;1,497,756;6,060,202;-0,032395044
597,898;149,996;6,061,223;-0,032435063
59,899,806;1,502,152;6,060,942;-0,032395044
600,098;1,504,348;6,061,432;-0,032415054
601,198;1,506,564;606,238;-0,032425058
60,229,806;1,508,748;6,062,274;-0,032395044
603,398;1,510,952;6,062,962;-0,032415054
60,449,806;151,316;606,391;-0,032445067
605,598;1,515,336;6,063,833;-0,032405049
60,669,806;1,517,532;6,064,631;-0,032415054
60,779,806;1,519,748;6,065,373;-0,032455072
608,898;152,194;6,065,238;-0,032455072
60,999,806;1,524,152;6,065,671;-0,032425058
611,098;1,526,352;6,066,375;-0,032425058
61,219,806;152,854;6,066,177;-0,032425058
61,329,806;153,074;6,066,805;-0,032445067
614,398;153,296;6,067,654;-0,032395044
61,549,806;1,535,148;6,067,733;-0,032415054
616,598;1,537,352;6,067,879;-0,032425058
61,769,806;153,956;6,068,624;-0,032425058
61,879,806;1,541,752;6,068,738;-0,032415054
619,898;1,543,952;6,069,199;-0,032425058
62,099,806;1,546,172;6,069,971;-0,032425058
622,098;1,548,368;6,070,215;-0,032445067
62,319,806;1,550,568;6,070,332;-0,032395044
62,429,806;1,552,768;6,070,916;-0,032435063
625,398;1,554,952;6,070,853;-0,032425058
62,649,806;1,557,152;6,071,359;-0,032415054
627,598;1,559,368;6,072,156;-0,032455072
62,869,806;156,156;6,072,253;-0,032425058
62,979,806;1,563,752;6,072,502;-0,032445067
630,898;1,565,956;6,073,382;-0,032445067
63,199,806;1,568,144;6,073,221;-0,032455072
633,098;157,034;6,073,627;-0,032425058
63,419,806;157,256;6,074,296;-0,032425058
63,529,806;1,574,756;6,074,189;-0,032465077
636,398;157,696;6,074,719;-0,032405049
63,749,806;1,579,168;607,511;-0,032405049
638,598;1,581,344;607,515;-0,032425058
63,969,806;1,583,536;6,075,619;-0,032405049
64,079,806;1,585,744;6,076,078;-0,032435063
641,898;1,587,948;6,076,475;-0,032405049
64,299,806;1,590,144;607,666;-0,032395044
644,098;1,592,348;6,077,195;-0,032425058
64,519,806;159,454;6,077,539;-0,032435063
64,629,806;1,596,736;6,077,792;-0,032405049
647,398;1,598,956;6,078,622;-0,032395044
64,849,806;1,601,148;6,078,796;-0,032415054
649,598;1,603,356;6,078,901;-0,032415054
65,069,806;1,605,572;6,079,226;-0,032435063
65,179,806;1,607,748;607,879;-0,032415054
652,898;160,994;6,079,379;-0,032445067
65,399,806;161,216;6,080,145;-0,032405049
655,098;1,614,364;6,080,455;-0,032455072
65,619,806;1,616,556;6,080,467;-0,032425058
65,729,806;1,618,756;6,080,418;-0,032425058
658,398;1,620,952;6,080,996;-0,032405049
65,949,806;1,623,152;6,081,246;-0,032445067
660,598;162,536;6,081,587;-0,032435063
66,169,806;1,627,552;6,081,712;-0,032425058
66,279,806;1,629,744;6,081,888;-0,032435063
663,898;1,631,944;6,082,316;-0,03238504
66,499,806;1,634,148;608,305;-0,032425058
666,098;1,636,356;608,317;-0,032455072
66,719,806;1,638,552;6,082,817;-0,032425058
66,829,806;1,640,756;6,083,311;-0,032425058
669,398;1,642,952;6,083,499;-0,032395044
67,049,806;1,645,144;6,083,646;-0,032405049
671,598;164,734;608,408;-0,03238504
67,269,806;1,649,544;6,084,922;-0,032415054
67,379,806;1,651,748;6,084,864;-0,032445067
674,898;1,653,952;6,085,261;-0,032435063
67,599,806;1,656,152;6,085,357;-0,032405049
677,098;165,834;6,085,234;-0,03238504
67,819,806;1,660,544;6,085,572;-0,03238504
67,929,806;1,662,756;6,086,319;-0,032395044
680,398;1,664,952;6,086,068;-0,032415054
68,149,806;1,667,152;6,086,469;-0,032425058
682,598;1,669,352;6,086,473;-0,032405049
68,369,806;167,154;6,086,391;-0,032425058
68,479,806;1,673,748;6,086,782;-0,032465077
685,898;167,596;6,087,345;-0,032425058
68,699,806;167,816;6,087,099;-0,032425058
688,098;1,680,368;6,087,474;-0,032425058
68,919,806;1,682,568;6,087,883;-0,032395044
69,029,806;1,684,752;6,087,583;-0,032455072
691,398;1,686,948;6,087,865;-0,032425058
69,249,806;1,689,164;6,088,375;-0,032395044
693,598;1,691,356;6,087,962;-0,032395044
69,469,806;1,693,556;6,088,073;-0,032435063
69,579,806;1,695,756;6,088,636;-0,032415054
696,898;1,697,944;6,088,526;-0,032405049
69,799,806;170,014;6,088,902;-0,032425058
699,098;170,236;6,089,382;-0,032375035
70,019,806;1,704,556;6,088,901;-0,032425058
70,129,806;1,706,764;6,089,003;-0,032375035
702,398;1,708,972;608,947;-0,032415054
70,349,806;1,711,156;6,089,066;-0,032405049
704,598;1,713,348;6,089,297;-0,032415054
70,569,806;171,556;6,089,848;-0,032375035
70,679,806;1,717,748;6,089,748;-0,032415054
707,898;1,719,956;6,089,906;-0,032375035
70,899,806;172,216;6,090,198;-0,03238504
710,098;1,724,352;6,089,919;-0,03238504
71,119,806;1,726,548;6,090,342;-0,032395044
71,229,806;1,728,772;6,090,649;-0,032455072
713,398;173,096;6,090,433;-0,032375035
71,449,806;1,733,164;6,090,531;-0,03238504
715,598;1,735,384;6,091,135;-0,032375035
71,669,806;1,737,572;6,090,447;-0,032405049
71,779,806;1,739,744;6,090,344;-0,032375035
718,898;1,741,964;6,091,163;-0,032395044
71,999,806;174,416;609,117;-0,032395044
721,098;174,636;6,091,055;-0,032415054
72,219,806;174,856;6,091,369;-0,03238504
72,329,806;1,750,756;6,091,407;-0,032405049
724,398;1,752,948;6,091,416;-0,03238504
72,549,806;1,755,164;6,091,704;-0,032375035
726,598;175,736;6,091,563;-0,03238504
72,769,806;1,759,556;6,091,566;-0,032415054
72,879,806;1,761,756;6,091,649;-0,032435063
729,898;1,763,952;6,091,858;-0,03238504
73,099,806;1,766,152;6,092,175;-0,032395044
732,098;1,768,368;6,092,469;-0,032405049
73,319,806;1,770,552;6,091,915;-0,03238504
73,429,806;1,772,752;6,092,045;-0,032415054
735,398;1,774,956;6,091,901;-0,032435063
73,649,806;1,777,152;6,092,057;-0,03238504
737,598;1,779,344;6,092,217;-0,032375035
73,869,806;1,781,556;6,092,508;-0,032445067
73,979,806;1,783,756;6,092,652;-0,032395044
740,898;1,785,952;6,092,442;-0,03238504
74,199,806;1,788,152;6,092,141;-0,032395044
743,098;1,790,352;6,092,538;-0,032405049
74,419,806;1,792,552;6,092,613;-0,032425058
74,529,806;1,794,768;6,092,734;-0,032415054
746,398;179,696;6,092,656;-0,03238504
74,749,806;1,799,152;6,092,617;-0,03238504
748,598;1,801,344;6,092,562;-0,032425058
74,969,806;1,803,544;6,092,827;-0,032375035
75,079,806;1,805,752;609,273;-0,032415054
751,898;1,807,956;6,092,601;-0,032405049
75,299,806;1,810,164;6,092,688;-0,032445067
754,098;181,236;6,092,555;-0,032415054
75,519,806;1,814,552;6,092,269;-0,032415054
75,629,806;181,674;6,092,477;-0,032415054
757,398;1,818,948;6,092,894;-0,032375035
75,849,806;1,821,152;6,092,594;-0,032415054
759,598;1,823,352;6,092,593;-0,032375035
76,069,806;1,825,544;6,092,615;-0,032395044
76,179,806;182,774;6,092,292;-0,032415054
762,898;1,829,948;6,092,632;-0,032415054
76,399,806;1,832,152;6,092,813;-0,032405049
765,098;1,834,352;6,092,511;-0,032415054
76,619,806;183,656;6,092,714;-0,032445067
76,729,806;1,838,772;6,092,761;-0,032425058
768,398;1,840,968;6,092,221;-0,032405049
76,949,806;1,843,156;6,092,088;-0,032415054
770,598;184,536;609,255;-0,032375035
77,169,806;1,847,552;6,091,911;-0,032405049
77,279,806;1,849,752;6,092,454;-0,032405049
773,898;185,196;6,092,493;-0,032405049
77,499,806;1,854,148;6,092,314;-0,032445067
776,098;1,856,348;6,092,247;-0,032405049
77,719,806;1,858,568;6,092,642;-0,03238504
77,829,806;186,076;6,091,824;-0,032455072
779,398;1,862,956;6,091,936;-0,032395044
78,049,806;186,518;6,092,439;-0,032415054
781,598;1,867,364;6,091,936;-0,03238504
78,269,806;1,869,532;6,091,244;-0,032395044
78,379,806;1,871,748;6,092,014;-0,032445067
784,898;1,873,948;6,091,675;-0,032445067
78,599,806;1,876,152;6,091,483;-0,032425058
787,098;187,836;6,091,678;-0,032425058
78,819,806;1,880,548;6,091,181;-0,032465077
78,929,806;1,882,744;6,091,112;-0,032405049
790,398;1,884,956;6,091,522;-0,03238504
79,149,806;1,887,156;6,091,089;-0,032415054
792,598;1,889,352;6,090,859;-0,032425058
79,369,806;1,891,564;6,090,994;-0,032435063
79,479,806;1,893,752;6,090,448;-0,032435063
795,898;1,895,956;6,090,565;-0,032455072
79,699,806;1,898,172;6,090,881;-0,032415054
798,098;1,900,356;6,090,029;-0,032435063
79,919,806;1,902,552;6,089,978;-0,032425058
80,029,806;1,904,764;609,012;-0,032455072
801,398;1,906,944;6,089,599;-0,032425058
80,249,806;190,914;6,089,687;-0,032395044
803,598;1,911,356;6,089,803;-0,032435063
80,469,806;1,913,548;6,089,468;-0,032435063
80,579,806;1,915,752;608,927;-0,032465077
806,898;1,917,956;6,089,581;-0,032415054
80,799,806;1,920,144;6,089,202;-0,032415054
809,098;1,922,344;6,089,239;-0,03238504
81,019,806;1,924,568;6,089,318;-0,032395044
81,129,806;192,676;6,088,756;-0,032445067
812,398;1,928,956;6,088,349;-0,032435063
81,349,806;1,931,156;6,088,397;-0,032425058
814,598;1,933,352;6,088,359;-0,032405049
81,569,806;1,935,552;6,088,488;-0,032405049
81,679,806;1,937,768;6,087,868;-0,032435063
817,898;1,939,968;6,087,745;-0,032415054
81,899,806;1,942,164;6,087,281;-0,032435063
820,098;1,944,364;6,087,148;-0,03238504
82,119,806;1,946,556;6,086,929;-0,032395044
82,229,806;1,948,752;6,086,977;-0,032415054
823,398;1,950,964;6,087,086;-0,032415054
82,449,806;1,953,156;6,086,721;-0,03236503
825,598;1,955,348;6,086,228;-0,032415054
82,669,806;1,957,548;608,606;-0,032405049
82,779,806;1,959,752;6,085,944;-0,032435063
828,898;1,961,952;6,085,927;-0,032395044
82,999,806;196,416;6,085,673;-0,032405049
831,098;196,636;6,085,525;-0,032415054
83,219,806;196,856;6,085,287;-0,032415054
83,329,806;1,970,764;6,084,607;-0,032405049
834,398;197,296;6,084,495;-0,032415054
83,549,806;197,516;6,084,332;-0,032425058
836,598;197,736;6,084,098;-0,032405049
83,769,806;197,956;6,084,051;-0,03238504
83,879,806;1,981,756;6,083,834;-0,032445067
839,898;1,983,952;6,083,111;-0,032435063
84,099,806;1,986,148;6,083,202;-0,032415054
842,098;198,836;6,083,241;-0,032405049
84,319,806;1,990,568;6,082,615;-0,032455072
84,429,806;1,992,768;6,082,266;-0,032445067
845,398;1,994,968;6,082,257;-0,032395044
84,649,806;1,997,176;6,081,656;-0,03238504
847,598;1,999,364;6,081,467;-0,032415054
84,869,806;2,001,556;6,081,387;-0,032435063
84,979,806;200,376;6,081,001;-0,032395044
850,898;2,005,964;6,080,776;-0,032445067
85,199,806;2,008,168;6,080,637;-0,032425058
853,098;201,036;6,079,736;-0,032435063
85,419,806;2,012,544;6,079,604;-0,032465077
85,529,806;201,476;6,079,857;-0,032405049
856,398;2,016,948;6,079,386;-0,032425058
85,749,806;2,019,152;6,079,304;-0,032415054
858,598;2,021,356;6,078,941;-0,032435063
85,969,806;2,023,552;6,078,328;-0,032395044
86,079,806;2,025,752;6,078,114;-0,032435063
86,189,806;2,027,976;6,078,155;-0,032435063
86,299,806;2,030,168;6,077,307;-0,032415054
864,098;203,236;6,076,915;-0,032415054
86,519,806;2,034,568;6,077,164;-0,032375035
86,629,806;2,036,756;6,076,259;-0,032425058
86,739,806;2,038,944;6,075,842;-0,03238504
86,849,806;2,041,168;6,076,066;-0,032395044
869,598;2,043,352;6,075,147;-0,032395044
87,069,806;2,045,556;6,075,078;-0,032415054
87,179,806;204,776;6,074,825;-0,032415054
87,289,806;204,994;6,074,172;-0,032415054
87,399,806;2,052,132;6,073,946;-0,032395044
875,098;2,054,356;6,074,132;-0,032435063
87,619,806;2,056,552;6,073,206;-0,032395044
87,729,806;2,058,748;6,072,782;-0,032375035
87,839,806;2,060,952;6,072,566;-0,032405049
87,949,806;2,063,136;6,071,929;-0,032395044
880,598;2,065,336;6,071,551;-0,032405049
88,169,806;2,067,548;6,071,717;-0,03236503
88,279,806;2,069,752;6,070,897;-0,032425058
88,389,806;207,196;607,056;-0,03238504
88,499,806;2,074,168;6,070,005;-0,032405049
886,098;2,076,344;6,069,184;-0,03238504
88,719,806;2,078,536;6,068,792;-0,032395044
88,829,806;2,080,752;6,068,821;-0,032435063
88,939,806;2,082,952;6,068,096;-0,032405049
89,049,806;2,085,144;6,067,534;-0,032375035
891,598;2,087,356;6,067,252;-0,032395044
89,269,806;208,954;6,066,567;-0,03238504
89,379,806;2,091,744;6,066,203;-0,032445067
89,489,806;209,396;6,065,993;-0,032395044
89,599,806;2,096,156;6,065,425;-0,032355026
897,098;2,098,356;6,064,789;-0,032395044
89,819,806;2,100,572;6,064,703;-0,032415054
89,929,806;210,276;6,063,809;-0,03238504
90,039,806;2,104,956;6,063,237;-0,032455072
90,149,806;2,107,164;6,062,814;-0,032395044
902,598;2,109,356;6,062,374;-0,032435063
90,369,806;2,111,548;6,061,623;-0,032405049
90,479,806;2,113,752;6,061,181;-0,032425058
90,589,806;2,115,944;6,060,633;-0,032405049
90,699,806;211,814;6,060,368;-0,032415054
908,098;2,120,364;6,059,713;-0,032415054
90,919,806;212,256;6,059,203;-0,032415054
91,029,806;2,124,752;6,058,246;-0,032425058
91,139,806;2,126,968;6,058,274;-0,032415054
91,249,806;2,129,172;6,057,408;-0,032405049
913,598;2,131,344;6,056,397;-0,032405049
91,469,806;213,356;6,056,372;-0,032415054
91,579,806;2,135,764;6,055,911;-0,032425058
91,689,806;213,796;6,054,644;-0,032395044
91,799,806;214,016;6,054,072;-0,03238504
919,098;214,236;6,053,675;-0,03238504
92,019,806;2,144,556;6,053,172;-0,032395044
92,129,806;2,146,764;6,052,496;-0,032435063
92,239,806;2,148,964;6,052,071;-0,032425058
92,349,806;215,116;605,132;-0,03236503
924,598;2,153,356;605,041;-0,032445067
92,569,806;2,155,556;6,049,851;-0,032395044
92,679,806;2,157,772;6,049,644;-0,032395044
92,789,806;2,159,984;6,048,677;-0,03238504
92,899,806;2,162,172;6,047,838;-0,03238504
930,098;2,164,376;6,047,357;-0,032395044
93,119,806;2,166,568;6,046,436;-0,032375035
93,229,806;2,168,764;6,045,772;-0,032415054
93,339,806;2,170,972;6,045,281;-0,03238504
93,449,806;2,173,176;6,044,222;-0,032405049
935,598;2,175,376;6,043,397;-0,032435063
93,669,806;2,177,584;6,042,867;-0,032425058
93,779,806;2,179,772;6,041,455;-0,032425058
93,889,806;2,181,964;6,040,951;-0,032425058
93,999,806;2,184,176;6,040,735;-0,032375035
941,098;2,186,372;6,039,323;-0,032415054
94,219,806;2,188,572;6,038,641;-0,032455072
94,329,806;2,190,776;6,037,956;-0,032435063
94,439,806;2,192,956;6,036,547;-0,032435063
94,549,806;2,195,152;6,036,074;-0,03238504
946,598;2,197,368;6,035,733;-0,032435063
94,769,806;219,956;6,034,311;-0,03238504
94,879,806;2,201,764;6,033,596;-0,032415054
94,989,806;2,203,976;6,032,959;-0,032415054
95,099,806;2,206,156;6,031,336;-0,032415054
952,098;2,208,348;6,030,589;-0,032445067
95,319,806;2,210,564;6,030,253;-0,032425058
95,429,806;2,212,756;6,028,753;-0,032425058
95,539,806;2,214,956;6,027,972;-0,032465077
95,649,806;2,217,152;602,732;-0,032465077
957,598;221,934;6,025,759;-0,032395044
95,869,806;222,154;6,024,905;-0,032425058
95,979,806;2,223,764;6,024,402;-0,032435063
96,089,806;2,225,956;6,022,846;-0,032445067
96,199,806;2,228,164;6,021,795;-0,032405049
963,098;2,230,372;6,021,127;-0,032425058
96,419,806;2,232,564;6,019,704;-0,032435063
96,529,806;2,234,752;6,018,455;-0,032395044
96,639,806;2,236,972;6,017,524;-0,032405049
96,749,806;2,239,156;6,016,101;-0,032435063
968,598;224,136;6,014,962;-0,032425058
96,969,806;2,243,568;6,014,035;-0,032425058
97,079,806;2,245,756;601,239;-0,032465077
97,189,806;2,247,948;6,011,349;-0,032445067
97,299,806;2,250,168;6,010,572;-0,032395044
974,098;225,236;6,008,828;-0,032425058
97,519,806;2,254,552;6,007,199;-0,032465077
97,629,806;2,256,764;6,006,411;-0,032455072
97,739,806;2,258,968;6,005,225;-0,032415054
97,849,806;226,116;6,003,552;-0,032425058
979,598;2,263,356;6,002,582;-0,032415054
98,069,806;2,265,552;6,001,297;-0,032405049
98,179,806;2,267,748;5,999,818;-0,032475081
98,289,806;2,269,964;599,838;-0,032425058
98,399,806;2,272,156;5,996,742;-0,032405049
985,098;2,274,356;5,995,132;-0,032475081
98,619,806;2,276,572;5,994,041;-0,032465077
98,729,806;2,278,768;5,992,348;-0,032465077
98,839,806;2,280,956;599,072;-0,032425058
98,949,806;2,283,164;5,989,318;-0,032435063
990,598;2,285,356;5,987,522;-0,032405049
99,169,806;228,756;598,609;-0,032415054
99,279,806;228,978;5,984,603;-0,032465077
99,389,806;2,291,968;5,982,338;-0,032435063
99,499,806;2,294,156;5,980,874;-0,032425058
996,098;2,296,364;5,979,103;-0,032495091
99,719,806;229,856;5,977,624;-0,032445067
99,829,806;2,300,756;5,975,874;-0,032435063
99,939,806;2,302,968;5,974,134;-0,032435063
100,049,806;2,305,168;5,972,127;-0,032435063
1,001,598;2,307,364;5,970,132;-0,032425058
100,269,806;230,956;5,968,221;-0,032445067
100,379,806;2,311,756;5,966,693;-0,032465077
100,489,806;231,396;5,965,233;-0,032465077
100,599,806;2,316,168;5,963,018;-0,032425058
1,007,098;2,318,364;5,961,227;-0,032415054
100,819,806;2,320,568;5,958,984;-0,032435063
100,929,806;2,322,764;5,956,513;-0,032455072
101,039,806;232,496;595,459;-0,032455072
101,149,806;2,327,172;5,953,085;-0,032445067
1,012,598;232,938;5,950,558;-0,032455072
101,369,806;233,158;594,849;-0,032425058
101,479,806;2,333,788;5,946,441;-0,032415054
101,589,806;233,598;5,944,039;-0,032425058
101,699,806;2,338,172;5,941,697;-0,032445067
1,018,098;2,340,384;5,939,975;-0,032445067
101,919,806;234,258;5,937,259;-0,032475081
102,029,806;234,478;5,935,003;-0,032455072
102,139,806;234,698;5,932,731;-0,032455072
102,249,806;2,349,172;5,930,264;-0,032415054
1,023,598;2,351,364;5,928,047;-0,032455072
1,024,698;2,353,572;5,925,891;-0,032425058
102,579,812;2,355,764;5,922,601;-0,032445067
102,689,806;2,357,968;5,920,569;-0,032415054
102,799,806;236,018;591,822;-0,032445067
1,029,098;2,362,372;5,915,178;-0,032415054
1,030,198;2,364,572;5,912,619;-0,032435063
103,129,812;236,678;5,910,439;-0,032445067
103,239,806;2,368,964;5,906,941;-0,032455072
103,349,806;2,371,164;5,904,637;-0,032415054
1,034,598;2,373,376;5,902,159;-0,032395044
1,035,698;2,375,564;5,898,712;-0,032435063
103,679,812;237,776;5,895,849;-0,032465077
103,789,806;2,379,976;589,359;-0,032435063
103,899,806;2,382,172;5,890,388;-0,032465077
1,040,098;2,384,372;5,887,161;-0,032475081
1,041,198;2,386,576;5,884,604;-0,032425058
104,229,812;2,388,776;5,881,519;-0,032455072
104,339,806;239,098;5,878,307;-0,032435063
104,449,806;2,393,172;5,875,276;-0,032405049
1,045,598;2,395,368;5,872,043;-0,032415054
1,046,698;2,397,576;5,868,974;-0,032435063
104,779,812;239,978;586,612;-0,032465077
104,889,812;2,401,972;5,862,361;-0,032405049
1,049,998;2,404,168;5,859,258;-0,032415054
1,051,098;2,406,392;585,634;-0,032425058
1,052,198;2,408,584;5,852,531;-0,032405049
105,329,812;2,410,788;5,849,118;-0,032395044
105,439,812;2,412,992;5,845,934;-0,032405049
1,055,498;241,518;5,842,186;-0,032435063
1,056,598;241,738;5,838,941;-0,032425058
1,057,698;2,419,604;5,835,612;-0,032415054
105,879,812;24,218;5,831,502;-0,032405049
105,989,812;2,423,988;5,827,471;-0,032405049
1,060,998;2,426,192;5,824,493;-0,032435063
1,062,098;2,428,388;5,820,571;-0,03238504
1,063,198;243,058;58,17;-0,032405049
106,429,812;2,432,796;581,348;-0,032425058
106,539,812;2,434,992;5,809,332;-0,032415054
1,066,498;2,437,184;580,542;-0,032405049
1,067,598;2,439,392;580,174;-0,032405049
1,068,698;244,158;5,797,496;-0,032415054
106,979,812;2,443,776;5,793,763;-0,032425058
107,089,812;24,46;5,790,032;-0,032425058
1,071,998;2,448,196;5,785,799;-0,032425058
1,073,098;2,450,388;5,781,454;-0,032395044
1,074,198;2,452,588;5,777,316;-0,032425058
107,529,812;2,454,776;5,773,134;-0,032395044
107,639,812;245,698;5,768,886;-0,032435063
1,077,498;24,592;5,764,758;-0,032405049
1,078,598;2,461,396;5,760,213;-0,03238504
1,079,698;2,463,592;5,755,691;-0,032415054
108,079,812;2,465,796;5,751,058;-0,032405049
108,189,812;2,467,988;5,746,553;-0,032395044
1,082,998;2,470,184;574,212;-0,032425058
1,084,098;2,472,392;5,737,752;-0,032455072
1,085,198;2,474,596;5,732,985;-0,03238504
108,629,812;2,476,788;5,728,089;-0,032415054
108,739,812;2,478,984;5,723,309;-0,032435063
1,088,498;2,481,176;5,718,819;-0,032405049
1,089,598;2,483,376;5,714,228;-0,032375035
1,090,698;2,485,584;5,709,243;-0,032415054
109,179,812;2,487,784;5,704,074;-0,032455072
109,289,812;248,998;5,699,255;-0,032405049
1,093,998;2,492,192;569,407;-0,032425058
1,095,098;2,494,388;5,689,009;-0,032415054
1,096,198;2,496,592;5,683,821;-0,032405049
109,729,812;2,498,792;5,678,534;-0,032435063
109,839,812;2,500,992;5,673,341;-0,032405049
1,099,498;2,503,192;5,667,621;-0,032415054
1,100,598;2,505,396;5,662,141;-0,032435063
1,101,698;2,507,592;5,656,748;-0,032425058
110,279,812;25,098;5,651,729;-0,032395044
110,389,812;2,512,008;5,645,778;-0,03238504
1,104,998;2,514,212;5,640,166;-0,032415054
1,106,098;2,516,412;563,469;-0,032425058
1,107,198;2,518,612;5,628,815;-0,032395044
110,829,812;252,082;5,623,127;-0,032345021
110,939,812;2,523,016;5,617,061;-0,032355026
1,110,498;2,525,204;5,611,096;-0,032425058
1,111,598;2,527,408;5,605,528;-0,032415054
1,112,698;2,529,616;5,599,571;-0,032425058
111,379,812;2,531,808;5,593,223;-0,032395044
111,489,812;25,34;5,587,177;-0,032425058
1,115,998;2,536,212;5,581,202;-0,032405049
1,117,098;2,538,404;5,574,375;-0,032415054
1,118,198;2,540,608;5,568,328;-0,032395044
111,929,812;2,542,812;5,561,824;-0,032405049
112,039,812;2,544,996;5,554,996;-0,032375035
1,121,498;2,547,192;5,548,586;-0,032415054
1,122,598;2,549,416;5,542,756;-0,032395044
1,123,698;2,551,608;5,535,193;-0,032425058
112,479,812;2,553,812;5,528,392;-0,032415054
112,589,812;2,556,016;5,521,712;-0,032415054
1,126,998;2,558,212;5,514,513;-0,03238504
1,128,098;2,560,404;5,507,318;-0,032415054
1,129,198;256,262;5,500,893;-0,032405049
113,029,812;2,564,816;5,493,182;-0,032435063
113,139,812;2,567,016;548,608;-0,032355026
1,132,498;2,569,232;5,478,854;-0,032415054
1,133,598;2,571,416;5,470,818;-0,032395044
1,134,698;2,573,608;5,463,319;-0,032445067
113,579,812;2,575,824;545,609;-0,032415054
113,689,812;257,802;5,448,197;-0,03238504
1,137,998;2,580,224;5,440,422;-0,032405049
1,139,098;2,582,432;5,432,895;-0,032405049
1,140,198;2,584,616;5,424,879;-0,032425058
114,129,812;2,586,812;5,416,521;-0,032405049
114,239,812;2,589,036;5,408,938;-0,03238504
1,143,498;2,591,236;5,400,345;-0,032435063
1,144,598;2,593,432;5,391,806;-0,032425058
1,145,698;2,595,644;5,383,707;-0,032435063
114,679,812;2,597,824;5,374,967;-0,032425058
114,789,812;2,600,016;5,366,624;-0,032415054
1,148,998;2,602,232;5,358,118;-0,032405049
1,150,098;2,604,432;5,348,808;-0,032405049
1,151,198;2,606,628;5,339,845;-0,032395044
115,229,812;2,608,832;5,330,735;-0,032405049
115,339,812;2,611,024;5,321,545;-0,032465077
1,154,498;261,322;5,312,631;-0,032395044
1,155,598;261,544;5,303,629;-0,03238504
1,156,698;2,617,636;5,293,876;-0,032405049
115,779,812;2,619,832;5,283,978;-0,032405049
115,889,812;2,622,044;5,274,515;-0,032405049
1,159,998;2,624,244;5,264,534;-0,032445067
1,161,098;262,644;5,254,728;-0,032395044
1,162,198;2,628,652;5,244,632;-0,032425058
116,329,812;2,630,832;5,234,436;-0,032405049
116,439,812;2,633,028;5,224,075;-0,03238504
1,165,498;2,635,236;521,376;-0,032395044
1,166,598;2,637,432;5,202,695;-0,032455072
1,167,698;2,639,624;5,192,221;-0,032415054
116,879,812;2,641,848;5,181,429;-0,032405049
116,989,812;2,644,048;5,170,419;-0,032415054
1,170,998;2,646,248;5,158,788;-0,032445067
1,172,098;2,648,448;5,147,367;-0,032405049
1,173,198;265,066;5,136,038;-0,032405049
117,429,812;2,652,856;5,124,075;-0,032415054
117,539,812;2,655,052;5,111,835;-0,032415054
1,176,498;2,657,248;5,100,038;-0,032445067
1,177,598;2,659,452;5,087,623;-0,032415054
1,178,698;2,661,652;5,074,939;-0,032425058
117,979,812;2,663,848;506,251;-0,032435063
118,089,812;2,666,048;5,049,609;-0,032395044
1,181,998;2,668,256;5,036,339;-0,03238504
1,183,098;2,670,456;5,022,557;-0,032445067
1,184,198;2,672,656;5,008,758;-0,032455072
118,529,812;2,674,856;4,994,271;-0,032435063
118,639,812;2,677,052;4,980,069;-0,032445067
1,187,498;2,679,252;4,965,419;-0,032395044
1,188,598;2,681,464;4,949,316;-0,032435063
1,189,698;2,683,672;4,931,534;-0,032395044
119,079,812;268,586;4,910,124;-0,032425058
119,189,812;2,688,064;4,858,574;-0,032445067
1,192,364;2,689,004;4,744,933;-0,032405049
119,246,012;2,689,208;4,589,009;-0,032405049
1,192,478;2,689,408;2,694,243;-0,032915286