File: tensile_test_ontology_TTO/data/primary_data/Zy4.csv
Time;Crosshead travel;Force;Strain
(s);(mm);(kN);(%)
0;0;0,21495;0
0,97;0,05164;0,5261;0,001180532
1,39;0,114;15,492;0,005222352
1,722;0,17556;257,624;0,009064082
2,008;0,2356;361,426;0,013015862
2,272;0,29608;465,694;0,016897611
2,548;0,36436;569,205;0,020999458
2,834;0,44108;671,644;0,025031274
3,098;0,51664;775,253;0,029053086
3,34;0,58924;87,982;0,033194951
3,568;0,66012;983,602;0,037226767
3,802;0,73552;1,089,126;0,04140865
4,054;0,8196;1,193,956;0,045510498
4,272;0,89476;129,867;0,049632354
4,474;0,96556;1,403,033;0,053754211
4,674;103,676;1,508,885;0,057916085
4,874;110,872;1,618,281;0,062218023
5,066;117,832;1,725,018;0,066439925
5,246;124,408;182,786;0,070421718
5,426;131,024;1,931,797;0,074613606
5,606;137,628;2,036,531;0,078705449
5,786;144,256;2,143,794;0,08292735
5,966;150,884;2,251,449;0,087259302
6,146;157,492;2,360,783;0,091571244
6,326;164,076;2,470,459;0,095953217
6,502;17,052;2,578,591;0,10024515
6,678;176,956;2,687,731;0,10470716
6,856;183,404;2,796,571;0,109149161
7,032;18,976;2,906,036;0,113631179
7,206;195,988;301,387;0,118153216
7,38;202,188;3,121,798;0,122685257
7,558;208,444;3,231,765;0,127417389
7,734;214,592;3,339,932;0,132119507
7,914;22,082;3,449,944;0,137061733
8,094;226,956;3,559,181;0,14207399
8,274;2,33;3,666,221;0,147216306
8,454;23,894;3,772,533;0,152288591
8,634;244,744;3,875,908;0,157540956
8,814;250,428;3,976,987;0,162763309
9,004;256,296;4,082,286;0,168455873
9,204;262,332;419,001;0,174548617
9,404;268,156;429,218;0,180531311
9,612;274,068;4,396,719;0,186924191
9,832;280,104;4,500,951;0,193617205
10,068;286,348;4,606,365;0,200750418
10,322;292,832;4,710,622;0,208233788
10,618;300,092;4,814,437;0,217127794
11,114;3,117;4,910,764;0,231564297
12,004;323,336;4,817,741;0,282037029
13,004;326,568;4,806,297;0,306948249
14,004;33,052;4,827,333;0,332819902
15,004;333,584;4,831,011;0,357611068
16,004;336,808;484,437;0,381281729
17,004;33,964;4,838,835;0,40779367
18,004;342,488;4,846,582;0,432574832
19,004;345,528;485,074;0,45823639
20,004;348,176;4,854,048;0,483017551
21,004;3,508;4,857,169;0,50652814
22,004;353,304;4,853,543;0,533610338
23,004;355,588;4,856,366;0,558211418
24,004;357,764;4,855,409;0,583422774
25,004;359,876;4,856,203;0,608954273
26,004;362,148;4,856,887;0,634655849
27,004;364,056;4,857,294;0,658666663
28,004;366,008;4,857,358;0,684138136
29,004;367,844;4,856,389;0,708939306
30,004;369,636;4,855,128;0,733920558
31,004;37,148;4,857,579;0,758701719
32,004;373,244;4,856,156;0,784143178
33,004;374,968;4,856,536;0,808954353
34,004;3,767;4,855,903;0,834105681
35,004;37,886;4,869,092;0,859196982
36,004;380,192;4,852,058;0,883647995
37,004;381,912;485,489;0,909249526
38,004;383,524;4,855,116;0,933830597
39,004;385,176;4,856,213;0,959172011
40,004;38,674;4,855,131;0,984453398
41,004;3,883;4,855,469;1,009,184,537
42,004;389,808;4,852,805;1,034,615,991
43,004;39,136;4,855,698;1,059,367,139
44,004;392,796;4,852,307;1,084,308,372
45,004;394,296;4,853,641;1,109,119,547
46,004;395,724;4,852,164;1,133,960,736
47,004;397,192;4,852,872;1,159,122,069
48,004;398,652;4,852,026;1,184,743,609
49,004;400,048;4,851,056;1,209,684,842
50,004;401,484;4,852,367;1,234,776,143
51,004;402,852;4,850,631;1,259,667,354
52,004;404,264;4,851,976;1,284,588,579
53,004;405,636;4,851,011;1,309,919,988
54,004;4,07;4,851,589;1,334,631,118
55,004;408,352;4,851,024;1,359,572,351
56,004;409,724;4,852,447;1,384,293,486
57,004;411,108;485,278;1,409,564,868
58,004;41,246;4,852,069;1,434,786,228
59,004;413,832;4,854,049;1,459,447,335
60,004;415,212;4,855,295;148,476,874
61,004;416,588;4,856,665;1,509,339,807
62,004;417,968;4,857,375;153,479,127
63,004;419,196;4,852,427;1,559,552,422
64,004;420,452;4,848,368;158,472,376
65,004;42,154;4,836,627;1,609,815,061
6,600,401;422,564;4,822,954;1,634,736,285
6,700,401;423,624;4,811,962;1,659,647,505
6,800,401;424,984;4,815,558;1,684,598,743
6,900,401;426,464;4,826,223;1,709,189,819
7,000,401;428,108;4,843,971;1,734,041,012
7,100,401;42,978;4,861,341;1,758,732,133
7,200,401;431,572;4,880,959;1,784,093,556
7,300,401;433,336;4,896,913;1,808,754,663
7,400,401;43,516;4,911,664;1,833,745,919
7,500,401;43,704;4,925,727;1,858,246,954
7,600,401;439,232;4,934,344;1,884,378,724
7,700,401;4,412;4,950,177;1,908,219,462
7,800,401;443,188;4,959,648;1,932,940,596
7,900,401;445,292;4,969,852;1,958,262,001
8,000,401;447,436;4,979,533;1,982,863,082
8,100,401;449,668;4,988,959;200,770,427
8,200,401;451,992;4,997,789;2,033,025,675
8,300,401;454,352;5,006,866;2,057,816,841
8,400,401;456,752;501,546;2,082,587,998
8,500,401;45,924;5,023,851;2,107,519,227
8,600,401;46,182;5,033,028;213,266,055
8,700,401;464,392;504,073;2,157,541,757
8,800,401;467,048;5,050,504;21,822,829
8,900,401;469,712;5,058,473;2,207,204,125
9,000,401;472,744;5,065,531;2,232,655,588
9,100,401;475,444;5,075,694;2,257,286,682
9,200,401;478,196;5,083,914;2,282,538,055
9,300,401;480,936;5,092,737;2,307,319,217
9,400,401;483,696;5,100,967;2,332,380,504
9,500,401;486,404;5,108,151;2,357,101,639
9,600,401;489,184;5,117,638;2,382,132,913
9,700,401;491,952;5,124,423;2,407,634,399
9,800,401;494,688;5,132,097;243,252,561
9,900,401;497,452;514,094;2,457,366,798
10,000,401;500,212;514,847;2,482,187,977
10,100,401;50,334;5,157,366;2,507,839,531
10,200,401;506,012;5,164,747;2,532,300,548
10,300,401;5,087;5,172,247;2,557,301,809
10,400,401;5,114;5,179,788;2,582,443,132
10,500,401;514,072;5,187,465;2,607,274,316
10,600,401;516,816;5,196,225;2,632,625,735
10,700,401;519,492;5,203,614;2,657,647,004
10,800,401;52,214;5,210,361;2,682,568,229
10,900,401;52,474;5,216,576;2,707,299,368
11,000,401;527,384;5,224,721;2,732,080,529
11,100,401;530,116;5,233,295;2,757,662,051
11,200,401;533,092;5,240,006;2,783,083,501
11,300,401;535,688;5,247,645;2,807,624,554
11,400,401;538,272;5,253,646;2,832,515,765
11,500,401;54,086;5,260,642;2,857,146,859
11,600,401;5,435;5,268,195;2,882,408,237
11,700,401;546,124;5,275,604;2,907,269,434
11,800,401;548,768;5,282,819;2,932,300,708
11,900,401;551,344;5,288,388;2,957,111,883
12,000,401;553,948;5,295,398;2,982,033,108
12,100,401;556,596;5,302,488;3,007,514,585
12,200,401;5,592;5,309,399;3,032,345,769
12,300,401;56,216;5,316,042;3,058,057,349
12,400,401;5,647;5,322,341;3,082,508,362
12,500,401;567,308;5,329,078;3,107,629,676
12,600,401;569,896;5,334,826;3,132,861,041
12,700,401;572,488;5,341,972;3,157,442,112
12,800,402;57,512;5,349,285;3,182,493,395
12,900,402;577,688;53,542;320,730,457
13,000,402;580,296;5,360,823;3,232,305,831
13,100,402;58,294;5,366,656;3,257,647,244
13,200,402;585,572;5,372,943;3,282,698,527
13,300,402;58,852;5,389,292;3,305,368,738
13,400,402;591,128;5,384,389;3,332,651,026
13,500,402;59,376;5,392,067;335,779,235
13,600,402;596,292;5,396,297;3,382,423,444
13,700,402;598,916;5,403,453;3,407,574,772
13,800,402;601,516;5,409,572;3,432,786,127
13,900,402;604,076;5,415,146;3,457,457,239
14,000,402;606,696;5,421,773;3,482,488,513
14,100,402;609,284;5,426,062;3,507,679,859
14,200,402;611,844;5,431,784;353,257,107
14,300,402;61,444;5,438,251;3,557,582,335
14,400,402;61,744;544,988;3,582,733,663
14,500,402;61,988;544,979;3,607,494,816
14,600,402;622,436;545,409;3,632,866,243
14,700,402;62,496;5,459,657;3,657,717,436
14,800,402;627,504;546,612;3,682,518,606
14,900,402;63,002;547,078;3,707,449,835
15,000,402;632,544;5,476,021;3,732,220,992
15,100,402;635,128;5,481,335;3,757,632,438
15,200,402;637,644;5,486,739;3,782,523,649
15,300,402;640,196;5,492,725;3,807,544,918
15,400,402;643,044;5,507,828;3,830,685,341
154,86;644,308;5,477,998;3,851,524,727
155,86;646,168;5,488,822;3,866,331,396
156,86;648,168;5,497,939;3,885,029,817
157,86;65,018;5,503,396;3,904,468,573
158,86;652,176;5,507,709;392,395,735
159,86;654,164;5,511,426;3,943,396,106
181,574;655,496;5,373,885;-0,069701394
182,574;657,472;5,455,374;-0,069651371
183,574;659,488;5,505,652;-0,069681384
184,574;661,488;5,526,834;-0,069711398
185,574;663,488;5,534,647;-0,069711398
186,574;665,496;5,539,685;-0,069721403
187,574;667,492;5,542,433;-0,069681384
188,574;669,484;5,545,727;-0,069651371
189,574;67,148;554,889;-0,069711398
190,574;673,488;5,552,289;-0,069681384
191,574;675,484;5,555,426;-0,069681384
192,574;677,476;5,558,389;-0,069701394
193,574;679,488;5,561,942;-0,069651371
194,574;681,476;5,565,181;-0,069721403
195,574;683,468;5,568,509;-0,069701394
196,574;685,484;5,572,512;-0,06967138
197,574;687,484;5,575,584;-0,06967138
198,574;689,488;5,579,137;-0,069701394
199,574;691,492;5,582,159;-0,069731407
200,574;693,492;5,585,338;-0,069681384
201,574;695,492;5,588,664;-0,069741412
202,574;697,496;5,592,155;-0,069701394
203,574;699,508;5,595,133;-0,069681384
204,574;7,015;559,808;-0,069701394
205,574;703,488;560,114;-0,06967138
206,574;7,055;5,604,987;-0,06967138
207,574;707,492;5,607,986;-0,069721403
208,574;709,484;5,611,252;-0,06967138
209,574;7,115;5,614,577;-0,069681384
210,574;713,492;5,617,307;-0,069691389
211,574;7,155;5,620,627;-0,069641366
212,574;717,496;5,623,665;-0,06967138
213,574;719,492;5,626,731;-0,069661375
214,574;721,492;5,629,862;-0,069681384
215,574;723,492;563,256;-0,069681384
216,574;725,496;5,635,045;-0,069661375
217,574;72,748;563,796;-0,069651371
218,574;72,948;5,640,843;-0,069661375
219,574;731,488;5,644,394;-0,069681384
220,574;73,348;5,646,918;-0,069651371
221,574;735,476;5,649,837;-0,069661375
222,574;737,488;5,653,228;-0,069681384
223,574;739,472;5,655,638;-0,069631362
224,574;741,484;5,659,098;-0,069661375
225,574;743,484;5,661,715;-0,069651371
226,574;74,548;5,664,105;-0,069651371
227,574;747,476;5,667,123;-0,06967138
228,574;749,472;56,7;-0,069691389
229,574;751,492;5,672,954;-0,069661375
230,574;753,496;5,675,811;-0,069641366
231,574;755,488;5,678,229;-0,069641366
232,574;757,484;5,681,242;-0,06967138
233,574;759,476;5,684,077;-0,069631362
234,574;761,468;5,686,845;-0,069641366
235,574;763,476;5,689,967;-0,069651371
236,574;765,476;5,692,439;-0,069681384
237,574;767,484;5,695,246;-0,069621357
238,574;76,948;5,697,868;-0,069681384
239,574;77,148;5,700,204;-0,069611353
240,574;773,472;5,703,192;-0,069651371
241,574;775,468;5,705,844;-0,069641366
242,574;777,484;5,709,186;-0,069661375
243,574;779,484;5,711,564;-0,069631362
244,574;781,484;5,714,189;-0,069631362
245,574;783,492;5,716,876;-0,069651371
246,574;785,468;5,718,977;-0,069631362
247,574;787,456;5,721,804;-0,06967138
248,574;789,472;5,725,044;-0,069681384
249,574;791,476;572,759;-0,069651371
250,574;79,348;5,730,343;-0,069641366
251,574;795,476;5,732,813;-0,069651371
252,574;79,748;5,735,272;-0,069621357
253,574;799,476;5,737,457;-0,069611353
254,574;801,468;5,740,148;-0,069651371
255,574;80,348;5,742,851;-0,069661375
256,574;805,476;5,745,469;-0,06967138
257,574;807,472;5,747,946;-0,069621357
258,574;809,476;5,751,157;-0,069631362
259,574;811,464;5,753,128;-0,069611353
260,574;813,456;5,755,559;-0,069611353
261,574;815,472;575,867;-0,069651371
262,574;817,468;5,760,647;-0,069651371
263,574;819,472;5,763,239;-0,069631362
264,574;821,468;5,765,585;-0,06967138
265,574;823,472;576,816;-0,069621357
266,574;825,472;5,770,625;-0,069691389
267,574;827,468;5,773,078;-0,069601348
268,574;829,484;5,775,672;-0,069611353
269,574;831,472;5,777,715;-0,069631362
270,574;833,468;5,779,833;-0,069621357
271,574;835,472;57,827;-0,069571335
272,574;837,468;5,784,937;-0,069631362
273,574;83,946;5,787,486;-0,069601348
274,574;841,472;5,790,317;-0,069611353
275,574;843,472;5,792,526;-0,069621357
276,574;845,476;5,794,902;-0,069651371
277,574;847,472;5,796,906;-0,069571335
278,574;849,472;5,799,078;-0,069601348
279,574;851,468;5,801,517;-0,069621357
280,574;853,476;5,803,693;-0,069631362
281,574;855,484;5,806,239;-0,069601348
282,574;85,746;5,807,962;-0,069591344
283,574;85,946;5,810,604;-0,069621357
284,574;861,472;5,813,187;-0,069581339
285,574;86,346;5,815,113;-0,069621357
286,574;865,456;5,817,379;-0,069601348
287,574;867,464;5,819,848;-0,069581339
288,574;869,464;582,193;-0,069591344
289,574;871,468;5,824,105;-0,069601348
290,574;87,346;5,826,258;-0,069601348
291,574;875,468;5,828,417;-0,069591344
292,574;877,456;5,830,618;-0,069611353
293,574;879,444;5,832,657;-0,069601348
294,574;881,464;5,835,467;-0,069601348
295,574;883,468;5,837,252;-0,069601348
296,574;885,468;5,839,303;-0,069611353
297,574;88,746;584,148;-0,069611353
298,574;889,456;5,843,543;-0,069621357
299,574;891,452;5,846,026;-0,069581339
300,574;893,456;5,848,017;-0,069571335
301,574;895,452;585,006;-0,069591344
302,574;897,464;5,852,407;-0,069641366
303,574;89,946;5,854,064;-0,069621357
304,574;90,146;5,856,244;-0,069621357
305,574;903,456;58,582;-0,069621357
306,574;905,448;5,860,186;-0,069651371
307,574;907,464;5,862,523;-0,069571335
308,574;90,946;5,864,464;-0,069591344
309,574;911,468;5,866,417;-0,069581339
310,574;913,472;5,868,637;-0,069581339
311,574;915,464;587,008;-0,069601348
312,574;917,452;5,871,835;-0,069631362
313,574;919,456;5,874,325;-0,069601348
314,574;921,464;5,876,148;-0,069591344
315,574;923,468;5,878,318;-0,069591344
316,574;925,456;5,879,875;-0,069531317
317,574;92,746;5,881,994;-0,069571335
318,574;929,456;5,883,715;-0,069601348
319,574;931,448;5,885,422;-0,069551326
320,574;933,468;5,887,756;-0,069631362
321,574;93,546;588,933;-0,069571335
322,574;93,746;5,891,415;-0,069601348
323,574;93,946;5,893,616;-0,069601348
324,574;941,452;589,532;-0,069591344
325,574;943,448;5,897,253;-0,069581339
326,574;945,452;5,899,271;-0,069591344
327,574;947,464;5,901,243;-0,06956133
328,574;949,468;5,902,955;-0,069601348
329,574;951,464;5,904,456;-0,069581339
330,574;953,468;5,906,226;-0,06956133
331,574;955,464;5,907,981;-0,069571335
332,574;95,746;5,909,721;-0,069601348
333,574;95,948;5,912,114;-0,069571335
334,574;961,468;5,913,434;-0,069621357
335,574;96,346;5,914,894;-0,069591344
336,574;96,546;5,917,066;-0,069581339
337,574;967,456;5,918,751;-0,06956133
338,574;969,452;5,920,589;-0,069581339
339,574;971,456;5,922,483;-0,069591344
340,574;97,346;5,924,173;-0,069611353
341,574;975,464;5,926,003;-0,069541321
342,574;977,456;5,927,503;-0,069571335
343,574;979,464;5,929,267;-0,069541321
344,574;981,444;5,930,407;-0,069581339
345,574;98,346;5,932,833;-0,069601348
346,574;985,476;5,934,482;-0,069571335
347,574;987,456;5,935,535;-0,069551326
348,574;989,456;5,937,278;-0,069581339
349,574;991,456;5,939,516;-0,069581339
350,574;993,452;5,940,802;-0,069651371
351,574;995,452;5,942,509;-0,069551326
352,574;99,746;5,944,336;-0,069551326
353,574;999,468;594,586;-0,06956133
354,574;1,001,468;5,947,378;-0,069541321
355,574;100,346;5,948,708;-0,069601348
356,574;1,005,472;5,950,766;-0,069621357
357,574;100,746;5,952,024;-0,069591344
358,574;1,009,452;5,953,729;-0,06956133
359,574;1,011,472;5,955,774;-0,069581339
360,574;1,013,468;595,717;-0,069601348
361,574;1,015,484;5,958,843;-0,069551326
362,574;1,017,472;5,960,108;-0,069591344
363,574;1,019,468;5,961,457;-0,06956133
364,574;1,021,464;5,962,977;-0,069581339
365,574;1,023,456;5,964,417;-0,069531317
366,574;102,546;596,611;-0,069541321
367,574;1,027,452;596,764;-0,069551326
368,574;1,029,448;5,969,082;-0,069571335
369,574;1,031,452;5,970,758;-0,06956133
370,574;1,033,448;5,972,106;-0,069571335
371,574;103,544;597,344;-0,069551326
372,574;1,037,456;5,975,581;-0,069581339
373,574;1,039,448;5,976,458;-0,069551326
374,574;1,041,452;5,978,385;-0,069531317
375,574;1,043,456;598,007;-0,06956133
376,574;1,045,448;5,981,172;-0,069591344
377,574;104,744;5,982,667;-0,069581339
378,574;104,944;5,984,125;-0,069571335
379,574;105,146;5,985,909;-0,069591344
380,574;105,346;5,986,969;-0,069551326
381,574;1,055,452;5,988,336;-0,06956133
382,574;105,746;5,990,067;-0,069581339
383,574;1,059,444;5,991,168;-0,069551326
384,574;106,144;5,992,689;-0,069581339
385,574;1,063,452;599,457;-0,069571335
386,574;1,065,444;5,995,242;-0,069591344
387,574;1,067,444;5,996,731;-0,069571335
388,574;1,069,444;5,998,347;-0,06956133
389,574;107,144;5,999,377;-0,069601348
390,574;1,073,428;6,001,077;-0,06956133
391,574;1,075,424;6,002,533;-0,069601348
392,574;107,744;6,004,314;-0,06956133
393,574;1,079,444;600,549;-0,069571335
394,574;1,081,444;6,006,382;-0,06956133
395,574;1,083,452;6,007,915;-0,06956133
396,574;1,085,448;6,009,101;-0,069541321
397,574;1,087,448;6,010,461;-0,069611353
398,574;1,089,468;6,012,408;-0,069601348
399,574;109,146;6,013,213;-0,069571335
400,574;109,346;6,014,514;-0,069551326
401,574;1,095,444;6,015,738;-0,069621357
402,574;1,097,444;6,016,677;-0,069601348
403,574;1,099,444;6,018,027;-0,069591344
404,574;1,101,444;6,019,369;-0,069581339
405,574;110,346;6,020,769;-0,069541321
406,574;1,105,456;6,022,168;-0,069571335
407,574;1,107,452;6,023,307;-0,069531317
408,574;1,109,456;6,024,824;-0,069551326
409,574;111,144;6,025,525;-0,069521312
410,574;111,344;6,027,014;-0,069571335
411,574;1,115,472;602,883;-0,069571335
412,574;1,117,464;6,029,139;-0,069581339
413,574;1,119,456;6,030,443;-0,069571335
414,574;1,121,448;6,031,584;-0,069601348
415,574;1,123,444;6,032,825;-0,06956133
416,574;1,125,444;6,034,275;-0,06956133
417,574;1,127,436;6,035,247;-0,069601348
418,574;112,946;603,687;-0,06956133
419,574;1,131,452;6,037,693;-0,069581339
420,574;1,133,452;60,386;-0,069571335
421,574;1,135,456;6,040,055;-0,069541321
422,574;1,137,444;604,101;-0,06956133
423,574;1,139,436;6,042,235;-0,069551326
424,574;1,141,452;6,044,287;-0,069531317
425,574;1,143,452;6,044,939;-0,069541321
426,574;1,145,464;6,046,147;-0,069571335
427,574;114,746;6,047,043;-0,069571335
428,574;1,149,444;6,047,624;-0,069551326
42,957,403;1,151,444;6,049,157;-0,069541321
43,057,403;1,153,444;6,050,174;-0,069531317
43,157,403;1,155,448;6,051,477;-0,069571335
43,257,403;115,744;6,052,362;-0,069551326
43,357,403;115,944;6,053,476;-0,069521312
43,457,403;1,161,448;6,054,964;-0,069521312
43,557,403;1,163,436;6,055,474;-0,069531317
43,657,403;1,165,432;6,056,615;-0,069531317
43,757,403;1,167,452;605,821;-0,069551326
43,857,403;1,169,444;6,058,905;-0,069541321
43,957,403;1,171,456;6,060,222;-0,069581339
44,057,403;1,173,452;6,061,166;-0,069571335
44,157,403;1,175,456;6,061,891;-0,069531317
44,257,403;1,177,444;6,063,004;-0,06956133
44,357,403;1,179,436;6,064,013;-0,069571335
44,457,403;1,181,456;6,065,277;-0,069531317
44,557,403;118,346;6,066,284;-0,069581339
44,657,403;118,546;6,067,083;-0,069541321
44,757,403;1,187,468;606,823;-0,069541321
44,857,403;118,946;606,882;-0,06956133
44,957,403;1,191,456;6,070,169;-0,069521312
45,057,403;1,193,464;6,071,413;-0,069571335
45,157,403;1,195,452;6,072,105;-0,069541321
45,257,403;119,746;6,073,312;-0,069531317
45,357,403;1,199,456;6,074,129;-0,069531317
45,457,403;1,201,456;6,075,097;-0,069511308
45,557,403;1,203,444;6,075,982;-0,069551326
45,657,403;1,205,432;6,076,946;-0,069551326
45,757,403;1,207,448;607,841;-0,069581339
45,857,403;120,944;6,079,234;-0,069521312
45,957,403;1,211,436;6,080,061;-0,069491299
46,057,403;1,213,444;6,081,282;-0,069521312
46,157,403;1,215,436;6,081,813;-0,069551326
46,257,403;1,217,436;6,083,071;-0,069541321
46,357,403;1,219,452;6,084,433;-0,069551326
46,457,403;1,221,452;6,084,902;-0,069501303
46,557,403;122,344;6,085,876;-0,069551326
46,657,403;1,225,424;6,086,675;-0,069541321
46,757,403;1,227,424;6,087,398;-0,069521312
46,857,403;1,229,428;608,869;-0,06956133
46,957,403;1,231,424;6,089,336;-0,069571335
47,057,403;123,344;6,090,623;-0,069581339
47,157,403;1,235,432;6,091,179;-0,069551326
47,257,403;123,744;6,092,194;-0,069551326
47,357,403;1,239,448;609,335;-0,069541321
47,457,403;124,144;6,093,948;-0,069581339
47,557,403;1,243,432;6,094,827;-0,069531317
47,657,403;124,546;6,096,331;-0,069551326
47,757,403;1,247,464;6,096,668;-0,069511308
47,857,403;1,249,452;609,707;-0,069551326
47,957,403;1,251,444;6,098,052;-0,069551326
48,057,403;1,253,452;6,099,105;-0,069511308
48,157,403;1,255,444;6,099,936;-0,069521312
48,257,403;125,744;6,100,923;-0,069491299
48,357,403;1,259,456;610,219;-0,069531317
48,457,403;1,261,448;6,102,407;-0,069521312
48,557,403;1,263,452;6,103,106;-0,069531317
48,657,403;1,265,456;6,104,161;-0,069541321
48,757,403;1,267,444;6,104,589;-0,069571335
48,857,403;1,269,428;6,105,329;-0,069531317
48,957,403;1,271,436;6,106,708;-0,06956133
49,057,403;1,273,436;6,107,571;-0,069541321
49,157,403;1,275,448;6,108,595;-0,069521312
49,257,403;127,744;6,109,175;-0,069511308
49,357,403;1,279,436;610,945;-0,069551326
49,457,403;1,281,428;6,110,491;-0,069521312
49,557,403;1,283,428;6,111,323;-0,069531317
49,657,403;1,285,436;6,112,313;-0,069511308
49,757,403;1,287,424;6,112,878;-0,069521312
49,857,403;1,289,428;6,113,738;-0,069551326
49,957,403;1,291,444;61,152;-0,069551326
50,057,403;1,293,432;6,115,282;-0,069521312
50,157,403;1,295,428;6,116,097;-0,069501303
50,257,403;1,297,444;6,117,091;-0,069521312
50,357,403;1,299,444;6,117,626;-0,069531317
50,457,403;1,301,448;6,118,655;-0,069521312
50,557,403;1,303,444;6,119,019;-0,069531317
50,657,403;1,305,448;6,119,794;-0,06947129
50,757,403;130,744;6,120,347;-0,069551326
50,857,403;1,309,424;6,121,025;-0,069531317
50,957,403;1,311,444;6,122,211;-0,069521312
51,057,403;131,344;6,122,555;-0,069571335
51,157,403;1,315,452;6,123,272;-0,069511308
51,257,403;1,317,456;6,124,082;-0,069521312
51,357,403;1,319,448;6,124,642;-0,069501303
51,457,403;1,321,448;6,125,373;-0,069521312
51,557,403;1,323,448;6,126,339;-0,069531317
51,657,403;1,325,448;612,694;-0,069531317
51,757,403;1,327,448;6,127,505;-0,069511308
51,857,403;132,944;6,127,988;-0,069541321
51,957,403;1,331,444;612,874;-0,069511308
52,057,403;133,344;6,129,106;-0,069521312
52,157,403;1,335,428;6,129,797;-0,069551326
52,257,403;1,337,444;6,131,096;-0,069491299
52,357,403;133,944;6,131,381;-0,069521312
52,457,406;1,341,444;6,132,289;-0,069571335
52,557,406;1,343,452;6,133,173;-0,069571335
52,657,406;1,345,444;6,133,226;-0,069541321
52,757,406;1,347,448;6,134,124;-0,069531317
52,857,406;1,349,456;6,134,745;-0,069551326
52,957,406;135,146;613,546;-0,069521312
53,057,406;1,353,456;6,135,956;-0,069521312
53,157,406;1,355,436;61,363;-0,069541321
53,257,406;135,744;6,137,153;-0,069511308
53,357,406;1,359,428;6,137,797;-0,069491299
53,457,406;1,361,432;6,138,572;-0,069501303
53,557,406;1,363,448;6,139,354;-0,069501303
53,657,406;136,544;6,139,725;-0,069551326
53,757,406;1,367,448;6,140,378;-0,069571335
53,857,406;1,369,456;6,141,371;-0,069531317
53,957,406;1,371,448;6,141,394;-0,069531317
54,057,406;1,373,436;6,141,983;-0,069541321
54,157,406;1,375,452;6,143,277;-0,069551326
54,257,406;1,377,464;6,143,844;-0,069521312
54,357,406;1,379,448;6,143,687;-0,069501303
54,457,406;1,381,436;6,144,381;-0,069511308
54,557,406;1,383,448;6,145,228;-0,069531317
54,657,406;1,385,436;6,145,425;-0,069501303
54,757,406;1,387,432;6,146,084;-0,069511308
54,857,406;1,389,452;6,147,053;-0,069531317
54,957,406;1,391,444;6,147,389;-0,069601348
55,057,406;1,393,448;6,148,071;-0,069531317
55,157,406;1,395,452;6,148,776;-0,069531317
55,257,406;1,397,448;6,149,008;-0,069501303
55,357,406;139,944;6,149,423;-0,069551326
55,457,406;1,401,444;6,150,249;-0,06956133
55,557,406;1,403,452;6,150,613;-0,069491299
55,657,406;1,405,452;6,151,252;-0,069511308
55,757,406;1,407,452;6,151,609;-0,069531317
55,857,406;1,409,452;6,152,247;-0,069531317
55,957,406;1,411,432;6,152,425;-0,069511308
56,057,406;1,413,428;6,153,154;-0,06947129
56,157,406;1,415,452;6,154,192;-0,069511308
56,257,406;1,417,436;6,153,849;-0,069491299
56,357,406;1,419,444;6,154,721;-0,069531317
56,457,406;1,421,452;6,155,379;-0,069481294
56,557,406;142,344;6,155,614;-0,069501303
56,657,406;1,425,436;6,156,435;-0,069531317
56,757,406;1,427,436;6,157,024;-0,069541321
56,857,406;1,429,452;6,157,683;-0,069531317
56,957,406;1,431,448;6,157,891;-0,069551326
57,057,406;1,433,452;6,158,319;-0,06947129
57,157,406;143,546;6,158,853;-0,069481294
57,257,406;1,437,448;6,159,034;-0,069531317
57,357,406;1,439,436;6,159,306;-0,069541321
57,457,406;1,441,448;6,160,542;-0,069551326
57,557,406;144,344;6,160,802;-0,069481294
57,657,406;1,445,448;6,161,282;-0,069521312
57,757,406;1,447,452;6,161,782;-0,069521312
57,857,406;144,944;6,161,776;-0,069501303
57,957,406;145,144;6,162,562;-0,069521312
58,057,406;145,344;6,162,909;-0,069541321
58,157,406;1,455,444;6,163,443;-0,069491299
58,257,406;1,457,436;6,163,765;-0,069521312
58,357,406;1,459,428;616,412;-0,069551326
58,457,406;1,461,436;6,165,095;-0,069511308
58,557,406;1,463,424;6,165,309;-0,069551326
58,657,406;1,465,416;6,165,416;-0,069501303
58,757,406;1,467,424;6,166,256;-0,069551326
58,857,406;1,469,428;6,166,571;-0,069501303
58,957,406;147,144;6,167,223;-0,069511308
59,057,406;1,473,436;6,167,548;-0,069551326
59,157,406;1,475,428;6,167,657;-0,069531317
59,257,406;1,477,424;6,168,367;-0,069501303
59,357,406;1,479,432;6,168,997;-0,069531317
59,457,406;1,481,448;6,169,483;-0,069511308
59,557,406;1,483,444;6,169,605;-0,069501303
59,657,406;1,485,436;616,959;-0,069511308
59,757,406;1,487,432;6,170,331;-0,069501303
59,857,406;148,942;6,170,522;-0,069511308
59,957,406;1,491,416;6,171,309;-0,069511308
60,057,406;1,493,432;6,171,993;-0,069551326
60,157,406;1,495,428;6,171,961;-0,069541321
60,257,406;1,497,432;6,172,487;-0,069521312
60,357,406;1,499,436;6,172,896;-0,069521312
60,457,406;1,501,432;6,172,906;-0,069541321
60,557,406;1,503,428;6,173,276;-0,069491299
60,657,406;1,505,424;6,174,023;-0,069531317
60,757,406;1,507,452;617,467;-0,069541321
60,857,406;1,509,444;6,174,468;-0,069541321
60,957,406;151,142;6,174,529;-0,069531317
61,057,406;1,513,424;617,538;-0,069521312
61,157,406;151,542;6,175,649;-0,069551326
61,257,406;151,742;6,175,763;-0,06956133
61,357,406;1,519,436;6,176,675;-0,069481294
61,457,406;1,521,436;6,176,543;-0,06956133
61,557,406;152,344;6,177,104;-0,069501303
61,657,406;152,544;6,177,654;-0,069541321
61,757,406;1,527,432;6,177,589;-0,069521312
61,857,406;1,529,428;6,178,013;-0,069551326
61,957,406;1,531,424;6,178,285;-0,069551326
62,057,406;1,533,444;617,881;-0,069491299
62,157,406;153,544;6,178,895;-0,069531317
62,257,406;1,537,444;6,179,165;-0,069541321
62,357,406;1,539,452;6,179,619;-0,069531317
62,457,406;1,541,424;6,179,239;-0,069531317
62,557,406;1,543,424;6,180,081;-0,069511308
62,657,406;1,545,436;6,181,008;-0,069501303
62,757,406;1,547,424;6,180,509;-0,069531317
62,857,406;1,549,424;6,181,011;-0,069501303
62,957,406;1,551,432;6,181,451;-0,069511308
63,057,406;1,553,428;6,181,514;-0,06956133
63,157,406;155,542;6,181,954;-0,069531317
63,257,406;155,742;6,182,089;-0,069511308
63,357,406;1,559,436;6,182,889;-0,069501303
63,457,406;1,561,432;6,183,081;-0,069531317
63,557,406;1,563,428;618,332;-0,069491299
63,657,406;1,565,448;6,183,867;-0,069521312
63,757,406;156,744;6,183,561;-0,069531317
63,857,406;1,569,428;6,183,938;-0,06956133
63,957,406;157,144;6,184,537;-0,069521312
64,057,406;1,573,436;6,184,486;-0,069531317
64,157,406;1,575,448;6,185,053;-0,069531317
64,257,406;1,577,444;6,185,484;-0,069531317
64,357,406;1,579,444;6,185,257;-0,069551326
64,457,406;158,144;6,185,592;-0,069521312
64,557,406;158,344;6,185,747;-0,069491299
64,657,406;1,585,448;6,186,246;-0,069511308
64,757,406;1,587,444;618,629;-0,069541321
64,857,406;158,944;6,186,436;-0,069571335
64,957,406;1,591,448;6,187,208;-0,069551326
65,057,406;1,593,428;6,186,724;-0,069521312
65,157,406;159,542;6,187,399;-0,06956133
65,257,406;1,597,436;6,187,972;-0,069511308
65,357,406;1,599,432;6,187,686;-0,069521312
65,457,406;160,144;6,188,257;-0,069491299
65,557,406;160,344;6,188,141;-0,069541321
65,657,406;1,605,432;6,188,226;-0,069521312
65,757,406;1,607,428;6,188,213;-0,069541321
65,857,406;1,609,428;6,189,166;-0,069531317
65,957,406;1,611,448;6,189,425;-0,069511308
66,057,406;1,613,444;6,189,155;-0,069541321
66,157,406;161,544;6,189,269;-0,069531317
66,257,406;161,744;61,896;-0,069501303
66,357,406;1,619,428;6,189,649;-0,069551326
66,457,406;1,621,428;6,189,957;-0,069531317
66,557,406;162,344;6,190,702;-0,069521312
66,657,406;1,625,436;619,013;-0,069541321
66,757,406;162,744;6,190,826;-0,069521312
66,857,406;1,629,436;6,190,991;-0,069541321
66,957,406;1,631,436;6,190,764;-0,069521312
67,057,406;1,633,432;6,190,975;-0,069491299
67,157,406;1,635,428;6,191,158;-0,069521312
67,257,406;1,637,452;6,192,034;-0,069511308
67,357,406;1,639,452;6,191,673;-0,06956133
67,457,406;1,641,432;6,191,365;-0,069521312
67,557,406;1,643,436;6,192,326;-0,069541321
67,657,406;1,645,424;6,192,232;-0,069481294
67,757,406;1,647,424;6,192,434;-0,069531317
67,857,406;1,649,432;6,192,732;-0,069551326
67,957,406;1,651,436;6,192,691;-0,069551326
68,057,406;1,653,436;6,192,749;-0,069501303
68,157,406;1,655,428;6,192,901;-0,069511308
68,257,406;1,657,424;6,192,783;-0,069531317
68,357,406;1,659,424;6,193,485;-0,069511308
68,457,406;166,142;6,193,573;-0,069541321
68,557,406;1,663,436;6,194,061;-0,069531317
68,657,406;1,665,436;6,193,878;-0,069501303
68,757,406;166,744;6,194,085;-0,069521312
68,857,406;1,669,452;619,445;-0,069521312
68,957,406;1,671,436;6,193,823;-0,069501303
69,057,406;1,673,428;6,194,256;-0,069491299
69,157,406;167,544;6,194,795;-0,069521312
69,257,406;1,677,432;61,945;-0,069531317
69,357,406;1,679,432;6,194,996;-0,069501303
69,457,406;1,681,424;6,194,925;-0,069501303
69,557,406;1,683,428;6,194,961;-0,06947129
69,657,406;168,542;6,194,989;-0,069521312
69,757,406;1,687,416;6,195,343;-0,069491299
69,857,406;1,689,428;6,195,809;-0,069511308
69,957,406;169,142;619,579;-0,06956133
70,057,406;1,693,416;6,195,815;-0,069501303
70,157,406;1,695,432;6,196,424;-0,069511308
70,257,406;1,697,424;619,612;-0,069551326
70,357,406;1,699,416;6,195,973;-0,069521312
70,457,406;1,701,424;6,196,498;-0,069491299
70,557,406;170,342;6,196,156;-0,069501303
70,657,406;1,705,428;6,196,573;-0,069501303
70,757,406;1,707,428;6,196,412;-0,069521312
70,857,406;1,709,416;6,196,442;-0,069501303
70,957,406;1,711,424;6,196,786;-0,069511308
71,057,406;1,713,424;6,196,692;-0,069521312
71,157,406;1,715,444;6,197,127;-0,069511308
71,257,406;1,717,428;6,196,472;-0,06947129
71,357,406;1,719,428;619,673;-0,069521312
71,457,406;1,721,436;6,196,995;-0,069501303
71,557,406;1,723,424;6,196,798;-0,069491299
71,657,406;172,542;6,197,029;-0,069521312
71,757,406;1,727,424;6,197,455;-0,069511308
71,857,406;1,729,424;6,197,114;-0,069511308
71,957,406;1,731,428;6,197,318;-0,069521312
72,057,406;1,733,428;6,197,173;-0,069501303
72,157,406;1,735,432;6,197,102;-0,069511308
72,257,406;173,742;6,197,217;-0,069491299
72,357,406;173,942;6,197,239;-0,069531317
72,457,406;1,741,444;6,197,807;-0,069511308
72,557,406;1,743,444;6,197,532;-0,069491299
72,657,406;174,544;619,721;-0,069531317
72,757,406;1,747,444;6,197,699;-0,069511308
72,857,406;1,749,424;6,197,333;-0,069501303
72,957,406;1,751,424;6,197,608;-0,069481294
73,057,406;1,753,428;6,197,875;-0,069491299
73,157,406;1,755,428;619,777;-0,069541321
73,257,406;1,757,428;6,197,883;-0,069521312
73,357,406;1,759,424;6,197,934;-0,069531317
73,457,406;1,761,432;6,197,932;-0,069521312
73,557,406;1,763,424;6,197,585;-0,069501303
73,657,406;176,542;6,197,491;-0,069541321
73,757,406;1,767,444;6,198,334;-0,069491299
73,857,406;1,769,448;619,792;-0,069511308
73,957,406;1,771,444;6,197,456;-0,069521312
74,057,406;1,773,436;6,197,774;-0,069491299
74,157,406;1,775,428;6,197,671;-0,069521312
74,257,406;1,777,428;6,197,841;-0,069521312
74,357,406;177,944;6,198,182;-0,069501303
74,457,406;1,781,444;6,197,903;-0,069511308
74,557,406;1,783,452;6,197,934;-0,069491299
74,657,406;1,785,444;6,197,577;-0,069571335
74,757,406;1,787,444;6,197,637;-0,069521312
74,857,406;1,789,436;6,197,444;-0,069521312
74,957,406;1,791,428;6,197,512;-0,069531317
75,057,406;1,793,444;619,804;-0,069531317
75,157,406;1,795,436;6,197,574;-0,069521312
75,257,406;1,797,448;6,197,724;-0,069571335
75,357,406;179,946;6,198,007;-0,069501303
75,457,406;1,801,452;6,197,616;-0,069541321
75,557,406;180,344;6,197,313;-0,069531317
75,657,406;1,805,448;6,197,876;-0,069541321
75,757,406;1,807,456;6,197,533;-0,069521312
75,857,406;1,809,448;6,197,474;-0,069531317
75,957,406;181,144;6,197,338;-0,06956133
76,057,406;1,813,448;6,197,234;-0,069551326
76,157,406;1,815,444;6,197,217;-0,069551326
76,257,406;1,817,436;6,197,158;-0,069531317
76,357,406;1,819,456;6,197,475;-0,06956133
76,457,406;1,821,448;6,196,882;-0,069521312
76,557,406;1,823,444;6,196,766;-0,069541321
76,657,406;1,825,452;6,197,401;-0,069501303
76,757,406;1,827,436;6,196,927;-0,069521312
76,857,406;1,829,436;6,196,829;-0,069521312
76,957,406;1,831,436;6,196,952;-0,069521312
77,057,406;183,344;6,196,935;-0,069541321
77,157,406;1,835,436;6,196,949;-0,069511308
77,257,406;1,837,428;6,196,837;-0,069541321
77,357,406;1,839,436;6,196,674;-0,069531317
77,457,406;1,841,424;6,196,517;-0,069531317
77,557,406;1,843,428;6,196,805;-0,069541321
77,657,406;1,845,444;6,196,785;-0,069571335
77,757,406;1,847,436;6,196,221;-0,069531317
77,857,406;1,849,428;6,195,912;-0,069531317
77,957,406;185,144;6,196,424;-0,069551326
78,057,406;1,853,432;6,196,033;-0,069521312
78,157,406;1,855,428;6,195,927;-0,069531317
78,257,406;1,857,424;6,195,878;-0,069551326
78,357,406;1,859,428;6,195,965;-0,06956133
78,457,406;1,861,428;6,195,748;-0,069581339
78,557,406;1,863,428;6,195,408;-0,069551326
78,657,406;186,544;6,195,356;-0,069551326
78,757,406;1,867,428;6,194,991;-0,069541321
78,857,406;1,869,424;619,507;-0,069601348
78,957,406;1,871,448;6,195,455;-0,06956133
79,057,406;1,873,444;619,503;-0,069551326
79,157,406;1,875,448;6,194,811;-0,069531317
79,257,406;1,877,444;6,194,677;-0,069531317
79,357,406;1,879,428;6,194,016;-0,069541321
79,457,406;1,881,424;6,194,112;-0,069571335
79,557,406;1,883,428;6,194,292;-0,069501303
79,657,406;1,885,436;6,194,108;-0,06956133
79,757,406;1,887,432;6,193,947;-0,069521312
79,857,406;1,889,428;6,193,627;-0,069541321
79,957,406;1,891,432;619,402;-0,069531317
80,057,406;189,342;6,193,597;-0,069521312
80,157,406;1,895,408;6,193,365;-0,069511308
80,257,406;1,897,428;6,193,515;-0,069541321
80,357,406;1,899,436;619,326;-0,069511308
80,457,406;1,901,444;6,193,216;-0,069521312
80,557,406;1,903,428;6,192,682;-0,069501303
80,657,406;190,542;6,192,528;-0,06956133
80,757,406;1,907,424;6,192,725;-0,069531317
80,857,406;1,909,416;6,192,576;-0,069531317
80,957,406;1,911,436;6,192,657;-0,069531317
81,057,406;1,913,436;6,192,092;-0,069501303
81,157,406;1,915,436;6,191,626;-0,069551326
81,257,406;1,917,444;6,191,642;-0,069501303
81,357,406;1,919,432;6,191,171;-0,069521312
81,457,406;1,921,432;6,191,028;-0,069571335
81,557,406;192,344;6,191,417;-0,06956133
81,657,406;1,925,436;619,084;-0,069521312
81,757,406;192,744;6,190,691;-0,069541321
81,857,406;1,929,452;6,190,856;-0,069501303
81,957,406;1,931,448;6,189,947;-0,069521312
82,057,406;1,933,436;6,189,477;-0,06956133
82,157,406;1,935,432;6,189,539;-0,069501303
82,257,406;1,937,448;6,189,554;-0,069521312
82,357,406;1,939,436;6,189,006;-0,069541321
82,457,406;1,941,428;6,188,976;-0,06956133
82,557,406;1,943,436;6,189,159;-0,069541321
82,657,406;1,945,424;6,188,354;-0,069501303
82,757,406;1,947,424;6,188,129;-0,069541321
82,857,406;194,944;6,188,449;-0,069571335
82,957,406;1,951,428;6,187,596;-0,069521312
83,057,406;195,344;6,187,723;-0,069541321
83,157,406;1,955,436;6,187,606;-0,069521312
83,257,406;195,744;6,187,275;-0,069541321
83,357,406;1,959,428;6,187,044;-0,069541321
83,457,406;1,961,424;6,186,754;-0,06956133
83,557,406;1,963,432;6,186,578;-0,069541321
83,657,406;1,965,436;6,186,249;-0,069571335
83,757,406;196,744;6,185,788;-0,069511308
83,857,406;1,969,452;6,185,839;-0,069531317
83,957,406;197,144;6,185,034;-0,069541321
84,057,406;1,973,436;6,184,853;-0,069541321
84,157,406;197,546;6,185,133;-0,069541321
84,257,406;1,977,452;6,184,273;-0,06956133
84,357,406;1,979,452;6,184,261;-0,069501303
84,457,406;1,981,456;6,183,994;-0,069511308
84,557,406;1,983,448;618,323;-0,069531317
84,657,406;198,544;6,182,936;-0,069581339
84,757,406;1,987,436;6,182,802;-0,069531317
84,857,406;1,989,448;6,182,806;-0,06956133
84,957,406;199,144;6,182,621;-0,069531317
85,057,406;1,993,436;6,182,212;-0,069531317
85,157,406;1,995,444;6,181,988;-0,069541321
85,257,406;1,997,428;6,181,229;-0,069581339
85,357,406;199,942;6,181,064;-0,069531317
85,457,406;2,001,448;6,181,471;-0,06956133
85,557,406;2,003,444;6,180,492;-0,069551326
85,657,406;2,005,452;6,180,389;-0,06956133
85,757,406;2,007,452;6,180,047;-0,069541321
85,857,406;2,009,428;6,179,352;-0,06956133
85,957,406;2,011,424;6,179,304;-0,06956133
86,057,406;2,013,424;6,178,945;-0,069541321
86,157,406;2,015,448;6,178,825;-0,069521312
86,257,406;2,017,444;6,177,946;-0,06956133
86,357,406;2,019,436;6,177,422;-0,069571335
86,457,406;2,021,448;61,775;-0,069571335
86,557,406;2,023,432;6,176,729;-0,069521312
86,657,406;2,025,428;6,176,574;-0,069581339
86,757,406;2,027,436;6,176,616;-0,069571335
86,857,406;2,029,444;6,176,075;-0,06956133
86,957,406;2,031,456;6,175,631;-0,069531317
87,057,406;2,033,436;6,174,702;-0,069511308
87,157,406;2,035,428;617,421;-0,069541321
87,257,406;2,037,428;6,174,232;-0,069541321
87,357,406;2,039,424;61,737;-0,069541321
87,457,406;2,041,444;6,173,816;-0,069521312
87,557,406;2,043,444;6,173,213;-0,06956133
87,657,406;204,544;6,172,411;-0,06956133
87,757,406;2,047,456;6,172,361;-0,069531317
87,857,406;2,049,444;6,171,323;-0,069551326
87,957,406;2,051,444;6,171,131;-0,069581339
88,057,406;2,053,456;6,170,963;-0,069551326
88,157,406;2,055,448;6,170,101;-0,069541321
88,257,406;2,057,456;6,169,785;-0,069581339
88,357,406;2,059,456;6,169,547;-0,069551326
88,457,406;206,146;616,878;-0,069541321
88,557,406;2,063,452;6,168,309;-0,069531317
88,657,406;2,065,444;6,167,701;-0,069511308
88,757,406;206,746;6,167,495;-0,069541321
88,857,406;2,069,452;6,166,695;-0,069521312
88,957,406;207,144;6,165,918;-0,06956133
89,057,406;2,073,452;6,166,009;-0,069541321
89,157,406;207,544;6,165,091;-0,069571335
89,257,406;2,077,432;616,432;-0,069551326
89,357,406;2,079,448;6,164,507;-0,069541321
89,457,406;208,144;6,163,496;-0,069571335
89,557,406;2,083,444;6,163,027;-0,069551326
89,657,406;208,544;6,162,485;-0,06956133
89,757,406;2,087,444;6,161,919;-0,069551326
89,857,406;2,089,444;6,161,336;-0,069581339
89,957,406;2,091,428;6,160,786;-0,069541321
90,057,406;209,344;6,160,393;-0,069571335
90,157,406;2,095,428;6,159,603;-0,069551326
90,257,406;2,097,432;6,159,061;-0,069531317
90,357,406;2,099,452;6,158,834;-0,06956133
90,457,406;2,101,436;6,157,601;-0,069541321
90,557,406;2,103,436;6,156,958;-0,06956133
90,657,406;2,105,448;6,156,875;-0,069541321
90,757,406;2,107,448;6,155,493;-0,06956133
90,857,406;210,944;6,155,176;-0,069571335
90,957,406;2,111,436;615,423;-0,069521312
91,057,406;2,113,432;6,153,482;-0,069571335
91,157,406;2,115,428;6,152,858;-0,069531317
91,257,406;211,742;6,152,069;-0,069591344
91,357,406;2,119,436;6,151,654;-0,069531317
91,457,406;2,121,428;6,150,606;-0,06956133
91,557,406;2,123,424;6,150,023;-0,069511308
91,657,406;212,544;614,964;-0,06956133
91,757,406;212,742;6,148,457;-0,06956133
91,857,406;212,942;6,147,755;-0,069551326
91,957,406;2,131,432;6,147,314;-0,069551326
92,057,406;2,133,444;6,146,137;-0,06956133
92,157,406;2,135,444;6,145,285;-0,069551326
92,257,406;2,137,436;6,144,129;-0,06956133
92,357,406;2,139,432;6,142,915;-0,06956133
92,457,406;214,142;6,142,329;-0,069591344
92,557,406;214,342;6,141,665;-0,069551326
92,657,406;2,145,444;6,140,946;-0,069571335
92,757,406;214,744;6,139,677;-0,069571335
92,857,406;214,944;6,138,695;-0,069591344
92,957,406;2,151,452;613,808;-0,069581339
93,057,406;2,153,444;6,136,701;-0,069581339
93,157,406;215,544;613,588;-0,069571335
93,257,406;2,157,448;6,135,076;-0,06956133
93,357,406;2,159,452;6,134,061;-0,069581339
93,457,406;2,161,464;6,133,029;-0,069551326
93,557,406;2,163,456;6,131,783;-0,069571335
93,657,406;216,544;6,130,375;-0,069521312
93,757,406;2,167,436;6,129,571;-0,069551326
93,857,406;2,169,436;6,128,668;-0,069551326
93,957,406;2,171,456;6,127,761;-0,069551326
94,057,406;2,173,444;612,623;-0,06956133
94,157,406;2,175,448;6,125,117;-0,069541321
94,257,406;2,177,448;6,124,326;-0,069581339
94,357,406;217,944;6,122,476;-0,069571335
94,457,406;2,181,432;6,121,619;-0,069581339
94,557,406;2,183,448;6,120,704;-0,069551326
94,657,406;2,185,444;6,118,979;-0,06956133
94,757,406;2,187,448;6,117,955;-0,06956133
94,857,406;2,189,444;6,116,499;-0,069551326
94,957,406;2,191,452;6,115,373;-0,069541321
95,057,406;219,344;6,113,789;-0,069571335
95,157,406;2,195,424;6,112,567;-0,06956133
95,257,406;2,197,452;6,111,578;-0,069551326
95,357,406;2,199,452;6,109,849;-0,069571335
95,457,406;220,144;6,107,973;-0,06956133
95,557,406;2,203,448;610,697;-0,069531317
95,657,406;220,544;6,105,247;-0,06956133
95,757,406;220,744;6,103,881;-0,06956133
95,857,406;2,209,444;6,102,846;-0,069531317
95,957,406;2,211,452;6,100,863;-0,069591344
96,057,406;2,213,452;6,098,968;-0,069611353
96,157,406;2,215,444;6,097,115;-0,069531317
96,257,406;2,217,452;6,095,586;-0,069591344
96,357,406;2,219,448;6,093,793;-0,069611353
96,457,406;2,221,444;6,092,002;-0,069601348
96,557,406;2,223,456;6,090,681;-0,069581339
96,657,406;222,544;6,088,716;-0,069571335
96,757,406;2,227,444;6,087,142;-0,069551326
96,857,406;222,946;6,085,741;-0,069621357
96,957,406;2,231,448;6,083,308;-0,069591344
97,057,406;2,233,452;6,081,506;-0,069611353
97,157,406;223,546;6,079,814;-0,06956133
97,257,406;2,237,464;6,077,815;-0,069581339
97,357,406;2,239,456;6,075,596;-0,069611353
97,457,406;224,144;6,073,663;-0,069581339
97,557,406;2,243,448;6,071,851;-0,069601348
97,657,406;2,245,436;6,069,451;-0,069571335
97,757,406;2,247,432;6,067,221;-0,069591344
97,857,406;2,249,452;6,065,543;-0,069631362
97,957,406;2,251,448;6,062,992;-0,069601348
98,057,406;2,253,444;606,074;-0,069581339
98,157,406;2,255,456;6,059,105;-0,069591344
98,257,406;2,257,444;6,056,548;-0,069571335
98,357,406;2,259,436;6,054,537;-0,069581339
98,457,406;2,261,444;6,052,389;-0,069591344
98,557,406;2,263,456;6,049,887;-0,069601348
98,657,406;2,265,464;6,047,505;-0,069571335
98,757,406;2,267,452;6,044,686;-0,06956133
98,857,406;2,269,456;6,042,508;-0,069601348
98,957,406;2,271,432;6,039,536;-0,069581339
99,057,406;2,273,428;6,037,617;-0,069591344
99,157,406;2,275,448;6,035,748;-0,069611353
99,257,406;227,744;6,032,581;-0,069581339
99,357,406;2,279,444;6,029,767;-0,069571335
99,457,406;2,281,452;6,027,582;-0,069571335
99,557,406;2,283,448;6,024,638;-0,069591344
99,657,406;228,544;6,022,087;-0,069551326
99,757,406;2,287,444;6,019,774;-0,069581339
99,857,406;2,289,452;6,016,959;-0,069601348
99,957,406;229,146;6,014,516;-0,069581339
100,057,406;2,293,456;6,011,022;-0,069571335
100,157,406;2,295,444;6,007,895;-0,069581339
100,257,406;2,297,432;6,005,066;-0,069551326
100,357,406;2,299,428;6,002,314;-0,069601348
100,457,406;2,301,452;5,999,854;-0,069591344
100,557,406;2,303,448;5,996,243;-0,069571335
100,657,406;2,305,452;5,993,479;-0,069551326
100,757,406;230,746;5,990,642;-0,069581339
100,857,406;2,309,448;5,987,104;-0,069581339
100,957,406;231,144;5,983,986;-0,069621357
101,057,406;2,313,444;5,980,868;-0,069591344
101,157,406;231,546;5,977,486;-0,069581339
101,257,406;2,317,456;5,974,095;-0,069571335
101,357,406;2,319,452;5,970,643;-0,069631362
101,457,406;232,146;5,967,638;-0,069591344
101,557,406;2,323,448;5,964,101;-0,069581339
101,657,406;232,544;5,960,709;-0,069591344
101,757,406;2,327,456;5,958,092;-0,069581339
101,857,406;2,329,456;5,953,847;-0,069571335
101,957,406;2,331,452;5,949,898;-0,069591344
102,057,406;2,333,452;5,946,673;-0,06956133
102,157,406;2,335,444;5,942,935;-0,069581339
102,257,406;2,337,444;5,939,763;-0,069611353
102,357,406;2,339,444;5,936,279;-0,069601348
102,457,413;2,341,456;5,932,747;-0,069581339
102,557,413;2,343,452;5,928,801;-0,069591344
102,657,413;234,544;5,924,444;-0,069581339
102,757,413;2,347,452;5,921,175;-0,069581339
102,857,413;2,349,444;5,917,084;-0,06956133
102,957,413;235,144;5,913,169;-0,06956133
103,057,413;2,353,456;5,909,662;-0,069591344
103,157,413;2,355,444;5,905,296;-0,069601348
103,257,413;2,357,448;5,901,546;-0,069591344
103,357,413;2,359,452;5,897,899;-0,069591344
103,457,413;2,361,448;5,893,238;-0,069621357
103,557,413;2,363,448;5,889,094;-0,069581339
103,657,413;2,365,452;5,885,136;-0,069591344
103,757,413;2,367,464;5,880,993;-0,069571335
103,857,413;2,369,452;587,667;-0,069581339
103,957,413;2,371,452;5,872,242;-0,069591344
104,057,413;237,346;5,868,378;-0,069601348
104,157,413;2,375,444;586,354;-0,069621357
104,257,413;237,744;5,859,293;-0,069611353
104,357,413;237,946;58,551;-0,069641366
104,457,413;2,381,448;5,850,131;-0,069621357
104,557,413;2,383,452;5,845,798;-0,069581339
104,657,413;238,546;5,841,482;-0,069581339
104,757,413;2,387,456;5,836,644;-0,069601348
104,857,413;2,389,456;583,216;-0,069601348
104,957,413;2,391,452;582,762;-0,069571335
105,057,413;2,393,476;5,822,992;-0,069611353
105,157,413;239,548;5,817,745;-0,069571335
105,257,413;2,397,484;5,812,589;-0,069581339
105,357,413;2,399,492;5,807,917;-0,069571335
105,457,413;2,401,476;580,269;-0,069571335
105,557,413;2,403,464;5,797,721;-0,069551326
105,657,413;2,405,484;5,793,642;-0,069581339
105,757,413;240,748;5,787,926;-0,069601348
105,857,413;240,948;5,782,911;-0,069571335
105,957,413;2,411,484;5,777,877;-0,069551326
106,057,413;241,348;577,221;-0,069571335
106,157,413;2,415,484;5,767,232;-0,069541321
106,257,413;2,417,476;5,761,747;-0,06956133
106,357,413;2,419,488;5,756,587;-0,069531317
106,457,413;2,421,492;5,751,317;-0,069541321
106,557,413;2,423,492;5,745,536;-0,069551326
106,657,413;2,425,492;5,739,963;-0,06956133
106,757,413;2,427,464;5,734,284;-0,069571335
106,857,413;2,429,464;5,728,759;-0,06956133
106,957,413;2,431,484;5,723,293;-0,06956133
107,057,413;2,433,484;5,717,303;-0,06956133
107,157,413;243,548;571,147;-0,069541321
107,257,413;243,748;5,705,912;-0,069571335
107,357,413;243,948;5,699,611;-0,06956133
107,457,413;2,441,476;5,694,219;-0,069531317
107,557,413;2,443,476;5,688,232;-0,06956133
107,657,413;2,445,484;568,204;-0,06956133
107,757,413;2,447,484;5,675,675;-0,069551326
107,857,413;244,948;5,669,163;-0,069521312
107,957,413;2,451,492;5,663,168;-0,069521312
108,057,413;2,453,488;5,656,502;-0,069521312
108,157,413;2,455,484;5,650,396;-0,069551326
108,257,413;2,457,488;5,644,138;-0,069541321
108,357,413;2,459,484;5,637,279;-0,069531317
108,457,413;2,461,492;5,630,817;-0,069551326
108,557,413;2,463,484;5,623,894;-0,069541321
108,657,413;2,465,488;5,617,036;-0,069531317
108,757,413;2,467,484;5,610,429;-0,069501303
108,857,413;2,469,484;5,603,694;-0,069521312
108,957,413;2,471,504;5,596,828;-0,069541321
109,057,413;2,473,496;5,589,859;-0,069521312
109,157,413;2,475,492;5,582,421;-0,069461285
109,257,413;24,775;5,575,418;-0,069511308
109,357,413;2,479,496;5,567,772;-0,069501303
109,457,413;2,481,488;5,560,388;-0,069491299
109,557,413;2,483,504;5,553,462;-0,069551326
109,657,413;2,485,496;5,545,729;-0,069511308
109,757,413;2,487,496;5,538,582;-0,069491299
109,857,413;24,895;5,531,071;-0,069491299
109,957,413;2,491,504;5,523,299;-0,06947129
110,057,413;24,935;5,515,375;-0,069491299
110,157,413;2,495,496;5,507,602;-0,069501303
110,257,413;249,752;5,499,442;-0,069511308
110,357,413;2,499,516;5,491,128;-0,069481294
110,457,413;2,501,504;5,482,947;-0,069501303
110,557,413;2,503,512;5,475,038;-0,06947129
110,657,413;25,055;5,466,861;-0,069521312
110,757,413;2,507,496;545,846;-0,069511308
110,857,413;2,509,508;5,450,475;-0,069491299
110,957,413;2,511,504;5,441,179;-0,069491299
111,057,413;25,135;5,432,412;-0,069481294
111,157,413;25,155;5,423,787;-0,069491299
111,257,413;25,175;5,414,454;-0,069481294
111,357,413;25,195;5,405,914;-0,069491299
111,457,413;2,521,492;5,396,868;-0,069481294
111,557,413;2,523,508;5,387,897;-0,069511308
111,657,413;2,525,516;5,378,447;-0,069491299
111,757,413;2,527,516;5,368,753;-0,069451281
111,857,413;2,529,524;5,359,264;-0,069451281
111,957,413;2,531,512;5,349,015;-0,06947129
112,057,413;2,533,504;5,339,497;-0,069461285
112,157,413;253,552;5,329,928;-0,069511308
112,257,413;2,537,524;5,319,768;-0,069451281
112,357,413;2,539,528;530,958;-0,069451281
112,457,413;2,541,524;5,299,295;-0,069481294
112,557,413;2,543,528;5,288,604;-0,069461285
112,657,413;2,545,528;527,828;-0,069491299
112,757,413;2,547,524;5,267,391;-0,06947129
112,857,413;2,549,536;5,256,584;-0,069501303
112,957,413;2,551,536;5,245,538;-0,069441276
113,057,413;2,553,544;5,234,575;-0,069501303
113,157,413;2,555,552;5,223,503;-0,069441276
113,257,413;2,557,524;5,211,453;-0,069461285
113,357,413;2,559,524;5,200,194;-0,069451281
113,457,413;256,154;5,188,649;-0,069441276
113,557,413;2,563,536;5,175,933;-0,06947129
113,657,413;2,565,544;5,163,404;-0,069481294
113,757,413;2,567,544;515,022;-0,069451281
113,857,413;2,569,548;5,136,148;-0,069491299
113,957,413;2,571,544;5,120,828;-0,069451281
114,057,413;257,354;5,100,414;-0,069461285
114,157,413;257,556;5,049,978;-0,069461285
1,142,228;2,576,868;4,949,037;-0,069441276
1,142,344;2,577,112;4,819,482;-0,069451281
1,142,364;2,577,332;2,780,709;-0,073353038